Workbook

Sheet 2
A1: 武汉康恩农贸发展有限公司送货单
A3: 收货单位： | B3: 汉南数智化检测分公司
A4: 配送日期： | B4: 45201
A5: 序号 | B5: 名称 | C5: 规格 | D5: 单位 | E5: 数量 | F5: 超市价格 | G5: 折扣率 | H5: 折后价 | I5: 折后金额 | J5: 备注
A6: 1 | B6: （新鲜）河粉 | D6: 斤 | E6: 6 | F6: =H6/0.85 -> 3.5294118 | G6: =H6/F6 -> 0.85 | H6: 3 | I6: =E6*H6 -> 18
A7: 2 | B7: 热干面（熟） | D7: 斤 | E7: 5 | F7: =H7/0.85 -> 4.1176471 | G7: =H7/F7 -> 0.85 | H7: 3.5 | I7: =E7*H7 -> 17.5
A8: 3 | B8: 大红薯 | D8: 斤 | E8: 7 | F8: =H8/0.85 -> 4.1176471 | G8: =H8/F8 -> 0.85 | H8: 3.5 | I8: =E8*H8 -> 24.5
A9: 4 | B9: 西红柿 | D9: 斤 | E9: 3 | F9: =H9/0.85 -> 4.4705882 | G9: =H9/F9 -> 0.85 | H9: 3.8 | I9: =E9*H9 -> 11.4
A10: 5 | B10: 大白菜 | D10: 斤 | E10: 8 | F10: =H10/0.85 -> 2.1176471 | G10: =H10/F10 -> 0.85 | H10: 1.8 | I10: =E10*H10 -> 14.4
A11: 6 | B11: 【鲜】猪瘦肉丝 | D11: 斤 | E11: 4 | F11: =H11/0.85 -> 25.882353 | G11: =H11/F11 -> 0.85 | H11: 22 | I11: =E11*H11 -> 88
A12: 7 | B12: 芝麻酱 | C12: 散称 | D12: 斤 | E12: 3 | F12: =H12/0.85 -> 14.117647 | G12: =H12/F12 -> 0.85 | H12: 12 | I12: =E12*H12 -> 36
A13: 8
A14: 9
A15: 10
A16: 12
A17: 13
A18: 14
A19: 15
A20: 16
A21: 17
A22: 18
A23: 19
A24: 20
... A32: 28
A33: 供货合计: | B33: =SUM(I6:I32) -> 209.8
A34: 金额大写： | B34: =B33 -> 209.8
A35: 制表人 ：樊君丽 收货人： 送货人：

Sheet 3
A1: 武汉康恩农贸发展有限公司送货单
A3: 收货单位： | B3: 汉南数智化检测分公司
A4: 配送日期： | B4: 45202
A5: 序号 | B5: 名称 | C5: 规格 | D5: 单位 | E5: 数量 | F5: 超市价格 | G5: 折扣率 | H5: 折后价 | I5: 折后金额 | J5: 备注
A6: 1 | B6: （新鲜）河粉 | D6: 斤 | E6: 5 | F6: =H6/0.85 -> 3.5294118 | G6: =H6/F6 -> 0.85 | H6: 3 | I6: =E6*H6 -> 15
A7: 2 | B7: 热干面（熟） | D7: 斤 | E7: 5 | F7: =H7/0.85 -> 4.1176471 | G7: =H7/F7 -> 0.85 | H7: 3.5 | I7: =E7*H7 -> 17.5
A8: 3 | B8: 大红薯 | D8: 斤 | E8: 10 | F8: =H8/0.85 -> 4.1176471 | G8: =H8/F8 -> 0.85 | H8: 3.5 | I8: =E8*H8 -> 35
A9: 4 | B9: 红椒 | D9: 斤 | E9: 2 | F9: =H9/0.85 -> 9.1764706 | G9: =H9/F9 -> 0.85 | H9: 7.8 | I9: =E9*H9 -> 15.6
A10: 5 | B10: 甜玉米棒 | D10: 个 | E10: 8 | F10: =H10/0.85 -> 3.5294118 | G10: =H10/F10 -> 0.85 | H10: 3 | I10: =E10*H10 -> 24
A11: 6 | B11: 芜湖青椒 | D11: 斤 | E11: 2 | F11: =H11/0.85 -> 6.4705882 | G11: =H11/F11 -> 0.85 | H11: 5.5 | I11: =E11*H11 -> 11
A12: 7 | B12: 西红柿 | D12: 斤 | E12: 3 | F12: =H12/0.85 -> 4.4705882 | G12: =H12/F12 -> 0.85 | H12: 3.8 | I12: =E12*H12 -> 11.4
A13: 8 | B13: 紫长茄子（细长） | D13: 斤 | E13: 6 | F13: =H13/0.85 -> 4.4705882 | G13: =H13/F13 -> 0.85 | H13: 3.8 | I13: =E13*H13 -> 22.8
A14: 9 | B14: 生菜 | D14: 斤 | E14: 7 | F14: =H14/0.85 -> 5.6470588 | G14: =H14/F14 -> 0.85 | H14: 4.8 | I14: =E14*H14 -> 33.6
A15: 10 | B15: 油麦菜 | D15: 斤 | E15: 7 | F15: =H15/0.85 -> 5.2941176 | G15: =H15/F15 -> 0.85 | H15: 4.5 | I15: =E15*H15 -> 31.5
A16: 12 | B16: 厚干子 | D16: 斤 | E16: 6 | F16: =H16/0.85 -> 8 | G16: =H16/F16 -> 0.85 | H16: 6.8 | I16: =E16*H16 -> 40.8
A17: 13 | B17: 嫩豆腐 | D17: 斤 | E17: 8 | F17: =H17/0.85 -> 4.1176471 | G17: =H17/F17 -> 0.85 | H17: 3.5 | I17: =E17*H17 -> 28
... A19: 15 | B19: 【鲜】五花肉沫 | D19: 斤 | E19: 5 | F19: =H19/0.85 -> 19.764706 | G19: =H19/F19 -> 0.85 | H19: 16.8 | I19: =E19*H19 -> 84
A20: 17 | B20: 光明益生菌酸奶（原味） | C20: 100g | D20: 杯 | E20: 20 | F20: =H20/0.85 -> 1.7647059 | G20: =H20/F20 -> 0.85 | H20: 1.5 | I20: =E20*H20 -> 30
A21: 18
A22: 19
A23: 20
A24: 21
A25: 22
A26: 23
A27: 24
A28: 25
A29: 26
A30: 27
A31: 28
A32: 供货合计: | B32: =SUM(I6:I31) -> 525
A33: 金额大写： | B33: =B32 -> 525
A34: 制表人 ：樊君丽 收货人： 送货人：

Sheet 5
A1: 武汉康恩农贸发展有限公司送货单
A3: 收货单位： | B3: 汉南数智化检测分公司
A4: 配送日期： | B4: 45204
A5: 序号 | B5: 名称 | C5: 规格 | D5: 单位 | E5: 数量 | F5: 超市价格 | G5: 折扣率 | H5: 折后价 | I5: 折后金额 | J5: 备注
A6: 1 | B6: （新鲜）河粉 | D6: 斤 | E6: 2 | F6: =H6/0.85 -> 3.5294118 | G6: =H6/F6 -> 0.85 | H6: 3 | I6: =E6*H6 -> 6
A7: 2 | B7: 干细粉 | C7: 散称 | D7: 斤 | E7: 6 | F7: =H7/0.85 -> 4.1176471 | G7: =H7/F7 -> 0.85 | H7: 3.5 | I7: =E7*H7 -> 21
A8: 3 | B8: 白萝卜 | D8: 斤 | E8: 3 | F8: =H8/0.85 -> 2.3529412 | G8: =H8/F8 -> 0.85 | H8: 2 | I8: =E8*H8 -> 6
A9: 4 | B9: 红椒 | D9: 斤 | E9: 2 | F9: =H9/0.85 -> 9.1764706 | G9: =H9/F9 -> 0.85 | H9: 7.8 | I9: =E9*H9 -> 15.6
A10: 5 | B10: 芜湖青椒 | D10: 斤 | E10: 6 | F10: =H10/0.85 -> 6.4705882 | G10: =H10/F10 -> 0.85 | H10: 5.5 | I10: =E10*H10 -> 33
A11: 6 | B11: 西红柿 | D11: 斤 | E11: 6 | F11: =H11/0.85 -> 4.4705882 | G11: =H11/F11 -> 0.85 | H11: 3.8 | I11: =E11*H11 -> 22.8
A12: 7 | B12: 金针菇 | D12: 斤 | E12: 4 | F12: =H12/0.85 -> 8 | G12: =H12/F12 -> 0.85 | H12: 6.8 | I12: =E12*H12 -> 27.2
A13: 8 | B13: 大白菜 | D13: 斤 | E13: 8 | F13: =H13/0.85 -> 2.1176471 | G13: =H13/F13 -> 0.85 | H13: 1.8 | I13: =E13*H13 -> 14.4
A14: 9 | B14: 【鲜】净三黄鸡 | D14: 斤 | E14: 6 | F14: =H14/0.85 -> 17.411765 | G14: =H14/F14 -> 0.85 | H14: 14.8 | I14: =E14*H14 -> 88.8
A15: 10 | B15: 【鲜】猪脊骨 | D15: 斤 | E15: 2 | F15: =H15/0.85 -> 17.411765 | G15: =H15/F15 -> 0.85 | H15: 14.8 | I15: =E15*H15 -> 29.6
A16: 12 | B16: 【鲜】猪瘦肉丝 | D16: 斤 | E16: 5 | F16: =H16/0.85 -> 25.882353 | G16: =H16/F16 -> 0.85 | H16: 22 | I16: =E16*H16 -> 110
A17: 13 | B17: 安琪酵母 | C17: 500g*20袋/件 | D17: 袋 | E17: 1 | F17: =H17/0.85 -> 29.411765 | G17: =H17/F17 -> 0.85 | H17: 25 | I17: =E17*H17 -> 25
A18: 14 | B18: 光明益生菌酸奶（红枣味） | C18: 100g | D18: 杯 | E18: 20 | F18: =H18/0.85 -> 1.8823529 | G18: =H18/F18 -> 0.85 | H18: 1.6 | I18: =E18*H18 -> 32
A19: 15
A20: 16
A21: 17
A22: 18
A23: 19
A24: 20
A25: 21
A26: 22
A27: 23
A28: 24
A29: 25
A30: 26
... A32: 28
A33: 供货合计: | B33: =SUM(I6:I32) -> 431.4
A34: 金额大写： | B34: =B33 -> 431.4
A35: 制表人 ：樊君丽 收货人： 送货人：

Sheet 6
A1: 武汉康恩农贸发展有限公司送货单
A3: 收货单位： | B3: 汉南数智化检测分公司
A4: 配送日期： | B4: 45205
A5: 序号 | B5: 名称 | C5: 规格 | D5: 单位 | E5: 数量 | F5: 超市价格 | G5: 折扣率 | H5: 折后价 | I5: 折后金额 | J5: 备注
A6: 1 | B6: 蒜米 | D6: 斤 | E6: 4 | F6: =H6/0.85 -> 9.1764706 | G6: =H6/F6 -> 0.85 | H6: 7.8 | I6: =E6*H6 -> 31.2
A7: 2 | B7: 大藕 | D7: 斤 | E7: 5.5 | F7: =H7/0.85 -> 5.2941176 | G7: =H7/F7 -> 0.85 | H7: 4.5 | I7: =E7*H7 -> 24.75
A8: 3 | B8: 大土豆 | D8: 斤 | E8: 5 | F8: =H8/0.85 -> 4.1176471 | G8: =H8/F8 -> 0.85 | H8: 3.5 | I8: =E8*H8 -> 17.5
A9: 4 | B9: 西红柿 | D9: 斤 | E9: 5 | F9: =H9/0.85 -> 4.4705882 | G9: =H9/F9 -> 0.85 | H9: 3.8 | I9: =E9*H9 -> 19
A10: 5 | B10: 紫长茄子（细长） | D10: 斤 | E10: 3 | F10: =H10/0.85 -> 4.4705882 | G10: =H10/F10 -> 0.85 | H10: 3.8 | I10: =E10*H10 -> 11.4
A11: 6 | B11: 平包菜 | D11: 斤 | E11: 5 | F11: =H11/0.85 -> 2.3529412 | G11: =H11/F11 -> 0.85 | H11: 2 | I11: =E11*H11 -> 10
A12: 7 | B12: 花生米 | C12: 散称 | D12: 斤 | E12: 6 | F12: =H12/0.85 -> 11.529412 | G12: =H12/F12 -> 0.85 | H12: 9.8 | I12: =E12*H12 -> 58.8
A13: 8 | B13: 烤鸭 | D13: 只 | E13: 3 | F13: =H13/0.85 -> 34.117647 | G13: =H13/F13 -> 0.85 | H13: 29 | I13: =E13*H13 -> 87
A14: 9 | B14: 1911老酸奶 | D14: 杯 | E14: 20 | F14: =H14/0.85 -> 4.1176471 | G14: =H14/F14 -> 0.85 | H14: 3.5 | I14: =E14*H14 -> 70
A15: 10
A16: 12
A17: 13
A18: 14
A19: 15
A20: 16
A21: 17
A22: 18
A23: 19
A24: 20
A25: 21
A26: 22
... A32: 28
A33: 供货合计: | B33: =SUM(I6:I32) -> 329.65
A34: 金额大写： | B34: =B33 -> 329.65
A35: 制表人 ：樊君丽 收货人： 送货人：

Sheet 7
A1: 武汉康恩农贸发展有限公司送货单
A3: 收货单位： | B3: 汉南数智化检测分公司
A4: 配送日期： | B4: 45206
A5: 序号 | B5: 名称 | C5: 规格 | D5: 单位 | E5: 数量 | F5: 超市价格 | G5: 折扣率 | H5: 折后价 | I5: 折后金额 | J5: 备注
A6: 1 | B6: （新鲜）河粉 | D6: 斤 | E6: 5 | F6: =H6/0.85 -> 3.5294118 | G6: =H6/F6 -> 0.85 | H6: 3 | I6: =E6*H6 -> 15
A7: 2 | B7: 干细粉 | C7: 散称 | D7: 斤 | E7: 6 | F7: =H7/0.85 -> 4.1176471 | G7: =H7/F7 -> 0.85 | H7: 3.5 | I7: =E7*H7 -> 21
A8: 3 | B8: 馄饨皮 | D8: 斤 | E8: 2 | F8: =H8/0.85 -> 4.1176471 | G8: =H8/F8 -> 0.85 | H8: 3.5 | I8: =E8*H8 -> 7
A9: 4 | B9: 饺子皮 | D9: 斤 | E9: 2 | F9: =H9/0.85 -> 4.1176471 | G9: =H9/F9 -> 0.85 | H9: 3.5 | I9: =E9*H9 -> 7
A10: 5 | B10: 热干面（熟） | D10: 斤 | E10: 5 | F10: =H10/0.85 -> 4.1176471 | G10: =H10/F10 -> 0.85 | H10: 3.5 | I10: =E10*H10 -> 17.5
A11: 6 | B11: 大葱 | D11: 斤 | E11: 2 | F11: =H11/0.85 -> 4.1176471 | G11: =H11/F11 -> 0.85 | H11: 3.5 | I11: =E11*H11 -> 7
A12: 7 | B12: 小葱 | D12: 斤 | E12: 1 | F12: =H12/0.85 -> 8 | G12: =H12/F12 -> 0.85 | H12: 6.8 | I12: =E12*H12 -> 6.8
A13: 8 | B13: 红椒 | D13: 斤 | E13: 3 | F13: =H13/0.85 -> 9.1764706 | G13: =H13/F13 -> 0.85 | H13: 7.8 | I13: =E13*H13 -> 23.4
A14: 9 | B14: 蒜苗 | D14: 斤 | E14: 6 | F14: =H14/0.85 -> 11.529412 | G14: =H14/F14 -> 0.85 | H14: 9.8 | I14: =E14*H14 -> 58.8
A15: 10 | B15: 西红柿 | D15: 斤 | E15: 8 | F15: =H15/0.85 -> 4.4705882 | G15: =H15/F15 -> 0.85 | H15: 3.8 | I15: =E15*H15 -> 30.4
A16: 11 | B16: 有机花菜 | D16: 斤 | E16: 10 | F16: =H16/0.85 -> 6.4705882 | G16: =H16/F16 -> 0.85 | H16: 5.5 | I16: =E16*H16 -> 55
A17: 12 | B17: 净莴苣 | D17: 斤 | E17: 18 | F17: =H17/0.85 -> 6.8235294 | G17: =H17/F17 -> 0.85 | H17: 5.8 | I17: =E17*H17 -> 104.4
A18: 13 | B18: 金针菇 | D18: 斤 | E18: 6 | F18: =H18/0.85 -> 8 | G18: =H18/F18 -> 0.85 | H18: 6.8 | I18: =E18*H18 -> 40.8
A19: 14 | B19: 油麦菜 | D19: 斤 | E19: 16 | F19: =H19/0.85 -> 5.2941176 | G19: =H19/F19 -> 0.85 | H19: 4.5 | I19: =E19*H19 -> 72
A20: 15 | B20: 红壳鸡蛋 | C20: 12板/件 | D20: 件 | E20: 1 | F20: =H20/0.85 -> 352.94118 | G20: =H20/F20 -> 0.85 | H20: 300 | I20: =E20*H20 -> 300
A21: 16 | B21: 【鲜】五花肉沫 | D21: 斤 | E21: 4 | F21: =H21/0.85 -> 19.764706 | G21: =H21/F21 -> 0.85 | H21: 16.8 | I21: =E21*H21 -> 67.2
A22: 17 | B22: 【鲜】猪瘦肉丝 | D22: 斤 | E22: 6 | F22: =H22/0.85 -> 25.882353 | G22: =H22/F22 -> 0.85 | H22: 22 | I22: =E22*H22 -> 132
A23: 18 | B23: 【鲜】猪五花肉片 | D23: 斤 | E23: 6 | F23: =H23/0.85 -> 21.764706 | G23: =H23/F23 -> 0.85 | H23: 18.5 | I23: =E23*H23 -> 111
A24: 19 | B24: 净鳝鱼 | D24: 斤 | E24: 5 | F24: =H24/0.85 -> 76.470588 | G24: =H24/F24 -> 0.85 | H24: 65 | I24: =E24*H24 -> 325
A25: 20 | B25: 干莲子米（去芯） | C25: 散称 | D25: 斤 | E25: 2 | F25: =H25/0.85 -> 44.705882 | G25: =H25/F25 -> 0.85 | H25: 38 | I25: =E25*H25 -> 76
A26: 21 | B26: 洪湖泡藕带 | C26: 400g*20袋 | D26: 袋 | E26: 8 | F26: =H26/0.85 -> 12.705882 | G26: =H26/F26 -> 0.85 | H26: 10.8 | I26: =E26*H26 -> 86.4
A27: 22 | B27: 卤牛肉 | D27: 斤 | E27: 3 | F27: =H27/0.85 -> 103.52941 | G27: =H27/F27 -> 0.85 | H27: 88 | I27: =E27*H27 -> 264
A28: 23 | B28: 八宝粥米 | C28: 散称 | D28: 斤 | E28: 5 | F28: =H28/0.85 -> 8 | G28: =H28/F28 -> 0.85 | H28: 6.8 | I28: =E28*H28 -> 34
A29: 24 | B29: 干黄豆 | C29: 50斤/件 | D29: 斤 | E29: 5 | F29: =H29/0.85 -> 6.4705882 | G29: =H29/F29 -> 0.85 | H29: 5.5 | I29: =E29*H29 -> 27.5
A30: 25 | B30: 黑米 | C30: 散称 | D30: 斤 | E30: 2 | F30: =H30/0.85 -> 8 | G30: =H30/F30 -> 0.85 | H30: 6.8 | I30: =E30*H30 -> 13.6
A31: 26 | B31: 红米 | C31: 散称 | D31: 斤 | E31: 2 | F31: =H31/0.85 -> 8 | G31: =H31/F31 -> 0.85 | H31: 6.8 | I31: =E31*H31 -> 13.6
A32: 27 | B32: 小米 | C32: 散称 | D32: 斤 | E32: 2 | F32: =H32/0.85 -> 8 | G32: =H32/F32 -> 0.85 | H32: 6.8 | I32: =E32*H32 -> 13.6
A33: 28 | B33: 1911老酸奶 | D33: 杯 | E33: 75 | F33: =H33/0.85 -> 4.1176471 | G33: =H33/F33 -> 0.85 | H33: 3.5 | I33: =E33*H33 -> 262.5
A34: 供货合计: | B34: =SUM(I6:I33) -> 2192.5
A35: 金额大写： | B35: =B34 -> 2192.5
A36: 制表人 ：樊君丽 收货人： 送货人：

Sheet 8
A1: 武汉康恩农贸发展有限公司送货单
A3: 收货单位： | B3: 汉南数智化检测分公司
A4: 配送日期： | B4: 45207
A5: 序号 | B5: 名称 | C5: 规格 | D5: 单位 | E5: 数量 | F5: 超市价格 | G5: 折扣率 | H5: 折后价 | I5: 折后金额 | J5: 备注
A6: 1 | B6: （新鲜）河粉 | D6: 斤 | E6: 6 | F6: =H6/0.85 -> 3.5294118 | G6: =H6/F6 -> 0.85 | H6: 3 | I6: =E6*H6 -> 18
A7: 2 | B7: 热干面（熟） | D7: 斤 | E7: 6 | F7: =H7/0.85 -> 4.1176471 | G7: =H7/F7 -> 0.85 | H7: 3.5 | I7: =E7*H7 -> 21
A8: 3 | B8: 红皮洋葱 | D8: 斤 | E8: 5 | F8: =H8/0.85 -> 2.9411765 | G8: =H8/F8 -> 0.85 | H8: 2.5 | I8: =E8*H8 -> 12.5
A9: 4 | B9: 大土豆 | D9: 斤 | E9: 18 | F9: =H9/0.85 -> 4.1176471 | G9: =H9/F9 -> 0.85 | H9: 3.5 | I9: =E9*H9 -> 63
A10: 5 | B10: 红椒 | D10: 斤 | E10: 2 | F10: =H10/0.85 -> 9.1764706 | G10: =H10/F10 -> 0.85 | H10: 7.8 | I10: =E10*H10 -> 15.6
A11: 6 | B11: 甜玉米棒 | D11: 个 | E11: 8 | F11: =H11/0.85 -> 3.5294118 | G11: =H11/F11 -> 0.85 | H11: 3 | I11: =E11*H11 -> 24
A12: 7 | B12: 芜湖青椒 | D12: 斤 | E12: 2 | F12: =H12/0.85 -> 6.4705882 | G12: =H12/F12 -> 0.85 | H12: 5.5 | I12: =E12*H12 -> 11
A13: 8 | B13: 平菇 | D13: 斤 | E13: 3 | F13: =H13/0.85 -> 10.352941 | G13: =H13/F13 -> 0.85 | H13: 8.8 | I13: =E13*H13 -> 26.4
A14: 9 | B14: 生菜 | D14: 斤 | E14: 19 | F14: =H14/0.85 -> 5.6470588 | G14: =H14/F14 -> 0.85 | H14: 4.8 | I14: =E14*H14 -> 91.2
A15: 10 | B15: 薄干子 | D15: 斤 | E15: 10 | F15: =H15/0.85 -> 8 | G15: =H15/F15 -> 0.85 | H15: 6.8 | I15: =E15*H15 -> 68
A16: 11 | B16: 【鲜】五花肉沫 | D16: 斤 | E16: 2 | F16: =H16/0.85 -> 19.764706 | G16: =H16/F16 -> 0.85 | H16: 16.8 | I16: =E16*H16 -> 33.6
A17: 12 | B17: 【鲜】猪通排骨 | D17: 斤 | E17: 7 | F17: =H17/0.85 -> 33.882353 | G17: =H17/F17 -> 0.85 | H17: 28.8 | I17: =E17*H17 -> 201.6
A18: 13 | B18: 白芝麻 | C18: 散称 | D18: 斤 | E18: 2 | F18: =H18/0.85 -> 17.647059 | G18: =H18/F18 -> 0.85 | H18: 15 | I18: =E18*H18 -> 30
A19: 14 | B19: 水发海带头 | C19: 18斤/件 | D19: 斤 | E19: 6 | F19: =H19/0.85 -> 9.4117647 | G19: =H19/F19 -> 0.85 | H19: 8 | I19: =E19*H19 -> 48
A20: 15 | B20: 云鹤精制碘盐 | C20: 500g*50袋/件 | D20: 袋 | E20: 10 | F20: =H20/0.85 -> 2.3529412 | G20: =H20/F20 -> 0.85 | H20: 2 | I20: =E20*H20 -> 20
A21: 17 | B21: 1911老酸奶 | D21: 杯 | E21: 60 | F21: =H21/0.85 -> 4.1176471 | G21: =H21/F21 -> 0.85 | H21: 3.5 | I21: =E21*H21 -> 210
A22: 20
A23: 21
A24: 22
A25: 23
A26: 24
A27: 25
A28: 26
A29: 27
A30: 28
A31: 供货合计: | B31: =SUM(I6:I30) -> 893.9
A32: 金额大写： | B32: =B31 -> 893.9
A33: 制表人 ：樊君丽 收货人： 送货人：

Sheet 9
A1: 武汉康恩农贸发展有限公司送货单
A3: 收货单位： | B3: 汉南数智化检测分公司
A4: 配送日期： | B4: 45208
A5: 序号 | B5: 名称 | C5: 规格 | D5: 单位 | E5: 数量 | F5: 超市价格 | G5: 折扣率 | H5: 折后价 | I5: 折后金额 | J5: 备注
A6: 1 | B6: （新鲜）河粉 | D6: 斤 | E6: 6 | F6: =H6/0.85 -> 3.5294118 | G6: =H6/F6 -> 0.85 | H6: 3 | I6: =E6*H6 -> 18
A7: 2 | B7: 干细粉 | C7: 散称 | D7: 斤 | E7: 10 | F7: =H7/0.85 -> 4.1176471 | G7: =H7/F7 -> 0.85 | H7: 3.5 | I7: =E7*H7 -> 35
A8: 3 | B8: 热干面（熟） | D8: 斤 | E8: 6 | F8: =H8/0.85 -> 4.1176471 | G8: =H8/F8 -> 0.85 | H8: 3.5 | I8: =E8*H8 -> 21
A9: 4 | B9: 黄豆芽 | D9: 斤 | E9: 18 | F9: =H9/0.85 -> 2.9411765 | G9: =H9/F9 -> 0.85 | H9: 2.5 | I9: =E9*H9 -> 45
A10: 6 | B10: 白萝卜 | D10: 斤 | E10: 18 | F10: =H10/0.85 -> 2.3529412 | G10: =H10/F10 -> 0.85 | H10: 2 | I10: =E10*H10 -> 36
A11: 7 | B11: 西红柿 | D11: 斤 | E11: 17 | F11: =H11/0.85 -> 4.4705882 | G11: =H11/F11 -> 0.85 | H11: 3.8 | I11: =E11*H11 -> 64.6
A12: 8 | B12: 冬瓜 | D12: 斤 | E12: 4 | F12: =H12/0.85 -> 2.9411765 | G12: =H12/F12 -> 0.85 | H12: 2.5 | I12: =E12*H12 -> 10
A13: 9 | B13: 鲜香菇 | D13: 斤 | E13: 1 | F13: =H13/0.85 -> 11.529412 | G13: =H13/F13 -> 0.85 | H13: 9.8 | I13: =E13*H13 -> 9.8
A14: 10 | B14: 韭菜 | D14: 斤 | E14: 2 | F14: =H14/0.85 -> 5.6470588 | G14: =H14/F14 -> 0.85 | H14: 4.8 | I14: =E14*H14 -> 9.6
A15: 11 | B15: 【鲜】净三黄鸡 | D15: 斤 | E15: 6.7 | F15: =H15/0.85 -> 17.411765 | G15: =H15/F15 -> 0.85 | H15: 14.8 | I15: =E15*H15 -> 99.16
A16: 12 | B16: 【鲜】精品五花 | D16: 斤 | E16: 2 | F16: =H16/0.85 -> 24.470588 | G16: =H16/F16 -> 0.85 | H16: 20.8 | I16: =E16*H16 -> 41.6
A17: 13 | B17: 【鲜】猪五花肉片 | D17: 斤 | E17: 5 | F17: =H17/0.85 -> 21.764706 | G17: =H17/F17 -> 0.85 | H17: 18.5 | I17: =E17*H17 -> 92.5
A18: 15 | B18: 白砂糖 | D18: 斤 | E18: 8 | F18: =H18/0.85 -> 5.7647059 | G18: =H18/F18 -> 0.85 | H18: 4.9 | I18: =E18*H18 -> 39.2
A19: 16 | B19: 三象水磨籼米粉 | C19: 500g*20包/件 | D19: 包 | E19: 5 | F19: =H19/0.85 -> 10 | G19: =H19/F19 -> 0.85 | H19: 8.5 | I19: =E19*H19 -> 42.5
A20: 17 | B20: 细苕粉 | C20: 散称 | D20: 斤 | E20: 3 | F20: =H20/0.85 -> 8 | G20: =H20/F20 -> 0.85 | H20: 6.8 | I20: =E20*H20 -> 20.4
A21: 18 | B21: 金像牌面包用小麦粉 | C21: 22.7kg | D21: 袋 | E21: 2 | F21: =H21/0.85 -> 35.294118 | G21: =H21/F21 -> 0.85 | H21: 30 | I21: =E21*H21 -> 60
A22: 19 | B22: 1911老酸奶 | D22: 杯 | E22: 55 | F22: =H22/0.85 -> 4.1176471 | G22: =H22/F22 -> 0.85 | H22: 3.5 | I22: =E22*H22 -> 192.5
A23: 20
A24: 21
A25: 22
A26: 23
A27: 24
A28: 25
A29: 26
A30: 27
A31: 28
A32: 供货合计: | B32: =SUM(I6:I31) -> 836.86
A33: 金额大写： | B33: =B32 -> 836.86
A34: 制表人 ：樊君丽 收货人： 送货人：

Sheet 10
A1: 武汉康恩农贸发展有限公司送货单
A3: 收货单位： | B3: 汉南数智化检测分公司
A4: 配送日期： | B4: 45209
A5: 序号 | B5: 名称 | C5: 规格 | D5: 单位 | E5: 数量 | F5: 超市价格 | G5: 折扣率 | H5: 折后价 | I5: 折后金额 | J5: 备注
A6: 1 | B6: （新鲜）河粉 | D6: 斤 | E6: 7 | F6: =H6/0.85 -> 3.5294118 | G6: =H6/F6 -> 0.85 | H6: 3 | I6: =E6*H6 -> 21
A7: 2 | B7: 馄饨皮 | D7: 斤 | E7: 1 | F7: =H7/0.85 -> 4.1176471 | G7: =H7/F7 -> 0.85 | H7: 3.5 | I7: =E7*H7 -> 3.5
A8: 3 | B8: 饺子皮 | D8: 斤 | E8: 2 | F8: =H8/0.85 -> 4.1176471 | G8: =H8/F8 -> 0.85 | H8: 3.5 | I8: =E8*H8 -> 7
A9: 4 | B9: 热干面（熟） | D9: 斤 | E9: 6 | F9: =H9/0.85 -> 4.1176471 | G9: =H9/F9 -> 0.85 | H9: 3.5 | I9: =E9*H9 -> 21
A10: 5 | B10: 糯玉米棒（带叶） | D10: 个 | E10: 8 | F10: =H10/0.85 -> 3.5294118 | G10: =H10/F10 -> 0.85 | H10: 3 | I10: =E10*H10 -> 24
A11: 6 | B11: 红椒 | D11: 斤 | E11: 6 | F11: =H11/0.85 -> 9.1764706 | G11: =H11/F11 -> 0.85 | H11: 7.8 | I11: =E11*H11 -> 46.8
A12: 7 | B12: 芜湖青椒 | D12: 斤 | E12: 6 | F12: =H12/0.85 -> 6.4705882 | G12: =H12/F12 -> 0.85 | H12: 5.5 | I12: =E12*H12 -> 33
A13: 8 | B13: 紫长茄子（细长） | D13: 斤 | E13: 8 | F13: =H13/0.85 -> 4.4705882 | G13: =H13/F13 -> 0.85 | H13: 3.8 | I13: =E13*H13 -> 30.4
A14: 9 | B14: 冬瓜 | D14: 斤 | E14: 8 | F14: =H14/0.85 -> 2.9411765 | G14: =H14/F14 -> 0.85 | H14: 2.5 | I14: =E14*H14 -> 20
A15: 10 | B15: 杏鲍菇 | D15: 斤 | E15: 18 | F15: =H15/0.85 -> 6.8235294 | G15: =H15/F15 -> 0.85 | H15: 5.8 | I15: =E15*H15 -> 104.4
A16: 11 | B16: 平包菜 | D16: 斤 | E16: 19 | F16: =H16/0.85 -> 2.3529412 | G16: =H16/F16 -> 0.85 | H16: 2 | I16: =E16*H16 -> 38
A17: 12 | B17: 细土芹 | D17: 斤 | E17: 4 | F17: =H17/0.85 -> 6.4705882 | G17: =H17/F17 -> 0.85 | H17: 5.5 | I17: =E17*H17 -> 22
... A21: 16 | B21: 【鲜】净黄骨鱼 | D21: 斤 | E21: 6 | F21: =H21/0.85 -> 28.235294 | G21: =H21/F21 -> 0.85 | H21: 24 | I21: =E21*H21 -> 144
A22: 17 | B22: 鑫怡久久海带丝 | C22: 19斤/件 | D22: 斤 | E22: 2 | F22: =H22/0.85 -> 7.0588235 | G22: =H22/F22 -> 0.85 | H22: 6 | I22: =E22*H22 -> 12
A23: 18 | B23: 合鑫泰东北珍珠香米 | C23: 25kg/包 | D23: 袋 | E23: 2 | F23: =H23/0.85 -> 205.88235 | G23: =H23/F23 -> 0.85 | H23: 175 | I23: =E23*H23 -> 350
A24: 19 | B24: 鲁花压榨玉米油 | C24: 5L*4壶 | D24: 壶 | E24: 1 | F24: =H24/0.85 -> 127.05882 | G24: =H24/F24 -> 0.85 | H24: 108 | I24: =E24*H24 -> 108
A25: 20 | B25: 1911老酸奶 | D25: 杯 | E25: 70 | F25: =H25/0.85 -> 4.1176471 | G25: =H25/F25 -> 0.85 | H25: 3.5 | I25: =E25*H25 -> 245
A26: 21
A27: 22
A28: 23
A29: 24
A30: 25
A31: 26
A32: 27
A33: 28
A34: 供货合计: | B34: =SUM(I6:I33) -> 1336
A35: 金额大写： | B35: =B34 -> 1336
A36: 制表人 ：樊君丽 收货人： 送货人：

Sheet 11
A1: 武汉康恩农贸发展有限公司送货单
A3: 收货单位： | B3: 汉南数智化检测分公司
A4: 配送日期： | B4: 45210
A5: 序号 | B5: 名称 | C5: 规格 | D5: 单位 | E5: 数量 | F5: 超市价格 | G5: 折扣率 | H5: 折后价 | I5: 折后金额 | J5: 备注
A6: 1 | B6: （新鲜）河粉 | D6: 斤 | E6: 7 | F6: =H6/0.85 -> 3.5294118 | G6: =H6/F6 -> 0.85 | H6: 3 | I6: =E6*H6 -> 21
A7: 2 | B7: 大圆皮 | D7: 斤 | E7: 2 | F7: =H7/0.85 -> 4.7058824 | G7: =H7/F7 -> 0.85 | H7: 4 | I7: =E7*H7 -> 8
A8: 3 | B8: 热干面（熟） | D8: 斤 | E8: 6 | F8: =H8/0.85 -> 4.1176471 | G8: =H8/F8 -> 0.85 | H8: 3.5 | I8: =E8*H8 -> 21
A9: 4 | B9: 大藕 | D9: 斤 | E9: 5 | F9: =H9/0.85 -> 5.2941176 | G9: =H9/F9 -> 0.85 | H9: 4.5 | I9: =E9*H9 -> 22.5
A10: 5 | B10: 大土豆 | D10: 斤 | E10: 5 | F10: =H10/0.85 -> 4.1176471 | G10: =H10/F10 -> 0.85 | H10: 3.5 | I10: =E10*H10 -> 17.5
A11: 6 | B11: 红椒 | D11: 斤 | E11: 5 | F11: =H11/0.85 -> 9.1764706 | G11: =H11/F11 -> 0.85 | H11: 7.8 | I11: =E11*H11 -> 39
A12: 7 | B12: 芜湖青椒 | D12: 斤 | E12: 5 | F12: =H12/0.85 -> 6.4705882 | G12: =H12/F12 -> 0.85 | H12: 5.5 | I12: =E12*H12 -> 27.5
A13: 8 | B13: 海鲜菇 | D13: 斤 | E13: 15 | F13: =H13/0.85 -> 7.6470588 | G13: =H13/F13 -> 0.85 | H13: 6.5 | I13: =E13*H13 -> 97.5
A14: 9 | B14: 菠菜 | D14: 斤 | E14: 19 | F14: =H14/0.85 -> 5.6470588 | G14: =H14/F14 -> 0.85 | H14: 4.8 | I14: =E14*H14 -> 91.2
A15: 10 | B15: 大白菜 | D15: 斤 | E15: 14 | F15: =H15/0.85 -> 2.1176471 | G15: =H15/F15 -> 0.85 | H15: 1.8 | I15: =E15*H15 -> 25.2
A16: 11 | B16: 生菜 | D16: 斤 | E16: 8 | F16: =H16/0.85 -> 5.6470588 | G16: =H16/F16 -> 0.85 | H16: 4.8 | I16: =E16*H16 -> 38.4
A17: 12 | B17: 香蕉 | D17: 斤 | E17: 6.8 | F17: =H17/0.85 -> 6.4705882 | G17: =H17/F17 -> 0.85 | H17: 5.5 | I17: =E17*H17 -> 37.4
... A20: 15 | B20: 水塔陈醋 | D20: 件 | E20: 1 | F20: =H20/0.85 -> 76.470588 | G20: =H20/F20 -> 0.85 | H20: 65 | I20: =E20*H20 -> 65
A21: 16 | B21: 天车甜面酱 | C21: 500g*12瓶/件 | D21: 瓶 | E21: 5 | F21: =H21/0.85 -> 14.117647 | G21: =H21/F21 -> 0.85 | H21: 12 | I21: =E21*H21 -> 60
A22: 17 | B22: 优质干腐竹 | D22: 斤 | E22: 4 | F22: =H22/0.85 -> 19.764706 | G22: =H22/F22 -> 0.85 | H22: 16.8 | I22: =E22*H22 -> 67.2
A23: 18 | B23: 肉圆 | D23: 斤 | E23: 8 | F23: =H23/0.85 -> 23.529412 | G23: =H23/F23 -> 0.85 | H23: 20 | I23: =E23*H23 -> 160
A24: 19 | B24: 福达坊芝麻香油 | C24: 360ml*12瓶 | D24: 瓶 | E24: 3 | F24: =H24/0.85 -> 14.705882 | G24: =H24/F24 -> 0.85 | H24: 12.5 | I24: =E24*H24 -> 37.5
A25: 20 | B25: 黑米 | C25: 散称 | D25: 斤 | E25: 5 | F25: =H25/0.85 -> 8 | G25: =H25/F25 -> 0.85 | H25: 6.8 | I25: =E25*H25 -> 34
A26: 21 | B26: 正和珍珠糯米 | C26: 50斤/袋 | D26: 斤 | E26: 5 | F26: =H26/0.85 -> 5.7647059 | G26: =H26/F26 -> 0.85 | H26: 4.9 | I26: =E26*H26 -> 24.5
A27: 22 | B27: 1911老酸奶 | D27: 杯 | E27: 45 | F27: =H27/0.85 -> 4.1176471 | G27: =H27/F27 -> 0.85 | H27: 3.5 | I27: =E27*H27 -> 157.5
A28: 26
A29: 27
A30: 28
A31: 供货合计: | B31: =SUM(I6:I30) -> 1316.5
A32: 金额大写： | B32: =B31 -> 1316.5
A33: 制表人 ：樊君丽 收货人： 送货人：

Sheet 12
A1: 武汉康恩农贸发展有限公司送货单
A3: 收货单位： | B3: 汉南数智化检测分公司
A4: 配送日期： | B4: 45211
A5: 序号 | B5: 名称 | C5: 规格 | D5: 单位 | E5: 数量 | F5: 超市价格 | G5: 折扣率 | H5: 折后价 | I5: 折后金额 | J5: 备注
A6: 1 | B6: （新鲜）河粉 | D6: 斤 | E6: 7 | F6: =H6/0.85 -> 3.5294118 | G6: =H6/F6 -> 0.85 | H6: 3 | I6: =E6*H6 -> 21
A7: 2 | B7: 馄饨皮 | D7: 斤 | E7: 2 | F7: =H7/0.85 -> 4.1176471 | G7: =H7/F7 -> 0.85 | H7: 3.5 | I7: =E7*H7 -> 7
A8: 3 | B8: 热干面（熟） | D8: 斤 | E8: 6 | F8: =H8/0.85 -> 4.1176471 | G8: =H8/F8 -> 0.85 | H8: 3.5 | I8: =E8*H8 -> 21
A9: 4 | B9: 生姜 | D9: 斤 | E9: 5 | F9: =H9/0.85 -> 15.058824 | G9: =H9/F9 -> 0.85 | H9: 12.8 | I9: =E9*H9 -> 64
A10: 5 | B10: 四季豆 | D10: 斤 | E10: 21 | F10: =H10/0.85 -> 10 | G10: =H10/F10 -> 0.85 | H10: 8.5 | I10: =E10*H10 -> 178.5
A11: 6 | B11: 新鲜毛豆米 | D11: 斤 | E11: 6 | F11: =H11/0.85 -> 17.058824 | G11: =H11/F11 -> 0.85 | H11: 14.5 | I11: =E11*H11 -> 87
A12: 7 | B12: 白萝卜 | D12: 斤 | E12: 8 | F12: =H12/0.85 -> 2.3529412 | G12: =H12/F12 -> 0.85 | H12: 2 | I12: =E12*H12 -> 16
A13: 8 | B13: 红椒 | D13: 斤 | E13: 3 | F13: =H13/0.85 -> 9.1764706 | G13: =H13/F13 -> 0.85 | H13: 7.8 | I13: =E13*H13 -> 23.4
A14: 9 | B14: 甜玉米棒 | D14: 个 | E14: 8 | F14: =H14/0.85 -> 3.5294118 | G14: =H14/F14 -> 0.85 | H14: 3 | I14: =E14*H14 -> 24
A15: 10 | B15: 芜湖青椒 | D15: 斤 | E15: 3 | F15: =H15/0.85 -> 6.4705882 | G15: =H15/F15 -> 0.85 | H15: 5.5 | I15: =E15*H15 -> 16.5
A16: 11 | B16: 大白菜 | D16: 斤 | E16: 16 | F16: =H16/0.85 -> 2.1176471 | G16: =H16/F16 -> 0.85 | H16: 1.8 | I16: =E16*H16 -> 28.8
A17: 12 | B17: 韭菜 | D17: 斤 | E17: 2 | F17: =H17/0.85 -> 5.6470588 | G17: =H17/F17 -> 0.85 | H17: 4.8 | I17: =E17*H17 -> 9.6
... A20: 15 | B20: 香梨 | D20: 斤 | E20: 12.54 | F20: =H20/0.85 -> 15.058824 | G20: =H20/F20 -> 0.85 | H20: 12.8 | I20: =E20*H20 -> 160.512
A21: 16 | B21: 红壳鸡蛋 | C21: 12板/件 | D21: 件 | E21: 1 | F21: =H21/0.85 -> 352.94118 | G21: =H21/F21 -> 0.85 | H21: 300 | I21: =E21*H21 -> 300
A22: 17 | B22: 【鲜】五花肉沫 | D22: 斤 | E22: 6 | F22: =H22/0.85 -> 19.764706 | G22: =H22/F22 -> 0.85 | H22: 16.8 | I22: =E22*H22 -> 100.8
A23: 18 | B23: 【鲜】猪通排骨 | D23: 斤 | E23: 7 | F23: =H23/0.85 -> 33.882353 | G23: =H23/F23 -> 0.85 | H23: 28.8 | I23: =E23*H23 -> 201.6
A24: 19 | B24: 【鲜】净大草鱼 | D24: 斤 | E24: 10.8 | F24: =H24/0.85 -> 16.235294 | G24: =H24/F24 -> 0.85 | H24: 13.8 | I24: =E24*H24 -> 149.04
A25: 20 | B25: 思念白糯小汤圆（无馅） | C25: 500g*20包/件 | D25: 袋 | E25: 5 | F25: =H25/0.85 -> 10.588235 | G25: =H25/F25 -> 0.85 | H25: 9 | I25: =E25*H25 -> 45
A26: 21 | B26: 白砂糖 | C26: 50kg/袋 | D26: 袋 | E26: 1 | F26: =H26/0.85 -> 576.47059 | G26: =H26/F26 -> 0.85 | H26: 490 | I26: =E26*H26 -> 490
A27: 22 | B27: 干红辣椒皮 | C27: 散称 | D27: 斤 | E27: 1 | F27: =H27/0.85 -> 24.705882 | G27: =H27/F27 -> 0.85 | H27: 21 | I27: =E27*H27 -> 21
A28: 23 | B28: 辣椒面 | C28: 散称 | D28: 斤 | E28: 1 | F28: =H28/0.85 -> 24.705882 | G28: =H28/F28 -> 0.85 | H28: 21 | I28: =E28*H28 -> 21
A29: 24 | B29: 孝感米酒900g | C29: 900g*6瓶/件 | D29: 瓶 | E29: 5 | F29: =H29/0.85 -> 10 | G29: =H29/F29 -> 0.85 | H29: 8.5 | I29: =E29*H29 -> 42.5
A30: 25 | B30: 卤牛肚 | D30: 斤 | E30: 3 | F30: =H30/0.85 -> 103.52941 | G30: =H30/F30 -> 0.85 | H30: 88 | I30: =E30*H30 -> 264
A31: 26 | B31: 手撕鸡 | D31: 只 | E31: 5 | F31: =H31/0.85 -> 30.588235 | G31: =H31/F31 -> 0.85 | H31: 26 | I31: =E31*H31 -> 130
A32: 27 | B32: 光明健能酸奶180g | C32: 180g | D32: 杯 | E32: 60 | F32: =H32/0.85 -> 4.1176471 | G32: =H32/F32 -> 0.85 | H32: 3.5 | I32: =E32*H32 -> 210
A33: 28
A34: 供货合计: | B34: =SUM(I6:I33) -> 2688.652
A35: 金额大写： | B35: =B34 -> 2688.652
A36: 制表人 ：樊君丽 收货人： 送货人：

Sheet 13
A1: 武汉康恩农贸发展有限公司送货单
A3: 收货单位： | B3: 汉南数智化检测分公司
A4: 配送日期： | B4: 45212
A5: 序号 | B5: 名称 | C5: 规格 | D5: 单位 | E5: 数量 | F5: 超市价格 | G5: 折扣率 | H5: 折后价 | I5: 折后金额 | J5: 备注
A6: 1 | B6: （新鲜）河粉 | D6: 斤 | E6: 7 | F6: =H6/0.85 -> 3.5294118 | G6: =H6/F6 -> 0.85 | H6: 3 | I6: =E6*H6 -> 21
A7: 2 | B7: 饺子皮 | D7: 斤 | E7: 3 | F7: =H7/0.85 -> 4.1176471 | G7: =H7/F7 -> 0.85 | H7: 3.5 | I7: =E7*H7 -> 10.5
A8: 3 | B8: 热干面（熟） | D8: 斤 | E8: 6 | F8: =H8/0.85 -> 4.1176471 | G8: =H8/F8 -> 0.85 | H8: 3.5 | I8: =E8*H8 -> 21
A9: 4 | B9: 青杭椒 | D9: 斤 | E9: 6 | F9: =H9/0.85 -> 6.8235294 | G9: =H9/F9 -> 0.85 | H9: 5.8 | I9: =E9*H9 -> 34.8
A10: 5 | B10: 绿豆芽 | D10: 斤 | E10: 16 | F10: =H10/0.85 -> 2.9411765 | G10: =H10/F10 -> 0.85 | H10: 2.5 | I10: =E10*H10 -> 40
A11: 6 | B11: 大藕 | D11: 斤 | E11: 5 | F11: =H11/0.85 -> 5.2941176 | G11: =H11/F11 -> 0.85 | H11: 4.5 | I11: =E11*H11 -> 22.5
A12: 7 | B12: 红椒 | D12: 斤 | E12: 4 | F12: =H12/0.85 -> 9.1764706 | G12: =H12/F12 -> 0.85 | H12: 7.8 | I12: =E12*H12 -> 31.2
A13: 8 | B13: 胡萝卜 | D13: 斤 | E13: 5 | F13: =H13/0.85 -> 2.9411765 | G13: =H13/F13 -> 0.85 | H13: 2.5 | I13: =E13*H13 -> 12.5
A14: 9 | B14: 芜湖青椒 | D14: 斤 | E14: 7 | F14: =H14/0.85 -> 6.4705882 | G14: =H14/F14 -> 0.85 | H14: 5.5 | I14: =E14*H14 -> 38.5
A15: 10 | B15: 西红柿 | D15: 斤 | E15: 5 | F15: =H15/0.85 -> 4.4705882 | G15: =H15/F15 -> 0.85 | H15: 3.8 | I15: =E15*H15 -> 19
A16: 11 | B16: 冬瓜 | D16: 斤 | E16: 8 | F16: =H16/0.85 -> 2.9411765 | G16: =H16/F16 -> 0.85 | H16: 2.5 | I16: =E16*H16 -> 20
A17: 12 | B17: 黄瓜 | D17: 斤 | E17: 5 | F17: =H17/0.85 -> 5.6470588 | G17: =H17/F17 -> 0.85 | H17: 4.8 | I17: =E17*H17 -> 24
... A20: 15 | B20: 嫩豆腐 | D20: 斤 | E20: 17 | F20: =H20/0.85 -> 4.1176471 | G20: =H20/F20 -> 0.85 | H20: 3.5 | I20: =E20*H20 -> 59.5
A21: 16 | B21: 皮蛋 | C21: 180个/件 | D21: 个 | E21: 60 | F21: =H21/0.85 -> 2.1176471 | G21: =H21/F21 -> 0.85 | H21: 1.8 | I21: =E21*H21 -> 108
A22: 17 | B22: 【鲜】净麻鸭 | D22: 斤 | E22: 6.2 | F22: =H22/0.85 -> 25.882353 | G22: =H22/F22 -> 0.85 | H22: 22 | I22: =E22*H22 -> 136.4
A23: 18 | B23: 【鲜】猪通排骨 | D23: 斤 | E23: 6 | F23: =H23/0.85 -> 33.882353 | G23: =H23/F23 -> 0.85 | H23: 28.8 | I23: =E23*H23 -> 172.8
A24: 19 | B24: 【鲜】猪五花肉片 | D24: 斤 | E24: 5 | F24: =H24/0.85 -> 21.764706 | G24: =H24/F24 -> 0.85 | H24: 18.5 | I24: =E24*H24 -> 92.5
A25: 20 | B25: 惠万家烟鸭胸 | C25: 5公斤/件/（32个） | D25: 件 | E25: 1 | F25: =H25/0.85 -> 141.17647 | G25: =H25/F25 -> 0.85 | H25: 120 | I25: =E25*H25 -> 120
A26: 21 | B26: 大桥鸡精900g | C26: 900g*10袋/件 | D26: 件 | E26: 1 | F26: =H26/0.85 -> 411.76471 | G26: =H26/F26 -> 0.85 | H26: 350 | I26: =E26*H26 -> 350
A27: 22 | B27: 光明健能酸奶180g | C27: 180g | D27: 杯 | E27: 65 | F27: =H27/0.85 -> 4.1176471 | G27: =H27/F27 -> 0.85 | H27: 3.5 | I27: =E27*H27 -> 227.5
A28: 24
A29: 25
A30: 26
A31: 27
A32: 28
A33: 供货合计: | B33: =SUM(I6:I32) -> 1670.7
A34: 金额大写： | B34: =B33 -> 1670.7
A35: 制表人 ：樊君丽 收货人： 送货人：

Sheet 14
A1: 武汉康恩农贸发展有限公司送货单
A3: 收货单位： | B3: 汉南数智化检测分公司
A4: 配送日期： | B4: 45213
A5: 序号 | B5: 名称 | C5: 规格 | D5: 单位 | E5: 数量 | F5: 超市价格 | G5: 折扣率 | H5: 折后价 | I5: 折后金额 | J5: 备注
A6: 1 | B6: 青杭椒 | D6: 斤 | E6: 5 | F6: =H6/0.85 -> 6.8235294 | G6: =H6/F6 -> 0.85 | H6: 5.8 | I6: =E6*H6 -> 29
A7: 2 | B7: 老南瓜 | D7: 斤 | E7: 14 | F7: =H7/0.85 -> 2.9411765 | G7: =H7/F7 -> 0.85 | H7: 2.5 | I7: =E7*H7 -> 35
A8: 3 | B8: 净莴苣 | D8: 斤 | E8: 5 | F8: =H8/0.85 -> 6.8235294 | G8: =H8/F8 -> 0.85 | H8: 5.8 | I8: =E8*H8 -> 29
A9: 4 | B9: 油麦菜 | D9: 斤 | E9: 10 | F9: =H9/0.85 -> 5.2941176 | G9: =H9/F9 -> 0.85 | H9: 4.5 | I9: =E9*H9 -> 45
A10: 5 | B10: 香梨 | D10: 斤 | E10: 8 | F10: =H10/0.85 -> 15.058824 | G10: =H10/F10 -> 0.85 | H10: 12.8 | I10: =E10*H10 -> 102.4
A11: 6 | B11: 【鲜】净三黄鸡 | D11: 斤 | E11: 5.8 | F11: =H11/0.85 -> 17.411765 | G11: =H11/F11 -> 0.85 | H11: 14.8 | I11: =E11*H11 -> 85.84
A12: 7
A13: 8
A14: 9
A15: 10
A16: 11
A17: 12
A18: 13
A19: 14
A20: 15
A21: 16
A22: 17
A23: 19
... A32: 28
A33: 供货合计: | B33: =SUM(I6:I32) -> 326.24
A34: 金额大写： | B34: =B33 -> 326.24
A35: 制表人 ：樊君丽 收货人： 送货人：

Sheet 15
A1: 武汉康恩农贸发展有限公司送货单
A3: 收货单位： | B3: 汉南数智化检测分公司
A4: 配送日期： | B4: 45214
A5: 序号 | B5: 名称 | C5: 规格 | D5: 单位 | E5: 数量 | F5: 超市价格 | G5: 折扣率 | H5: 折后价 | I5: 折后金额 | J5: 备注
A6: 1 | B6: 蒜米 | D6: 斤 | E6: 4 | F6: =H6/0.85 -> 9.1764706 | G6: =H6/F6 -> 0.85 | H6: 7.8 | I6: =E6*H6 -> 31.2
A7: 2 | B7: 新鲜毛豆米 | D7: 斤 | E7: 5 | F7: =H7/0.85 -> 17.058824 | G7: =H7/F7 -> 0.85 | H7: 14.5 | I7: =E7*H7 -> 72.5
A8: 3 | B8: 白萝卜 | D8: 斤 | E8: 8 | F8: =H8/0.85 -> 2.3529412 | G8: =H8/F8 -> 0.85 | H8: 2 | I8: =E8*H8 -> 16
A9: 4 | B9: 红椒 | D9: 斤 | E9: 2 | F9: =H9/0.85 -> 9.1764706 | G9: =H9/F9 -> 0.85 | H9: 7.8 | I9: =E9*H9 -> 15.6
A10: 5 | B10: 胡萝卜 | D10: 斤 | E10: 3.1 | F10: =H10/0.85 -> 2.9411765 | G10: =H10/F10 -> 0.85 | H10: 2.5 | I10: =E10*H10 -> 7.75
A11: 6 | B11: 芜湖青椒 | D11: 斤 | E11: 15 | F11: =H11/0.85 -> 6.4705882 | G11: =H11/F11 -> 0.85 | H11: 5.5 | I11: =E11*H11 -> 82.5
A12: 7 | B12: 西红柿 | D12: 斤 | E12: 12 | F12: =H12/0.85 -> 4.4705882 | G12: =H12/F12 -> 0.85 | H12: 3.8 | I12: =E12*H12 -> 45.6
A13: 8 | B13: 有机花菜 | D13: 斤 | E13: 7 | F13: =H13/0.85 -> 6.4705882 | G13: =H13/F13 -> 0.85 | H13: 5.5 | I13: =E13*H13 -> 38.5
A14: 9 | B14: 金针菇 | D14: 斤 | E14: 3 | F14: =H14/0.85 -> 8 | G14: =H14/F14 -> 0.85 | H14: 6.8 | I14: =E14*H14 -> 20.4
A15: 10 | B15: 大白菜 | D15: 斤 | E15: 10 | F15: =H15/0.85 -> 2.1176471 | G15: =H15/F15 -> 0.85 | H15: 1.8 | I15: =E15*H15 -> 18
A16: 11 | B16: 生菜 | D16: 斤 | E16: 8.6 | F16: =H16/0.85 -> 5.6470588 | G16: =H16/F16 -> 0.85 | H16: 4.8 | I16: =E16*H16 -> 41.28
A17: 12 | B17: 细土芹 | D17: 斤 | E17: 4 | F17: =H17/0.85 -> 6.4705882 | G17: =H17/F17 -> 0.85 | H17: 5.5 | I17: =E17*H17 -> 22
A18: 13 | B18: 厚干子 | D18: 斤 | E18: 6 | F18: =H18/0.85 -> 8 | G18: =H18/F18 -> 0.85 | H18: 6.8 | I18: =E18*H18 -> 40.8
A19: 14
A20: 15
A21: 16
A22: 17
A23: 18
A24: 19
A25: 20
A26: 21
A27: 22
A28: 23
A29: 24
A30: 25
... A33: 28
A34: 供货合计: | B34: =SUM(I6:I33) -> 452.13
A35: 金额大写： | B35: =B34 -> 452.13
A36: 制表人 ：樊君丽 收货人： 送货人：

Sheet 16
A1: 武汉康恩农贸发展有限公司送货单
A3: 收货单位： | B3: 汉南数智化检测分公司
A4: 配送日期： | B4: 45215
A5: 序号 | B5: 名称 | C5: 规格 | D5: 单位 | E5: 数量 | F5: 超市价格 | G5: 折扣率 | H5: 折后价 | I5: 折后金额 | J5: 备注
A6: 1 | B6: （新鲜）河粉 | D6: 斤 | E6: 7 | F6: =H6/0.85 -> 3.5294118 | G6: =H6/F6 -> 0.85 | H6: 3 | I6: =E6*H6 -> 21
A7: 2 | B7: 馄饨皮 | D7: 斤 | E7: 2 | F7: =H7/0.85 -> 4.1176471 | G7: =H7/F7 -> 0.85 | H7: 3.5 | I7: =E7*H7 -> 7
A8: 3 | B8: 热干面（熟） | D8: 斤 | E8: 6 | F8: =H8/0.85 -> 4.1176471 | G8: =H8/F8 -> 0.85 | H8: 3.5 | I8: =E8*H8 -> 21
A9: 4 | B9: 四季豆 | D9: 斤 | E9: 19 | F9: =H9/0.85 -> 10 | G9: =H9/F9 -> 0.85 | H9: 8.5 | I9: =E9*H9 -> 161.5
A10: 5 | B10: 大藕 | D10: 斤 | E10: 5 | F10: =H10/0.85 -> 5.2941176 | G10: =H10/F10 -> 0.85 | H10: 4.5 | I10: =E10*H10 -> 22.5
A11: 6 | B11: 大土豆 | D11: 斤 | E11: 5 | F11: =H11/0.85 -> 4.1176471 | G11: =H11/F11 -> 0.85 | H11: 3.5 | I11: =E11*H11 -> 17.5
A12: 7 | B12: 红椒 | D12: 斤 | E12: 4 | F12: =H12/0.85 -> 9.1764706 | G12: =H12/F12 -> 0.85 | H12: 7.8 | I12: =E12*H12 -> 31.2
A13: 8 | B13: 蒜苗 | D13: 斤 | E13: 4 | F13: =H13/0.85 -> 11.529412 | G13: =H13/F13 -> 0.85 | H13: 9.8 | I13: =E13*H13 -> 39.2
A14: 9 | B14: 甜玉米棒 | D14: 个 | E14: 8 | F14: =H14/0.85 -> 3.5294118 | G14: =H14/F14 -> 0.85 | H14: 3 | I14: =E14*H14 -> 24
A15: 10 | B15: 芜湖青椒 | D15: 斤 | E15: 4 | F15: =H15/0.85 -> 6.4705882 | G15: =H15/F15 -> 0.85 | H15: 5.5 | I15: =E15*H15 -> 22
A16: 11 | B16: 西红柿 | D16: 斤 | E16: 5 | F16: =H16/0.85 -> 4.4705882 | G16: =H16/F16 -> 0.85 | H16: 3.8 | I16: =E16*H16 -> 19
A17: 12 | B17: 冬瓜 | D17: 斤 | E17: 23.7 | F17: =H17/0.85 -> 2.9411765 | G17: =H17/F17 -> 0.85 | H17: 2.5 | I17: =E17*H17 -> 59.25
... A20: 15 | B20: 平包菜 | D20: 斤 | E20: 9 | F20: =H20/0.85 -> 2.3529412 | G20: =H20/F20 -> 0.85 | H20: 2 | I20: =E20*H20 -> 18
A21: 16 | B21: 娃娃菜 | C21: 散装 | D21: 斤 | E21: 10 | F21: =H21/0.85 -> 5.2941176 | G21: =H21/F21 -> 0.85 | H21: 4.5 | I21: =E21*H21 -> 45
A22: 17 | B22: 细土芹 | D22: 斤 | E22: 4 | F22: =H22/0.85 -> 6.4705882 | G22: =H22/F22 -> 0.85 | H22: 5.5 | I22: =E22*H22 -> 22
A23: 18 | B23: 橙子 | D23: 斤 | E23: 8.8 | F23: =H23/0.85 -> 11.529412 | G23: =H23/F23 -> 0.85 | H23: 9.8 | I23: =E23*H23 -> 86.24
A24: 19 | B24: 厚干子 | D24: 斤 | E24: 6 | F24: =H24/0.85 -> 8 | G24: =H24/F24 -> 0.85 | H24: 6.8 | I24: =E24*H24 -> 40.8
A25: 20 | B25: 嫩豆腐 | D25: 斤 | E25: 8 | F25: =H25/0.85 -> 4.1176471 | G25: =H25/F25 -> 0.85 | H25: 3.5 | I25: =E25*H25 -> 28
A26: 21 | B26: 熟鹌鹑蛋 | D26: 斤 | E26: 5 | F26: =H26/0.85 -> 16.235294 | G26: =H26/F26 -> 0.85 | H26: 13.8 | I26: =E26*H26 -> 69
A27: 22 | B27: 【鲜】精品五花 | D27: 斤 | E27: 4 | F27: =H27/0.85 -> 24.470588 | G27: =H27/F27 -> 0.85 | H27: 20.8 | I27: =E27*H27 -> 83.2
A28: 23 | B28: 【鲜】五花肉沫 | D28: 斤 | E28: 2 | F28: =H28/0.85 -> 19.764706 | G28: =H28/F28 -> 0.85 | H28: 16.8 | I28: =E28*H28 -> 33.6
A29: 24 | B29: 【鲜】猪瘦肉丝 | D29: 斤 | E29: 5 | F29: =H29/0.85 -> 25.882353 | G29: =H29/F29 -> 0.85 | H29: 22 | I29: =E29*H29 -> 110
A30: 25 | B30: 【鲜】净胖头鱼头 | D30: 斤 | E30: 5 | F30: =H30/0.85 -> 23.529412 | G30: =H30/F30 -> 0.85 | H30: 20 | I30: =E30*H30 -> 100
A31: 27 | B31: 雀巢怡运奶粉 | C31: 300g*12袋 | D31: 袋 | E31: 1 | F31: =H31/0.85 -> 30.588235 | G31: =H31/F31 -> 0.85 | H31: 26 | I31: =E31*H31 -> 26
A32: 28 | B32: 王守义十三香 | C32: 45g*10盒/条 | D32: 盒 | E32: 3 | F32: =H32/0.85 -> 4.9411765 | G32: =H32/F32 -> 0.85 | H32: 4.2 | I32: =E32*H32 -> 12.6
A33: 29 | B33: 卤牛肉 | D33: 斤 | E33: 3 | F33: =H33/0.85 -> 103.52941 | G33: =H33/F33 -> 0.85 | H33: 88 | I33: =E33*H33 -> 264
A34: 30 | B34: 合鑫泰东北珍珠香米 | C34: 25kg/包 | D34: 袋 | E34: 2 | F34: =H34/0.85 -> 205.88235 | G34: =H34/F34 -> 0.85 | H34: 175 | I34: =E34*H34 -> 350
A35: 31 | B35: 1911老酸奶 | D35: 杯 | E35: 70 | F35: =H35/0.85 -> 4.1176471 | G35: =H35/F35 -> 0.85 | H35: 3.5 | I35: =E35*H35 -> 245
A36: 供货合计: | B36: =SUM(I6:I35) -> 2024.99
A37: 金额大写： | B37: =B36 -> 2024.99
A38: 制表人 ：樊君丽 收货人： 送货人：

Sheet 17
A1: 武汉康恩农贸发展有限公司送货单
A3: 收货单位： | B3: 汉南数智化检测分公司
A4: 配送日期： | B4: 45216
A5: 序号 | B5: 名称 | C5: 规格 | D5: 单位 | E5: 数量 | F5: 超市价格 | G5: 折扣率 | H5: 折后价 | I5: 折后金额 | J5: 备注
A6: 1 | B6: 小葱 | D6: 斤 | E6: 1 | F6: =H6/0.85 -> 8 | G6: =H6/F6 -> 0.85 | H6: 6.8 | I6: =E6*H6 -> 6.8
A7: 2 | B7: 铁棍山药 | D7: 斤 | E7: 15 | F7: =H7/0.85 -> 11.529412 | G7: =H7/F7 -> 0.85 | H7: 9.8 | I7: =E7*H7 -> 147
A8: 3 | B8: 芜湖青椒 | D8: 斤 | E8: 4 | F8: =H8/0.85 -> 6.4705882 | G8: =H8/F8 -> 0.85 | H8: 5.5 | I8: =E8*H8 -> 22
A9: 4 | B9: 西红柿 | D9: 斤 | E9: 8 | F9: =H9/0.85 -> 4.4705882 | G9: =H9/F9 -> 0.85 | H9: 3.8 | I9: =E9*H9 -> 30.4
A10: 5 | B10: 有机花菜 | D10: 斤 | E10: 8 | F10: =H10/0.85 -> 6.4705882 | G10: =H10/F10 -> 0.85 | H10: 5.5 | I10: =E10*H10 -> 44
A11: 6 | B11: 紫长茄子（细长） | D11: 斤 | E11: 19 | F11: =H11/0.85 -> 4.4705882 | G11: =H11/F11 -> 0.85 | H11: 3.8 | I11: =E11*H11 -> 72.2
A12: 7 | B12: 大白菜 | D12: 斤 | E12: 10 | F12: =H12/0.85 -> 2.1176471 | G12: =H12/F12 -> 0.85 | H12: 1.8 | I12: =E12*H12 -> 18
A13: 8 | B13: 韭菜 | D13: 斤 | E13: 4 | F13: =H13/0.85 -> 5.6470588 | G13: =H13/F13 -> 0.85 | H13: 4.8 | I13: =E13*H13 -> 19.2
A14: 9 | B14: 油麦菜 | D14: 斤 | E14: 19 | F14: =H14/0.85 -> 5.2941176 | G14: =H14/F14 -> 0.85 | H14: 4.5 | I14: =E14*H14 -> 85.5
A15: 10 | B15: 面筋 | D15: 斤 | E15: 8 | F15: =H15/0.85 -> 8 | G15: =H15/F15 -> 0.85 | H15: 6.8 | I15: =E15*H15 -> 54.4
A16: 11 | B16: 【鲜】五花肉沫 | D16: 斤 | E16: 7 | F16: =H16/0.85 -> 19.764706 | G16: =H16/F16 -> 0.85 | H16: 16.8 | I16: =E16*H16 -> 117.6
A17: 12 | B17: 【鲜】猪五花肉片 | D17: 斤 | E17: 5 | F17: =H17/0.85 -> 21.764706 | G17: =H17/F17 -> 0.85 | H17: 18.5 | I17: =E17*H17 -> 92.5
A18: 13 | B18: 【鲜】净大草鱼 | D18: 斤 | E18: 11 | F18: =H18/0.85 -> 16.235294 | G18: =H18/F18 -> 0.85 | H18: 13.8 | I18: =E18*H18 -> 151.8
A19: 14 | B19: 光明健能酸奶180g | C19: 180g | D19: 杯 | E19: 70 | F19: =H19/0.85 -> 4.1176471 | G19: =H19/F19 -> 0.85 | H19: 3.5 | I19: =E19*H19 -> 245
A20: 15
A21: 16
A22: 17
A23: 18
A24: 19
A25: 20
A26: 21
A27: 22
A28: 23
A29: 24
A30: 25
A31: 26
... A33: 28
A34: 供货合计: | B34: =SUM(I6:I33) -> 1106.4
A35: 金额大写： | B35: =B34 -> 1106.4
A36: 制表人 ：樊君丽 收货人： 送货人：

Sheet 18
A1: 武汉康恩农贸发展有限公司送货单
A3: 收货单位： | B3: 汉南数智化检测分公司
A4: 配送日期： | B4: 45217
A5: 序号 | B5: 名称 | C5: 规格 | D5: 单位 | E5: 数量 | F5: 超市价格 | G5: 折扣率 | H5: 折后价 | I5: 折后金额 | J5: 备注
A6: 1 | B6: （新鲜）河粉 | D6: 斤 | E6: 7 | F6: =H6/0.85 -> 3.5294118 | G6: =H6/F6 -> 0.85 | H6: 3 | I6: =E6*H6 -> 21
A7: 2 | B7: 饺子皮 | D7: 斤 | E7: 3 | F7: =H7/0.85 -> 4.1176471 | G7: =H7/F7 -> 0.85 | H7: 3.5 | I7: =E7*H7 -> 10.5
A8: 3 | B8: 热干面（熟） | D8: 斤 | E8: 3 | F8: =H8/0.85 -> 4.1176471 | G8: =H8/F8 -> 0.85 | H8: 3.5 | I8: =E8*H8 -> 10.5
A9: 4 | B9: 生面窝浆 | D9: 斤 | E9: 4 | F9: =H9/0.85 -> 7.0588235 | G9: =H9/F9 -> 0.85 | H9: 6 | I9: =E9*H9 -> 24
A10: 5 | B10: 青大蒜 | D10: 斤 | E10: 5 | F10: =H10/0.85 -> 9.1764706 | G10: =H10/F10 -> 0.85 | H10: 7.8 | I10: =E10*H10 -> 39
A11: 6 | B11: 生姜 | D11: 斤 | E11: 5 | F11: =H11/0.85 -> 15.058824 | G11: =H11/F11 -> 0.85 | H11: 12.8 | I11: =E11*H11 -> 64
A12: 7 | B12: 菱角米（去壳） | D12: 斤 | E12: 1 | F12: =H12/0.85 -> 23.529412 | G12: =H12/F12 -> 0.85 | H12: 20 | I12: =E12*H12 -> 20
A13: 8 | B13: 白萝卜 | D13: 斤 | E13: 6 | F13: =H13/0.85 -> 2.3529412 | G13: =H13/F13 -> 0.85 | H13: 2 | I13: =E13*H13 -> 12
A14: 9 | B14: 大藕 | D14: 斤 | E14: 15.5 | F14: =H14/0.85 -> 5.2941176 | G14: =H14/F14 -> 0.85 | H14: 4.5 | I14: =E14*H14 -> 69.75
A15: 10 | B15: 大土豆 | D15: 斤 | E15: 5 | F15: =H15/0.85 -> 4.1176471 | G15: =H15/F15 -> 0.85 | H15: 3.5 | I15: =E15*H15 -> 17.5
A16: 11 | B16: 红椒 | D16: 斤 | E16: 4 | F16: =H16/0.85 -> 9.1764706 | G16: =H16/F16 -> 0.85 | H16: 7.8 | I16: =E16*H16 -> 31.2
A17: 12 | B17: 蒜苗 | D17: 斤 | E17: 9 | F17: =H17/0.85 -> 11.529412 | G17: =H17/F17 -> 0.85 | H17: 9.8 | I17: =E17*H17 -> 88.2
... A29: 24 | B29: 素鸡 | D29: 斤 | E29: 11 | F29: =H29/0.85 -> 8 | G29: =H29/F29 -> 0.85 | H29: 6.8 | I29: =E29*H29 -> 74.8
A30: 25 | B30: 红壳鸡蛋 | C30: 12板/件 | D30: 件 | E30: 1 | F30: =H30/0.85 -> 352.94118 | G30: =H30/F30 -> 0.85 | H30: 300 | I30: =E30*H30 -> 300
A31: 26 | B31: 【鲜】净三黄鸡 | D31: 斤 | E31: 5.5 | F31: =H31/0.85 -> 17.411765 | G31: =H31/F31 -> 0.85 | H31: 14.8 | I31: =E31*H31 -> 81.4
A32: 27 | B32: 【鲜】五花肉沫 | D32: 斤 | E32: 6 | F32: =H32/0.85 -> 19.764706 | G32: =H32/F32 -> 0.85 | H32: 16.8 | I32: =E32*H32 -> 100.8
A33: 28 | B33: 【鲜】净小鲫鱼 | C33: 2-3两 | D33: 斤 | E33: 5 | F33: =H33/0.85 -> 17.411765 | G33: =H33/F33 -> 0.85 | H33: 14.8 | I33: =E33*H33 -> 74
A34: 29 | B34: 净鳝鱼 | D34: 斤 | E34: 2.5 | F34: =H34/0.85 -> 76.470588 | G34: =H34/F34 -> 0.85 | H34: 65 | I34: =E34*H34 -> 162.5
A35: 30 | B35: 鱿鱼须 | C35: 350g*10袋 | D35: 件 | E35: 1 | F35: =H35/0.85 -> 235.29412 | G35: =H35/F35 -> 0.85 | H35: 200 | I35: =E35*H35 -> 200
A36: 31 | B36: 鸡汁脆笋 | C36: 30袋/件 | D36: 袋 | E36: 4 | F36: =H36/0.85 -> 8 | G36: =H36/F36 -> 0.85 | H36: 6.8 | I36: =E36*H36 -> 27.2
A37: 32 | B37: 坛坛乡剁椒1.15kg | C37: 1.15kg*6瓶/件 | D37: 瓶 | E37: 2 | F37: =H37/0.85 -> 19.411765 | G37: =H37/F37 -> 0.85 | H37: 16.5 | I37: =E37*H37 -> 33
A38: 33 | B38: 鑫海贸紫菜50g | C38: 50g*48包 | D38: 包 | E38: 6 | F38: =H38/0.85 -> 8 | G38: =H38/F38 -> 0.85 | H38: 6.8 | I38: =E38*H38 -> 40.8
A39: 34 | B39: 金龙鱼玉米油 | C39: 5L*4壶/件 | D39: 件 | E39: 1 | F39: =H39/0.85 -> 411.76471 | G39: =H39/F39 -> 0.85 | H39: 350 | I39: =E39*H39 -> 350
A40: 35 | B40: 正和珍珠糯米 | C40: 50斤/袋 | D40: 斤 | E40: 6 | F40: =H40/0.85 -> 5.7647059 | G40: =H40/F40 -> 0.85 | H40: 4.9 | I40: =E40*H40 -> 29.4
A41: 36 | B41: 光明健能酸奶180g | C41: 180g | D41: 杯 | E41: 60 | F41: =H41/0.85 -> 4.1176471 | G41: =H41/F41 -> 0.85 | H41: 3.5 | I41: =E41*H41 -> 210
A42: 供货合计: | B42: =SUM(I6:I41) -> 2674.65
A43: 金额大写： | B43: =B42 -> 2674.65
A44: 制表人 ：樊君丽 收货人： 送货人：

Sheet 19
A1: 武汉康恩农贸发展有限公司送货单
A3: 收货单位： | B3: 汉南数智化检测分公司
A4: 配送日期： | B4: 45218
A5: 序号 | B5: 名称 | C5: 规格 | D5: 单位 | E5: 数量 | F5: 超市价格 | G5: 折扣率 | H5: 折后价 | I5: 折后金额 | J5: 备注
A6: 1 | B6: （新鲜）河粉 | D6: 斤 | E6: 3 | F6: =H6/0.85 -> 3.5294118 | G6: =H6/F6 -> 0.85 | H6: 3 | I6: =E6*H6 -> 9
A7: 2 | B7: 饺子皮 | D7: 斤 | E7: 6 | F7: =H7/0.85 -> 4.1176471 | G7: =H7/F7 -> 0.85 | H7: 3.5 | I7: =E7*H7 -> 21
A8: 3 | B8: 热干面（熟） | D8: 斤 | E8: 3 | F8: =H8/0.85 -> 4.1176471 | G8: =H8/F8 -> 0.85 | H8: 3.5 | I8: =E8*H8 -> 10.5
A9: 4 | B9: 四季豆 | D9: 斤 | E9: 8 | F9: =H9/0.85 -> 10 | G9: =H9/F9 -> 0.85 | H9: 8.5 | I9: =E9*H9 -> 68
A10: 5 | B10: 白萝卜 | D10: 斤 | E10: 9 | F10: =H10/0.85 -> 2.3529412 | G10: =H10/F10 -> 0.85 | H10: 2 | I10: =E10*H10 -> 18
A11: 6 | B11: 蒜苗 | D11: 斤 | E11: 4 | F11: =H11/0.85 -> 11.529412 | G11: =H11/F11 -> 0.85 | H11: 9.8 | I11: =E11*H11 -> 39.2
A12: 7 | B12: 芜湖青椒 | D12: 斤 | E12: 8 | F12: =H12/0.85 -> 6.4705882 | G12: =H12/F12 -> 0.85 | H12: 5.5 | I12: =E12*H12 -> 44
A13: 8 | B13: 有机花菜 | D13: 斤 | E13: 8 | F13: =H13/0.85 -> 6.4705882 | G13: =H13/F13 -> 0.85 | H13: 5.5 | I13: =E13*H13 -> 44
A14: 9 | B14: 平菇 | D14: 斤 | E14: 3 | F14: =H14/0.85 -> 10.352941 | G14: =H14/F14 -> 0.85 | H14: 8.8 | I14: =E14*H14 -> 26.4
A15: 10 | B15: 鲜香菇 | D15: 斤 | E15: 8 | F15: =H15/0.85 -> 11.529412 | G15: =H15/F15 -> 0.85 | H15: 9.8 | I15: =E15*H15 -> 78.4
A16: 11 | B16: 大白菜 | D16: 斤 | E16: 19 | F16: =H16/0.85 -> 2.1176471 | G16: =H16/F16 -> 0.85 | H16: 1.8 | I16: =E16*H16 -> 34.2
A17: 12 | B17: 小白菜 | D17: 斤 | E17: 10 | F17: =H17/0.85 -> 4.1176471 | G17: =H17/F17 -> 0.85 | H17: 3.5 | I17: =E17*H17 -> 35
... A27: 22 | B27: 【鲜】猪五花肉片 | D27: 斤 | E27: 6 | F27: =H27/0.85 -> 21.764706 | G27: =H27/F27 -> 0.85 | H27: 18.5 | I27: =E27*H27 -> 111
A28: 23 | B28: 海天精制蚝油6kg | C28: 6kg*2桶 | D28: 桶 | E28: 1 | F28: =H28/0.85 -> 49.411765 | G28: =H28/F28 -> 0.85 | H28: 42 | I28: =E28*H28 -> 42
A29: 24 | B29: 陶华碧老干妈 | C29: 280g*24瓶/件 | D29: 瓶 | E29: 5 | F29: =H29/0.85 -> 13.882353 | G29: =H29/F29 -> 0.85 | H29: 11.8 | I29: =E29*H29 -> 59
A30: 25 | B30: 云鹤精制碘盐 | C30: 500g*50袋/件 | D30: 袋 | E30: 10 | F30: =H30/0.85 -> 2.3529412 | G30: =H30/F30 -> 0.85 | H30: 2 | I30: =E30*H30 -> 20
A31: 26 | B31: 小米 | C31: 散称 | D31: 斤 | E31: 5 | F31: =H31/0.85 -> 8 | G31: =H31/F31 -> 0.85 | H31: 6.8 | I31: =E31*H31 -> 34
A32: 27 | B32: 光明健能酸奶180g | C32: 180g | D32: 杯 | E32: 65 | F32: =H32/0.85 -> 4.1176471 | G32: =H32/F32 -> 0.85 | H32: 3.5 | I32: =E32*H32 -> 227.5
A33: 供货合计: | B33: =SUM(I6:I32) -> 1772
A34: 金额大写： | B34: =B33 -> 1772
A35: 制表人 ：樊君丽 收货人： 送货人：

Sheet 20.
A1: 武汉康恩农贸发展有限公司送货单
A3: 收货单位： | B3: 汉南数智化检测分公司
A4: 配送日期： | B4: 45219
A5: 序号 | B5: 名称 | C5: 规格 | D5: 单位 | E5: 数量 | F5: 超市价格 | G5: 折扣率 | H5: 折后价 | I5: 折后金额 | J5: 备注
A6: 1 | B6: （新鲜）河粉 | D6: 斤 | E6: 7 | F6: =H6/0.85 -> 3.5294118 | G6: =H6/F6 -> 0.85 | H6: 3 | I6: =E6*H6 -> 21
A7: 2 | B7: 大圆皮 | D7: 斤 | E7: 1 | F7: =H7/0.85 -> 4.7058824 | G7: =H7/F7 -> 0.85 | H7: 4 | I7: =E7*H7 -> 4
A8: 3 | B8: 馄饨皮 | D8: 斤 | E8: 1 | F8: =H8/0.85 -> 4.1176471 | G8: =H8/F8 -> 0.85 | H8: 3.5 | I8: =E8*H8 -> 3.5
A9: 4 | B9: 热干面（熟） | D9: 斤 | E9: 4 | F9: =H9/0.85 -> 4.1176471 | G9: =H9/F9 -> 0.85 | H9: 3.5 | I9: =E9*H9 -> 14
A10: 5 | B10: 青豆角 | D10: 斤 | E10: 4 | F10: =H10/0.85 -> 5.2941176 | G10: =H10/F10 -> 0.85 | H10: 4.5 | I10: =E10*H10 -> 18
A11: 6 | B11: 新鲜毛豆米 | D11: 斤 | E11: 17 | F11: =H11/0.85 -> 17.058824 | G11: =H11/F11 -> 0.85 | H11: 14.5 | I11: =E11*H11 -> 246.5
A12: 7 | B12: 大藕 | D12: 斤 | E12: 12 | F12: =H12/0.85 -> 5.2941176 | G12: =H12/F12 -> 0.85 | H12: 4.5 | I12: =E12*H12 -> 54
A13: 8 | B13: 红椒 | D13: 斤 | E13: 4 | F13: =H13/0.85 -> 9.1764706 | G13: =H13/F13 -> 0.85 | H13: 7.8 | I13: =E13*H13 -> 31.2
A14: 9 | B14: 甜玉米棒 | D14: 个 | E14: 8 | F14: =H14/0.85 -> 3.5294118 | G14: =H14/F14 -> 0.85 | H14: 3 | I14: =E14*H14 -> 24
A15: 10 | B15: 芜湖青椒 | D15: 斤 | E15: 4 | F15: =H15/0.85 -> 6.4705882 | G15: =H15/F15 -> 0.85 | H15: 5.5 | I15: =E15*H15 -> 22
A16: 11 | B16: 西红柿 | D16: 斤 | E16: 11 | F16: =H16/0.85 -> 4.4705882 | G16: =H16/F16 -> 0.85 | H16: 3.8 | I16: =E16*H16 -> 41.8
A17: 12 | B17: 西芹 | D17: 斤 | E17: 15 | F17: =H17/0.85 -> 6.8235294 | G17: =H17/F17 -> 0.85 | H17: 5.8 | I17: =E17*H17 -> 87
... A23: 18 | B23: 烤鸭 | D23: 只 | E23: 3 | F23: =H23/0.85 -> 34.117647 | G23: =H23/F23 -> 0.85 | H23: 29 | I23: =E23*H23 -> 87
A24: 19 | B24: 合鑫泰东北珍珠香米 | C24: 25kg/包 | D24: 袋 | E24: 2 | F24: =H24/0.85 -> 205.88235 | G24: =H24/F24 -> 0.85 | H24: 175 | I24: =E24*H24 -> 350
A25: 20 | B25: 红米 | C25: 散称 | D25: 斤 | E25: 2 | F25: =H25/0.85 -> 8 | G25: =H25/F25 -> 0.85 | H25: 6.8 | I25: =E25*H25 -> 13.6
A26: 21 | B26: 光明健能酸奶180g | C26: 180g | D26: 杯 | E26: 65 | F26: =H26/0.85 -> 4.1176471 | G26: =H26/F26 -> 0.85 | H26: 3.5 | I26: =E26*H26 -> 227.5
A27: 23
A28: 24
A29: 25
A30: 26
A31: 27
A32: 28
A33: 供货合计: | B33: =SUM(I6:I32) -> 1583.8
A34: 金额大写： | B34: =B33 -> 1583.8
A35: 制表人 ：樊君丽 收货人： 送货人：

Sheet 21.
A1: 武汉康恩农贸发展有限公司送货单
A3: 收货单位： | B3: 汉南数智化检测分公司
A4: 配送日期： | B4: 45220
A5: 序号 | B5: 名称 | C5: 规格 | D5: 单位 | E5: 数量 | F5: 超市价格 | G5: 折扣率 | H5: 折后价 | I5: 折后金额 | J5: 备注
A6: 1 | B6: 白萝卜 | D6: 斤 | E6: 6 | F6: =H6/0.85 -> 2.3529412 | G6: =H6/F6 -> 0.85 | H6: 2 | I6: =E6*H6 -> 12
A7: 2 | B7: 大土豆 | D7: 斤 | E7: 8 | F7: =H7/0.85 -> 4.1176471 | G7: =H7/F7 -> 0.85 | H7: 3.5 | I7: =E7*H7 -> 28
A8: 3 | B8: 红椒 | D8: 斤 | E8: 3 | F8: =H8/0.85 -> 9.1764706 | G8: =H8/F8 -> 0.85 | H8: 7.8 | I8: =E8*H8 -> 23.4
A9: 4 | B9: 芜湖青椒 | D9: 斤 | E9: 3 | F9: =H9/0.85 -> 6.4705882 | G9: =H9/F9 -> 0.85 | H9: 5.5 | I9: =E9*H9 -> 16.5
A10: 5 | B10: 有机花菜 | D10: 斤 | E10: 8.8 | F10: =H10/0.85 -> 6.4705882 | G10: =H10/F10 -> 0.85 | H10: 5.5 | I10: =E10*H10 -> 48.4
A11: 6 | B11: 杏鲍菇 | D11: 斤 | E11: 13 | F11: =H11/0.85 -> 6.8235294 | G11: =H11/F11 -> 0.85 | H11: 5.8 | I11: =E11*H11 -> 75.4
A12: 7 | B12: 平包菜 | D12: 斤 | E12: 10.9 | F12: =H12/0.85 -> 2.3529412 | G12: =H12/F12 -> 0.85 | H12: 2 | I12: =E12*H12 -> 21.8
A13: 8 | B13: 细土芹 | D13: 斤 | E13: 5 | F13: =H13/0.85 -> 6.4705882 | G13: =H13/F13 -> 0.85 | H13: 5.5 | I13: =E13*H13 -> 27.5
A14: 9 | B14: 香蕉 | D14: 斤 | E14: 10.6 | F14: =H14/0.85 -> 6.4705882 | G14: =H14/F14 -> 0.85 | H14: 5.5 | I14: =E14*H14 -> 58.3
A15: 10 | B15: 【鲜】猪瘦肉片 | D15: 斤 | E15: 5 | F15: =H15/0.85 -> 25.882353 | G15: =H15/F15 -> 0.85 | H15: 22 | I15: =E15*H15 -> 110
A16: 11 | B16: 【鲜】猪瘦肉丝 | D16: 斤 | E16: 5 | F16: =H16/0.85 -> 25.882353 | G16: =H16/F16 -> 0.85 | H16: 22 | I16: =E16*H16 -> 110
A17: 12 | B17: 【鲜】猪五花肉片 | D17: 斤 | E17: 3 | F17: =H17/0.85 -> 21.764706 | G17: =H17/F17 -> 0.85 | H17: 18.5 | I17: =E17*H17 -> 55.5
A18: 14 | B18: 1911老酸奶 | D18: 杯 | E18: 50 | F18: =H18/0.85 -> 4.1176471 | G18: =H18/F18 -> 0.85 | H18: 3.5 | I18: =E18*H18 -> 175
A19: 15
A20: 16
A21: 17
A22: 18
A23: 19
A24: 20
A25: 21
A26: 22
A27: 23
A28: 24
A29: 25
A30: 26
... A32: 28
A33: 供货合计: | B33: =SUM(I6:I32) -> 761.8
A34: 金额大写： | B34: =B33 -> 761.8
A35: 制表人 ：樊君丽 收货人： 送货人：

Sheet 22
A1: 武汉康恩农贸发展有限公司送货单
A3: 收货单位： | B3: 汉南数智化检测分公司
A4: 配送日期： | B4: 45221
A5: 序号 | B5: 名称 | C5: 规格 | D5: 单位 | E5: 数量 | F5: 超市价格 | G5: 折扣率 | H5: 折后价 | I5: 折后金额 | J5: 备注
A6: 1 | B6: 大白菜 | D6: 斤 | E6: 10.9 | F6: =H6/0.85 -> 2.1176471 | G6: =H6/F6 -> 0.85 | H6: 1.8 | I6: =E6*H6 -> 19.62
A7: 2 | B7: 【鲜】五花肉沫 | D7: 斤 | E7: 2 | F7: =H7/0.85 -> 19.764706 | G7: =H7/F7 -> 0.85 | H7: 16.8 | I7: =E7*H7 -> 33.6
A8: 3 | B8: 手撕鸡 | D8: 只 | E8: 5 | F8: =H8/0.85 -> 30.588235 | G8: =H8/F8 -> 0.85 | H8: 26 | I8: =E8*H8 -> 130
A9: 4
A10: 5
A11: 6
A12: 7
A13: 8
A14: 9
A15: 10
A16: 11
A17: 12
A18: 15
A19: 17
A20: 18
... A30: 28
A31: 供货合计: | B31: =SUM(I6:I30) -> 183.22
A32: 金额大写： | B32: =B31 -> 183.22
A33: 制表人 ：樊君丽 收货人： 送货人：

Sheet 23
A1: 武汉康恩农贸发展有限公司送货单
A3: 收货单位： | B3: 汉南数智化检测分公司
A4: 配送日期： | B4: 45222
A5: 序号 | B5: 名称 | C5: 规格 | D5: 单位 | E5: 数量 | F5: 超市价格 | G5: 折扣率 | H5: 折后价 | I5: 折后金额 | J5: 备注
A6: 1 | B6: （新鲜）河粉 | D6: 斤 | E6: 7 | F6: =H6/0.85 -> 3.5294118 | G6: =H6/F6 -> 0.85 | H6: 3 | I6: =E6*H6 -> 21
A7: 2 | B7: 馄饨皮 | D7: 斤 | E7: 2 | F7: =H7/0.85 -> 4.1176471 | G7: =H7/F7 -> 0.85 | H7: 3.5 | I7: =E7*H7 -> 7
A8: 3 | B8: 热干面（熟） | D8: 斤 | E8: 5 | F8: =H8/0.85 -> 4.1176471 | G8: =H8/F8 -> 0.85 | H8: 3.5 | I8: =E8*H8 -> 17.5
A9: 4 | B9: 蒜米 | D9: 斤 | E9: 4 | F9: =H9/0.85 -> 9.1764706 | G9: =H9/F9 -> 0.85 | H9: 7.8 | I9: =E9*H9 -> 31.2
A10: 5 | B10: 四季豆 | D10: 斤 | E10: 8 | F10: =H10/0.85 -> 10 | G10: =H10/F10 -> 0.85 | H10: 8.5 | I10: =E10*H10 -> 68
A11: 6 | B11: 大土豆 | D11: 斤 | E11: 8 | F11: =H11/0.85 -> 4.1176471 | G11: =H11/F11 -> 0.85 | H11: 3.5 | I11: =E11*H11 -> 28
A12: 7 | B12: 红椒 | D12: 斤 | E12: 4 | F12: =H12/0.85 -> 9.1764706 | G12: =H12/F12 -> 0.85 | H12: 7.8 | I12: =E12*H12 -> 31.2
A13: 8 | B13: 甜玉米棒 | D13: 个 | E13: 8 | F13: =H13/0.85 -> 3.5294118 | G13: =H13/F13 -> 0.85 | H13: 3 | I13: =E13*H13 -> 24
A14: 9 | B14: 芜湖青椒 | D14: 斤 | E14: 4 | F14: =H14/0.85 -> 6.4705882 | G14: =H14/F14 -> 0.85 | H14: 5.5 | I14: =E14*H14 -> 22
A15: 10 | B15: 西红柿 | D15: 斤 | E15: 5 | F15: =H15/0.85 -> 4.4705882 | G15: =H15/F15 -> 0.85 | H15: 3.8 | I15: =E15*H15 -> 19
A16: 11 | B16: 青丝瓜 | D16: 斤 | E16: 19 | F16: =H16/0.85 -> 9.1764706 | G16: =H16/F16 -> 0.85 | H16: 7.8 | I16: =E16*H16 -> 148.2
A17: 12 | B17: 金针菇 | D17: 斤 | E17: 5 | F17: =H17/0.85 -> 8 | G17: =H17/F17 -> 0.85 | H17: 6.8 | I17: =E17*H17 -> 34
... A21: 16 | B21: 嫩豆腐 | D21: 斤 | E21: 8 | F21: =H21/0.85 -> 4.1176471 | G21: =H21/F21 -> 0.85 | H21: 3.5 | I21: =E21*H21 -> 28
A22: 17 | B22: 红壳鸡蛋 | C22: 12板/件 | D22: 件 | E22: 1 | F22: =H22/0.85 -> 352.94118 | G22: =H22/F22 -> 0.85 | H22: 300 | I22: =E22*H22 -> 300
A23: 18 | B23: 【鲜】五花肉沫 | D23: 斤 | E23: 3 | F23: =H23/0.85 -> 19.764706 | G23: =H23/F23 -> 0.85 | H23: 16.8 | I23: =E23*H23 -> 50.4
A24: 19 | B24: 【鲜】猪瘦肉丝 | D24: 斤 | E24: 5 | F24: =H24/0.85 -> 25.882353 | G24: =H24/F24 -> 0.85 | H24: 22 | I24: =E24*H24 -> 110
A25: 20 | B25: 【鲜】猪五花肉片 | D25: 斤 | E25: 5 | F25: =H25/0.85 -> 21.764706 | G25: =H25/F25 -> 0.85 | H25: 18.5 | I25: =E25*H25 -> 92.5
A26: 21 | B26: 【鲜】猪血 | D26: 斤 | E26: 6 | F26: =H26/0.85 -> 5.8823529 | G26: =H26/F26 -> 0.85 | H26: 5 | I26: =E26*H26 -> 30
A27: 22 | B27: 【鲜】净大草鱼 | D27: 斤 | E27: 4 | F27: =H27/0.85 -> 16.235294 | G27: =H27/F27 -> 0.85 | H27: 13.8 | I27: =E27*H27 -> 55.2
A28: 23 | B28: 【鲜】净牛蛙 | D28: 斤 | E28: 6 | F28: =H28/0.85 -> 45.882353 | G28: =H28/F28 -> 0.85 | H28: 39 | I28: =E28*H28 -> 234
A29: 24 | B29: 思念白糯小汤圆（无馅） | C29: 500g*20包/件 | D29: 袋 | E29: 6 | F29: =H29/0.85 -> 10.588235 | G29: =H29/F29 -> 0.85 | H29: 9 | I29: =E29*H29 -> 54
A30: 25 | B30: 孝感米酒900g | C30: 900g*6瓶/件 | D30: 瓶 | E30: 6 | F30: =H30/0.85 -> 10 | G30: =H30/F30 -> 0.85 | H30: 8.5 | I30: =E30*H30 -> 51
A31: 26 | B31: 蒸肉白米粉(细） | C31: 散称 | D31: 斤 | E31: 8 | F31: =H31/0.85 -> 5.2941176 | G31: =H31/F31 -> 0.85 | H31: 4.5 | I31: =E31*H31 -> 36
A32: 28 | B32: 文武酱菜外婆菜 | C32: 208g*40包/件 | D32: 件 | E32: 1 | F32: =H32/0.85 -> 117.64706 | G32: =H32/F32 -> 0.85 | H32: 100 | I32: =E32*H32 -> 100
A33: 29 | B33: 永超榨菜 | C33: 8斤 | D33: 件 | E33: 1 | F33: =H33/0.85 -> 64.705882 | G33: =H33/F33 -> 0.85 | H33: 55 | I33: =E33*H33 -> 55
A34: 30 | B34: 光明健能酸奶180g | C34: 180g | D34: 杯 | E34: 70 | F34: =H34/0.85 -> 4.1176471 | G34: =H34/F34 -> 0.85 | H34: 3.5 | I34: =E34*H34 -> 245
A35: 供货合计: | B35: =SUM(I6:I34) -> 2086.3
A36: 金额大写： | B36: =B35 -> 2086.3
A37: 制表人 ：樊君丽 收货人： 送货人：

Sheet 24
A1: 武汉康恩农贸发展有限公司送货单
A3: 收货单位： | B3: 汉南数智化检测分公司
A4: 配送日期： | B4: 45223
A5: 序号 | B5: 名称 | C5: 规格 | D5: 单位 | E5: 数量 | F5: 超市价格 | G5: 折扣率 | H5: 折后价 | I5: 折后金额 | J5: 备注
A6: 1 | B6: （新鲜）河粉 | D6: 斤 | E6: 7 | F6: =H6/0.85 -> 3.5294118 | G6: =H6/F6 -> 0.85 | H6: 3 | I6: =E6*H6 -> 21
A7: 2 | B7: 干细粉 | C7: 散称 | D7: 斤 | E7: 10 | F7: =H7/0.85 -> 4.1176471 | G7: =H7/F7 -> 0.85 | H7: 3.5 | I7: =E7*H7 -> 35
A8: 3 | B8: 热干面（熟） | D8: 斤 | E8: 5 | F8: =H8/0.85 -> 4.1176471 | G8: =H8/F8 -> 0.85 | H8: 3.5 | I8: =E8*H8 -> 17.5
A9: 4 | B9: 小葱 | D9: 斤 | E9: 1 | F9: =H9/0.85 -> 8 | G9: =H9/F9 -> 0.85 | H9: 6.8 | I9: =E9*H9 -> 6.8
A10: 5 | B10: 青豆角 | D10: 斤 | E10: 15 | F10: =H10/0.85 -> 5.2941176 | G10: =H10/F10 -> 0.85 | H10: 4.5 | I10: =E10*H10 -> 67.5
A11: 6 | B11: 大红薯 | D11: 斤 | E11: 10 | F11: =H11/0.85 -> 4.1176471 | G11: =H11/F11 -> 0.85 | H11: 3.5 | I11: =E11*H11 -> 35
A12: 7 | B12: 红椒 | D12: 斤 | E12: 3 | F12: =H12/0.85 -> 9.1764706 | G12: =H12/F12 -> 0.85 | H12: 7.8 | I12: =E12*H12 -> 23.4
A13: 8 | B13: 胡萝卜 | D13: 斤 | E13: 15 | F13: =H13/0.85 -> 2.9411765 | G13: =H13/F13 -> 0.85 | H13: 2.5 | I13: =E13*H13 -> 37.5
A14: 9 | B14: 芜湖青椒 | D14: 斤 | E14: 10 | F14: =H14/0.85 -> 6.4705882 | G14: =H14/F14 -> 0.85 | H14: 5.5 | I14: =E14*H14 -> 55
A15: 10 | B15: 冬瓜 | D15: 斤 | E15: 9.4 | F15: =H15/0.85 -> 2.9411765 | G15: =H15/F15 -> 0.85 | H15: 2.5 | I15: =E15*H15 -> 23.5
A16: 11 | B16: 黄瓜 | D16: 斤 | E16: 10 | F16: =H16/0.85 -> 5.6470588 | G16: =H16/F16 -> 0.85 | H16: 4.8 | I16: =E16*H16 -> 48
A17: 12 | B17: 平菇 | D17: 斤 | E17: 2 | F17: =H17/0.85 -> 10.352941 | G17: =H17/F17 -> 0.85 | H17: 8.8 | I17: =E17*H17 -> 17.6
A18: 13 | B18: 韭菜 | D18: 斤 | E18: 3 | F18: =H18/0.85 -> 5.6470588 | G18: =H18/F18 -> 0.85 | H18: 4.8 | I18: =E18*H18 -> 14.4
A19: 14 | B19: 生菜 | D19: 斤 | E19: 22.5 | F19: =H19/0.85 -> 5.6470588 | G19: =H19/F19 -> 0.85 | H19: 4.8 | I19: =E19*H19 -> 108
... A26: 21 | B26: 【鲜】猪通排骨 | D26: 斤 | E26: 5 | F26: =H26/0.85 -> 33.882353 | G26: =H26/F26 -> 0.85 | H26: 28.8 | I26: =E26*H26 -> 144
A27: 22 | B27: 劲宝超级生粉 | C27: 5kg | D27: 袋 | E27: 1 | F27: =H27/0.85 -> 97.647059 | G27: =H27/F27 -> 0.85 | H27: 83 | I27: =E27*H27 -> 83
A28: 23 | B28: 水发海带头 | C28: 18斤/件 | D28: 斤 | E28: 8 | F28: =H28/0.85 -> 9.4117647 | G28: =H28/F28 -> 0.85 | H28: 8 | I28: =E28*H28 -> 64
A29: 24 | B29: 干黄豆 | C29: 50斤/件 | D29: 斤 | E29: 8 | F29: =H29/0.85 -> 6.4705882 | G29: =H29/F29 -> 0.85 | H29: 5.5 | I29: =E29*H29 -> 44
A30: 25 | B30: 金龙鱼玉米油 | C30: 5L*4壶/件 | D30: 件 | E30: 1 | F30: =H30/0.85 -> 411.76471 | G30: =H30/F30 -> 0.85 | H30: 350 | I30: =E30*H30 -> 350
A31: 26 | B31: 光明健能酸奶180g | C31: 180g | D31: 杯 | E31: 45 | F31: =H31/0.85 -> 4.1176471 | G31: =H31/F31 -> 0.85 | H31: 3.5 | I31: =E31*H31 -> 157.5
A32: 27
A33: 28
A34: 供货合计: | B34: =SUM(I6:I33) -> 2038.56
A35: 金额大写： | B35: =B34 -> 2038.56
A36: 制表人 ：樊君丽 收货人： 送货人：

Sheet 25
A1: 武汉康恩农贸发展有限公司送货单
A3: 收货单位： | B3: 汉南数智化检测分公司
A4: 配送日期： | B4: 45224
A5: 序号 | B5: 名称 | C5: 规格 | D5: 单位 | E5: 数量 | F5: 超市价格 | G5: 折扣率 | H5: 折后价 | I5: 折后金额 | J5: 备注
A6: 1 | B6: （新鲜）河粉 | D6: 斤 | E6: 6 | F6: =H6/0.85 -> 3.5294118 | G6: =H6/F6 -> 0.85 | H6: 3 | I6: =E6*H6 -> 18
A7: 2 | B7: 饺子皮 | D7: 斤 | E7: 5 | F7: =H7/0.85 -> 4.1176471 | G7: =H7/F7 -> 0.85 | H7: 3.5 | I7: =E7*H7 -> 17.5
A8: 3 | B8: 热干面（熟） | D8: 斤 | E8: 4 | F8: =H8/0.85 -> 4.1176471 | G8: =H8/F8 -> 0.85 | H8: 3.5 | I8: =E8*H8 -> 14
A9: 4 | B9: 生面窝浆 | D9: 斤 | E9: 4 | F9: =H9/0.85 -> 7.0588235 | G9: =H9/F9 -> 0.85 | H9: 6 | I9: =E9*H9 -> 24
A10: 5 | B10: 新鲜毛豆米 | D10: 斤 | E10: 9 | F10: =H10/0.85 -> 17.058824 | G10: =H10/F10 -> 0.85 | H10: 14.5 | I10: =E10*H10 -> 130.5
A11: 6 | B11: 大土豆 | D11: 斤 | E11: 19 | F11: =H11/0.85 -> 4.1176471 | G11: =H11/F11 -> 0.85 | H11: 3.5 | I11: =E11*H11 -> 66.5
A12: 7 | B12: 胡萝卜 | D12: 斤 | E12: 3 | F12: =H12/0.85 -> 2.9411765 | G12: =H12/F12 -> 0.85 | H12: 2.5 | I12: =E12*H12 -> 7.5
A13: 8 | B13: 甜玉米棒 | D13: 个 | E13: 8 | F13: =H13/0.85 -> 3.5294118 | G13: =H13/F13 -> 0.85 | H13: 3 | I13: =E13*H13 -> 24
A14: 9 | B14: 西红柿 | D14: 斤 | E14: 8 | F14: =H14/0.85 -> 4.4705882 | G14: =H14/F14 -> 0.85 | H14: 3.8 | I14: =E14*H14 -> 30.4
A15: 10 | B15: 紫长茄子（细长） | D15: 斤 | E15: 9 | F15: =H15/0.85 -> 4.4705882 | G15: =H15/F15 -> 0.85 | H15: 3.8 | I15: =E15*H15 -> 34.2
A16: 11 | B16: 黄瓜 | D16: 斤 | E16: 10 | F16: =H16/0.85 -> 5.6470588 | G16: =H16/F16 -> 0.85 | H16: 4.8 | I16: =E16*H16 -> 48
A17: 12 | B17: 大白菜 | D17: 斤 | E17: 19 | F17: =H17/0.85 -> 2.1176471 | G17: =H17/F17 -> 0.85 | H17: 1.8 | I17: =E17*H17 -> 34.2
... A21: 16 | B21: 【鲜】五花肉沫 | D21: 斤 | E21: 2 | F21: =H21/0.85 -> 19.764706 | G21: =H21/F21 -> 0.85 | H21: 16.8 | I21: =E21*H21 -> 33.6
A22: 17 | B22: 思念白糯小汤圆（无馅） | C22: 500g*20包/件 | D22: 袋 | E22: 3 | F22: =H22/0.85 -> 10.588235 | G22: =H22/F22 -> 0.85 | H22: 9 | I22: =E22*H22 -> 27
A23: 18 | B23: 云鹤精制碘盐 | C23: 500g*50袋/件 | D23: 袋 | E23: 10 | F23: =H23/0.85 -> 2.3529412 | G23: =H23/F23 -> 0.85 | H23: 2 | I23: =E23*H23 -> 20
A24: 19 | B24: 干黄豆 | C24: 50斤/件 | D24: 斤 | E24: 5 | F24: =H24/0.85 -> 6.4705882 | G24: =H24/F24 -> 0.85 | H24: 5.5 | I24: =E24*H24 -> 27.5
A25: 20 | B25: 合鑫泰东北珍珠香米 | C25: 25kg/包 | D25: 袋 | E25: 2 | F25: =H25/0.85 -> 205.88235 | G25: =H25/F25 -> 0.85 | H25: 175 | I25: =E25*H25 -> 350
A26: 21 | B26: 正和珍珠糯米 | C26: 50斤/袋 | D26: 斤 | E26: 4 | F26: =H26/0.85 -> 5.7647059 | G26: =H26/F26 -> 0.85 | H26: 4.9 | I26: =E26*H26 -> 19.6
A27: 22 | B27: 1911老酸奶 | D27: 杯 | E27: 18 | F27: =H27/0.85 -> 4.1176471 | G27: =H27/F27 -> 0.85 | H27: 3.5 | I27: =E27*H27 -> 63
A28: 23 | B28: 光明健能酸奶180g | C28: 180g | D28: 杯 | E28: 12 | F28: =H28/0.85 -> 4.1176471 | G28: =H28/F28 -> 0.85 | H28: 3.5 | I28: =E28*H28 -> 42
A29: 24
A30: 25
A31: 26
A32: 27
A33: 28
A34: 供货合计: | B34: =SUM(I6:I33) -> 1484
A35: 金额大写： | B35: =B34 -> 1484
A36: 制表人 ：樊君丽 收货人： 送货人：

Sheet 26
A1: 武汉康恩农贸发展有限公司送货单
A3: 收货单位： | B3: 汉南数智化检测分公司
A4: 配送日期： | B4: 45225
A5: 序号 | B5: 名称 | C5: 规格 | D5: 单位 | E5: 数量 | F5: 超市价格 | G5: 折扣率 | H5: 折后价 | I5: 折后金额 | J5: 备注
A6: 1 | B6: （新鲜）河粉 | D6: 斤 | E6: 7 | F6: =H6/0.85 -> 3.5294118 | G6: =H6/F6 -> 0.85 | H6: 3 | I6: =E6*H6 -> 21
A7: 2 | B7: 热干面（熟） | D7: 斤 | E7: 5 | F7: =H7/0.85 -> 4.1176471 | G7: =H7/F7 -> 0.85 | H7: 3.5 | I7: =E7*H7 -> 17.5
A8: 3 | B8: 烧麦皮 | D8: 斤 | E8: 2 | F8: =H8/0.85 -> 4.1176471 | G8: =H8/F8 -> 0.85 | H8: 3.5 | I8: =E8*H8 -> 7
A9: 4 | B9: 白豆角 | D9: 斤 | E9: 9 | F9: =H9/0.85 -> 10 | G9: =H9/F9 -> 0.85 | H9: 8.5 | I9: =E9*H9 -> 76.5
A10: 5 | B10: 白萝卜 | D10: 斤 | E10: 15 | F10: =H10/0.85 -> 2.3529412 | G10: =H10/F10 -> 0.85 | H10: 2 | I10: =E10*H10 -> 30
A11: 6 | B11: 红椒 | D11: 斤 | E11: 3 | F11: =H11/0.85 -> 9.1764706 | G11: =H11/F11 -> 0.85 | H11: 7.8 | I11: =E11*H11 -> 23.4
A12: 7 | B12: 铁棍山药 | D12: 斤 | E12: 3 | F12: =H12/0.85 -> 11.529412 | G12: =H12/F12 -> 0.85 | H12: 9.8 | I12: =E12*H12 -> 29.4
A13: 8 | B13: 芜湖青椒 | D13: 斤 | E13: 3 | F13: =H13/0.85 -> 6.4705882 | G13: =H13/F13 -> 0.85 | H13: 5.5 | I13: =E13*H13 -> 16.5
A14: 9 | B14: 冬瓜 | D14: 斤 | E14: 20 | F14: =H14/0.85 -> 2.9411765 | G14: =H14/F14 -> 0.85 | H14: 2.5 | I14: =E14*H14 -> 50
A15: 10 | B15: 平包菜 | D15: 斤 | E15: 10 | F15: =H15/0.85 -> 2.3529412 | G15: =H15/F15 -> 0.85 | H15: 2 | I15: =E15*H15 -> 20
A16: 11 | B16: 细土芹 | D16: 斤 | E16: 6.5 | F16: =H16/0.85 -> 6.4705882 | G16: =H16/F16 -> 0.85 | H16: 5.5 | I16: =E16*H16 -> 35.75
A17: 12 | B17: 油麦菜 | D17: 斤 | E17: 19 | F17: =H17/0.85 -> 5.2941176 | G17: =H17/F17 -> 0.85 | H17: 4.5 | I17: =E17*H17 -> 85.5
... A22: 17 | B22: 【鲜】净胖头鱼头 | D22: 斤 | E22: 4.9 | F22: =H22/0.85 -> 23.529412 | G22: =H22/F22 -> 0.85 | H22: 20 | I22: =E22*H22 -> 98
A23: 18 | B23: 福达坊芝麻香油 | C23: 360ml*12瓶 | D23: 瓶 | E23: 5 | F23: =H23/0.85 -> 14.705882 | G23: =H23/F23 -> 0.85 | H23: 12.5 | I23: =E23*H23 -> 62.5
A24: 19 | B24: 芝麻酱 | C24: 散称 | D24: 斤 | E24: 6 | F24: =H24/0.85 -> 14.117647 | G24: =H24/F24 -> 0.85 | H24: 12 | I24: =E24*H24 -> 72
A25: 20 | B25: 肉圆 | D25: 斤 | E25: 8 | F25: =H25/0.85 -> 23.529412 | G25: =H25/F25 -> 0.85 | H25: 20 | I25: =E25*H25 -> 160
A26: 21 | B26: 光明健能酸奶180g | C26: 180g | D26: 杯 | E26: 60 | F26: =H26/0.85 -> 4.1176471 | G26: =H26/F26 -> 0.85 | H26: 3.5 | I26: =E26*H26 -> 210
A27: 22
A28: 23
A29: 24
A30: 25
A31: 26
A32: 27
A33: 28
A34: 供货合计: | B34: =SUM(I6:I33) -> 1370.33
A35: 金额大写： | B35: =B34 -> 1370.33
A36: 制表人 ：樊君丽 收货人： 送货人：

Sheet 27
A1: 武汉康恩农贸发展有限公司送货单
A3: 收货单位： | B3: 汉南数智化检测分公司
A4: 配送日期： | B4: 45226
A5: 序号 | B5: 名称 | C5: 规格 | D5: 单位 | E5: 数量 | F5: 超市价格 | G5: 折扣率 | H5: 折后价 | I5: 折后金额 | J5: 备注
A6: 1 | B6: （新鲜）河粉 | D6: 斤 | E6: 7 | F6: =H6/0.85 -> 3.5294118 | G6: =H6/F6 -> 0.85 | H6: 3 | I6: =E6*H6 -> 21
A7: 2 | B7: 馄饨皮 | D7: 斤 | E7: 1 | F7: =H7/0.85 -> 4.1176471 | G7: =H7/F7 -> 0.85 | H7: 3.5 | I7: =E7*H7 -> 3.5
A8: 3 | B8: 饺子皮 | D8: 斤 | E8: 1 | F8: =H8/0.85 -> 4.1176471 | G8: =H8/F8 -> 0.85 | H8: 3.5 | I8: =E8*H8 -> 3.5
A9: 4 | B9: 热干面（熟） | D9: 斤 | E9: 5 | F9: =H9/0.85 -> 4.1176471 | G9: =H9/F9 -> 0.85 | H9: 3.5 | I9: =E9*H9 -> 17.5
A10: 5 | B10: 带皮蒜头 | D10: 斤 | E10: 4 | F10: =H10/0.85 -> 10.352941 | G10: =H10/F10 -> 0.85 | H10: 8.8 | I10: =E10*H10 -> 35.2
A11: 6 | B11: 青大蒜 | D11: 斤 | E11: 4 | F11: =H11/0.85 -> 9.1764706 | G11: =H11/F11 -> 0.85 | H11: 7.8 | I11: =E11*H11 -> 31.2
A12: 7 | B12: 生姜 | D12: 斤 | E12: 5 | F12: =H12/0.85 -> 15.058824 | G12: =H12/F12 -> 0.85 | H12: 12.8 | I12: =E12*H12 -> 64
A13: 8 | B13: 黄豆芽 | D13: 斤 | E13: 19 | F13: =H13/0.85 -> 2.9411765 | G13: =H13/F13 -> 0.85 | H13: 2.5 | I13: =E13*H13 -> 47.5
A14: 9 | B14: 红椒 | D14: 斤 | E14: 4 | F14: =H14/0.85 -> 9.1764706 | G14: =H14/F14 -> 0.85 | H14: 7.8 | I14: =E14*H14 -> 31.2
