Workbook

Sheet 1
A1: 武汉康恩农贸发展有限公司送货单
A3: 收货单位： | B3: 汉南数智化检测分公司
A4: 配送日期： | B4: 45261
A5: 序号 | B5: 名称 | C5: 规格 | D5: 单位 | E5: 数量 | F5: 超市价格 | G5: 折扣率 | H5: 折后价 | I5: 折后金额 | J5: 备注
A6: 1 | B6: （新鲜）河粉 | D6: 斤 | E6: 4 | F6: =H6/0.85 -> 3.5294118 | G6: =H6/F6 -> 0.85 | H6: 3 | I6: =E6*H6 -> 12
A7: 2 | B7: 干细粉 | C7: 散称 | D7: 斤 | E7: 6 | F7: =H7/0.85 -> 4.1176471 | G7: =H7/F7 -> 0.85 | H7: 3.5 | I7: =E7*H7 -> 21
A8: 3 | B8: 馄饨皮 | D8: 斤 | E8: 1 | F8: =H8/0.85 -> 4.1176471 | G8: =H8/F8 -> 0.85 | H8: 3.5 | I8: =E8*H8 -> 3.5
A9: 4 | B9: 热干面（熟） | D9: 斤 | E9: 5 | F9: =H9/0.85 -> 4.1176471 | G9: =H9/F9 -> 0.85 | H9: 3.5 | I9: =E9*H9 -> 17.5
A10: 5 | B10: 小葱 | D10: 斤 | E10: 1 | F10: =H10/0.85 -> 8 | G10: =H10/F10 -> 0.85 | H10: 6.8 | I10: =E10*H10 -> 6.8
A11: 6 | B11: 青豆角 | D11: 斤 | E11: 6 | F11: =H11/0.85 -> 6.8235294 | G11: =H11/F11 -> 0.85 | H11: 5.8 | I11: =E11*H11 -> 34.8
A12: 7 | B12: 白萝卜 | D12: 斤 | E12: 10 | F12: =H12/0.85 -> 2.3529412 | G12: =H12/F12 -> 0.85 | H12: 2 | I12: =E12*H12 -> 20
A13: 8 | B13: 胡萝卜 | D13: 斤 | E13: 9 | F13: =H13/0.85 -> 2.9411765 | G13: =H13/F13 -> 0.85 | H13: 2.5 | I13: =E13*H13 -> 22.5
A14: 9 | B14: 蒜苗 | D14: 斤 | E14: 3 | F14: =H14/0.85 -> 11.529412 | G14: =H14/F14 -> 0.85 | H14: 9.8 | I14: =E14*H14 -> 29.4
A15: 10 | B15: 甜玉米棒 | D15: 个 | E15: 13 | F15: =H15/0.85 -> 3.5294118 | G15: =H15/F15 -> 0.85 | H15: 3 | I15: =E15*H15 -> 39
A16: 11 | B16: 紫长茄子（细长） | D16: 斤 | E16: 7 | F16: =H16/0.85 -> 4.4705882 | G16: =H16/F16 -> 0.85 | H16: 3.8 | I16: =E16*H16 -> 26.6
A17: 12 | B17: 大白菜 | D17: 斤 | E17: 14 | F17: =H17/0.85 -> 2.1176471 | G17: =H17/F17 -> 0.85 | H17: 1.8 | I17: =E17*H17 -> 25.2
A18: 13 | B18: 牛脊骨 | D18: 斤 | E18: 8 | F18: =H18/0.85 -> 25.882353 | G18: =H18/F18 -> 0.85 | H18: 22 | I18: =E18*H18 -> 176
A19: 14 | B19: 鲜羊肉（纯肉去骨） | D19: 斤 | E19: 8 | F19: =H19/0.85 -> 56.470588 | G19: =H19/F19 -> 0.85 | H19: 48 | I19: =E19*H19 -> 384
... A23: 18 | B23: 卤牛肉 | D23: 斤 | E23: 4 | F23: =H23/0.85 -> 103.52941 | G23: =H23/F23 -> 0.85 | H23: 88 | I23: =E23*H23 -> 352
A24: 19
A25: 20
A26: 21
A27: 22
A28: 23
A29: 24
A30: 25
A31: 26
A32: 27
A33: 供货合计: | B33: =SUM(I6:I32) -> 1619.4
A34: 金额大写： | B34: =B33 -> 1619.4
A35: 制表人 ：樊君丽 收货人： 送货人：

Sheet 4
A1: 武汉康恩农贸发展有限公司送货单
A3: 收货单位： | B3: 汉南数智化检测分公司
A4: 配送日期： | B4: 45264
A5: 序号 | B5: 名称 | C5: 规格 | D5: 单位 | E5: 数量 | F5: 超市价格 | G5: 折扣率 | H5: 折后价 | I5: 折后金额 | J5: 备注
A6: 1 | B6: （新鲜）河粉 | D6: 斤 | E6: 8 | F6: =H6/0.85 -> 3.5294118 | G6: =H6/F6 -> 0.85 | H6: 3 | I6: =E6*H6 -> 24
A7: 2 | B7: 馄饨皮 | D7: 斤 | E7: 2 | F7: =H7/0.85 -> 4.1176471 | G7: =H7/F7 -> 0.85 | H7: 3.5 | I7: =E7*H7 -> 7
A8: 3 | B8: 饺子皮 | D8: 斤 | E8: 6 | F8: =H8/0.85 -> 4.1176471 | G8: =H8/F8 -> 0.85 | H8: 3.5 | I8: =E8*H8 -> 21
A9: 4 | B9: 热干面（熟） | D9: 斤 | E9: 5 | F9: =H9/0.85 -> 4.1176471 | G9: =H9/F9 -> 0.85 | H9: 3.5 | I9: =E9*H9 -> 17.5
A10: 5 | B10: 烧麦皮 | D10: 斤 | E10: 2 | F10: =H10/0.85 -> 4.1176471 | G10: =H10/F10 -> 0.85 | H10: 3.5 | I10: =E10*H10 -> 7
A11: 6 | B11: 大藕 | D11: 斤 | E11: 18 | F11: =H11/0.85 -> 4.4705882 | G11: =H11/F11 -> 0.85 | H11: 3.8 | I11: =E11*H11 -> 68.4
A12: 7 | B12: 红椒 | D12: 斤 | E12: 3 | F12: =H12/0.85 -> 8.8235294 | G12: =H12/F12 -> 0.85 | H12: 7.5 | I12: =E12*H12 -> 22.5
A13: 8 | B13: 胡萝卜 | D13: 斤 | E13: 8 | F13: =H13/0.85 -> 2.9411765 | G13: =H13/F13 -> 0.85 | H13: 2.5 | I13: =E13*H13 -> 20
A14: 9 | B14: 芜湖青椒 | D14: 斤 | E14: 6 | F14: =H14/0.85 -> 4.7058824 | G14: =H14/F14 -> 0.85 | H14: 4 | I14: =E14*H14 -> 24
A15: 10 | B15: 平菇 | D15: 斤 | E15: 2 | F15: =H15/0.85 -> 9.1764706 | G15: =H15/F15 -> 0.85 | H15: 7.8 | I15: =E15*H15 -> 15.6
A16: 12 | B16: 韭菜 | D16: 斤 | E16: 3 | F16: =H16/0.85 -> 5.6470588 | G16: =H16/F16 -> 0.85 | H16: 4.8 | I16: =E16*H16 -> 14.4
A17: 13 | B17: 上海青（小颗） | D17: 斤 | E17: 16 | F17: =H17/0.85 -> 2.9411765 | G17: =H17/F17 -> 0.85 | H17: 2.5 | I17: =E17*H17 -> 40
A18: 14 | B18: 红壳鸡蛋 | C18: 12板/件 | D18: 件 | E18: 1 | F18: =H18/0.85 -> 352.94118 | G18: =H18/F18 -> 0.85 | H18: 300 | I18: =E18*H18 -> 300
A19: 15 | B19: 【鲜】净麻鸭 | D19: 斤 | E19: 17.3 | F19: =H19/0.85 -> 25.882353 | G19: =H19/F19 -> 0.85 | H19: 22 | I19: =E19*H19 -> 380.6
A20: 16 | B20: 【鲜】五花肉沫 | D20: 斤 | E20: 4 | F20: =H20/0.85 -> 16.235294 | G20: =H20/F20 -> 0.85 | H20: 13.8 | I20: =E20*H20 -> 55.2
A21: 17 | B21: 【鲜】猪瘦肉片 | D21: 斤 | E21: 5 | F21: =H21/0.85 -> 23.529412 | G21: =H21/F21 -> 0.85 | H21: 20 | I21: =E21*H21 -> 100
A22: 18 | B22: 【鲜】净大草鱼 | D22: 斤 | E22: 14.7 | F22: =H22/0.85 -> 16.235294 | G22: =H22/F22 -> 0.85 | H22: 13.8 | I22: =E22*H22 -> 202.86
A23: 19 | B23: 鲁至尊面粉 | C23: 25kg | D23: 袋 | E23: 1 | F23: =H23/0.85 -> 174.11765 | G23: =H23/F23 -> 0.85 | H23: 148 | I23: =E23*H23 -> 148
A24: 20 | B24: 1911老酸奶 | D24: 杯 | E24: 50 | F24: =H24/0.85 -> 4.1176471 | G24: =H24/F24 -> 0.85 | H24: 3.5 | I24: =E24*H24 -> 175
A25: 21
A26: 22
A27: 23
A28: 24
A29: 25
A30: 26
A31: 27
A32: 供货合计: | B32: =SUM(I6:I31) -> 1643.06
A33: 金额大写： | B33: =B32 -> 1643.06
A34: 制表人 ：樊君丽 收货人： 送货人：

Sheet 5
A1: 武汉康恩农贸发展有限公司送货单
A3: 收货单位： | B3: 汉南数智化检测分公司
A4: 配送日期： | B4: 45265
A5: 序号 | B5: 名称 | C5: 规格 | D5: 单位 | E5: 数量 | F5: 超市价格 | G5: 折扣率 | H5: 折后价 | I5: 折后金额 | J5: 备注
A6: 1 | B6: （新鲜）河粉 | D6: 斤 | E6: 5 | F6: =H6/0.85 -> 3.5294118 | G6: =H6/F6 -> 0.85 | H6: 3 | I6: =E6*H6 -> 15
A7: 2 | B7: 热干面（熟） | D7: 斤 | E7: 6 | F7: =H7/0.85 -> 4.1176471 | G7: =H7/F7 -> 0.85 | H7: 3.5 | I7: =E7*H7 -> 21
A8: 3 | B8: 生姜 | D8: 斤 | E8: 5 | F8: =H8/0.85 -> 15.058824 | G8: =H8/F8 -> 0.85 | H8: 12.8 | I8: =E8*H8 -> 64
A9: 4 | B9: 甜玉米棒 | D9: 个 | E9: 8 | F9: =H9/0.85 -> 3.5294118 | G9: =H9/F9 -> 0.85 | H9: 3 | I9: =E9*H9 -> 24
A10: 5 | B10: 紫长茄子（细长） | D10: 斤 | E10: 15 | F10: =H10/0.85 -> 4.4705882 | G10: =H10/F10 -> 0.85 | H10: 3.8 | I10: =E10*H10 -> 57
A11: 6 | B11: 大白菜 | D11: 斤 | E11: 14 | F11: =H11/0.85 -> 2.1176471 | G11: =H11/F11 -> 0.85 | H11: 1.8 | I11: =E11*H11 -> 25.2
A12: 7 | B12: 细土芹 | D12: 斤 | E12: 2 | F12: =H12/0.85 -> 5.6470588 | G12: =H12/F12 -> 0.85 | H12: 4.8 | I12: =E12*H12 -> 9.6
A13: 8 | B13: 香菜 | D13: 斤 | E13: 1 | F13: =H13/0.85 -> 9.4117647 | G13: =H13/F13 -> 0.85 | H13: 8 | I13: =E13*H13 -> 8
A14: 9 | B14: 丑八怪柑 | D14: 斤 | E14: 28.4 | F14: =H14/0.85 -> 5.8823529 | G14: =H14/F14 -> 0.85 | H14: 5 | I14: =E14*H14 -> 142
A15: 10 | B15: 嫩豆腐 | D15: 斤 | E15: 6 | F15: =H15/0.85 -> 4.1176471 | G15: =H15/F15 -> 0.85 | H15: 3.5 | I15: =E15*H15 -> 21
A16: 11 | B16: 熟鹌鹑蛋 | D16: 斤 | E16: 4 | F16: =H16/0.85 -> 16.235294 | G16: =H16/F16 -> 0.85 | H16: 13.8 | I16: =E16*H16 -> 55.2
A17: 12 | B17: 【鲜】精品五花 | D17: 斤 | E17: 10 | F17: =H17/0.85 -> 22.941176 | G17: =H17/F17 -> 0.85 | H17: 19.5 | I17: =E17*H17 -> 195
A18: 13 | B18: 【鲜】净胖头鱼头 | D18: 斤 | E18: 6.7 | F18: =H18/0.85 -> 23.529412 | G18: =H18/F18 -> 0.85 | H18: 20 | I18: =E18*H18 -> 134
A19: 14 | B19: 海天草菇老抽1.9L | C19: 1.9L*6壶/件 | D19: 件 | E19: 1 | F19: =H19/0.85 -> 170.58824 | G19: =H19/F19 -> 0.85 | H19: 145 | I19: =E19*H19 -> 145
A20: 15 | B20: 劲宝超级生粉 | C20: 5kg | D20: 袋 | E20: 1 | F20: =H20/0.85 -> 97.647059 | G20: =H20/F20 -> 0.85 | H20: 83 | I20: =E20*H20 -> 83
A21: 16 | B21: 合鑫泰东北珍珠香米 | C21: 25kg/包 | D21: 袋 | E21: 2 | F21: =H21/0.85 -> 205.88235 | G21: =H21/F21 -> 0.85 | H21: 175 | I21: =E21*H21 -> 350
A22: 17 | B22: 玉米片 | C22: 散称 | D22: 斤 | E22: 1 | F22: =H22/0.85 -> 5.2941176 | G22: =H22/F22 -> 0.85 | H22: 4.5 | I22: =E22*H22 -> 4.5
A23: 18 | B23: 正和珍珠糯米 | C23: 50斤/袋 | D23: 斤 | E23: 4 | F23: =H23/0.85 -> 5.7647059 | G23: =H23/F23 -> 0.85 | H23: 4.9 | I23: =E23*H23 -> 19.6
A24: 19 | B24: 卤牛肉 | D24: 斤 | E24: 5 | F24: =H24/0.85 -> 103.52941 | G24: =H24/F24 -> 0.85 | H24: 88 | I24: =E24*H24 -> 440
A25: 20
A26: 21
A27: 22
A28: 23
A29: 24
A30: 25
A31: 26
A32: 27
A33: 28
A34: 供货合计: | B34: =SUM(I6:I33) -> 1813.1
A35: 金额大写： | B35: =B34 -> 1813.1
A36: 制表人 ：樊君丽 收货人： 送货人：

Sheet 6
A1: 武汉康恩农贸发展有限公司送货单
A3: 收货单位： | B3: 汉南数智化检测分公司
A4: 配送日期： | B4: 45266
A5: 序号 | B5: 名称 | C5: 规格 | D5: 单位 | E5: 数量 | F5: 超市价格 | G5: 折扣率 | H5: 折后价 | I5: 折后金额 | J5: 备注
A6: 1 | B6: （新鲜）河粉 | D6: 斤 | E6: 5 | F6: =H6/0.85 -> 3.5294118 | G6: =H6/F6 -> 0.85 | H6: 3 | I6: =E6*H6 -> 15
A7: 2 | B7: 馄饨皮 | D7: 斤 | E7: 2 | F7: =H7/0.85 -> 4.1176471 | G7: =H7/F7 -> 0.85 | H7: 3.5 | I7: =E7*H7 -> 7
A8: 3 | B8: 热干面（熟） | D8: 斤 | E8: 7 | F8: =H8/0.85 -> 4.1176471 | G8: =H8/F8 -> 0.85 | H8: 3.5 | I8: =E8*H8 -> 24.5
A9: 4 | B9: 生面窝浆 | D9: 斤 | E9: 4 | F9: =H9/0.85 -> 7.0588235 | G9: =H9/F9 -> 0.85 | H9: 6 | I9: =E9*H9 -> 24
A10: 5 | B10: 小葱 | D10: 斤 | E10: 1 | F10: =H10/0.85 -> 8 | G10: =H10/F10 -> 0.85 | H10: 6.8 | I10: =E10*H10 -> 6.8
A11: 6 | B11: 大藕 | D11: 斤 | E11: 8 | F11: =H11/0.85 -> 4.4705882 | G11: =H11/F11 -> 0.85 | H11: 3.8 | I11: =E11*H11 -> 30.4
A12: 7 | B12: 大土豆 | D12: 斤 | E12: 18 | F12: =H12/0.85 -> 4.1176471 | G12: =H12/F12 -> 0.85 | H12: 3.5 | I12: =E12*H12 -> 63
A13: 8 | B13: 红椒 | D13: 斤 | E13: 2 | F13: =H13/0.85 -> 8.8235294 | G13: =H13/F13 -> 0.85 | H13: 7.5 | I13: =E13*H13 -> 15
A14: 9 | B14: 蒜苗 | D14: 斤 | E14: 9 | F14: =H14/0.85 -> 11.529412 | G14: =H14/F14 -> 0.85 | H14: 9.8 | I14: =E14*H14 -> 88.2
A15: 10 | B15: 芜湖青椒 | D15: 斤 | E15: 2 | F15: =H15/0.85 -> 4.7058824 | G15: =H15/F15 -> 0.85 | H15: 4 | I15: =E15*H15 -> 8
A16: 12 | B16: 平菇 | D16: 斤 | E16: 2 | F16: =H16/0.85 -> 9.1764706 | G16: =H16/F16 -> 0.85 | H16: 7.8 | I16: =E16*H16 -> 15.6
A17: 13 | B17: 鲜香菇 | D17: 斤 | E17: 5 | F17: =H17/0.85 -> 11.529412 | G17: =H17/F17 -> 0.85 | H17: 9.8 | I17: =E17*H17 -> 49
... A22: 18 | B22: 1911老酸奶 | D22: 杯 | E22: 48 | F22: =H22/0.85 -> 4.1176471 | G22: =H22/F22 -> 0.85 | H22: 3.5 | I22: =E22*H22 -> 168
A23: 19
A24: 20
A25: 21
A26: 22
A27: 23
A28: 24
A29: 25
A30: 26
A31: 27
A32: 28
A33: 供货合计: | B33: =SUM(I6:I32) -> 1042.1
A34: 金额大写： | B34: =B33 -> 1042.1
A35: 制表人 ：樊君丽 收货人： 送货人：

Sheet 7
A1: 武汉康恩农贸发展有限公司送货单
A3: 收货单位： | B3: 汉南数智化检测分公司
A4: 配送日期： | B4: 45267
A5: 序号 | B5: 名称 | C5: 规格 | D5: 单位 | E5: 数量 | F5: 超市价格 | G5: 折扣率 | H5: 折后价 | I5: 折后金额 | J5: 备注
A6: 1 | B6: （新鲜）河粉 | D6: 斤 | E6: 4 | F6: =H6/0.85 -> 3.5294118 | G6: =H6/F6 -> 0.85 | H6: 3 | I6: =E6*H6 -> 12
A7: 2 | B7: 热干面（熟） | D7: 斤 | E7: 6 | F7: =H7/0.85 -> 4.1176471 | G7: =H7/F7 -> 0.85 | H7: 3.5 | I7: =E7*H7 -> 21
A8: 3 | B8: 小葱 | D8: 斤 | E8: 1 | F8: =H8/0.85 -> 8 | G8: =H8/F8 -> 0.85 | H8: 6.8 | I8: =E8*H8 -> 6.8
A9: 4 | B9: 大藕 | D9: 斤 | E9: 8 | F9: =H9/0.85 -> 4.4705882 | G9: =H9/F9 -> 0.85 | H9: 3.8 | I9: =E9*H9 -> 30.4
A10: 5 | B10: 大土豆 | D10: 斤 | E10: 10 | F10: =H10/0.85 -> 4.1176471 | G10: =H10/F10 -> 0.85 | H10: 3.5 | I10: =E10*H10 -> 35
A11: 6 | B11: 红椒 | D11: 斤 | E11: 3 | F11: =H11/0.85 -> 8.8235294 | G11: =H11/F11 -> 0.85 | H11: 7.5 | I11: =E11*H11 -> 22.5
A12: 7 | B12: 胡萝卜 | D12: 斤 | E12: 3 | F12: =H12/0.85 -> 2.9411765 | G12: =H12/F12 -> 0.85 | H12: 2.5 | I12: =E12*H12 -> 7.5
A13: 8 | B13: 芜湖青椒 | D13: 斤 | E13: 3 | F13: =H13/0.85 -> 4.7058824 | G13: =H13/F13 -> 0.85 | H13: 4 | I13: =E13*H13 -> 12
A14: 9 | B14: 西芹 | D14: 斤 | E14: 8 | F14: =H14/0.85 -> 5.6470588 | G14: =H14/F14 -> 0.85 | H14: 4.8 | I14: =E14*H14 -> 38.4
A15: 10 | B15: 有机花菜 | D15: 斤 | E15: 8 | F15: =H15/0.85 -> 5.2941176 | G15: =H15/F15 -> 0.85 | H15: 4.5 | I15: =E15*H15 -> 36
A16: 11 | B16: 老南瓜 | D16: 斤 | E16: 18 | F16: =H16/0.85 -> 2.9411765 | G16: =H16/F16 -> 0.85 | H16: 2.5 | I16: =E16*H16 -> 45
A17: 12 | B17: 平包菜 | D17: 斤 | E17: 12 | F17: =H17/0.85 -> 2.3529412 | G17: =H17/F17 -> 0.85 | H17: 2 | I17: =E17*H17 -> 24
... A22: 17 | B22: 小麦仁 | D22: 斤 | E22: 2 | F22: =H22/0.85 -> 4.7058824 | G22: =H22/F22 -> 0.85 | H22: 4 | I22: =E22*H22 -> 8
A23: 18 | B23: 鑫怡久久海带头 | C23: 9KG/件 | D23: 斤 | E23: 4 | F23: =H23/0.85 -> 10 | G23: =H23/F23 -> 0.85 | H23: 8.5 | I23: =E23*H23 -> 34
A24: 19 | B24: 高粱米 | C24: 散称 | D24: 斤 | E24: 2 | F24: =H24/0.85 -> 5.8823529 | G24: =H24/F24 -> 0.85 | H24: 5 | I24: =E24*H24 -> 10
A25: 20 | B25: 荞麦米 | C25: 散称 | D25: 斤 | E25: 2 | F25: =H25/0.85 -> 7.6470588 | G25: =H25/F25 -> 0.85 | H25: 6.5 | I25: =E25*H25 -> 13
A26: 21 | B26: 燕麦米 | D26: 斤 | E26: 2 | F26: =H26/0.85 -> 5.8823529 | G26: =H26/F26 -> 0.85 | H26: 5 | I26: =E26*H26 -> 10
A27: 22 | B27: 玉米碎 | C27: 散称 | D27: 斤 | E27: 2 | F27: =H27/0.85 -> 4.7058824 | G27: =H27/F27 -> 0.85 | H27: 4 | I27: =E27*H27 -> 8
A28: 23 | B28: 正和珍珠糯米 | C28: 50斤/袋 | D28: 斤 | E28: 3 | F28: =H28/0.85 -> 5.7647059 | G28: =H28/F28 -> 0.85 | H28: 4.9 | I28: =E28*H28 -> 14.7
A29: 24 | B29: 卤牛骨头 | D29: 斤 | E29: 6 | F29: =H29/0.85 -> 51.764706 | G29: =H29/F29 -> 0.85 | H29: 44 | I29: =E29*H29 -> 264
A30: 25
A31: 26
A32: 27
A33: 28
A34: 供货合计: | B34: =SUM(I6:I33) -> 1243.4
A35: 金额大写： | B35: =B34 -> 1243.4
A36: 制表人 ：樊君丽 收货人： 送货人：

Sheet 8
A1: 武汉康恩农贸发展有限公司送货单
A3: 收货单位： | B3: 汉南数智化检测分公司
A4: 配送日期： | B4: 45268
A5: 序号 | B5: 名称 | C5: 规格 | D5: 单位 | E5: 数量 | F5: 超市价格 | G5: 折扣率 | H5: 折后价 | I5: 折后金额 | J5: 备注
A6: 1 | B6: （新鲜）河粉 | D6: 斤 | E6: 4 | F6: =H6/0.85 -> 3.5294118 | G6: =H6/F6 -> 0.85 | H6: 3 | I6: =E6*H6 -> 12
A7: 2 | B7: 干细粉 | C7: 散称 | D7: 斤 | E7: 6 | F7: =H7/0.85 -> 4.1176471 | G7: =H7/F7 -> 0.85 | H7: 3.5 | I7: =E7*H7 -> 21
A8: 3 | B8: 热干面（熟） | D8: 斤 | E8: 7 | F8: =H8/0.85 -> 4.1176471 | G8: =H8/F8 -> 0.85 | H8: 3.5 | I8: =E8*H8 -> 24.5
A9: 4 | B9: 烧麦皮 | D9: 斤 | E9: 4 | F9: =H9/0.85 -> 4.1176471 | G9: =H9/F9 -> 0.85 | H9: 3.5 | I9: =E9*H9 -> 14
A10: 5 | B10: 黄豆芽 | D10: 斤 | E10: 3 | F10: =H10/0.85 -> 2.9411765 | G10: =H10/F10 -> 0.85 | H10: 2.5 | I10: =E10*H10 -> 7.5
A11: 6 | B11: 四季豆 | D11: 斤 | E11: 15 | F11: =H11/0.85 -> 10 | G11: =H11/F11 -> 0.85 | H11: 8.5 | I11: =E11*H11 -> 127.5
A12: 7 | B12: 白萝卜 | D12: 斤 | E12: 11 | F12: =H12/0.85 -> 2.3529412 | G12: =H12/F12 -> 0.85 | H12: 2 | I12: =E12*H12 -> 22
A13: 8 | B13: 甜玉米棒 | D13: 个 | E13: 8 | F13: =H13/0.85 -> 3.5294118 | G13: =H13/F13 -> 0.85 | H13: 3 | I13: =E13*H13 -> 24
A14: 9 | B14: 生菜 | D14: 斤 | E14: 12 | F14: =H14/0.85 -> 5.6470588 | G14: =H14/F14 -> 0.85 | H14: 4.8 | I14: =E14*H14 -> 57.6
A15: 10 | B15: 薄千张 | D15: 斤 | E15: 3 | F15: =H15/0.85 -> 8 | G15: =H15/F15 -> 0.85 | H15: 6.8 | I15: =E15*H15 -> 20.4
A16: 11 | B16: 鲜羊蝎子 | D16: 斤 | E16: 8 | F16: =H16/0.85 -> 37.647059 | G16: =H16/F16 -> 0.85 | H16: 32 | I16: =E16*H16 -> 256
A17: 12 | B17: 【鲜】五花肉沫 | D17: 斤 | E17: 4 | F17: =H17/0.85 -> 16.235294 | G17: =H17/F17 -> 0.85 | H17: 13.8 | I17: =E17*H17 -> 55.2
A18: 13 | B18: 泽西客巴沙鱼 | C18: 5斤/袋*4袋/件 | D18: 斤 | E18: 15 | F18: =H18/0.85 -> 15.058824 | G18: =H18/F18 -> 0.85 | H18: 12.8 | I18: =E18*H18 -> 192
A19: 14 | B19: 云鹤精制碘盐 | C19: 500g*50袋/件 | D19: 袋 | E19: 10 | F19: =H19/0.85 -> 2.3529412 | G19: =H19/F19 -> 0.85 | H19: 2 | I19: =E19*H19 -> 20
A20: 15 | B20: 金龙鱼玉米油 | C20: 5L*4壶/件 | D20: 件 | E20: 2 | F20: =H20/0.85 -> 411.76471 | G20: =H20/F20 -> 0.85 | H20: 350 | I20: =E20*H20 -> 700
A21: 16 | B21: 光明健能酸奶180g | C21: 180g | D21: 杯 | E21: 45 | F21: =H21/0.85 -> 4.1176471 | G21: =H21/F21 -> 0.85 | H21: 3.5 | I21: =E21*H21 -> 157.5
A22: 17
A23: 18
A24: 19
A25: 20
A26: 21
A27: 22
A28: 23
A29: 24
A30: 25
A31: 26
A32: 27
A33: 28
A34: 供货合计: | B34: =SUM(I6:I33) -> 1711.2
A35: 金额大写： | B35: =B34 -> 1711.2
A36: 制表人 ：樊君丽 收货人： 送货人：

Sheet 9
A1: 武汉康恩农贸发展有限公司送货单
A3: 收货单位： | B3: 汉南数智化检测分公司
A4: 配送日期： | B4: 45269
A5: 序号 | B5: 名称 | C5: 规格 | D5: 单位 | E5: 数量 | F5: 超市价格 | G5: 折扣率 | H5: 折后价 | I5: 折后金额 | J5: 备注
A6: 1 | B6: 白萝卜 | D6: 斤 | E6: 8.5 | F6: =H6/0.85 -> 2.3529412 | G6: =H6/F6 -> 0.85 | H6: 2 | I6: =E6*H6 -> 17
A7: 2 | B7: 大藕 | D7: 斤 | E7: 8 | F7: =H7/0.85 -> 4.4705882 | G7: =H7/F7 -> 0.85 | H7: 3.8 | I7: =E7*H7 -> 30.4
A8: 3 | B8: 大土豆 | D8: 斤 | E8: 8.3 | F8: =H8/0.85 -> 4.1176471 | G8: =H8/F8 -> 0.85 | H8: 3.5 | I8: =E8*H8 -> 29.05
A9: 4 | B9: 红椒 | D9: 斤 | E9: 2 | F9: =H9/0.85 -> 8.8235294 | G9: =H9/F9 -> 0.85 | H9: 7.5 | I9: =E9*H9 -> 15
A10: 5 | B10: 芜湖青椒 | D10: 斤 | E10: 2 | F10: =H10/0.85 -> 4.7058824 | G10: =H10/F10 -> 0.85 | H10: 4 | I10: =E10*H10 -> 8
A11: 6 | B11: 西红柿 | D11: 斤 | E11: 8 | F11: =H11/0.85 -> 4.4705882 | G11: =H11/F11 -> 0.85 | H11: 3.8 | I11: =E11*H11 -> 30.4
A12: 7 | B12: 冬瓜 | D12: 斤 | E12: 9.3 | F12: =H12/0.85 -> 2.9411765 | G12: =H12/F12 -> 0.85 | H12: 2.5 | I12: =E12*H12 -> 23.25
A13: 8 | B13: 大白菜 | D13: 斤 | E13: 9.6 | F13: =H13/0.85 -> 2.1176471 | G13: =H13/F13 -> 0.85 | H13: 1.8 | I13: =E13*H13 -> 17.28
A14: 9 | B14: 平包菜 | D14: 斤 | E14: 10.3 | F14: =H14/0.85 -> 2.3529412 | G14: =H14/F14 -> 0.85 | H14: 2 | I14: =E14*H14 -> 20.6
A15: 10 | B15: 细土芹 | D15: 斤 | E15: 2 | F15: =H15/0.85 -> 5.6470588 | G15: =H15/F15 -> 0.85 | H15: 4.8 | I15: =E15*H15 -> 9.6
A16: 11 | B16: 油麦菜 | D16: 斤 | E16: 8.2 | F16: =H16/0.85 -> 5.2941176 | G16: =H16/F16 -> 0.85 | H16: 4.5 | I16: =E16*H16 -> 36.9
A17: 12 | B17: 【鲜】五花肉沫 | D17: 斤 | E17: 5 | F17: =H17/0.85 -> 16.235294 | G17: =H17/F17 -> 0.85 | H17: 13.8 | I17: =E17*H17 -> 69
A18: 13 | B18: 【鲜】猪瘦肉片 | D18: 斤 | E18: 5 | F18: =H18/0.85 -> 23.529412 | G18: =H18/F18 -> 0.85 | H18: 20 | I18: =E18*H18 -> 100
A19: 14 | B19: 清水笋丝 | C19: 2.5kg*6包/件 | D19: 包 | E19: 3 | F19: =H19/0.85 -> 16.235294 | G19: =H19/F19 -> 0.85 | H19: 13.8 | I19: =E19*H19 -> 41.4
A20: 15 | B20: 鑫石羊郫县豆瓣酱1kg | C20: 1kg*8桶/件 | D20: 桶 | E20: 1 | F20: =H20/0.85 -> 12.941176 | G20: =H20/F20 -> 0.85 | H20: 11 | I20: =E20*H20 -> 11
A21: 16 | B21: 红油榨菜丝 | C21: 1.5kg*6袋/件 | D21: 件 | E21: 1 | F21: =H21/0.85 -> 76.470588 | G21: =H21/F21 -> 0.85 | H21: 65 | I21: =E21*H21 -> 65
A22: 17
A23: 18
A24: 19
A25: 20
A26: 21
A27: 22
A28: 23
A29: 24
A30: 25
A31: 26
A32: 27
A33: 28
A34: 供货合计: | B34: =SUM(I6:I33) -> 523.88
A35: 金额大写： | B35: =B34 -> 523.88
A36: 制表人 ：樊君丽 收货人： 送货人：

Sheet 11
A1: 武汉康恩农贸发展有限公司送货单
A3: 收货单位： | B3: 汉南数智化检测分公司
A4: 配送日期： | B4: 45271
A5: 序号 | B5: 名称 | C5: 规格 | D5: 单位 | E5: 数量 | F5: 超市价格 | G5: 折扣率 | H5: 折后价 | I5: 折后金额 | J5: 备注
A6: 1 | B6: （新鲜）河粉 | D6: 斤 | E6: 3 | F6: =H6/0.85 -> 3.5294118 | G6: =H6/F6 -> 0.85 | H6: 3 | I6: =E6*H6 -> 9
A7: 2 | B7: 馄饨皮 | D7: 斤 | E7: 2 | F7: =H7/0.85 -> 4.1176471 | G7: =H7/F7 -> 0.85 | H7: 3.5 | I7: =E7*H7 -> 7
A8: 3 | B8: 饺子皮 | D8: 斤 | E8: 6 | F8: =H8/0.85 -> 4.1176471 | G8: =H8/F8 -> 0.85 | H8: 3.5 | I8: =E8*H8 -> 21
A9: 4 | B9: 大红薯 | D9: 斤 | E9: 10 | F9: =H9/0.85 -> 4.1176471 | G9: =H9/F9 -> 0.85 | H9: 3.5 | I9: =E9*H9 -> 35
A10: 6 | B10: 螺丝椒 | D10: 斤 | E10: 7 | F10: =H10/0.85 -> 5.6470588 | G10: =H10/F10 -> 0.85 | H10: 4.8 | I10: =E10*H10 -> 33.6
A11: 7 | B11: 西红柿 | D11: 斤 | E11: 5 | F11: =H11/0.85 -> 4.4705882 | G11: =H11/F11 -> 0.85 | H11: 3.8 | I11: =E11*H11 -> 19
A12: 8 | B12: 紫薯 | D12: 斤 | E12: 5 | F12: =H12/0.85 -> 6.8235294 | G12: =H12/F12 -> 0.85 | H12: 5.8 | I12: =E12*H12 -> 29
A13: 9 | B13: 平菇 | D13: 斤 | E13: 2 | F13: =H13/0.85 -> 9.1764706 | G13: =H13/F13 -> 0.85 | H13: 7.8 | I13: =E13*H13 -> 15.6
A14: 10 | B14: 白菜苔 | D14: 斤 | E14: 13 | F14: =H14/0.85 -> 3.2941176 | G14: =H14/F14 -> 0.85 | H14: 2.8 | I14: =E14*H14 -> 36.4
A15: 11 | B15: 韭菜 | D15: 斤 | E15: 5 | F15: =H15/0.85 -> 5.6470588 | G15: =H15/F15 -> 0.85 | H15: 4.8 | I15: =E15*H15 -> 24
A16: 12 | B16: 香蕉 | D16: 斤 | E16: 24.3 | F16: =H16/0.85 -> 5.2941176 | G16: =H16/F16 -> 0.85 | H16: 4.5 | I16: =E16*H16 -> 109.35
A17: 13 | B17: 嫩豆腐 | D17: 斤 | E17: 15 | F17: =H17/0.85 -> 4.1176471 | G17: =H17/F17 -> 0.85 | H17: 3.5 | I17: =E17*H17 -> 52.5
... A20: 16 | B20: 【鲜】净黄骨鱼 | D20: 斤 | E20: 6.5 | F20: =H20/0.85 -> 28.235294 | G20: =H20/F20 -> 0.85 | H20: 24 | I20: =E20*H20 -> 156
A21: 17 | B21: 思念白糯小汤圆（无馅） | C21: 500g*20包/件 | D21: 袋 | E21: 5 | F21: =H21/0.85 -> 10.588235 | G21: =H21/F21 -> 0.85 | H21: 9 | I21: =E21*H21 -> 45
A22: 18 | B22: 孝感米酒900g | C22: 900g*6瓶/件 | D22: 瓶 | E22: 6 | F22: =H22/0.85 -> 10 | G22: =H22/F22 -> 0.85 | H22: 8.5 | I22: =E22*H22 -> 51
A23: 19 | B23: 正和珍珠糯米 | C23: 50斤/袋 | D23: 斤 | E23: 7 | F23: =H23/0.85 -> 5.7647059 | G23: =H23/F23 -> 0.85 | H23: 4.9 | I23: =E23*H23 -> 34.3
A24: 20
A25: 21
A26: 22
A27: 23
A28: 24
A29: 25
A30: 26
A31: 27
A32: 28
A33: 供货合计: | B33: =SUM(I6:I32) -> 760.55
A34: 金额大写： | B34: =B33 -> 760.55
A35: 制表人 ：樊君丽 收货人： 送货人：

Sheet 12
A1: 武汉康恩农贸发展有限公司送货单
A3: 收货单位： | B3: 汉南数智化检测分公司
A4: 配送日期： | B4: 45272
A5: 序号 | B5: 名称 | C5: 规格 | D5: 单位 | E5: 数量 | F5: 超市价格 | G5: 折扣率 | H5: 折后价 | I5: 折后金额 | J5: 备注
A6: 1 | B6: （新鲜）河粉 | D6: 斤 | E6: 7 | F6: =H6/0.85 -> 3.5294118 | G6: =H6/F6 -> 0.85 | H6: 3 | I6: =E6*H6 -> 21
A7: 2 | B7: 大圆皮 | D7: 斤 | E7: 2 | F7: =H7/0.85 -> 4.7058824 | G7: =H7/F7 -> 0.85 | H7: 4 | I7: =E7*H7 -> 8
A8: 3 | B8: 热干面（熟） | D8: 斤 | E8: 7 | F8: =H8/0.85 -> 4.1176471 | G8: =H8/F8 -> 0.85 | H8: 3.5 | I8: =E8*H8 -> 24.5
A9: 4 | B9: 生姜 | D9: 斤 | E9: 5 | F9: =H9/0.85 -> 15.058824 | G9: =H9/F9 -> 0.85 | H9: 12.8 | I9: =E9*H9 -> 64
A10: 5 | B10: 蒜米 | D10: 斤 | E10: 4 | F10: =H10/0.85 -> 9.1764706 | G10: =H10/F10 -> 0.85 | H10: 7.8 | I10: =E10*H10 -> 31.2
A11: 6 | B11: 小葱 | D11: 斤 | E11: 2 | F11: =H11/0.85 -> 8 | G11: =H11/F11 -> 0.85 | H11: 6.8 | I11: =E11*H11 -> 13.6
A12: 7 | B12: 红椒 | D12: 斤 | E12: 2 | F12: =H12/0.85 -> 8.8235294 | G12: =H12/F12 -> 0.85 | H12: 7.5 | I12: =E12*H12 -> 15
A13: 8 | B13: 甜玉米棒 | D13: 个 | E13: 14 | F13: =H13/0.85 -> 3.5294118 | G13: =H13/F13 -> 0.85 | H13: 3 | I13: =E13*H13 -> 42
A14: 9 | B14: 芜湖青椒 | D14: 斤 | E14: 2 | F14: =H14/0.85 -> 4.7058824 | G14: =H14/F14 -> 0.85 | H14: 4 | I14: =E14*H14 -> 8
A15: 10 | B15: 西兰花 | D15: 斤 | E15: 14 | F15: =H15/0.85 -> 6.8235294 | G15: =H15/F15 -> 0.85 | H15: 5.8 | I15: =E15*H15 -> 81.2
A16: 11 | B16: 平菇 | D16: 斤 | E16: 2 | F16: =H16/0.85 -> 9.1764706 | G16: =H16/F16 -> 0.85 | H16: 7.8 | I16: =E16*H16 -> 15.6
A17: 12 | B17: 鲜香菇 | D17: 斤 | E17: 2 | F17: =H17/0.85 -> 11.529412 | G17: =H17/F17 -> 0.85 | H17: 9.8 | I17: =E17*H17 -> 19.6
... A21: 16 | B21: 小白菜 | D21: 斤 | E21: 2 | F21: =H21/0.85 -> 4.1176471 | G21: =H21/F21 -> 0.85 | H21: 3.5 | I21: =E21*H21 -> 7
A22: 17 | B22: 红壳鸡蛋 | C22: 12板/件 | D22: 件 | E22: 1 | F22: =H22/0.85 -> 352.94118 | G22: =H22/F22 -> 0.85 | H22: 300 | I22: =E22*H22 -> 300
A23: 18 | B23: 【鲜】五花肉沫 | D23: 斤 | E23: 3 | F23: =H23/0.85 -> 16.235294 | G23: =H23/F23 -> 0.85 | H23: 13.8 | I23: =E23*H23 -> 41.4
A24: 19 | B24: 【鲜】猪通排骨 | D24: 斤 | E24: 8 | F24: =H24/0.85 -> 32.941176 | G24: =H24/F24 -> 0.85 | H24: 28 | I24: =E24*H24 -> 224
A25: 20 | B25: 【鲜】净大草鱼 | D25: 斤 | E25: 15.3 | F25: =H25/0.85 -> 16.235294 | G25: =H25/F25 -> 0.85 | H25: 13.8 | I25: =E25*H25 -> 211.14
A26: 21 | B26: 1911老酸奶 | D26: 杯 | E26: 55 | F26: =H26/0.85 -> 4.1176471 | G26: =H26/F26 -> 0.85 | H26: 3.5 | I26: =E26*H26 -> 192.5
A27: 22 | B27: 卤牛肚 | D27: 斤 | E27: 5 | F27: =H27/0.85 -> 103.52941 | G27: =H27/F27 -> 0.85 | H27: 88 | I27: =E27*H27 -> 440
A28: 23
A29: 24
A30: 25
A31: 26
A32: 27
A33: 28
A34: 供货合计: | B34: =SUM(I6:I33) -> 1908.94
A35: 金额大写： | B35: =B34 -> 1908.94
A36: 制表人 ：樊君丽 收货人： 送货人：

Sheet 13
A1: 武汉康恩农贸发展有限公司送货单
A3: 收货单位： | B3: 汉南数智化检测分公司
A4: 配送日期： | B4: 45273
A5: 序号 | B5: 名称 | C5: 规格 | D5: 单位 | E5: 数量 | F5: 超市价格 | G5: 折扣率 | H5: 折后价 | I5: 折后金额 | J5: 备注
A6: 1 | B6: （新鲜）河粉 | D6: 斤 | E6: 5 | F6: =H6/0.85 -> 3.5294118 | G6: =H6/F6 -> 0.85 | H6: 3 | I6: =E6*H6 -> 15
A7: 2 | B7: 大圆皮 | D7: 斤 | E7: 2 | F7: =H7/0.85 -> 4.7058824 | G7: =H7/F7 -> 0.85 | H7: 4 | I7: =E7*H7 -> 8
A8: 3 | B8: 馄饨皮 | D8: 斤 | E8: 2 | F8: =H8/0.85 -> 4.1176471 | G8: =H8/F8 -> 0.85 | H8: 3.5 | I8: =E8*H8 -> 7
A9: 4 | B9: 热干面（熟） | D9: 斤 | E9: 6 | F9: =H9/0.85 -> 4.1176471 | G9: =H9/F9 -> 0.85 | H9: 3.5 | I9: =E9*H9 -> 21
A10: 5 | B10: 烧麦皮 | D10: 斤 | E10: 2 | F10: =H10/0.85 -> 4.1176471 | G10: =H10/F10 -> 0.85 | H10: 3.5 | I10: =E10*H10 -> 7
A11: 6 | B11: 生面窝浆 | D11: 斤 | E11: 5 | F11: =H11/0.85 -> 7.0588235 | G11: =H11/F11 -> 0.85 | H11: 6 | I11: =E11*H11 -> 30
A12: 7 | B12: 白萝卜 | D12: 斤 | E12: 6 | F12: =H12/0.85 -> 2.3529412 | G12: =H12/F12 -> 0.85 | H12: 2 | I12: =E12*H12 -> 12
A13: 8 | B13: 胡萝卜 | D13: 斤 | E13: 8 | F13: =H13/0.85 -> 2.9411765 | G13: =H13/F13 -> 0.85 | H13: 2.5 | I13: =E13*H13 -> 20
A14: 9 | B14: 铁棍山药 | D14: 斤 | E14: 2 | F14: =H14/0.85 -> 10.352941 | G14: =H14/F14 -> 0.85 | H14: 8.8 | I14: =E14*H14 -> 17.6
A15: 10 | B15: 冬瓜 | D15: 斤 | E15: 12 | F15: =H15/0.85 -> 2.9411765 | G15: =H15/F15 -> 0.85 | H15: 2.5 | I15: =E15*H15 -> 30
A16: 11 | B16: 生菜 | D16: 斤 | E16: 12 | F16: =H16/0.85 -> 5.6470588 | G16: =H16/F16 -> 0.85 | H16: 4.8 | I16: =E16*H16 -> 57.6
A17: 12 | B17: 果冻橙 | D17: 斤 | E17: 22.3 | F17: =H17/0.85 -> 8 | G17: =H17/F17 -> 0.85 | H17: 6.8 | I17: =E17*H17 -> 151.64
... A20: 15 | B20: 【鲜】猪瘦肉丝 | D20: 斤 | E20: 9 | F20: =H20/0.85 -> 23.529412 | G20: =H20/F20 -> 0.85 | H20: 20 | I20: =E20*H20 -> 180
A21: 16 | B21: 百味佳香脆炸粉 | C21: 1.2kg/袋 | D21: 袋 | E21: 2 | F21: =H21/0.85 -> 25.882353 | G21: =H21/F21 -> 0.85 | H21: 22 | I21: =E21*H21 -> 44
A22: 17 | B22: 桂皮 | C22: 散称 | D22: 斤 | E22: 1 | F22: =H22/0.85 -> 32.941176 | G22: =H22/F22 -> 0.85 | H22: 28 | I22: =E22*H22 -> 28
A23: 18 | B23: 卤牛肉 | D23: 斤 | E23: 5 | F23: =H23/0.85 -> 103.52941 | G23: =H23/F23 -> 0.85 | H23: 88 | I23: =E23*H23 -> 440
A24: 19
A25: 20
A26: 21
A27: 22
A28: 23
A29: 24
A30: 25
A31: 26
A32: 27
A33: 供货合计: | B33: =SUM(I6:I32) -> 1663.64
A34: 金额大写： | B34: =B33 -> 1663.64
A35: 制表人 ：樊君丽 收货人： 送货人：

Sheet 14
A1: 武汉康恩农贸发展有限公司送货单
A3: 收货单位： | B3: 汉南数智化检测分公司
A4: 配送日期： | B4: 45274
A5: 序号 | B5: 名称 | C5: 规格 | D5: 单位 | E5: 数量 | F5: 超市价格 | G5: 折扣率 | H5: 折后价 | I5: 折后金额 | J5: 备注
A6: 1 | B6: （新鲜）河粉 | D6: 斤 | E6: 5 | F6: =H6/0.85 -> 3.5294118 | G6: =H6/F6 -> 0.85 | H6: 3 | I6: =E6*H6 -> 15
A7: 2 | B7: 热干面（熟） | D7: 斤 | E7: 4 | F7: =H7/0.85 -> 4.1176471 | G7: =H7/F7 -> 0.85 | H7: 3.5 | I7: =E7*H7 -> 14
A8: 3 | B8: 大土豆 | D8: 斤 | E8: 9 | F8: =H8/0.85 -> 4.1176471 | G8: =H8/F8 -> 0.85 | H8: 3.5 | I8: =E8*H8 -> 31.5
A9: 4 | B9: 红椒 | D9: 斤 | E9: 3 | F9: =H9/0.85 -> 8.8235294 | G9: =H9/F9 -> 0.85 | H9: 7.5 | I9: =E9*H9 -> 22.5
A10: 5 | B10: 芜湖青椒 | D10: 斤 | E10: 3 | F10: =H10/0.85 -> 4.7058824 | G10: =H10/F10 -> 0.85 | H10: 4 | I10: =E10*H10 -> 12
A11: 6 | B11: 冬瓜 | D11: 斤 | E11: 7 | F11: =H11/0.85 -> 2.9411765 | G11: =H11/F11 -> 0.85 | H11: 2.5 | I11: =E11*H11 -> 17.5
A12: 7 | B12: 老南瓜 | D12: 斤 | E12: 5.9 | F12: =H12/0.85 -> 2.9411765 | G12: =H12/F12 -> 0.85 | H12: 2.5 | I12: =E12*H12 -> 14.75
A13: 8 | B13: 净芋头 | C13: （去皮，小） | D13: 斤 | E13: 7 | F13: =H13/0.85 -> 10.352941 | G13: =H13/F13 -> 0.85 | H13: 8.8 | I13: =E13*H13 -> 61.6
A14: 9 | B14: 鲜香菇 | D14: 斤 | E14: 2 | F14: =H14/0.85 -> 11.529412 | G14: =H14/F14 -> 0.85 | H14: 9.8 | I14: =E14*H14 -> 19.6
A15: 10 | B15: 细土芹 | D15: 斤 | E15: 2 | F15: =H15/0.85 -> 5.6470588 | G15: =H15/F15 -> 0.85 | H15: 4.8 | I15: =E15*H15 -> 9.6
A16: 11 | B16: 油麦菜 | D16: 斤 | E16: 12 | F16: =H16/0.85 -> 5.2941176 | G16: =H16/F16 -> 0.85 | H16: 4.5 | I16: =E16*H16 -> 54
A17: 12 | B17: 厚干子 | D17: 斤 | E17: 5 | F17: =H17/0.85 -> 8 | G17: =H17/F17 -> 0.85 | H17: 6.8 | I17: =E17*H17 -> 34
A18: 13 | B18: 嫩豆腐 | D18: 斤 | E18: 6 | F18: =H18/0.85 -> 4.1176471 | G18: =H18/F18 -> 0.85 | H18: 3.5 | I18: =E18*H18 -> 21
A19: 14 | B19: 【鲜】净麻鸭 | D19: 斤 | E19: 9.4 | F19: =H19/0.85 -> 25.882353 | G19: =H19/F19 -> 0.85 | H19: 22 | I19: =E19*H19 -> 206.8
A20: 15 | B20: 【鲜】净三黄鸡 | D20: 斤 | E20: 6 | F20: =H20/0.85 -> 17.411765 | G20: =H20/F20 -> 0.85 | H20: 14.8 | I20: =E20*H20 -> 88.8
A21: 16 | B21: 【鲜】五花肉沫 | D21: 斤 | E21: 2 | F21: =H21/0.85 -> 16.235294 | G21: =H21/F21 -> 0.85 | H21: 13.8 | I21: =E21*H21 -> 27.6
A22: 17 | B22: 【鲜】猪瘦肉片 | D22: 斤 | E22: 6 | F22: =H22/0.85 -> 23.529412 | G22: =H22/F22 -> 0.85 | H22: 20 | I22: =E22*H22 -> 120
A23: 18 | B23: 【鲜】猪五花肉片 | D23: 斤 | E23: 7 | F23: =H23/0.85 -> 19.764706 | G23: =H23/F23 -> 0.85 | H23: 16.8 | I23: =E23*H23 -> 117.6
A24: 19 | B24: 【鲜】猪血 | D24: 斤 | E24: 6 | F24: =H24/0.85 -> 5.8823529 | G24: =H24/F24 -> 0.85 | H24: 5 | I24: =E24*H24 -> 30
A25: 20 | B25: 1911老酸奶 | D25: 杯 | E25: 55 | F25: =H25/0.85 -> 4.1176471 | G25: =H25/F25 -> 0.85 | H25: 3.5 | I25: =E25*H25 -> 192.5
A26: 21 | B26: 卤牛骨头 | D26: 斤 | E26: 8 | F26: =H26/0.85 -> 51.764706 | G26: =H26/F26 -> 0.85 | H26: 44 | I26: =E26*H26 -> 352
A27: 22
A28: 23
A29: 24
A30: 25
A31: 供货合计: | B31: =SUM(I6:I30) -> 1462.35
A32: 金额大写： | B32: =B31 -> 1462.35
A33: 制表人 ：樊君丽 收货人： 送货人：

Sheet 15
A1: 武汉康恩农贸发展有限公司送货单
A3: 收货单位： | B3: 汉南数智化检测分公司
A4: 配送日期： | B4: 45275
A5: 序号 | B5: 名称 | C5: 规格 | D5: 单位 | E5: 数量 | F5: 超市价格 | G5: 折扣率 | H5: 折后价 | I5: 折后金额 | J5: 备注
A6: 1 | B6: （新鲜）河粉 | D6: 斤 | E6: 4 | F6: =H6/0.85 -> 3.5294118 | G6: =H6/F6 -> 0.85 | H6: 3 | I6: =E6*H6 -> 12
A7: 2 | B7: 干细粉 | C7: 散称 | D7: 斤 | E7: 10 | F7: =H7/0.85 -> 4.1176471 | G7: =H7/F7 -> 0.85 | H7: 3.5 | I7: =E7*H7 -> 35
A8: 3 | B8: 热干面（熟） | D8: 斤 | E8: 3 | F8: =H8/0.85 -> 4.1176471 | G8: =H8/F8 -> 0.85 | H8: 3.5 | I8: =E8*H8 -> 10.5
A9: 4 | B9: 白萝卜 | D9: 斤 | E9: 4 | F9: =H9/0.85 -> 2.3529412 | G9: =H9/F9 -> 0.85 | H9: 2 | I9: =E9*H9 -> 8
A10: 5 | B10: 红椒 | D10: 斤 | E10: 2 | F10: =H10/0.85 -> 8.8235294 | G10: =H10/F10 -> 0.85 | H10: 7.5 | I10: =E10*H10 -> 15
A11: 6 | B11: 胡萝卜 | D11: 斤 | E11: 3 | F11: =H11/0.85 -> 2.9411765 | G11: =H11/F11 -> 0.85 | H11: 2.5 | I11: =E11*H11 -> 7.5
A12: 7 | B12: 甜玉米棒 | D12: 个 | E12: 8 | F12: =H12/0.85 -> 3.5294118 | G12: =H12/F12 -> 0.85 | H12: 3 | I12: =E12*H12 -> 24
A13: 8 | B13: 铁棍山药 | D13: 斤 | E13: 5 | F13: =H13/0.85 -> 10.352941 | G13: =H13/F13 -> 0.85 | H13: 8.8 | I13: =E13*H13 -> 44
A14: 9 | B14: 芜湖青椒 | D14: 斤 | E14: 2 | F14: =H14/0.85 -> 4.7058824 | G14: =H14/F14 -> 0.85 | H14: 4 | I14: =E14*H14 -> 8
A15: 10 | B15: 紫长茄子（细长） | D15: 斤 | E15: 14 | F15: =H15/0.85 -> 4.4705882 | G15: =H15/F15 -> 0.85 | H15: 3.8 | I15: =E15*H15 -> 53.2
A16: 11 | B16: 黄瓜 | D16: 斤 | E16: 5 | F16: =H16/0.85 -> 4.4705882 | G16: =H16/F16 -> 0.85 | H16: 3.8 | I16: =E16*H16 -> 19
A17: 12 | B17: 大白菜 | D17: 斤 | E17: 13 | F17: =H17/0.85 -> 2.1176471 | G17: =H17/F17 -> 0.85 | H17: 1.8 | I17: =E17*H17 -> 23.4
A18: 13 | B18: 香梨 | D18: 斤 | E18: 28.7 | F18: =H18/0.85 -> 12.705882 | G18: =H18/F18 -> 0.85 | H18: 10.8 | I18: =E18*H18 -> 309.96
A19: 14 | B19: 【鲜】净三黄鸡 | D19: 斤 | E19: 5.7 | F19: =H19/0.85 -> 17.411765 | G19: =H19/F19 -> 0.85 | H19: 14.8 | I19: =E19*H19 -> 84.36
A20: 15 | B20: 【鲜】基围虾 | D20: 斤 | E20: 8 | F20: =H20/0.85 -> 44.705882 | G20: =H20/F20 -> 0.85 | H20: 38 | I20: =E20*H20 -> 304
A21: 16 | B21: 奥利客烘焙调理奶油 | C21: 907g/12瓶/件 | D21: 瓶 | E21: 12 | F21: =H21/0.85 -> 25.882353 | G21: =H21/F21 -> 0.85 | H21: 22 | I21: =E21*H21 -> 264
A22: 17 | B22: 爆浆糍粑 | C22: 300克 | D22: 袋 | E22: 20 | F22: =H22/0.85 -> 10.588235 | G22: =H22/F22 -> 0.85 | H22: 9 | I22: =E22*H22 -> 180
A23: 18 | B23: 鸿升泰桂花白糖米糕 | C23: 400g*16袋 | D23: 件 | E23: 1 | F23: =H23/0.85 -> 176.47059 | G23: =H23/F23 -> 0.85 | H23: 150 | I23: =E23*H23 -> 150
A24: 19 | B24: 太合鸡脯肉 | C24: 9.8kg/件 | D24: 斤 | E24: 6 | F24: =H24/0.85 -> 11.529412 | G24: =H24/F24 -> 0.85 | H24: 9.8 | I24: =E24*H24 -> 58.8
A25: 20 | B25: 南德调味料 | C25: 150g*46袋 | D25: 袋 | E25: 2 | F25: =H25/0.85 -> 8 | G25: =H25/F25 -> 0.85 | H25: 6.8 | I25: =E25*H25 -> 13.6
A26: 21 | B26: 三象水磨糯米粉 | C26: 500g | D26: 袋 | E26: 5 | F26: =H26/0.85 -> 11.529412 | G26: =H26/F26 -> 0.85 | H26: 9.8 | I26: =E26*H26 -> 49
A27: 22 | B27: 双效泡打粉（小袋） | C27: 50g | D27: 袋 | E27: 1 | F27: =H27/0.85 -> 1.7647059 | G27: =H27/F27 -> 0.85 | H27: 1.5 | I27: =E27*H27 -> 1.5
A28: 23 | B28: 王守义十三香 | C28: 45g*10盒/条 | D28: 盒 | E28: 3 | F28: =H28/0.85 -> 4.9411765 | G28: =H28/F28 -> 0.85 | H28: 4.2 | I28: =E28*H28 -> 12.6
A29: 24
A30: 25
A31: 26
A32: 27
A33: 28
A34: 供货合计: | B34: =SUM(I6:I33) -> 1687.42
A35: 金额大写： | B35: =B34 -> 1687.42
A36: 制表人 ：樊君丽 收货人： 送货人：

Sheet 18
A1: 武汉康恩农贸发展有限公司送货单
A3: 收货单位： | B3: 汉南数智化检测分公司
A4: 配送日期： | B4: 45278
A5: 序号 | B5: 名称 | C5: 规格 | D5: 单位 | E5: 数量 | F5: 超市价格 | G5: 折扣率 | H5: 折后价 | I5: 折后金额 | J5: 备注
A6: 1 | B6: （新鲜）河粉 | D6: 斤 | E6: 5 | F6: =H6/0.85 -> 3.5294118 | G6: =H6/F6 -> 0.85 | H6: 3 | I6: =E6*H6 -> 15
A7: 2 | B7: 馄饨皮 | D7: 斤 | E7: 2 | F7: =H7/0.85 -> 4.1176471 | G7: =H7/F7 -> 0.85 | H7: 3.5 | I7: =E7*H7 -> 7
A8: 3 | B8: 热干面（熟） | D8: 斤 | E8: 7 | F8: =H8/0.85 -> 4.1176471 | G8: =H8/F8 -> 0.85 | H8: 3.5 | I8: =E8*H8 -> 24.5
A9: 4 | B9: 大红薯 | D9: 斤 | E9: 5 | F9: =H9/0.85 -> 4.1176471 | G9: =H9/F9 -> 0.85 | H9: 3.5 | I9: =E9*H9 -> 17.5
A10: 5 | B10: 大土豆 | D10: 斤 | E10: 10 | F10: =H10/0.85 -> 4.1176471 | G10: =H10/F10 -> 0.85 | H10: 3.5 | I10: =E10*H10 -> 35
A11: 6 | B11: 红椒 | D11: 斤 | E11: 2 | F11: =H11/0.85 -> 8.8235294 | G11: =H11/F11 -> 0.85 | H11: 7.5 | I11: =E11*H11 -> 15
A12: 7 | B12: 芜湖青椒 | D12: 斤 | E12: 2 | F12: =H12/0.85 -> 4.7058824 | G12: =H12/F12 -> 0.85 | H12: 4 | I12: =E12*H12 -> 8
A13: 8 | B13: 生菜 | D13: 斤 | E13: 13 | F13: =H13/0.85 -> 5.6470588 | G13: =H13/F13 -> 0.85 | H13: 4.8 | I13: =E13*H13 -> 62.4
A14: 9 | B14: 细土芹 | D14: 斤 | E14: 3 | F14: =H14/0.85 -> 5.6470588 | G14: =H14/F14 -> 0.85 | H14: 4.8 | I14: =E14*H14 -> 14.4
A15: 10 | B15: 香菜 | D15: 斤 | E15: 1 | F15: =H15/0.85 -> 9.4117647 | G15: =H15/F15 -> 0.85 | H15: 8 | I15: =E15*H15 -> 8
A16: 11 | B16: 厚干子 | D16: 斤 | E16: 7 | F16: =H16/0.85 -> 8 | G16: =H16/F16 -> 0.85 | H16: 6.8 | I16: =E16*H16 -> 47.6
A17: 12 | B17: 【鲜】五花肉沫 | D17: 斤 | E17: 5 | F17: =H17/0.85 -> 16.235294 | G17: =H17/F17 -> 0.85 | H17: 13.8 | I17: =E17*H17 -> 69
A18: 13 | B18: 【鲜】猪瘦肉丝 | D18: 斤 | E18: 5 | F18: =H18/0.85 -> 23.529412 | G18: =H18/F18 -> 0.85 | H18: 20 | I18: =E18*H18 -> 100
A19: 14 | B19: 太合琵琶腿 | C19: 10kg/件 | D19: 件 | E19: 1 | F19: =H19/0.85 -> 223.52941 | G19: =H19/F19 -> 0.85 | H19: 190 | I19: =E19*H19 -> 190
A20: 15 | B20: 白豆蔻 | C20: 散称 | D20: 斤 | E20: 0.5 | F20: =H20/0.85 -> 56.470588 | G20: =H20/F20 -> 0.85 | H20: 48 | I20: =E20*H20 -> 24
A21: 16 | B21: 干白芷片 | C21: 散称 | D21: 斤 | E21: 0.5 | F21: =H21/0.85 -> 32.941176 | G21: =H21/F21 -> 0.85 | H21: 28 | I21: =E21*H21 -> 14
A22: 17 | B22: 王致和精制料酒500ml | C22: 500ml*15瓶/件 | D22: 瓶 | E22: 2 | F22: =H22/0.85 -> 7.0588235 | G22: =H22/F22 -> 0.85 | H22: 6 | I22: =E22*H22 -> 12
A23: 18 | B23: 香砂仁 | D23: 斤 | E23: 1 | F23: =H23/0.85 -> 32.941176 | G23: =H23/F23 -> 0.85 | H23: 28 | I23: =E23*H23 -> 28
A24: 19 | B24: 正和珍珠糯米 | C24: 50斤/袋 | D24: 斤 | E24: 4 | F24: =H24/0.85 -> 5.7647059 | G24: =H24/F24 -> 0.85 | H24: 4.9 | I24: =E24*H24 -> 19.6
A25: 20 | B25: 1911老酸奶 | D25: 杯 | E25: 55 | F25: =H25/0.85 -> 4.1176471 | G25: =H25/F25 -> 0.85 | H25: 3.5 | I25: =E25*H25 -> 192.5
A26: 21 | B26: 卤牛肉 | D26: 斤 | E26: 5 | F26: =H26/0.85 -> 103.52941 | G26: =H26/F26 -> 0.85 | H26: 88 | I26: =E26*H26 -> 440
A27: 22
A28: 23
A29: 24
A30: 25
A31: 26
A32: 27
A33: 28
A34: 供货合计: | B34: =SUM(I6:I33) -> 1343.5
A35: 金额大写： | B35: =B34 -> 1343.5
A36: 制表人 ：樊君丽 收货人： 送货人：

Sheet 19
A1: 武汉康恩农贸发展有限公司送货单
A3: 收货单位： | B3: 汉南数智化检测分公司
A4: 配送日期： | B4: 45279
A5: 序号 | B5: 名称 | C5: 规格 | D5: 单位 | E5: 数量 | F5: 超市价格 | G5: 折扣率 | H5: 折后价 | I5: 折后金额 | J5: 备注
A6: 1 | B6: （新鲜）河粉 | D6: 斤 | E6: 4 | F6: =H6/0.85 -> 3.5294118 | G6: =H6/F6 -> 0.85 | H6: 3 | I6: =E6*H6 -> 12
A7: 2 | B7: 饺子皮 | D7: 斤 | E7: 6 | F7: =H7/0.85 -> 4.1176471 | G7: =H7/F7 -> 0.85 | H7: 3.5 | I7: =E7*H7 -> 21
A8: 3 | B8: 热干面（熟） | D8: 斤 | E8: 5 | F8: =H8/0.85 -> 4.1176471 | G8: =H8/F8 -> 0.85 | H8: 3.5 | I8: =E8*H8 -> 17.5
A9: 4 | B9: 生姜 | D9: 斤 | E9: 5 | F9: =H9/0.85 -> 15.058824 | G9: =H9/F9 -> 0.85 | H9: 12.8 | I9: =E9*H9 -> 64
A10: 5 | B10: 大藕 | D10: 斤 | E10: 10 | F10: =H10/0.85 -> 4.4705882 | G10: =H10/F10 -> 0.85 | H10: 3.8 | I10: =E10*H10 -> 38
A11: 6 | B11: 大土豆 | D11: 斤 | E11: 8 | F11: =H11/0.85 -> 4.1176471 | G11: =H11/F11 -> 0.85 | H11: 3.5 | I11: =E11*H11 -> 28
A12: 7 | B12: 胡萝卜 | D12: 斤 | E12: 6 | F12: =H12/0.85 -> 2.9411765 | G12: =H12/F12 -> 0.85 | H12: 2.5 | I12: =E12*H12 -> 15
A13: 8 | B13: 甜玉米棒 | D13: 个 | E13: 8 | F13: =H13/0.85 -> 3.5294118 | G13: =H13/F13 -> 0.85 | H13: 3 | I13: =E13*H13 -> 24
A14: 9 | B14: 铁棍山药 | D14: 斤 | E14: 8 | F14: =H14/0.85 -> 10.352941 | G14: =H14/F14 -> 0.85 | H14: 8.8 | I14: =E14*H14 -> 70.4
A15: 10 | B15: 平菇 | D15: 斤 | E15: 2 | F15: =H15/0.85 -> 9.1764706 | G15: =H15/F15 -> 0.85 | H15: 7.8 | I15: =E15*H15 -> 15.6
A16: 11 | B16: 韭菜 | D16: 斤 | E16: 4 | F16: =H16/0.85 -> 5.6470588 | G16: =H16/F16 -> 0.85 | H16: 4.8 | I16: =E16*H16 -> 19.2
A17: 12 | B17: 上海青（小颗） | D17: 斤 | E17: 13 | F17: =H17/0.85 -> 2.9411765 | G17: =H17/F17 -> 0.85 | H17: 2.5 | I17: =E17*H17 -> 32.5
... A22: 17 | B22: 【鲜】猪通排骨 | D22: 斤 | E22: 7 | F22: =H22/0.85 -> 32.941176 | G22: =H22/F22 -> 0.85 | H22: 28 | I22: =E22*H22 -> 196
A23: 18 | B23: 厨师乐加鲜味精 | C23: 2.27kg*10袋/件 | D23: 件 | E23: 1 | F23: =H23/0.85 -> 529.41176 | G23: =H23/F23 -> 0.85 | H23: 450 | I23: =E23*H23 -> 450
A24: 19 | B24: 水塔陈醋 | D24: 件 | E24: 1 | F24: =H24/0.85 -> 76.470588 | G24: =H24/F24 -> 0.85 | H24: 65 | I24: =E24*H24 -> 65
A25: 20 | B25: 合鑫泰东北珍珠香米 | C25: 25kg/包 | D25: 袋 | E25: 2 | F25: =H25/0.85 -> 205.88235 | G25: =H25/F25 -> 0.85 | H25: 175 | I25: =E25*H25 -> 350
A26: 21 | B26: 金龙鱼玉米油 | C26: 5L*4壶/件 | D26: 件 | E26: 3 | F26: =H26/0.85 -> 411.76471 | G26: =H26/F26 -> 0.85 | H26: 350 | I26: =E26*H26 -> 1050
A27: 22
A28: 23
A29: 24
A30: 25
A31: 26
A32: 27
A33: 供货合计: | B33: =SUM(I6:I32) -> 3125.5
A34: 金额大写： | B34: =B33 -> 3125.5
A35: 制表人 ：樊君丽 收货人： 送货人：

Sheet 20.
A1: 武汉康恩农贸发展有限公司送货单
A3: 收货单位： | B3: 汉南数智化检测分公司
A4: 配送日期： | B4: 45280
A5: 序号 | B5: 名称 | C5: 规格 | D5: 单位 | E5: 数量 | F5: 超市价格 | G5: 折扣率 | H5: 折后价 | I5: 折后金额 | J5: 备注
A6: 1 | B6: （新鲜）河粉 | D6: 斤 | E6: 3 | F6: =H6/0.85 -> 3.5294118 | G6: =H6/F6 -> 0.85 | H6: 3 | I6: =E6*H6 -> 9
A7: 2 | B7: 饺子皮 | D7: 斤 | E7: 10 | F7: =H7/0.85 -> 4.1176471 | G7: =H7/F7 -> 0.85 | H7: 3.5 | I7: =E7*H7 -> 35
A8: 3 | B8: 热干面（熟） | D8: 斤 | E8: 5 | F8: =H8/0.85 -> 4.1176471 | G8: =H8/F8 -> 0.85 | H8: 3.5 | I8: =E8*H8 -> 17.5
A9: 4 | B9: 小葱 | D9: 斤 | E9: 1 | F9: =H9/0.85 -> 8 | G9: =H9/F9 -> 0.85 | H9: 6.8 | I9: =E9*H9 -> 6.8
A10: 5 | B10: 刀豆 | D10: 斤 | E10: 13 | F10: =H10/0.85 -> 10.588235 | G10: =H10/F10 -> 0.85 | H10: 9 | I10: =E10*H10 -> 117
A11: 6 | B11: 红菜苔 | D11: 斤 | E11: 12 | F11: =H11/0.85 -> 4.7058824 | G11: =H11/F11 -> 0.85 | H11: 4 | I11: =E11*H11 -> 48
A12: 7 | B12: 红椒 | D12: 斤 | E12: 2 | F12: =H12/0.85 -> 8.8235294 | G12: =H12/F12 -> 0.85 | H12: 7.5 | I12: =E12*H12 -> 15
A13: 8 | B13: 青椒 | D13: 斤 | E13: 2 | F13: =H13/0.85 -> 4.7058824 | G13: =H13/F13 -> 0.85 | H13: 4 | I13: =E13*H13 -> 8
A14: 9 | B14: 蒜苗 | D14: 斤 | E14: 10 | F14: =H14/0.85 -> 11.529412 | G14: =H14/F14 -> 0.85 | H14: 9.8 | I14: =E14*H14 -> 98
A15: 10 | B15: 甜玉米棒 | D15: 个 | E15: 6 | F15: =H15/0.85 -> 3.5294118 | G15: =H15/F15 -> 0.85 | H15: 3 | I15: =E15*H15 -> 18
A16: 11 | B16: 铁棍山药 | D16: 斤 | E16: 3 | F16: =H16/0.85 -> 10.352941 | G16: =H16/F16 -> 0.85 | H16: 8.8 | I16: =E16*H16 -> 26.4
A17: 12 | B17: 黄瓜 | D17: 斤 | E17: 6.4 | F17: =H17/0.85 -> 4.4705882 | G17: =H17/F17 -> 0.85 | H17: 3.8 | I17: =E17*H17 -> 24.32
A18: 13 | B18: 红壳鸡蛋 | C18: 12板/件 | D18: 件 | E18: 1 | F18: =H18/0.85 -> 352.94118 | G18: =H18/F18 -> 0.85 | H18: 300 | I18: =E18*H18 -> 300
A19: 14 | B19: 【鲜】净麻鸭 | D19: 斤 | E19: 9.6 | F19: =H19/0.85 -> 25.882353 | G19: =H19/F19 -> 0.85 | H19: 22 | I19: =E19*H19 -> 211.2
A20: 15 | B20: 【鲜】净三黄鸡 | D20: 斤 | E20: 6.6 | F20: =H20/0.85 -> 17.411765 | G20: =H20/F20 -> 0.85 | H20: 14.8 | I20: =E20*H20 -> 97.68
A21: 16 | B21: 【鲜】五花肉沫 | D21: 斤 | E21: 4 | F21: =H21/0.85 -> 16.235294 | G21: =H21/F21 -> 0.85 | H21: 13.8 | I21: =E21*H21 -> 55.2
A22: 17 | B22: 【鲜】净大草鱼 | D22: 斤 | E22: 13 | F22: =H22/0.85 -> 16.235294 | G22: =H22/F22 -> 0.85 | H22: 13.8 | I22: =E22*H22 -> 179.4
A23: 18 | B23: 李锦记蒸鱼豉油1.9L | C23: 1.9L*6瓶/件 | D23: 件 | E23: 1 | F23: =H23/0.85 -> 303.52941 | G23: =H23/F23 -> 0.85 | H23: 258 | I23: =E23*H23 -> 258
A24: 19 | B24: 海天金标生抽1.9L | C24: 1.9L*6壶/件 | D24: 箱 | E24: 1 | F24: =H24/0.85 -> 152.94118 | G24: =H24/F24 -> 0.85 | H24: 130 | I24: =E24*H24 -> 130
A25: 20 | B25: 双效泡打粉（小袋） | C25: 50g | D25: 袋 | E25: 20 | F25: =H25/0.85 -> 1.7647059 | G25: =H25/F25 -> 0.85 | H25: 1.5 | I25: =E25*H25 -> 30
A26: 21 | B26: 1911老酸奶 | D26: 杯 | E26: 45 | F26: =H26/0.85 -> 4.1176471 | G26: =H26/F26 -> 0.85 | H26: 3.5 | I26: =E26*H26 -> 157.5
A27: 22 | B27: 生面窝浆 | D27: 斤 | E27: 5 | F27: =H27/0.85 -> 7.0588235 | G27: =H27/F27 -> 0.85 | H27: 6 | I27: =E27*H27 -> 30
A28: 23 | B28: 大葱 | D28: 斤 | E28: 4 | F28: =H28/0.85 -> 4.1176471 | G28: =H28/F28 -> 0.85 | H28: 3.5 | I28: =E28*H28 -> 14
A29: 24
A30: 25
A31: 26
A32: 27
A33: 28
A34: 供货合计: | B34: =SUM(I6:I33) -> 1886
A35: 金额大写： | B35: =B34 -> 1886
A36: 制表人 ：樊君丽 收货人： 送货人：

Sheet 21.
A1: 武汉康恩农贸发展有限公司送货单
A3: 收货单位： | B3: 汉南数智化检测分公司
A4: 配送日期： | B4: 45281
A5: 序号 | B5: 名称 | C5: 规格 | D5: 单位 | E5: 数量 | F5: 超市价格 | G5: 折扣率 | H5: 折后价 | I5: 折后金额 | J5: 备注
A6: 1 | B6: （新鲜）河粉 | D6: 斤 | E6: 3 | F6: =H6/0.85 -> 3.5294118 | G6: =H6/F6 -> 0.85 | H6: 3 | I6: =E6*H6 -> 9
A7: 2 | B7: 热干面（熟） | D7: 斤 | E7: 4 | F7: =H7/0.85 -> 4.1176471 | G7: =H7/F7 -> 0.85 | H7: 3.5 | I7: =E7*H7 -> 14
A8: 3 | B8: 青杭椒 | D8: 斤 | E8: 8 | F8: =H8/0.85 -> 6.8235294 | G8: =H8/F8 -> 0.85 | H8: 5.8 | I8: =E8*H8 -> 46.4
A9: 4 | B9: 新鲜甜青豆米 | D9: 斤 | E9: 5 | F9: =H9/0.85 -> 32.941176 | G9: =H9/F9 -> 0.85 | H9: 28 | I9: =E9*H9 -> 140
A10: 5 | B10: 新鲜玉米粒 | D10: 斤 | E10: 5 | F10: =H10/0.85 -> 14.117647 | G10: =H10/F10 -> 0.85 | H10: 12 | I10: =E10*H10 -> 60
A11: 6 | B11: 胡萝卜 | D11: 斤 | E11: 5 | F11: =H11/0.85 -> 2.9411765 | G11: =H11/F11 -> 0.85 | H11: 2.5 | I11: =E11*H11 -> 12.5
A12: 7 | B12: 西红柿 | D12: 斤 | E12: 13 | F12: =H12/0.85 -> 4.4705882 | G12: =H12/F12 -> 0.85 | H12: 3.8 | I12: =E12*H12 -> 49.4
A13: 8 | B13: 平菇 | D13: 斤 | E13: 3 | F13: =H13/0.85 -> 9.1764706 | G13: =H13/F13 -> 0.85 | H13: 7.8 | I13: =E13*H13 -> 23.4
A14: 9 | B14: 大白菜 | D14: 斤 | E14: 13 | F14: =H14/0.85 -> 2.1176471 | G14: =H14/F14 -> 0.85 | H14: 1.8 | I14: =E14*H14 -> 23.4
A15: 10 | B15: 果冻橙 | D15: 斤 | E15: 28 | F15: =H15/0.85 -> 8 | G15: =H15/F15 -> 0.85 | H15: 6.8 | I15: =E15*H15 -> 190.4
A16: 11 | B16: 【鲜】筒子骨 | D16: 斤 | E16: 8 | F16: =H16/0.85 -> 16.235294 | G16: =H16/F16 -> 0.85 | H16: 13.8 | I16: =E16*H16 -> 110.4
A17: 12 | B17: 【鲜】五花肉沫 | D17: 斤 | E17: 2 | F17: =H17/0.85 -> 16.235294 | G17: =H17/F17 -> 0.85 | H17: 13.8 | I17: =E17*H17 -> 27.6
A18: 13 | B18: 【鲜】猪瘦肉丝 | D18: 斤 | E18: 5 | F18: =H18/0.85 -> 23.529412 | G18: =H18/F18 -> 0.85 | H18: 20 | I18: =E18*H18 -> 100
A19: 14 | B19: 劲宝超级生粉 | C19: 5kg | D19: 袋 | E19: 1 | F19: =H19/0.85 -> 97.647059 | G19: =H19/F19 -> 0.85 | H19: 83 | I19: =E19*H19 -> 83
A20: 15 | B20: 小麦仁 | D20: 斤 | E20: 2 | F20: =H20/0.85 -> 4.7058824 | G20: =H20/F20 -> 0.85 | H20: 4 | I20: =E20*H20 -> 8
A21: 16 | B21: 鑫怡久久海带头 | C21: 9KG/件 | D21: 斤 | E21: 4 | F21: =H21/0.85 -> 10 | G21: =H21/F21 -> 0.85 | H21: 8.5 | I21: =E21*H21 -> 34
A22: 17 | B22: 高粱米 | C22: 散称 | D22: 斤 | E22: 2 | F22: =H22/0.85 -> 5.2941176 | G22: =H22/F22 -> 0.85 | H22: 4.5 | I22: =E22*H22 -> 9
A23: 18 | B23: 荞麦米 | C23: 散称 | D23: 斤 | E23: 2 | F23: =H23/0.85 -> 5.8823529 | G23: =H23/F23 -> 0.85 | H23: 5 | I23: =E23*H23 -> 10
A24: 19 | B24: 燕麦米 | D24: 斤 | E24: 2 | F24: =H24/0.85 -> 5.2941176 | G24: =H24/F24 -> 0.85 | H24: 4.5 | I24: =E24*H24 -> 9
A25: 20 | B25: 玉米碎 | C25: 散称 | D25: 斤 | E25: 3 | F25: =H25/0.85 -> 4.1176471 | G25: =H25/F25 -> 0.85 | H25: 3.5 | I25: =E25*H25 -> 10.5
A26: 21 | B26: 卤牛骨头 | D26: 斤 | E26: 6 | F26: =H26/0.85 -> 51.764706 | G26: =H26/F26 -> 0.85 | H26: 44 | I26: =E26*H26 -> 264
A27: 22 | B27: 净鳝鱼 | D27: 斤 | E27: 4 | F27: =H27/0.85 -> 82.352941 | G27: =H27/F27 -> 0.85 | H27: 70 | I27: =E27*H27 -> 280
A28: 23
A29: 24
A30: 供货合计: | B30: =SUM(I6:I29) -> 1514
A31: 金额大写： | B31: =B30 -> 1514
A32: 制表人 ：樊君丽 收货人： 送货人：

Sheet 22
A1: 武汉康恩农贸发展有限公司送货单
A3: 收货单位： | B3: 汉南数智化检测分公司
A4: 配送日期： | B4: 45282
A5: 序号 | B5: 名称 | C5: 规格 | D5: 单位 | E5: 数量 | F5: 超市价格 | G5: 折扣率 | H5: 折后价 | I5: 折后金额 | J5: 备注
A6: 1 | B6: 干细粉 | C6: 散称 | D6: 斤 | E6: 10 | F6: =H6/0.85 -> 4.1176471 | G6: =H6/F6 -> 0.85 | H6: 3.5 | I6: =E6*H6 -> 35
A7: 2 | B7: 馄饨皮 | D7: 斤 | E7: 1 | F7: =H7/0.85 -> 4.1176471 | G7: =H7/F7 -> 0.85 | H7: 3.5 | I7: =E7*H7 -> 3.5
A8: 3 | B8: 热干面（熟） | D8: 斤 | E8: 5 | F8: =H8/0.85 -> 4.1176471 | G8: =H8/F8 -> 0.85 | H8: 3.5 | I8: =E8*H8 -> 17.5
A9: 4 | B9: 青豆角 | D9: 斤 | E9: 6 | F9: =H9/0.85 -> 6.8235294 | G9: =H9/F9 -> 0.85 | H9: 5.8 | I9: =E9*H9 -> 34.8
A10: 5 | B10: 白萝卜 | D10: 斤 | E10: 9 | F10: =H10/0.85 -> 2.3529412 | G10: =H10/F10 -> 0.85 | H10: 2 | I10: =E10*H10 -> 18
A11: 6 | B11: 大土豆 | D11: 斤 | E11: 18 | F11: =H11/0.85 -> 4.1176471 | G11: =H11/F11 -> 0.85 | H11: 3.5 | I11: =E11*H11 -> 63
A12: 7 | B12: 红椒 | D12: 斤 | E12: 3 | F12: =H12/0.85 -> 8.8235294 | G12: =H12/F12 -> 0.85 | H12: 7.5 | I12: =E12*H12 -> 22.5
A13: 8 | B13: 甜玉米棒 | D13: 个 | E13: 8 | F13: =H13/0.85 -> 3.5294118 | G13: =H13/F13 -> 0.85 | H13: 3 | I13: =E13*H13 -> 24
A14: 9 | B14: 芜湖青椒 | D14: 斤 | E14: 3 | F14: =H14/0.85 -> 4.7058824 | G14: =H14/F14 -> 0.85 | H14: 4 | I14: =E14*H14 -> 12
A15: 10 | B15: 紫长茄子（细长） | D15: 斤 | E15: 6 | F15: =H15/0.85 -> 4.4705882 | G15: =H15/F15 -> 0.85 | H15: 3.8 | I15: =E15*H15 -> 22.8
A16: 11 | B16: 油麦菜 | D16: 斤 | E16: 12 | F16: =H16/0.85 -> 5.2941176 | G16: =H16/F16 -> 0.85 | H16: 4.5 | I16: =E16*H16 -> 54
A17: 12 | B17: 鲜羊蝎子 | D17: 斤 | E17: 8 | F17: =H17/0.85 -> 37.647059 | G17: =H17/F17 -> 0.85 | H17: 32 | I17: =E17*H17 -> 256
A18: 13 | B18: 【鲜】精品五花 | D18: 斤 | E18: 8 | F18: =H18/0.85 -> 22.941176 | G18: =H18/F18 -> 0.85 | H18: 19.5 | I18: =E18*H18 -> 156
... A20: 15 | B20: 卤牛肉 | D20: 斤 | E20: 8 | F20: =H20/0.85 -> 103.52941 | G20: =H20/F20 -> 0.85 | H20: 88 | I20: =E20*H20 -> 704
A21: 16
A22: 17
A23: 18
A24: 19
A25: 20
A26: 21
A27: 22
A28: 23
A29: 24
A30: 25
A31: 26
A32: 27
A33: 28
A34: 供货合计: | B34: =SUM(I6:I33) -> 1563.1
A35: 金额大写： | B35: =B34 -> 1563.1
A36: 制表人 ：樊君丽 收货人： 送货人：

Sheet 25
A1: 武汉康恩农贸发展有限公司送货单
A3: 收货单位： | B3: 汉南数智化检测分公司
A4: 配送日期： | B4: 45283
A5: 序号 | B5: 名称 | C5: 规格 | D5: 单位 | E5: 数量 | F5: 超市价格 | G5: 折扣率 | H5: 折后价 | I5: 折后金额 | J5: 备注
A6: 1 | B6: （新鲜）河粉 | D6: 斤 | E6: 7 | F6: =H6/0.85 -> 3.5294118 | G6: =H6/F6 -> 0.85 | H6: 3 | I6: =E6*H6 -> 21
A7: 2 | B7: 馄饨皮 | D7: 斤 | E7: 2 | F7: =H7/0.85 -> 4.1176471 | G7: =H7/F7 -> 0.85 | H7: 3.5 | I7: =E7*H7 -> 7
A8: 3 | B8: 热干面（熟） | D8: 斤 | E8: 3 | F8: =H8/0.85 -> 4.1176471 | G8: =H8/F8 -> 0.85 | H8: 3.5 | I8: =E8*H8 -> 10.5
A9: 4 | B9: 小葱 | D9: 斤 | E9: 2 | F9: =H9/0.85 -> 8 | G9: =H9/F9 -> 0.85 | H9: 6.8 | I9: =E9*H9 -> 13.6
A10: 5 | B10: 大红薯 | D10: 斤 | E10: 10 | F10: =H10/0.85 -> 4.1176471 | G10: =H10/F10 -> 0.85 | H10: 3.5 | I10: =E10*H10 -> 35
A11: 6 | B11: 红菜苔 | D11: 斤 | E11: 13 | F11: =H11/0.85 -> 4.7058824 | G11: =H11/F11 -> 0.85 | H11: 4 | I11: =E11*H11 -> 52
A12: 7 | B12: 红椒 | D12: 斤 | E12: 3 | F12: =H12/0.85 -> 8.8235294 | G12: =H12/F12 -> 0.85 | H12: 7.5 | I12: =E12*H12 -> 22.5
A13: 8 | B13: 铁棍山药 | D13: 斤 | E13: 5 | F13: =H13/0.85 -> 10.352941 | G13: =H13/F13 -> 0.85 | H13: 8.8 | I13: =E13*H13 -> 44
A14: 9 | B14: 芜湖青椒 | D14: 斤 | E14: 3 | F14: =H14/0.85 -> 4.7058824 | G14: =H14/F14 -> 0.85 | H14: 4 | I14: =E14*H14 -> 12
A15: 10 | B15: 黄瓜 | D15: 斤 | E15: 6 | F15: =H15/0.85 -> 4.4705882 | G15: =H15/F15 -> 0.85 | H15: 3.8 | I15: =E15*H15 -> 22.8
A16: 11 | B16: 鲜香菇 | D16: 斤 | E16: 6 | F16: =H16/0.85 -> 11.529412 | G16: =H16/F16 -> 0.85 | H16: 9.8 | I16: =E16*H16 -> 58.8
A17: 12 | B17: 小白菜 | D17: 斤 | E17: 2 | F17: =H17/0.85 -> 4.1176471 | G17: =H17/F17 -> 0.85 | H17: 3.5 | I17: =E17*H17 -> 7
... A21: 16 | B21: 【鲜】猪通排骨 | D21: 斤 | E21: 8 | F21: =H21/0.85 -> 32.941176 | G21: =H21/F21 -> 0.85 | H21: 28 | I21: =E21*H21 -> 224
A22: 17 | B22: 白芝麻/38斤 | C22: 散称 | D22: 斤 | E22: 2 | F22: =H22/0.85 -> 17.647059 | G22: =H22/F22 -> 0.85 | H22: 15 | I22: =E22*H22 -> 30
A23: 18 | B23: 双塔龙口粉丝 | C23: 500g*24袋/件 | D23: 袋 | E23: 2 | F23: =H23/0.85 -> 14.117647 | G23: =H23/F23 -> 0.85 | H23: 12 | I23: =E23*H23 -> 24
A24: 19 | B24: 云鹤精制碘盐 | C24: 500g*50袋/件 | D24: 袋 | E24: 10 | F24: =H24/0.85 -> 2.3529412 | G24: =H24/F24 -> 0.85 | H24: 2 | I24: =E24*H24 -> 20
A25: 20 | B25: 鑫怡久久海带头 | C25: 9KG/件 | D25: 斤 | E25: 4 | F25: =H25/0.85 -> 10 | G25: =H25/F25 -> 0.85 | H25: 8.5 | I25: =E25*H25 -> 34
A26: 21 | B26: 红米 | C26: 散称 | D26: 斤 | E26: 2 | F26: =H26/0.85 -> 8 | G26: =H26/F26 -> 0.85 | H26: 6.8 | I26: =E26*H26 -> 13.6
A27: 22 | B27: 1911老酸奶 | D27: 杯 | E27: 50 | F27: =H27/0.85 -> 4.1176471 | G27: =H27/F27 -> 0.85 | H27: 3.5 | I27: =E27*H27 -> 175
A28: 23 | B28: 卤牛肉 | D28: 斤 | E28: 5 | F28: =H28/0.85 -> 103.52941 | G28: =H28/F28 -> 0.85 | H28: 88 | I28: =E28*H28 -> 440
A29: 24
A30: 25
A31: 26
A32: 27
A33: 28
A34: 供货合计: | B34: =SUM(I6:I33) -> 1615.8
A35: 金额大写： | B35: =B34 -> 1615.8
A36: 制表人 ：樊君丽 收货人： 送货人：

Sheet 26
A1: 武汉康恩农贸发展有限公司送货单
A3: 收货单位： | B3: 汉南数智化检测分公司
A4: 配送日期： | B4: 45286
A5: 序号 | B5: 名称 | C5: 规格 | D5: 单位 | E5: 数量 | F5: 超市价格 | G5: 折扣率 | H5: 折后价 | I5: 折后金额 | J5: 备注
A6: 1 | B6: （新鲜）河粉 | D6: 斤 | E6: 5 | F6: =H6/0.85 -> 3.5294118 | G6: =H6/F6 -> 0.85 | H6: 3 | I6: =E6*H6 -> 15
A7: 2 | B7: 热干面（熟） | D7: 斤 | E7: 2 | F7: =H7/0.85 -> 4.1176471 | G7: =H7/F7 -> 0.85 | H7: 3.5 | I7: =E7*H7 -> 7
A8: 3 | B8: 大藕 | D8: 斤 | E8: 18 | F8: =H8/0.85 -> 4.4705882 | G8: =H8/F8 -> 0.85 | H8: 3.8 | I8: =E8*H8 -> 68.4
A9: 4 | B9: 甜玉米棒 | D9: 个 | E9: 8 | F9: =H9/0.85 -> 3.5294118 | G9: =H9/F9 -> 0.85 | H9: 3 | I9: =E9*H9 -> 24
A10: 5 | B10: 西芹 | D10: 斤 | E10: 6 | F10: =H10/0.85 -> 5.6470588 | G10: =H10/F10 -> 0.85 | H10: 4.8 | I10: =E10*H10 -> 28.8
A11: 6 | B11: 大白菜 | D11: 斤 | E11: 14.5 | F11: =H11/0.85 -> 2.1176471 | G11: =H11/F11 -> 0.85 | H11: 1.8 | I11: =E11*H11 -> 26.1
A12: 7 | B12: 香菜 | D12: 斤 | E12: 1 | F12: =H12/0.85 -> 9.4117647 | G12: =H12/F12 -> 0.85 | H12: 8 | I12: =E12*H12 -> 8
A13: 8 | B13: 香梨 | D13: 斤 | E13: 23.4 | F13: =H13/0.85 -> 10 | G13: =H13/F13 -> 0.85 | H13: 8.5 | I13: =E13*H13 -> 198.9
A14: 9 | B14: 【鲜】净大草鱼 | D14: 斤 | E14: 13 | F14: =H14/0.85 -> 16.235294 | G14: =H14/F14 -> 0.85 | H14: 13.8 | I14: =E14*H14 -> 179.4
A15: 10 | B15: 黑米 | C15: 散称 | D15: 斤 | E15: 2 | F15: =H15/0.85 -> 8 | G15: =H15/F15 -> 0.85 | H15: 6.8 | I15: =E15*H15 -> 13.6
A16: 11 | B16: 正和珍珠糯米 | C16: 50斤/袋 | D16: 斤 | E16: 4 | F16: =H16/0.85 -> 5.7647059 | G16: =H16/F16 -> 0.85 | H16: 4.9 | I16: =E16*H16 -> 19.6
A17: 12
A18: 13
A19: 14
A20: 15
A21: 16
A22: 17
A23: 18
A24: 19
A25: 20
A26: 21
A27: 22
A28: 23
... A33: 28
A34: 供货合计: | B34: =SUM(I6:I33) -> 588.8
A35: 金额大写： | B35: =B34 -> 588.8
A36: 制表人 ：樊君丽 收货人： 送货人：

Sheet 27
A1: 武汉康恩农贸发展有限公司送货单
A3: 收货单位： | B3: 汉南数智化检测分公司
A4: 配送日期： | B4: 45287
A5: 序号 | B5: 名称 | C5: 规格 | D5: 单位 | E5: 数量 | F5: 超市价格 | G5: 折扣率 | H5: 折后价 | I5: 折后金额 | J5: 备注
A6: 1 | B6: （新鲜）河粉 | D6: 斤 | E6: 4 | F6: =H6/0.85 -> 3.5294118 | G6: =H6/F6 -> 0.85 | H6: 3 | I6: =E6*H6 -> 12
A7: 2 | B7: 馄饨皮 | D7: 斤 | E7: 2 | F7: =H7/0.85 -> 4.1176471 | G7: =H7/F7 -> 0.85 | H7: 3.5 | I7: =E7*H7 -> 7
A8: 3 | B8: 热干面（熟） | D8: 斤 | E8: 5 | F8: =H8/0.85 -> 4.1176471 | G8: =H8/F8 -> 0.85 | H8: 3.5 | I8: =E8*H8 -> 17.5
A9: 4 | B9: 生面窝浆 | D9: 斤 | E9: 5 | F9: =H9/0.85 -> 7.0588235 | G9: =H9/F9 -> 0.85 | H9: 6 | I9: =E9*H9 -> 30
A10: 5 | B10: 芜湖青椒 | D10: 斤 | E10: 16 | F10: =H10/0.85 -> 4.7058824 | G10: =H10/F10 -> 0.85 | H10: 4 | I10: =E10*H10 -> 64
A11: 6 | B11: 紫薯 | D11: 斤 | E11: 5 | F11: =H11/0.85 -> 6.8235294 | G11: =H11/F11 -> 0.85 | H11: 5.8 | I11: =E11*H11 -> 29
A12: 7 | B12: 金针菇 | D12: 斤 | E12: 5 | F12: =H12/0.85 -> 6.8235294 | G12: =H12/F12 -> 0.85 | H12: 5.8 | I12: =E12*H12 -> 29
A13: 8 | B13: 平菇 | D13: 斤 | E13: 3 | F13: =H13/0.85 -> 9.1764706 | G13: =H13/F13 -> 0.85 | H13: 7.8 | I13: =E13*H13 -> 23.4
A14: 9 | B14: 生菜 | D14: 斤 | E14: 13 | F14: =H14/0.85 -> 5.6470588 | G14: =H14/F14 -> 0.85 | H14: 4.8 | I14: =E14*H14 -> 62.4
A15: 10 | B15: 细土芹 | D15: 斤 | E15: 3 | F15: =H15/0.85 -> 5.6470588 | G15: =H15/F15 -> 0.85 | H15: 4.8 | I15: =E15*H15 -> 14.4
A16: 11 | B16: 面筋 | D16: 斤 | E16: 8 | F16: =H16/0.85 -> 8 | G16: =H16/F16 -> 0.85 | H16: 6.8 | I16: =E16*H16 -> 54.4
A17: 12 | B17: 红壳鸡蛋 | C17: 12板/件 | D17: 件 | E17: 1 | F17: =H17/0.85 -> 352.94118 | G17: =H17/F17 -> 0.85 | H17: 300 | I17: =E17*H17 -> 300
A18: 13 | B18: 【鲜】五花肉沫 | D18: 斤 | E18: 2 | F18: =H18/0.85 -> 16.235294 | G18: =H18/F18 -> 0.85 | H18: 13.8 | I18: =E18*H18 -> 27.6
A19: 14 | B19: 【鲜】猪瘦肉片 | D19: 斤 | E19: 5 | F19: =H19/0.85 -> 23.529412 | G19: =H19/F19 -> 0.85 | H19: 20 | I19: =E19*H19 -> 100
A20: 15 | B20: 【鲜】猪五花肉片 | D20: 斤 | E20: 5 | F20: =H20/0.85 -> 19.764706 | G20: =H20/F20 -> 0.85 | H20: 16.8 | I20: =E20*H20 -> 84
A21: 16 | B21: 1911老酸奶 | D21: 杯 | E21: 48 | F21: =H21/0.85 -> 4.1176471 | G21: =H21/F21 -> 0.85 | H21: 3.5 | I21: =E21*H21 -> 168
A22: 17 | B22: 卤牛肉 | D22: 斤 | E22: 8 | F22: =H22/0.85 -> 103.52941 | G22: =H22/F22 -> 0.85 | H22: 88 | I22: =E22*H22 -> 704
A23: 18
A24: 19
A25: 20
A26: 21
A27: 22
A28: 23
A29: 24
A30: 25
A31: 26
A32: 27
A33: 28
A34: 供货合计: | B34: =SUM(I6:I33) -> 1726.7
A35: 金额大写： | B35: =B34 -> 1726.7
A36: 制表人 ：樊君丽 收货人： 送货人：

Sheet 28
A1: 武汉康恩农贸发展有限公司送货单
A3: 收货单位： | B3: 汉南数智化检测分公司
A4: 配送日期： | B4: 45288
A5: 序号 | B5: 名称 | C5: 规格 | D5: 单位 | E5: 数量 | F5: 超市价格 | G5: 折扣率 | H5: 折后价 | I5: 折后金额 | J5: 备注
A6: 1 | B6: （新鲜）河粉 | D6: 斤 | E6: 6 | F6: =H6/0.85 -> 3.5294118 | G6: =H6/F6 -> 0.85 | H6: 3 | I6: =E6*H6 -> 18
A7: 2 | B7: 热干面（熟） | D7: 斤 | E7: 2 | F7: =H7/0.85 -> 4.1176471 | G7: =H7/F7 -> 0.85 | H7: 3.5 | I7: =E7*H7 -> 7
A8: 3 | B8: 生姜 | D8: 斤 | E8: 6 | F8: =H8/0.85 -> 15.058824 | G8: =H8/F8 -> 0.85 | H8: 12.8 | I8: =E8*H8 -> 76.8
A9: 4 | B9: 红椒 | D9: 斤 | E9: 2 | F9: =H9/0.85 -> 8.8235294 | G9: =H9/F9 -> 0.85 | H9: 7.5 | I9: =E9*H9 -> 15
A10: 5 | B10: 铁棍山药 | D10: 斤 | E10: 6 | F10: =H10/0.85 -> 10.352941 | G10: =H10/F10 -> 0.85 | H10: 8.8 | I10: =E10*H10 -> 52.8
A11: 6 | B11: 净芋头 | C11: （去皮，小） | D11: 斤 | E11: 8 | F11: =H11/0.85 -> 10.352941 | G11: =H11/F11 -> 0.85 | H11: 8.8 | I11: =E11*H11 -> 70.4
A12: 7 | B12: 平菇 | D12: 斤 | E12: 3 | F12: =H12/0.85 -> 9.1764706 | G12: =H12/F12 -> 0.85 | H12: 7.8 | I12: =E12*H12 -> 23.4
A13: 8 | B13: 鲜香菇 | D13: 斤 | E13: 1 | F13: =H13/0.85 -> 11.529412 | G13: =H13/F13 -> 0.85 | H13: 9.8 | I13: =E13*H13 -> 9.8
A14: 9 | B14: 菠菜 | D14: 斤 | E14: 15 | F14: =H14/0.85 -> 5.6470588 | G14: =H14/F14 -> 0.85 | H14: 4.8 | I14: =E14*H14 -> 72
A15: 10 | B15: 细土芹 | D15: 斤 | E15: 4 | F15: =H15/0.85 -> 5.6470588 | G15: =H15/F15 -> 0.85 | H15: 4.8 | I15: =E15*H15 -> 19.2
A16: 11 | B16: 85苹果 | D16: 斤 | E16: 34 | F16: =H16/0.85 -> 10 | G16: =H16/F16 -> 0.85 | H16: 8.5 | I16: =E16*H16 -> 289
A17: 12 | B17: 白色臭干子 | D17: 斤 | E17: 15 | F17: =H17/0.85 -> 8 | G17: =H17/F17 -> 0.85 | H17: 6.8 | I17: =E17*H17 -> 102
A18: 13 | B18: 熟鹌鹑蛋 | D18: 斤 | E18: 3 | F18: =H18/0.85 -> 16.235294 | G18: =H18/F18 -> 0.85 | H18: 13.8 | I18: =E18*H18 -> 41.4
A19: 14 | B19: 【鲜】净三黄鸡 | D19: 斤 | E19: 10.2 | F19: =H19/0.85 -> 17.411765 | G19: =H19/F19 -> 0.85 | H19: 14.8 | I19: =E19*H19 -> 150.96
A20: 15 | B20: 【鲜】猪后腿肉 | D20: 斤 | E20: 2 | F20: =H20/0.85 -> 18.588235 | G20: =H20/F20 -> 0.85 | H20: 15.8 | I20: =E20*H20 -> 31.6
A21: 16 | B21: 【鲜】猪五花肉片 | D21: 斤 | E21: 6 | F21: =H21/0.85 -> 19.764706 | G21: =H21/F21 -> 0.85 | H21: 16.8 | I21: =E21*H21 -> 100.8
A22: 17 | B22: （冻）川香鸡柳 | C22: 25支*10袋/件 | D22: 袋 | E22: 6 | F22: =H22/0.85 -> 32.941176 | G22: =H22/F22 -> 0.85 | H22: 28 | I22: =E22*H22 -> 168
A23: 18 | B23: 骨肉相连 | C23: 40g*10袋（25根/袋）/件 | D23: 袋 | E23: 5 | F23: =H23/0.85 -> 32.941176 | G23: =H23/F23 -> 0.85 | H23: 28 | I23: =E23*H23 -> 140
A24: 19 | B24: 佳芳奥尔良翅中 | C24: 900g*10袋/件 | D24: 袋 | E24: 6 | F24: =H24/0.85 -> 68.235294 | G24: =H24/F24 -> 0.85 | H24: 58 | I24: =E24*H24 -> 348
A25: 20 | B25: 薯条（冻 ） | C25: 2kg*6袋/件 | D25: 袋 | E25: 4 | F25: =H25/0.85 -> 49.411765 | G25: =H25/F25 -> 0.85 | H25: 42 | I25: =E25*H25 -> 168
A26: 21 | B26: 清水笋丝 | C26: 2.5kg*6包/件 | D26: 包 | E26: 3 | F26: =H26/0.85 -> 16.235294 | G26: =H26/F26 -> 0.85 | H26: 13.8 | I26: =E26*H26 -> 41.4
A27: 22 | B27: 金龙鱼玉米油 | C27: 5L*4壶/件 | D27: 件 | E27: 2 | F27: =H27/0.85 -> 411.76471 | G27: =H27/F27 -> 0.85 | H27: 350 | I27: =E27*H27 -> 700
A28: 23 | B28: 蒸肉白米粉（粗） | D28: 斤 | E28: 5 | F28: =H28/0.85 -> 4.7058824 | G28: =H28/F28 -> 0.85 | H28: 4 | I28: =E28*H28 -> 20
A29: 24 | B29: 卤牛骨头 | D29: 斤 | E29: 7 | F29: =H29/0.85 -> 51.764706 | G29: =H29/F29 -> 0.85 | H29: 44 | I29: =E29*H29 -> 308
A30: 25 | B30: 卤香干 | D30: 斤 | E30: 1 | F30: =H30/0.85 -> 11.529412 | G30: =H30/F30 -> 0.85 | H30: 9.8 | I30: =E30*H30 -> 9.8
A31: 26
A32: 供货合计: | B32: =SUM(I6:I31) -> 2983.36
A33: 金额大写： | B33: =B32 -> 2983.36
A34: 制表人 ：樊君丽 收货人： 送货人：

Sheet 29
A1: 武汉康恩农贸发展有限公司送货单
A3: 收货单位： | B3: 汉南数智化检测分公司
A4: 配送日期： | B4: 45289
A5: 序号 | B5: 名称 | C5: 规格 | D5: 单位 | E5: 数量 | F5: 超市价格 | G5: 折扣率 | H5: 折后价 | I5: 折后金额 | J5: 备注
A6: 1 | B6: （新鲜）河粉 | D6: 斤 | E6: 4 | F6: =H6/0.85 -> 3.5294118 | G6: =H6/F6 -> 0.85 | H6: 3 | I6: =E6*H6 -> 12
A7: 2 | B7: 干细粉 | C7: 散称 | D7: 斤 | E7: 10 | F7: =H7/0.85 -> 4.1176471 | G7: =H7/F7 -> 0.85 | H7: 3.5 | I7: =E7*H7 -> 35
A8: 3 | B8: 热干面（熟） | D8: 斤 | E8: 7 | F8: =H8/0.85 -> 4.1176471 | G8: =H8/F8 -> 0.85 | H8: 3.5 | I8: =E8*H8 -> 24.5
A9: 4 | B9: 白萝卜 | D9: 斤 | E9: 4 | F9: =H9/0.85 -> 2.3529412 | G9: =H9/F9 -> 0.85 | H9: 2 | I9: =E9*H9 -> 8
A10: 5 | B10: 大藕 | D10: 斤 | E10: 8 | F10: =H10/0.85 -> 4.4705882 | G10: =H10/F10 -> 0.85 | H10: 3.8 | I10: =E10*H10 -> 30.4
A11: 6 | B11: 红椒 | D11: 斤 | E11: 2 | F11: =H11/0.85 -> 8.8235294 | G11: =H11/F11 -> 0.85 | H11: 7.5 | I11: =E11*H11 -> 15
A12: 7 | B12: 蒜苗 | D12: 斤 | E12: 3 | F12: =H12/0.85 -> 11.529412 | G12: =H12/F12 -> 0.85 | H12: 9.8 | I12: =E12*H12 -> 29.4
A13: 8 | B13: 甜玉米棒 | D13: 个 | E13: 8 | F13: =H13/0.85 -> 3.5294118 | G13: =H13/F13 -> 0.85 | H13: 3 | I13: =E13*H13 -> 24
A14: 9 | B14: 芜湖青椒 | D14: 斤 | E14: 2 | F14: =H14/0.85 -> 4.7058824 | G14: =H14/F14 -> 0.85 | H14: 4 | I14: =E14*H14 -> 8
A15: 10 | B15: 黄瓜 | D15: 斤 | E15: 5 | F15: =H15/0.85 -> 4.4705882 | G15: =H15/F15 -> 0.85 | H15: 3.8 | I15: =E15*H15 -> 19
A16: 11 | B16: 水果黄瓜 | D16: 斤 | E16: 4 | F16: =H16/0.85 -> 14.117647 | G16: =H16/F16 -> 0.85 | H16: 12 | I16: =E16*H16 -> 48
A17: 12 | B17: 净泥蒿（去叶） | D17: 斤 | E17: 12 | F17: =H17/0.85 -> 31.764706 | G17: =H17/F17 -> 0.85 | H17: 27 | I17: =E17*H17 -> 324
A18: 13 | B18: 杏鲍菇 | D18: 斤 | E18: 8 | F18: =H18/0.85 -> 6.8235294 | G18: =H18/F18 -> 0.85 | H18: 5.8 | I18: =E18*H18 -> 46.4
A19: 14 | B19: 苦菊 | D19: 斤 | E19: 3 | F19: =H19/0.85 -> 9.4117647 | G19: =H19/F19 -> 0.85 | H19: 8 | I19: =E19*H19 -> 24
... A33: 28 | B33: 净田鸡 | D33: 斤 | E33: 4 | F33: =H33/0.85 -> 94.117647 | G33: =H33/F33 -> 0.85 | H33: 80 | I33: =E33*H33 -> 320
A34: 29 | B34: （冻）川香鸡柳 | C34: 25支*10袋/件 | D34: 袋 | E34: 2 | F34: =H34/0.85 -> 32.941176 | G34: =H34/F34 -> 0.85 | H34: 28 | I34: =E34*H34 -> 56
A35: 30 | B35: 骨肉相连 | C35: 40g*10袋（25根/袋）/件 | D35: 袋 | E35: 2 | F35: =H35/0.85 -> 32.941176 | G35: =H35/F35 -> 0.85 | H35: 28 | I35: =E35*H35 -> 56
A36: 31 | B36: 佳芳奥尔良翅中 | C36: 900g*10袋/件 | D36: 袋 | E36: 2 | F36: =H36/0.85 -> 68.235294 | G36: =H36/F36 -> 0.85 | H36: 58 | I36: =E36*H36 -> 116
A37: 32 | B37: 薯条（冻 ） | C37: 2kg*6袋/件 | D37: 袋 | E37: 3 | F37: =H37/0.85 -> 49.411765 | G37: =H37/F37 -> 0.85 | H37: 42 | I37: =E37*H37 -> 126
A38: 33 | B38: 旺食堂蒙古肉 | C38: 500g*24袋 | D38: 袋 | E38: 10 | F38: =H38/0.85 -> 14.117647 | G38: =H38/F38 -> 0.85 | H38: 12 | I38: =E38*H38 -> 120
A39: 34 | B39: 干莲子米（去芯） | C39: 散称 | D39: 斤 | E39: 1 | F39: =H39/0.85 -> 41.176471 | G39: =H39/F39 -> 0.85 | H39: 35 | I39: =E39*H39 -> 35
A40: 35 | B40: 亨氏番茄沙司 | C40: 90g*30袋/件 | D40: 袋 | E40: 5 | F40: =H40/0.85 -> 19.764706 | G40: =H40/F40 -> 0.85 | H40: 16.8 | I40: =E40*H40 -> 84
A41: 36 | B41: 丘比沙拉酱香甜口味1kg | C41: 1kg/瓶 | D41: 瓶 | E41: 4 | F41: =H41/0.85 -> 42.352941 | G41: =H41/F41 -> 0.85 | H41: 36 | I41: =E41*H41 -> 144
A42: 37 | B42: 十月稻田三色糙米 | C42: 2.5kg/袋 | D42: 袋 | E42: 2 | F42: =H42/0.85 -> 47.058824 | G42: =H42/F42 -> 0.85 | H42: 40 | I42: =E42*H42 -> 80
A43: 38 | B43: 百事可乐600ml（瓶） | C43: 600ml/瓶 | D43: 瓶 | E43: 3 | F43: =H43/0.85 -> 3.5294118 | G43: =H43/F43 -> 0.85 | H43: 3 | I43: =E43*H43 -> 9
A44: 39 | B44: 水溶C100西柚汁 | C44: 250ml*12瓶/件 | D44: 件 | E44: 3 | F44: =H44/0.85 -> 49.411765 | G44: =H44/F44 -> 0.85 | H44: 42 | I44: =E44*H44 -> 126
A45: 40 | B45: 外星人电解质水 | C45: 300ml*6瓶/件 | D45: 件 | E45: 4 | F45: =H45/0.85 -> 35.294118 | G45: =H45/F45 -> 0.85 | H45: 30 | I45: =E45*H45 -> 120
A46: 41 | B46: 元气森林（白桃味） | C46: 280ml*12瓶/箱 | D46: 箱 | E46: 2 | F46: =H46/0.85 -> 49.411765 | G46: =H46/F46 -> 0.85 | H46: 42 | I46: =E46*H46 -> 84
A47: 42 | B47: 冷记酱板鸭 | D47: 只 | E47: 7 | F47: =H47/0.85 -> 82.352941 | G47: =H47/F47 -> 0.85 | H47: 70 | I47: =E47*H47 -> 490
A48: 43 | B48: 卤牛肉 | D48: 斤 | E48: 8 | F48: =H48/0.85 -> 103.52941 | G48: =H48/F48 -> 0.85 | H48: 88 | I48: =E48*H48 -> 704
A49: 供货合计: | B49: =SUM(I6:I48) -> 5868.6
A50: 金额大写： | B50: =B49 -> 5868.6
A51: 制表人 ：樊君丽 收货人： 送货人：

Sheet 12月合计
A1: 39号食堂
A2: 日期 | B2: 单1
A3: 45261 | B3: ='1'!B33 -> 1619.4
A4: 45262 | B4: 0
A5: 45263 | B5: 0
A6: 45264 | B6: ='4'!B32 -> 1643.06
A7: 45265 | B7: ='5'!B34 -> 1813.1
A8: 45266 | B8: ='6'!B33 -> 1042.1
A9: 45267 | B9: ='7'!B34 -> 1243.4
A10: 45268 | B10: ='8'!B34 -> 1711.2
A11: 45269 | B11: ='9'!B34 -> 523.88
A12: 45270 | B12: 0
A13: 45271 | B13: ='11'!B33 -> 760.55
A14: 45272 | B14: ='12'!B34 -> 1908.94
A15: 45273 | B15: ='13'!B33 -> 1663.64
A16: 45274 | B16: ='14'!B31 -> 1462.35
A17: 45275 | B17: ='15'!B34 -> 1687.42
A18: 45276 | B18: 0
A19: 45277 | B19: 0
A20: 45278 | B20: ='18'!B34 -> 1343.5
A21: 45279 | B21: ='19'!B33 -> 3125.5
A22: 45280 | B22: ='20.'!B34 -> 1886
A23: 45281 | B23: ='21.'!B30 -> 1514
A24: 45282 | B24: ='22'!B34 -> 1563.1
A25: 45283 | B25: 0
A26: 45284 | B26: 0
A27: 45285 | B27: ='25'!B34 -> 1615.8
A28: 45286 | B28: ='26'!B34 -> 588.8
A29: 45287 | B29: ='27'!B34 -> 1726.7
