Workbook

Sheet 1
A1: 武汉康恩农贸发展有限公司送货单
A3: 收货单位：汉南数智化检测分公司
A4: 配送日期：2023-9-1
A5: 序号 | B5: 名称 | C5: 规格 | D5: 单位 | E5: 数量 | F5: 超市价格 | G5: 折扣率 | H5: 折后价 | I5: 折后金额 | J5: 备注
A6: 1 | B6: （新鲜）河粉 | D6: 斤 | E6: 5 | F6: =H6/0.85 -> 3.5294118 | G6: =H6/F6 -> 0.85 | H6: 3 | I6: =E6*H6 -> 15
A7: 2 | B7: 热干面（熟） | D7: 斤 | E7: 5 | F7: =H7/0.85 -> 4.1176471 | G7: =H7/F7 -> 0.85 | H7: 3.5 | I7: =E7*H7 -> 17.5
A8: 3 | B8: 绿豆芽 | D8: 斤 | E8: 12 | F8: =H8/0.85 -> 2.9411765 | G8: =H8/F8 -> 0.85 | H8: 2.5 | I8: =E8*H8 -> 30
A9: 4 | B9: 白萝卜 | D9: 斤 | E9: 4.7 | F9: =H9/0.85 -> 2.3529412 | G9: =H9/F9 -> 0.85 | H9: 2 | I9: =E9*H9 -> 9.4
A10: 5 | B10: 红椒 | D10: 斤 | E10: 3 | F10: =H10/0.85 -> 9.1764706 | G10: =H10/F10 -> 0.85 | H10: 7.8 | I10: =E10*H10 -> 23.4
A11: 6 | B11: 青椒 | D11: 斤 | E11: 22 | F11: =H11/0.85 -> 4.1176471 | G11: =H11/F11 -> 0.85 | H11: 3.5 | I11: =E11*H11 -> 77
A12: 7 | B12: 甜玉米棒 | D12: 个 | E12: 7 | F12: =H12/0.85 -> 3.5294118 | G12: =H12/F12 -> 0.85 | H12: 3 | I12: =E12*H12 -> 21
A13: 8 | B13: 黄瓜 | D13: 斤 | E13: 4 | F13: =H13/0.85 -> 3.2941176 | G13: =H13/F13 -> 0.85 | H13: 2.8 | I13: =E13*H13 -> 11.2
A14: 9 | B14: 青丝瓜 | D14: 斤 | E14: 4 | F14: =H14/0.85 -> 5.2941176 | G14: =H14/F14 -> 0.85 | H14: 4.5 | I14: =E14*H14 -> 18
A15: 10 | B15: 韭菜 | D15: 斤 | E15: 6 | F15: =H15/0.85 -> 5.8823529 | G15: =H15/F15 -> 0.85 | H15: 5 | I15: =E15*H15 -> 30
A16: 11 | B16: 【鲜】五花肉沫 | D16: 斤 | E16: 3 | F16: =H16/0.85 -> 19.764706 | G16: =H16/F16 -> 0.85 | H16: 16.8 | I16: =E16*H16 -> 50.4
A17: 12 | B17: 【鲜】猪脊骨 | D17: 斤 | E17: 3 | F17: =H17/0.85 -> 17.411765 | G17: =H17/F17 -> 0.85 | H17: 14.8 | I17: =E17*H17 -> 44.4
... A19: 14 | B19: 【鲜】净大草鱼 | D19: 斤 | E19: 10 | F19: =H19/0.85 -> 16.235294 | G19: =H19/F19 -> 0.85 | H19: 13.8 | I19: =E19*H19 -> 138
A20: 15 | B20: 【冻】思念白糯小汤圆（无馅） | C20: 500g*20包/件 | D20: 袋 | E20: 3 | F20: =H20/0.85 -> 10.588235 | G20: =H20/F20 -> 0.85 | H20: 9 | I20: =E20*H20 -> 27
A21: 16 | B21: 干黑木耳 | D21: 斤 | E21: 5 | F21: =H21/0.85 -> 68.235294 | G21: =H21/F21 -> 0.85 | H21: 58 | I21: =E21*H21 -> 290
A22: 17 | B22: 干辣椒节 | D22: 斤 | E22: 1 | F22: =H22/0.85 -> 30.588235 | G22: =H22/F22 -> 0.85 | H22: 26 | I22: =E22*H22 -> 26
A23: 18 | B23: 孝感米酒900g | C23: 900g*6瓶/件 | D23: 瓶 | E23: 3 | F23: =H23/0.85 -> 10 | G23: =H23/F23 -> 0.85 | H23: 8.5 | I23: =E23*H23 -> 25.5
A24: 19 | B24: 蒸肉白米粉(细） | C24: 散称 | D24: 斤 | E24: 5 | F24: =H24/0.85 -> 5.2941176 | G24: =H24/F24 -> 0.85 | H24: 4.5 | I24: =E24*H24 -> 22.5
A25: 20 | B25: 宣乐红丁 | C25: 13斤/件 | D25: 件 | E25: 1 | F25: =H25/0.85 -> 52.941176 | G25: =H25/F25 -> 0.85 | H25: 45 | I25: =E25*H25 -> 45
A26: 21 | B26: 米美佳东北香米15kg/袋 | C26: 15kg/袋 | D26: 袋 | E26: 1 | F26: =H26/0.85 -> 103.52941 | G26: =H26/F26 -> 0.85 | H26: 88 | I26: =E26*H26 -> 88
A27: 22 | B27: 光明健能酸奶180g | C27: 180g | D27: 杯 | E27: 60 | F27: =H27/0.85 -> 4.1176471 | G27: =H27/F27 -> 0.85 | H27: 3.5 | I27: =E27*H27 -> 210
A28: 23
A29: 24
A30: 25
A31: 26
A32: 27
A33: 28
A34: 合计: | B34: =SUM(I6:I33) -> 1329.3
A35: 金额大写： | B35: =B34 -> 1329.3
A36: 制表人 ：樊君丽 收货人： 送货人：

Sheet 2
A1: 武汉康恩农贸发展有限公司送货单
A3: 收货单位： | B3: 汉南数智化检测分公司
A4: 配送日期： | B4: 45171
A5: 序号 | B5: 名称 | C5: 规格 | D5: 单位 | E5: 数量 | F5: 超市价格 | G5: 折扣率 | H5: 折后价 | I5: 折后金额 | J5: 备注
A6: 1 | B6: 红椒 | D6: 斤 | E6: 2 | F6: =H6/0.85 -> 9.1764706 | G6: =H6/F6 -> 0.85 | H6: 7.8 | I6: =E6*H6 -> 15.6
A7: 2 | B7: 西红柿 | D7: 斤 | E7: 2 | F7: =H7/0.85 -> 4.4705882 | G7: =H7/F7 -> 0.85 | H7: 3.8 | I7: =E7*H7 -> 7.6
A8: 3 | B8: 油麦菜 | D8: 斤 | E8: 3.2 | F8: =H8/0.85 -> 4.1176471 | G8: =H8/F8 -> 0.85 | H8: 3.5 | I8: =E8*H8 -> 11.2
A9: 4
A10: 5
A11: 6
A12: 7
A13: 8
A14: 9
A15: 10
A16: 11
A17: 12
A18: 13
A19: 14
A20: 15
... A32: 27
A33: 供货合计: | B33: =SUM(I6:I32) -> 34.4
A34: 金额大写： | B34: =B33 -> 34.4
A35: 制表人 ：樊君丽 收货人： 送货人：

Sheet 4.
A1: 武汉康恩农贸发展有限公司送货单
A3: 收货单位：汉南数智化检测分公司
A4: 配送日期：2023-9-1 | B4: 45173
A5: 序号 | B5: 名称 | C5: 规格 | D5: 单位 | E5: 数量 | F5: 超市价格 | G5: 折扣率 | H5: 折后价 | I5: 折后金额 | J5: 备注
A6: 1 | B6: （新鲜）河粉 | D6: 斤 | E6: 5 | F6: =H6/0.85 -> 3.5294118 | G6: =H6/F6 -> 0.85 | H6: 3 | I6: =E6*H6 -> 15
A7: 2 | B7: 干细粉 | C7: 散称 | D7: 斤 | E7: 5 | F7: =H7/0.85 -> 4.1176471 | G7: =H7/F7 -> 0.85 | H7: 3.5 | I7: =E7*H7 -> 17.5
A8: 3 | B8: 热干面（熟） | D8: 斤 | E8: 5 | F8: =H8/0.85 -> 4.1176471 | G8: =H8/F8 -> 0.85 | H8: 3.5 | I8: =E8*H8 -> 17.5
A9: 4 | B9: 大葱 | D9: 斤 | E9: 2 | F9: =H9/0.85 -> 4.1176471 | G9: =H9/F9 -> 0.85 | H9: 3.5 | I9: =E9*H9 -> 7
A10: 5 | B10: 大土豆 | D10: 斤 | E10: 22 | F10: =H10/0.85 -> 4.1176471 | G10: =H10/F10 -> 0.85 | H10: 3.5 | I10: =E10*H10 -> 77
A11: 6 | B11: 红椒 | D11: 斤 | E11: 3 | F11: =H11/0.85 -> 9.1764706 | G11: =H11/F11 -> 0.85 | H11: 7.8 | I11: =E11*H11 -> 23.4
A12: 7 | B12: 甜玉米棒 | D12: 个 | E12: 4 | F12: =H12/0.85 -> 3.5294118 | G12: =H12/F12 -> 0.85 | H12: 3 | I12: =E12*H12 -> 12
A13: 8 | B13: 铁棍山药 | D13: 斤 | E13: 6 | F13: =H13/0.85 -> 11.529412 | G13: =H13/F13 -> 0.85 | H13: 9.8 | I13: =E13*H13 -> 58.8
A14: 9 | B14: 芜湖青椒 | D14: 斤 | E14: 3 | F14: =H14/0.85 -> 5.2941176 | G14: =H14/F14 -> 0.85 | H14: 4.5 | I14: =E14*H14 -> 13.5
A15: 10 | B15: 生菜 | D15: 斤 | E15: 18 | F15: =H15/0.85 -> 5.6470588 | G15: =H15/F15 -> 0.85 | H15: 4.8 | I15: =E15*H15 -> 86.4
A16: 11 | B16: 细土芹 | D16: 斤 | E16: 4 | F16: =H16/0.85 -> 6.4705882 | G16: =H16/F16 -> 0.85 | H16: 5.5 | I16: =E16*H16 -> 22
A17: 12 | B17: 红壳鸡蛋 | C17: 12板/件 | D17: 件 | E17: 1 | F17: =H17/0.85 -> 352.94118 | G17: =H17/F17 -> 0.85 | H17: 300 | I17: =E17*H17 -> 300
A18: 13 | B18: 【鲜】净三黄鸡 | D18: 斤 | E18: 6 | F18: =H18/0.85 -> 17.411765 | G18: =H18/F18 -> 0.85 | H18: 14.8 | I18: =E18*H18 -> 88.8
A19: 14 | B19: 【鲜】五花肉沫 | D19: 斤 | E19: 7 | F19: =H19/0.85 -> 19.764706 | G19: =H19/F19 -> 0.85 | H19: 16.8 | I19: =E19*H19 -> 117.6
A20: 16 | B20: 光明健能酸奶180g | C20: 180g | D20: 杯 | E20: 60 | F20: =H20/0.85 -> 4.1176471 | G20: =H20/F20 -> 0.85 | H20: 3.5 | I20: =E20*H20 -> 210
A21: 17
A22: 18
A23: 19
A24: 20
A25: 21
A26: 22
A27: 23
A28: 24
A29: 合计: | B29: =SUM(I6:I28) -> 1066.5
A30: 金额大写： | B30: =B29 -> 1066.5
A31: 制表人 ：樊君丽 收货人： 送货人：

Sheet 5
A1: 武汉康恩农贸发展有限公司送货单
A3: 收货单位： | B3: 汉南数智化检测分公司
A4: 配送日期： | B4: 45174
A5: 序号 | B5: 名称 | C5: 规格 | D5: 单位 | E5: 数量 | F5: 超市价格 | G5: 折扣率 | H5: 折后价 | I5: 折后金额 | J5: 备注
A6: 1 | B6: （新鲜）河粉 | D6: 斤 | E6: 5 | F6: =H6/0.85 -> 3.5294118 | G6: =H6/F6 -> 0.85 | H6: 3 | I6: =E6*H6 -> 15
A7: 2 | B7: 热干面（熟） | D7: 斤 | E7: 3 | F7: =H7/0.85 -> 4.1176471 | G7: =H7/F7 -> 0.85 | H7: 3.5 | I7: =E7*H7 -> 10.5
A8: 3 | B8: 小葱 | D8: 斤 | E8: 1 | F8: =H8/0.85 -> 8 | G8: =H8/F8 -> 0.85 | H8: 6.8 | I8: =E8*H8 -> 6.8
A9: 4 | B9: 大土豆 | D9: 斤 | E9: 8 | F9: =H9/0.85 -> 4.1176471 | G9: =H9/F9 -> 0.85 | H9: 3.5 | I9: =E9*H9 -> 28
A10: 5 | B10: 红椒 | D10: 斤 | E10: 3 | F10: =H10/0.85 -> 9.1764706 | G10: =H10/F10 -> 0.85 | H10: 7.8 | I10: =E10*H10 -> 23.4
A11: 6 | B11: 芜湖青椒 | D11: 斤 | E11: 3 | F11: =H11/0.85 -> 5.2941176 | G11: =H11/F11 -> 0.85 | H11: 4.5 | I11: =E11*H11 -> 13.5
A12: 7 | B12: 西红柿 | D12: 斤 | E12: 5 | F12: =H12/0.85 -> 4.4705882 | G12: =H12/F12 -> 0.85 | H12: 3.8 | I12: =E12*H12 -> 19
A13: 8 | B13: 老南瓜 | D13: 斤 | E13: 16 | F13: =H13/0.85 -> 2.9411765 | G13: =H13/F13 -> 0.85 | H13: 2.5 | I13: =E13*H13 -> 40
A14: 9 | B14: 生菜 | D14: 斤 | E14: 5 | F14: =H14/0.85 -> 5.6470588 | G14: =H14/F14 -> 0.85 | H14: 4.8 | I14: =E14*H14 -> 24
A15: 10 | B15: 油麦菜 | D15: 斤 | E15: 18 | F15: =H15/0.85 -> 4.1176471 | G15: =H15/F15 -> 0.85 | H15: 3.5 | I15: =E15*H15 -> 63
A16: 11 | B16: 厚干子 | D16: 斤 | E16: 16 | F16: =H16/0.85 -> 8 | G16: =H16/F16 -> 0.85 | H16: 6.8 | I16: =E16*H16 -> 108.8
A17: 12 | B17: 熟鹌鹑蛋 | D17: 斤 | E17: 5 | F17: =H17/0.85 -> 16.235294 | G17: =H17/F17 -> 0.85 | H17: 13.8 | I17: =E17*H17 -> 69
... A19: 14 | B19: 【鲜】猪瘦肉丝 | D19: 斤 | E19: 8 | F19: =H19/0.85 -> 25.882353 | G19: =H19/F19 -> 0.85 | H19: 22 | I19: =E19*H19 -> 176
A20: 15 | B20: 奥利客烘焙调理奶油 | C20: 907g/12瓶/件 | D20: 瓶 | E20: 2 | F20: =H20/0.85 -> 25.882353 | G20: =H20/F20 -> 0.85 | H20: 22 | I20: =E20*H20 -> 44
A21: 16 | B21: 鑫石羊郫县豆瓣酱1kg | C21: 1kg*8桶/件 | D21: 桶 | E21: 1 | F21: =H21/0.85 -> 12.941176 | G21: =H21/F21 -> 0.85 | H21: 11 | I21: =E21*H21 -> 11
A22: 17 | B22: 云鹤精制碘盐 | C22: 500g*50袋/件 | D22: 袋 | E22: 10 | F22: =H22/0.85 -> 2.3529412 | G22: =H22/F22 -> 0.85 | H22: 2 | I22: =E22*H22 -> 20
A23: 18 | B23: 光明健能酸奶180g | C23: 180g | D23: 杯 | E23: 62 | F23: =H23/0.85 -> 4.1176471 | G23: =H23/F23 -> 0.85 | H23: 3.5 | I23: =E23*H23 -> 217
A24: 19
A25: 20
A26: 21
A27: 22
A28: 23
A29: 24
A30: 25
A31: 供货合计: | B31: =SUM(I6:I30) -> 1013.8
A32: 金额大写： | B32: =B31 -> 1013.8
A33: 制表人 ：樊君丽 收货人： 送货人：

Sheet 6
A1: 武汉康恩农贸发展有限公司送货单
A3: 收货单位： | B3: 汉南数智化检测分公司
A4: 配送日期： | B4: 45175
A5: 序号 | B5: 名称 | C5: 规格 | D5: 单位 | E5: 数量 | F5: 超市价格 | G5: 折扣率 | H5: 折后价 | I5: 折后金额 | J5: 备注
A6: 1 | B6: （新鲜）河粉 | D6: 斤 | E6: 5 | F6: =H6/0.85 -> 3.5294118 | G6: =H6/F6 -> 0.85 | H6: 3 | I6: =E6*H6 -> 15
A7: 2 | B7: 干细粉 | C7: 散称 | D7: 斤 | E7: 6 | F7: =H7/0.85 -> 4.1176471 | G7: =H7/F7 -> 0.85 | H7: 3.5 | I7: =E7*H7 -> 21
A8: 3 | B8: 热干面（熟） | D8: 斤 | E8: 5 | F8: =H8/0.85 -> 4.1176471 | G8: =H8/F8 -> 0.85 | H8: 3.5 | I8: =E8*H8 -> 17.5
A9: 4 | B9: 刀豆 | D9: 斤 | E9: 19 | F9: =H9/0.85 -> 9.1764706 | G9: =H9/F9 -> 0.85 | H9: 7.8 | I9: =E9*H9 -> 148.2
A10: 5 | B10: 大土豆 | D10: 斤 | E10: 20 | F10: =H10/0.85 -> 4.1176471 | G10: =H10/F10 -> 0.85 | H10: 3.5 | I10: =E10*H10 -> 70
A11: 6 | B11: 红椒 | D11: 斤 | E11: 3 | F11: =H11/0.85 -> 9.1764706 | G11: =H11/F11 -> 0.85 | H11: 7.8 | I11: =E11*H11 -> 23.4
A12: 7 | B12: 甜玉米棒 | D12: 个 | E12: 7 | F12: =H12/0.85 -> 3.5294118 | G12: =H12/F12 -> 0.85 | H12: 3 | I12: =E12*H12 -> 21
A13: 8 | B13: 芜湖青椒 | D13: 斤 | E13: 3 | F13: =H13/0.85 -> 5.2941176 | G13: =H13/F13 -> 0.85 | H13: 4.5 | I13: =E13*H13 -> 13.5
A14: 9 | B14: 金针菇 | D14: 斤 | E14: 5 | F14: =H14/0.85 -> 8 | G14: =H14/F14 -> 0.85 | H14: 6.8 | I14: =E14*H14 -> 34
A15: 10 | B15: 平菇 | D15: 斤 | E15: 2 | F15: =H15/0.85 -> 12.705882 | G15: =H15/F15 -> 0.85 | H15: 10.8 | I15: =E15*H15 -> 21.6
A16: 11 | B16: 大白菜 | D16: 斤 | E16: 19 | F16: =H16/0.85 -> 2.1176471 | G16: =H16/F16 -> 0.85 | H16: 1.8 | I16: =E16*H16 -> 34.2
A17: 12 | B17: 鸡边腿剁块 | D17: 斤 | E17: 18 | F17: =H17/0.85 -> 11.764706 | G17: =H17/F17 -> 0.85 | H17: 10 | I17: =E17*H17 -> 180
A18: 13 | B18: 【鲜】五花肉沫 | D18: 斤 | E18: 3 | F18: =H18/0.85 -> 19.764706 | G18: =H18/F18 -> 0.85 | H18: 16.8 | I18: =E18*H18 -> 50.4
A19: 14 | B19: 【鲜】猪五花肉片 | D19: 斤 | E19: 5 | F19: =H19/0.85 -> 21.764706 | G19: =H19/F19 -> 0.85 | H19: 18.5 | I19: =E19*H19 -> 92.5
A20: 15 | B20: 海天精制蚝油6kg | C20: 6kg*2桶 | D20: 桶 | E20: 1 | F20: =H20/0.85 -> 48.823529 | G20: =H20/F20 -> 0.85 | H20: 41.5 | I20: =E20*H20 -> 41.5
A21: 16 | B21: 五仁酱丁 | C21: 9斤/件 | D21: 件 | E21: 1 | F21: =H21/0.85 -> 54.117647 | G21: =H21/F21 -> 0.85 | H21: 46 | I21: =E21*H21 -> 46
A22: 17 | B22: 永超榨菜 | C22: 8斤 | D22: 件 | E22: 1 | F22: =H22/0.85 -> 64.705882 | G22: =H22/F22 -> 0.85 | H22: 55 | I22: =E22*H22 -> 55
A23: 18 | B23: 原味酸豆角（切好的） | C23: 8斤/件 | D23: 件 | E23: 1 | F23: =H23/0.85 -> 51.764706 | G23: =H23/F23 -> 0.85 | H23: 44 | I23: =E23*H23 -> 44
A24: 19 | B24: 合鑫泰东北珍珠香米 | C24: 25kg/包 | D24: 袋 | E24: 1 | F24: =H24/0.85 -> 205.88235 | G24: =H24/F24 -> 0.85 | H24: 175 | I24: =E24*H24 -> 175
A25: 20 | B25: 光明健能酸奶180g | C25: 180g | D25: 杯 | E25: 60 | F25: =H25/0.85 -> 4.1176471 | G25: =H25/F25 -> 0.85 | H25: 3.5 | I25: =E25*H25 -> 210
A26: 21
A27: 22
A28: 23
A29: 24
A30: 25
A31: 供货合计: | B31: =SUM(I6:I30) -> 1313.8
A32: 金额大写： | B32: =B31 -> 1313.8
A33: 制表人 ：樊君丽 收货人： 送货人：

Sheet 7
A1: 武汉康恩农贸发展有限公司送货单
A3: 收货单位： | B3: 汉南数智化检测分公司
A4: 配送日期： | B4: 45176
A5: 序号 | B5: 名称 | C5: 规格 | D5: 单位 | E5: 数量 | F5: 超市价格 | G5: 折扣率 | H5: 折后价 | I5: 折后金额 | J5: 备注
A6: 1 | B6: （新鲜）河粉 | D6: 斤 | E6: 5 | F6: =H6/0.85 -> 3.5294118 | G6: =H6/F6 -> 0.85 | H6: 3 | I6: =E6*H6 -> 15
A7: 2 | B7: 干细粉 | C7: 散称 | D7: 斤 | E7: 6 | F7: =H7/0.85 -> 4.1176471 | G7: =H7/F7 -> 0.85 | H7: 3.5 | I7: =E7*H7 -> 21
A8: 3 | B8: 热干面（熟） | D8: 斤 | E8: 5 | F8: =H8/0.85 -> 4.1176471 | G8: =H8/F8 -> 0.85 | H8: 3.5 | I8: =E8*H8 -> 17.5
A9: 4 | B9: 青豆角 | D9: 斤 | E9: 8 | F9: =H9/0.85 -> 5.2941176 | G9: =H9/F9 -> 0.85 | H9: 4.5 | I9: =E9*H9 -> 36
A10: 5 | B10: 大红薯 | D10: 斤 | E10: 10 | F10: =H10/0.85 -> 4.1176471 | G10: =H10/F10 -> 0.85 | H10: 3.5 | I10: =E10*H10 -> 35
A11: 6 | B11: 大藕 | D11: 斤 | E11: 15 | F11: =H11/0.85 -> 5.2941176 | G11: =H11/F11 -> 0.85 | H11: 4.5 | I11: =E11*H11 -> 67.5
A12: 7 | B12: 大土豆 | D12: 斤 | E12: 8 | F12: =H12/0.85 -> 4.1176471 | G12: =H12/F12 -> 0.85 | H12: 3.5 | I12: =E12*H12 -> 28
A13: 8 | B13: 红椒 | D13: 斤 | E13: 9 | F13: =H13/0.85 -> 9.1764706 | G13: =H13/F13 -> 0.85 | H13: 7.8 | I13: =E13*H13 -> 70.2
A14: 9 | B14: 芜湖青椒 | D14: 斤 | E14: 9 | F14: =H14/0.85 -> 5.2941176 | G14: =H14/F14 -> 0.85 | H14: 4.5 | I14: =E14*H14 -> 40.5
A15: 10 | B15: 紫长茄子（细长） | D15: 斤 | E15: 13 | F15: =H15/0.85 -> 4.4705882 | G15: =H15/F15 -> 0.85 | H15: 3.8 | I15: =E15*H15 -> 49.4
A16: 11 | B16: 冬瓜 | D16: 斤 | E16: 5.3 | F16: =H16/0.85 -> 2.9411765 | G16: =H16/F16 -> 0.85 | H16: 2.5 | I16: =E16*H16 -> 13.25
A17: 12 | B17: 青丝瓜 | D17: 斤 | E17: 19 | F17: =H17/0.85 -> 5.2941176 | G17: =H17/F17 -> 0.85 | H17: 4.5 | I17: =E17*H17 -> 85.5
A18: 13 | B18: 韭菜 | D18: 斤 | E18: 2 | F18: =H18/0.85 -> 5.8823529 | G18: =H18/F18 -> 0.85 | H18: 5 | I18: =E18*H18 -> 10
A19: 14 | B19: 平包菜 | D19: 斤 | E19: 18 | F19: =H19/0.85 -> 2.3529412 | G19: =H19/F19 -> 0.85 | H19: 2 | I19: =E19*H19 -> 36
A20: 15 | B20: 娃娃菜 | C20: 散装 | D20: 斤 | E20: 7.5 | F20: =H20/0.85 -> 5.2941176 | G20: =H20/F20 -> 0.85 | H20: 4.5 | I20: =E20*H20 -> 33.75
A21: 16 | B21: 嫩豆腐 | D21: 斤 | E21: 4 | F21: =H21/0.85 -> 4.1176471 | G21: =H21/F21 -> 0.85 | H21: 3.5 | I21: =E21*H21 -> 14
A22: 17 | B22: 【鲜】五花肉沫 | D22: 斤 | E22: 3 | F22: =H22/0.85 -> 19.764706 | G22: =H22/F22 -> 0.85 | H22: 16.8 | I22: =E22*H22 -> 50.4
A23: 18 | B23: 【鲜】猪脊骨 | D23: 斤 | E23: 3 | F23: =H23/0.85 -> 17.411765 | G23: =H23/F23 -> 0.85 | H23: 14.8 | I23: =E23*H23 -> 44.4
A24: 19 | B24: 【鲜】猪五花肉片 | D24: 斤 | E24: 8 | F24: =H24/0.85 -> 21.764706 | G24: =H24/F24 -> 0.85 | H24: 18.5 | I24: =E24*H24 -> 148
A25: 21 | B25: 【鲜】净胖头鱼头 | D25: 斤 | E25: 5 | F25: =H25/0.85 -> 23.529412 | G25: =H25/F25 -> 0.85 | H25: 20 | I25: =E25*H25 -> 100
A26: 22 | B26: 白砂糖 | D26: 斤 | E26: 8 | F26: =H26/0.85 -> 5.7647059 | G26: =H26/F26 -> 0.85 | H26: 4.9 | I26: =E26*H26 -> 39.2
A27: 23 | B27: 光明畅优酸奶（原味） | C27: 180g | D27: 杯 | E27: 60 | F27: =H27/0.85 -> 4.1176471 | G27: =H27/F27 -> 0.85 | H27: 3.5 | I27: =E27*H27 -> 210
A28: 24
A29: 25
A30: 26
A31: 27
A32: 28
A33: 供货合计: | B33: =SUM(I6:I32) -> 1164.6
A34: 金额大写： | B34: =B33 -> 1164.6
A35: 制表人 ：樊君丽 收货人： 送货人：

Sheet 8
A1: 武汉康恩农贸发展有限公司送货单
A3: 收货单位： | B3: 汉南数智化检测分公司
A4: 配送日期： | B4: 45177
A5: 序号 | B5: 名称 | C5: 规格 | D5: 单位 | E5: 数量 | F5: 超市价格 | G5: 折扣率 | H5: 折后价 | I5: 折后金额 | J5: 备注
A6: 1 | B6: （新鲜）河粉 | D6: 斤 | E6: 5 | F6: =H6/0.85 -> 3.5294118 | G6: =H6/F6 -> 0.85 | H6: 3 | I6: =E6*H6 -> 15
A7: 2 | B7: 大圆皮 | D7: 斤 | E7: 2 | F7: =H7/0.85 -> 4.7058824 | G7: =H7/F7 -> 0.85 | H7: 4 | I7: =E7*H7 -> 8
A8: 3 | B8: 饺子皮 | D8: 斤 | E8: 2 | F8: =H8/0.85 -> 4.1176471 | G8: =H8/F8 -> 0.85 | H8: 3.5 | I8: =E8*H8 -> 7
A9: 4 | B9: 热干面（熟） | D9: 斤 | E9: 5 | F9: =H9/0.85 -> 4.1176471 | G9: =H9/F9 -> 0.85 | H9: 3.5 | I9: =E9*H9 -> 17.5
A10: 5 | B10: 红皮洋葱 | D10: 斤 | E10: 5 | F10: =H10/0.85 -> 2.9411765 | G10: =H10/F10 -> 0.85 | H10: 2.5 | I10: =E10*H10 -> 12.5
A11: 6 | B11: 生姜 | D11: 斤 | E11: 5 | F11: =H11/0.85 -> 15.058824 | G11: =H11/F11 -> 0.85 | H11: 12.8 | I11: =E11*H11 -> 64
A12: 7 | B12: 新鲜毛豆米 | D12: 斤 | E12: 8 | F12: =H12/0.85 -> 17.058824 | G12: =H12/F12 -> 0.85 | H12: 14.5 | I12: =E12*H12 -> 116
A13: 8 | B13: 红椒 | D13: 斤 | E13: 3 | F13: =H13/0.85 -> 9.1764706 | G13: =H13/F13 -> 0.85 | H13: 7.8 | I13: =E13*H13 -> 23.4
A14: 9 | B14: 胡萝卜 | D14: 斤 | E14: 5 | F14: =H14/0.85 -> 2.9411765 | G14: =H14/F14 -> 0.85 | H14: 2.5 | I14: =E14*H14 -> 12.5
A15: 10 | B15: 甜玉米棒 | D15: 个 | E15: 7 | F15: =H15/0.85 -> 3.5294118 | G15: =H15/F15 -> 0.85 | H15: 3 | I15: =E15*H15 -> 21
A16: 11 | B16: 芜湖青椒 | D16: 斤 | E16: 8 | F16: =H16/0.85 -> 5.2941176 | G16: =H16/F16 -> 0.85 | H16: 4.5 | I16: =E16*H16 -> 36
A17: 12 | B17: 西红柿 | D17: 斤 | E17: 7 | F17: =H17/0.85 -> 4.4705882 | G17: =H17/F17 -> 0.85 | H17: 3.8 | I17: =E17*H17 -> 26.6
... A24: 19 | B24: 香蕉 | D24: 斤 | E24: 14 | F24: =H24/0.85 -> 6.4705882 | G24: =H24/F24 -> 0.85 | H24: 5.5 | I24: =E24*H24 -> 77
A25: 20 | B25: 红壳鸡蛋 | C25: 12板/件 | D25: 件 | E25: 1 | F25: =H25/0.85 -> 352.94118 | G25: =H25/F25 -> 0.85 | H25: 300 | I25: =E25*H25 -> 300
A26: 21 | B26: 【鲜】五花肉沫 | D26: 斤 | E26: 4 | F26: =H26/0.85 -> 19.764706 | G26: =H26/F26 -> 0.85 | H26: 16.8 | I26: =E26*H26 -> 67.2
A27: 22 | B27: 奥利客烘焙调理奶油 | C27: 907g/12瓶/件 | D27: 件 | E27: 1 | F27: =H27/0.85 -> 25.882353 | G27: =H27/F27 -> 0.85 | H27: 22 | I27: =E27*H27 -> 22
A28: 23 | B28: 惠万家烟鸭胸 | C28: 5公斤/件/（32个） | D28: 件 | E28: 1 | F28: =H28/0.85 -> 141.17647 | G28: =H28/F28 -> 0.85 | H28: 120 | I28: =E28*H28 -> 120
A29: 25 | B29: 鱿鱼须 | C29: 350g*10袋 | D29: 件 | E29: 1 | F29: =H29/0.85 -> 235.29412 | G29: =H29/F29 -> 0.85 | H29: 200 | I29: =E29*H29 -> 200
A30: 26 | B30: 大桥鸡精900g | C30: 900g*10袋/件 | D30: 件 | E30: 1 | F30: =H30/0.85 -> 428.23529 | G30: =H30/F30 -> 0.85 | H30: 364 | I30: =E30*H30 -> 364
A31: 27 | B31: 光明健能酸奶180g | C31: 180g | D31: 杯 | E31: 68 | F31: =H31/0.85 -> 4.1176471 | G31: =H31/F31 -> 0.85 | H31: 3.5 | I31: =E31*H31 -> 238
A32: 28
A33: 供货合计: | B33: =SUM(I6:I32) -> 2051.1
A34: 金额大写： | B34: =B33 -> 2051.1
A35: 制表人 ：樊君丽 收货人： 送货人：

Sheet 9
A1: 武汉康恩农贸发展有限公司送货单
A3: 收货单位： | B3: 汉南数智化检测分公司
A4: 配送日期： | B4: 45178
A5: 序号 | B5: 名称 | C5: 规格 | D5: 单位 | E5: 数量 | F5: 超市价格 | G5: 折扣率 | H5: 折后价 | I5: 折后金额 | J5: 备注
A6: 1 | B6: 毛豆(剪好) | D6: 斤 | E6: 7 | F6: =H6/0.85 -> 8 | G6: =H6/F6 -> 0.85 | H6: 6.8 | I6: =E6*H6 -> 47.6
A7: 2 | B7: 红椒 | D7: 斤 | E7: 2 | F7: =H7/0.85 -> 9.1764706 | G7: =H7/F7 -> 0.85 | H7: 7.8 | I7: =E7*H7 -> 15.6
A8: 3 | B8: 芜湖青椒 | D8: 斤 | E8: 2 | F8: =H8/0.85 -> 5.2941176 | G8: =H8/F8 -> 0.85 | H8: 4.5 | I8: =E8*H8 -> 9
A9: 4 | B9: 鲜香菇 | D9: 斤 | E9: 4 | F9: =H9/0.85 -> 11.529412 | G9: =H9/F9 -> 0.85 | H9: 9.8 | I9: =E9*H9 -> 39.2
A10: 5 | B10: 油麦菜 | D10: 斤 | E10: 7 | F10: =H10/0.85 -> 4.1176471 | G10: =H10/F10 -> 0.85 | H10: 3.5 | I10: =E10*H10 -> 24.5
A11: 6 | B11: 【鲜】净三黄鸡 | D11: 斤 | E11: 7 | F11: =H11/0.85 -> 17.411765 | G11: =H11/F11 -> 0.85 | H11: 14.8 | I11: =E11*H11 -> 103.6
A12: 7 | B12: 【鲜】猪瘦肉丝 | D12: 斤 | E12: 3 | F12: =H12/0.85 -> 25.882353 | G12: =H12/F12 -> 0.85 | H12: 22 | I12: =E12*H12 -> 66
A13: 8 | B13: 清水笋丝 | C13: 2.5kg*6包/件 | D13: 包 | E13: 4 | F13: =H13/0.85 -> 15.929412 | G13: =H13/F13 -> 0.85 | H13: 13.54 | I13: =E13*H13 -> 54.16
A14: 9
A15: 10
A16: 11
A17: 12
A18: 13
A19: 14
A20: 15
A21: 16
A22: 17
A23: 18
A24: 19
A25: 20
... A32: 27
A33: 供货合计: | B33: =SUM(I6:I32) -> 359.66
A34: 金额大写： | B34: =B33 -> 359.66
A35: 制表人 ：樊君丽 收货人： 送货人：

Sheet 11
A1: 武汉康恩农贸发展有限公司送货单
A3: 收货单位： | B3: 汉南数智化检测分公司
A4: 配送日期： | B4: 45180
A5: 序号 | B5: 名称 | C5: 规格 | D5: 单位 | E5: 数量 | F5: 超市价格 | G5: 折扣率 | H5: 折后价 | I5: 折后金额 | J5: 备注
A6: 1 | B6: （新鲜）河粉 | D6: 斤 | E6: 6 | F6: =H6/0.85 -> 3.5294118 | G6: =H6/F6 -> 0.85 | H6: 3 | I6: =E6*H6 -> 18
A7: 2 | B7: 干细粉 | C7: 散称 | D7: 斤 | E7: 6 | F7: =H7/0.85 -> 4.1176471 | G7: =H7/F7 -> 0.85 | H7: 3.5 | I7: =E7*H7 -> 21
A8: 3 | B8: 热干面（熟） | D8: 斤 | E8: 5 | F8: =H8/0.85 -> 4.1176471 | G8: =H8/F8 -> 0.85 | H8: 3.5 | I8: =E8*H8 -> 17.5
A9: 4 | B9: 大葱 | D9: 斤 | E9: 2 | F9: =H9/0.85 -> 4.1176471 | G9: =H9/F9 -> 0.85 | H9: 3.5 | I9: =E9*H9 -> 7
A10: 5 | B10: 小葱 | D10: 斤 | E10: 1 | F10: =H10/0.85 -> 8 | G10: =H10/F10 -> 0.85 | H10: 6.8 | I10: =E10*H10 -> 6.8
A11: 6 | B11: 红椒 | D11: 斤 | E11: 2 | F11: =H11/0.85 -> 9.1764706 | G11: =H11/F11 -> 0.85 | H11: 7.8 | I11: =E11*H11 -> 15.6
A12: 7 | B12: 芜湖青椒 | D12: 斤 | E12: 2 | F12: =H12/0.85 -> 5.2941176 | G12: =H12/F12 -> 0.85 | H12: 4.5 | I12: =E12*H12 -> 9
A13: 8 | B13: 韭菜花 | D13: 斤 | E13: 14 | F13: =H13/0.85 -> 14.117647 | G13: =H13/F13 -> 0.85 | H13: 12 | I13: =E13*H13 -> 168
A14: 9 | B14: 细土芹 | D14: 斤 | E14: 6 | F14: =H14/0.85 -> 6.4705882 | G14: =H14/F14 -> 0.85 | H14: 5.5 | I14: =E14*H14 -> 33
A15: 10 | B15: 油麦菜 | D15: 斤 | E15: 15 | F15: =H15/0.85 -> 4.1176471 | G15: =H15/F15 -> 0.85 | H15: 3.5 | I15: =E15*H15 -> 52.5
A16: 11 | B16: 橙子 | D16: 斤 | E16: 14 | F16: =H16/0.85 -> 11.529412 | G16: =H16/F16 -> 0.85 | H16: 9.8 | I16: =E16*H16 -> 137.2
A17: 12 | B17: 嫩豆腐 | D17: 斤 | E17: 18 | F17: =H17/0.85 -> 4.1176471 | G17: =H17/F17 -> 0.85 | H17: 3.5 | I17: =E17*H17 -> 63
A18: 13 | B18: 【鲜】五花肉沫 | D18: 斤 | E18: 7 | F18: =H18/0.85 -> 19.764706 | G18: =H18/F18 -> 0.85 | H18: 16.8 | I18: =E18*H18 -> 117.6
A19: 14 | B19: 【鲜】猪通排骨 | D19: 斤 | E19: 8 | F19: =H19/0.85 -> 33.882353 | G19: =H19/F19 -> 0.85 | H19: 28.8 | I19: =E19*H19 -> 230.4
A20: 15 | B20: 干红枣片 | C20: 散称 | D20: 斤 | E20: 2 | F20: =H20/0.85 -> 18.823529 | G20: =H20/F20 -> 0.85 | H20: 16 | I20: =E20*H20 -> 32
A21: 16 | B21: 果珍风味固体饮料 | D21: 袋 | E21: 4 | F21: =H21/0.85 -> 22.352941 | G21: =H21/F21 -> 0.85 | H21: 19 | I21: =E21*H21 -> 76
A22: 17 | B22: 水发海带头 | C22: 18斤/件 | D22: 斤 | E22: 6 | F22: =H22/0.85 -> 9.4117647 | G22: =H22/F22 -> 0.85 | H22: 8 | I22: =E22*H22 -> 48
A23: 18 | B23: 卤牛肉 | D23: 斤 | E23: 5 | F23: =H23/0.85 -> 103.52941 | G23: =H23/F23 -> 0.85 | H23: 88 | I23: =E23*H23 -> 440
A24: 19 | B24: 陈克明高筋细圆挂面 | C24: 1000g*15筒/件 | D24: 筒 | E24: 3 | F24: =H24/0.85 -> 14.117647 | G24: =H24/F24 -> 0.85 | H24: 12 | I24: =E24*H24 -> 36
A25: 20 | B25: 干黄豆 | C25: 50斤/件 | D25: 斤 | E25: 5 | F25: =H25/0.85 -> 6.4705882 | G25: =H25/F25 -> 0.85 | H25: 5.5 | I25: =E25*H25 -> 27.5
A26: 21 | B26: 金龙鱼玉米油 | C26: 5L*4壶/件 | D26: 件 | E26: 1 | F26: =H26/0.85 -> 411.76471 | G26: =H26/F26 -> 0.85 | H26: 350 | I26: =E26*H26 -> 350
A27: 22 | B27: 正和珍珠糯米 | C27: 50斤/袋 | D27: 斤 | E27: 5 | F27: =H27/0.85 -> 5.7647059 | G27: =H27/F27 -> 0.85 | H27: 4.9 | I27: =E27*H27 -> 24.5
A28: 23 | B28: 光明健能酸奶180g | C28: 180g | D28: 杯 | E28: 75 | F28: =H28/0.85 -> 4.1176471 | G28: =H28/F28 -> 0.85 | H28: 3.5 | I28: =E28*H28 -> 262.5
A29: 24
A30: 25
A31: 26
A32: 27
A33: 28
A34: 供货合计: | B34: =SUM(I6:I33) -> 2193.1
A35: 金额大写： | B35: =B34 -> 2193.1
A36: 制表人 ：樊君丽 收货人： 送货人：

Sheet 12
A1: 武汉康恩农贸发展有限公司送货单
A3: 收货单位： | B3: 汉南数智化检测分公司
A4: 配送日期： | B4: 45181
A5: 序号 | B5: 名称 | C5: 规格 | D5: 单位 | E5: 数量 | F5: 超市价格 | G5: 折扣率 | H5: 折后价 | I5: 折后金额 | J5: 备注
A6: 1 | B6: （新鲜）河粉 | D6: 斤 | E6: 6 | F6: =H6/0.85 -> 3.5294118 | G6: =H6/F6 -> 0.85 | H6: 3 | I6: =E6*H6 -> 18
A7: 2 | B7: 热干面（熟） | D7: 斤 | E7: 5 | F7: =H7/0.85 -> 4.1176471 | G7: =H7/F7 -> 0.85 | H7: 3.5 | I7: =E7*H7 -> 17.5
A8: 3 | B8: 烧麦皮 | D8: 斤 | E8: 6 | F8: =H8/0.85 -> 4.1176471 | G8: =H8/F8 -> 0.85 | H8: 3.5 | I8: =E8*H8 -> 21
A9: 4 | B9: 大土豆 | D9: 斤 | E9: 16 | F9: =H9/0.85 -> 4.1176471 | G9: =H9/F9 -> 0.85 | H9: 3.5 | I9: =E9*H9 -> 56
A10: 5 | B10: 红椒 | D10: 斤 | E10: 3 | F10: =H10/0.85 -> 9.1764706 | G10: =H10/F10 -> 0.85 | H10: 7.8 | I10: =E10*H10 -> 23.4
A11: 6 | B11: 甜玉米棒 | D11: 个 | E11: 7 | F11: =H11/0.85 -> 3.5294118 | G11: =H11/F11 -> 0.85 | H11: 3 | I11: =E11*H11 -> 21
A12: 7 | B12: 芜湖青椒 | D12: 斤 | E12: 3 | F12: =H12/0.85 -> 5.2941176 | G12: =H12/F12 -> 0.85 | H12: 4.5 | I12: =E12*H12 -> 13.5
A13: 8 | B13: 西红柿 | D13: 斤 | E13: 3 | F13: =H13/0.85 -> 4.4705882 | G13: =H13/F13 -> 0.85 | H13: 3.8 | I13: =E13*H13 -> 11.4
A14: 9 | B14: 有机花菜 | D14: 斤 | E14: 14 | F14: =H14/0.85 -> 6.4705882 | G14: =H14/F14 -> 0.85 | H14: 5.5 | I14: =E14*H14 -> 77
A15: 10 | B15: 冬瓜 | D15: 斤 | E15: 9.5 | F15: =H15/0.85 -> 2.9411765 | G15: =H15/F15 -> 0.85 | H15: 2.5 | I15: =E15*H15 -> 23.75
A16: 11 | B16: 金针菇 | D16: 斤 | E16: 6 | F16: =H16/0.85 -> 8 | G16: =H16/F16 -> 0.85 | H16: 6.8 | I16: =E16*H16 -> 40.8
A17: 12 | B17: 大白菜 | D17: 斤 | E17: 16 | F17: =H17/0.85 -> 2.1176471 | G17: =H17/F17 -> 0.85 | H17: 1.8 | I17: =E17*H17 -> 28.8
... A24: 20 | B24: 烤鸭 | D24: 只 | E24: 6 | F24: =H24/0.85 -> 34.117647 | G24: =H24/F24 -> 0.85 | H24: 29 | I24: =E24*H24 -> 174
A25: 21 | B25: 合鑫泰东北珍珠香米 | C25: 25kg/包 | D25: 袋 | E25: 2 | F25: =H25/0.85 -> 205.88235 | G25: =H25/F25 -> 0.85 | H25: 175 | I25: =E25*H25 -> 350
A26: 22 | B26: 光明健能酸奶180g | C26: 180g | D26: 杯 | E26: 50 | F26: =H26/0.85 -> 4.1176471 | G26: =H26/F26 -> 0.85 | H26: 3.5 | I26: =E26*H26 -> 175
A27: 23
A28: 24
A29: 25
A30: 26
A31: 27
A32: 供货合计: | B32: =SUM(I6:I31) -> 1339.746
A33: 金额大写： | B33: =B32 -> 1339.746
A34: 制表人 ：樊君丽 收货人： 送货人：

Sheet 13
A1: 武汉康恩农贸发展有限公司送货单
A3: 收货单位： | B3: 汉南数智化检测分公司
A4: 配送日期： | B4: 45182
A5: 序号 | B5: 名称 | C5: 规格 | D5: 单位 | E5: 数量 | F5: 超市价格 | G5: 折扣率 | H5: 折后价 | I5: 折后金额 | J5: 备注
A6: 1 | B6: （新鲜）河粉 | D6: 斤 | E6: 7 | F6: =H6/0.85 -> 3.5294118 | G6: =H6/F6 -> 0.85 | H6: 3 | I6: =E6*H6 -> 21
A7: 2 | B7: 热干面（熟） | D7: 斤 | E7: 5 | F7: =H7/0.85 -> 4.1176471 | G7: =H7/F7 -> 0.85 | H7: 3.5 | I7: =E7*H7 -> 17.5
A8: 3 | B8: 生面窝浆 | D8: 斤 | E8: 5 | F8: =H8/0.85 -> 7.0588235 | G8: =H8/F8 -> 0.85 | H8: 6 | I8: =E8*H8 -> 30
A9: 4 | B9: 白萝卜 | D9: 斤 | E9: 3 | F9: =H9/0.85 -> 2.3529412 | G9: =H9/F9 -> 0.85 | H9: 2 | I9: =E9*H9 -> 6
A10: 5 | B10: 红椒 | D10: 斤 | E10: 3 | F10: =H10/0.85 -> 9.1764706 | G10: =H10/F10 -> 0.85 | H10: 7.8 | I10: =E10*H10 -> 23.4
A11: 6 | B11: 青椒 | D11: 斤 | E11: 3 | F11: =H11/0.85 -> 4.1176471 | G11: =H11/F11 -> 0.85 | H11: 3.5 | I11: =E11*H11 -> 10.5
A12: 7 | B12: 铁棍山药 | D12: 斤 | E12: 16 | F12: =H12/0.85 -> 11.529412 | G12: =H12/F12 -> 0.85 | H12: 9.8 | I12: =E12*H12 -> 156.8
A13: 8 | B13: 西红柿 | D13: 斤 | E13: 6 | F13: =H13/0.85 -> 4.4705882 | G13: =H13/F13 -> 0.85 | H13: 3.8 | I13: =E13*H13 -> 22.8
A14: 9 | B14: 净莴苣 | D14: 斤 | E14: 15 | F14: =H14/0.85 -> 5.6470588 | G14: =H14/F14 -> 0.85 | H14: 4.8 | I14: =E14*H14 -> 72
A15: 10 | B15: 杏鲍菇 | D15: 斤 | E15: 8 | F15: =H15/0.85 -> 6.8235294 | G15: =H15/F15 -> 0.85 | H15: 5.8 | I15: =E15*H15 -> 46.4
A16: 11 | B16: 平包菜 | D16: 斤 | E16: 8 | F16: =H16/0.85 -> 2.3529412 | G16: =H16/F16 -> 0.85 | H16: 2 | I16: =E16*H16 -> 16
A17: 12 | B17: 生菜 | D17: 斤 | E17: 15 | F17: =H17/0.85 -> 5.6470588 | G17: =H17/F17 -> 0.85 | H17: 4.8 | I17: =E17*H17 -> 72
... A21: 16 | B21: 【鲜】净大草鱼 | D21: 斤 | E21: 6.8 | F21: =H21/0.85 -> 16.235294 | G21: =H21/F21 -> 0.85 | H21: 13.8 | I21: =E21*H21 -> 93.84
A22: 17 | B22: 鑫石羊红油豆瓣酱6kg | C22: 6kg/桶 | D22: 桶 | E22: 1 | F22: =H22/0.85 -> 64.705882 | G22: =H22/F22 -> 0.85 | H22: 55 | I22: =E22*H22 -> 55
A23: 18 | B23: 1911老酸奶 | D23: 杯 | E23: 62 | F23: =H23/0.85 -> 4.1176471 | G23: =H23/F23 -> 0.85 | H23: 3.5 | I23: =E23*H23 -> 217
A24: 19
A25: 20
A26: 21
A27: 22
A28: 23
A29: 24
A30: 25
A31: 26
A32: 供货合计: | B32: =SUM(I6:I31) -> 1149.49
A33: 金额大写： | B33: =B32 -> 1149.49
A34: 制表人 ：樊君丽 收货人： 送货人：

Sheet 14
A1: 武汉康恩农贸发展有限公司送货单
A3: 收货单位： | B3: 汉南数智化检测分公司
A4: 配送日期： | B4: 45183
A5: 序号 | B5: 名称 | C5: 规格 | D5: 单位 | E5: 数量 | F5: 超市价格 | G5: 折扣率 | H5: 折后价 | I5: 折后金额 | J5: 备注
A6: 1 | B6: （新鲜）河粉 | D6: 斤 | E6: 6 | F6: =H6/0.85 -> 3.5294118 | G6: =H6/F6 -> 0.85 | H6: 3 | I6: =E6*H6 -> 18
A7: 2 | B7: 干细粉 | C7: 散称 | D7: 斤 | E7: 6 | F7: =H7/0.85 -> 4.1176471 | G7: =H7/F7 -> 0.85 | H7: 3.5 | I7: =E7*H7 -> 21
A8: 3 | B8: 热干面（熟） | D8: 斤 | E8: 5 | F8: =H8/0.85 -> 4.1176471 | G8: =H8/F8 -> 0.85 | H8: 3.5 | I8: =E8*H8 -> 17.5
A9: 4 | B9: 菱角米（去壳） | D9: 斤 | E9: 11 | F9: =H9/0.85 -> 23.529412 | G9: =H9/F9 -> 0.85 | H9: 20 | I9: =E9*H9 -> 220
A10: 5 | B10: 白萝卜 | D10: 斤 | E10: 9 | F10: =H10/0.85 -> 2.3529412 | G10: =H10/F10 -> 0.85 | H10: 2 | I10: =E10*H10 -> 18
A11: 6 | B11: 红椒 | D11: 斤 | E11: 3 | F11: =H11/0.85 -> 9.1764706 | G11: =H11/F11 -> 0.85 | H11: 7.8 | I11: =E11*H11 -> 23.4
A12: 7 | B12: 胡萝卜 | D12: 斤 | E12: 10 | F12: =H12/0.85 -> 2.9411765 | G12: =H12/F12 -> 0.85 | H12: 2.5 | I12: =E12*H12 -> 25
A13: 8 | B13: 嫩藕 | D13: 斤 | E13: 19 | F13: =H13/0.85 -> 5.2941176 | G13: =H13/F13 -> 0.85 | H13: 4.5 | I13: =E13*H13 -> 85.5
A14: 9 | B14: 青椒 | D14: 斤 | E14: 3 | F14: =H14/0.85 -> 4.1176471 | G14: =H14/F14 -> 0.85 | H14: 3.5 | I14: =E14*H14 -> 10.5
A15: 10 | B15: 甜玉米棒 | D15: 个 | E15: 7 | F15: =H15/0.85 -> 3.5294118 | G15: =H15/F15 -> 0.85 | H15: 3 | I15: =E15*H15 -> 21
A16: 11 | B16: 冬瓜 | D16: 斤 | E16: 7 | F16: =H16/0.85 -> 2.9411765 | G16: =H16/F16 -> 0.85 | H16: 2.5 | I16: =E16*H16 -> 17.5
A17: 12 | B17: 净芋头 | C17: （去皮，小） | D17: 斤 | E17: 5 | F17: =H17/0.85 -> 13.882353 | G17: =H17/F17 -> 0.85 | H17: 11.8 | I17: =E17*H17 -> 59
A18: 13 | B18: 平菇 | D18: 斤 | E18: 2 | F18: =H18/0.85 -> 12.705882 | G18: =H18/F18 -> 0.85 | H18: 10.8 | I18: =E18*H18 -> 21.6
A19: 14 | B19: 大白菜 | D19: 斤 | E19: 8 | F19: =H19/0.85 -> 2.1176471 | G19: =H19/F19 -> 0.85 | H19: 1.8 | I19: =E19*H19 -> 14.4
A20: 15 | B20: 油麦菜 | D20: 斤 | E20: 15 | F20: =H20/0.85 -> 4.1176471 | G20: =H20/F20 -> 0.85 | H20: 3.5 | I20: =E20*H20 -> 52.5
A21: 16 | B21: 红壳鸡蛋 | C21: 12板/件 | D21: 件 | E21: 1 | F21: =H21/0.85 -> 352.94118 | G21: =H21/F21 -> 0.85 | H21: 300 | I21: =E21*H21 -> 300
A22: 17 | B22: 熟鹌鹑蛋 | D22: 斤 | E22: 3 | F22: =H22/0.85 -> 16.235294 | G22: =H22/F22 -> 0.85 | H22: 13.8 | I22: =E22*H22 -> 41.4
A23: 19 | B23: 白砂糖 | D23: 斤 | E23: 10 | F23: =H23/0.85 -> 5.7647059 | G23: =H23/F23 -> 0.85 | H23: 4.9 | I23: =E23*H23 -> 49
A24: 20 | B24: 海天草菇老抽1.9L | C24: 1.9L*6壶/件 | D24: 件 | E24: 1 | F24: =H24/0.85 -> 170.58824 | G24: =H24/F24 -> 0.85 | H24: 145 | I24: =E24*H24 -> 145
A25: 21 | B25: 手撕鸡 | D25: 只 | E25: 5 | F25: =H25/0.85 -> 30.588235 | G25: =H25/F25 -> 0.85 | H25: 26 | I25: =E25*H25 -> 130
A26: 22 | B26: 正和珍珠糯米 | C26: 50斤/袋 | D26: 斤 | E26: 5 | F26: =H26/0.85 -> 5.7647059 | G26: =H26/F26 -> 0.85 | H26: 4.9 | I26: =E26*H26 -> 24.5
A27: 23 | B27: 1911老酸奶 | D27: 杯 | E27: 62 | F27: =H27/0.85 -> 4.1176471 | G27: =H27/F27 -> 0.85 | H27: 3.5 | I27: =E27*H27 -> 217
A28: 24
A29: 25
A30: 26
A31: 27
A32: 供货合计: | B32: =SUM(I6:I31) -> 1531.8
A33: 金额大写： | B33: =B32 -> 1531.8
A34: 制表人 ：樊君丽 收货人： 送货人：

Sheet 15
A1: 武汉康恩农贸发展有限公司送货单
A3: 收货单位： | B3: 汉南数智化检测分公司
A4: 配送日期： | B4: 45184
A5: 序号 | B5: 名称 | C5: 规格 | D5: 单位 | E5: 数量 | F5: 超市价格 | G5: 折扣率 | H5: 折后价 | I5: 折后金额 | J5: 备注
A6: 1 | B6: （新鲜）河粉 | D6: 斤 | E6: 7 | F6: =H6/0.85 -> 3.5294118 | G6: =H6/F6 -> 0.85 | H6: 3 | I6: =E6*H6 -> 21
A7: 2 | B7: 热干面（熟） | D7: 斤 | E7: 5 | F7: =H7/0.85 -> 4.1176471 | G7: =H7/F7 -> 0.85 | H7: 3.5 | I7: =E7*H7 -> 17.5
A8: 3 | B8: 西红柿 | D8: 斤 | E8: 8 | F8: =H8/0.85 -> 4.4705882 | G8: =H8/F8 -> 0.85 | H8: 3.8 | I8: =E8*H8 -> 30.4
A9: 4 | B9: 有机花菜 | D9: 斤 | E9: 15 | F9: =H9/0.85 -> 6.4705882 | G9: =H9/F9 -> 0.85 | H9: 5.5 | I9: =E9*H9 -> 82.5
A10: 5 | B10: 平菇 | D10: 斤 | E10: 5 | F10: =H10/0.85 -> 12.705882 | G10: =H10/F10 -> 0.85 | H10: 10.8 | I10: =E10*H10 -> 54
A11: 6 | B11: 韭菜 | D11: 斤 | E11: 3 | F11: =H11/0.85 -> 5.8823529 | G11: =H11/F11 -> 0.85 | H11: 5 | I11: =E11*H11 -> 15
A12: 7 | B12: 小白菜 | D12: 斤 | E12: 13 | F12: =H12/0.85 -> 4.1176471 | G12: =H12/F12 -> 0.85 | H12: 3.5 | I12: =E12*H12 -> 45.5
A13: 8 | B13: 厚干子 | D13: 斤 | E13: 5 | F13: =H13/0.85 -> 8 | G13: =H13/F13 -> 0.85 | H13: 6.8 | I13: =E13*H13 -> 34
A14: 9 | B14: 【鲜】五花肉沫 | D14: 斤 | E14: 8 | F14: =H14/0.85 -> 19.764706 | G14: =H14/F14 -> 0.85 | H14: 16.8 | I14: =E14*H14 -> 134.4
A15: 10 | B15: 【鲜】猪瘦肉丝 | D15: 斤 | E15: 5 | F15: =H15/0.85 -> 25.882353 | G15: =H15/F15 -> 0.85 | H15: 22 | I15: =E15*H15 -> 110
A16: 11 | B16: 【鲜】猪五花肉片 | D16: 斤 | E16: 5 | F16: =H16/0.85 -> 21.764706 | G16: =H16/F16 -> 0.85 | H16: 18.5 | I16: =E16*H16 -> 92.5
A17: 12 | B17: 【鲜】猪血 | D17: 斤 | E17: 5 | F17: =H17/0.85 -> 5.8823529 | G17: =H17/F17 -> 0.85 | H17: 5 | I17: =E17*H17 -> 25
A18: 13 | B18: 千叶豆腐 | C18: 400g*30袋/件 | D18: 件 | E18: 1 | F18: =H18/0.85 -> 240 | G18: =H18/F18 -> 0.85 | H18: 204 | I18: =E18*H18 -> 204
A19: 14 | B19: 干豆角 | C19: 散称 | D19: 斤 | E19: 7 | F19: =H19/0.85 -> 30.588235 | G19: =H19/F19 -> 0.85 | H19: 26 | I19: =E19*H19 -> 182
A20: 15 | B20: 雀巢怡运奶粉 | C20: 300g*12袋 | D20: 袋 | E20: 3 | F20: =H20/0.85 -> 30.588235 | G20: =H20/F20 -> 0.85 | H20: 26 | I20: =E20*H20 -> 78
A21: 16 | B21: 1911老酸奶 | D21: 杯 | E21: 60 | F21: =H21/0.85 -> 4.1176471 | G21: =H21/F21 -> 0.85 | H21: 3.5 | I21: =E21*H21 -> 210
A22: 17
A23: 18
A24: 19
A25: 20
A26: 21
A27: 22
A28: 23
A29: 24
A30: 25
A31: 26
A32: 供货合计: | B32: =SUM(I6:I31) -> 1335.8
A33: 金额大写： | B33: =B32 -> 1335.8
A34: 制表人 ：樊君丽 收货人： 送货人：

Sheet 18
A1: 武汉康恩农贸发展有限公司送货单
A3: 收货单位： | B3: 汉南数智化检测分公司
A4: 配送日期： | B4: 45187
A5: 序号 | B5: 名称 | C5: 规格 | D5: 单位 | E5: 数量 | F5: 超市价格 | G5: 折扣率 | H5: 折后价 | I5: 折后金额 | J5: 备注
A6: 1 | B6: （新鲜）河粉 | D6: 斤 | E6: 7 | F6: =H6/0.85 -> 3.5294118 | G6: =H6/F6 -> 0.85 | H6: 3 | I6: =E6*H6 -> 21
A7: 2 | B7: 干细粉 | C7: 散称 | D7: 斤 | E7: 6 | F7: =H7/0.85 -> 4.1176471 | G7: =H7/F7 -> 0.85 | H7: 3.5 | I7: =E7*H7 -> 21
A8: 3 | B8: 饺子皮 | D8: 斤 | E8: 3 | F8: =H8/0.85 -> 4.1176471 | G8: =H8/F8 -> 0.85 | H8: 3.5 | I8: =E8*H8 -> 10.5
A9: 4 | B9: 热干面（熟） | D9: 斤 | E9: 5 | F9: =H9/0.85 -> 4.1176471 | G9: =H9/F9 -> 0.85 | H9: 3.5 | I9: =E9*H9 -> 17.5
A10: 5 | B10: 刀豆 | D10: 斤 | E10: 12 | F10: =H10/0.85 -> 9.1764706 | G10: =H10/F10 -> 0.85 | H10: 7.8 | I10: =E10*H10 -> 93.6
A11: 6 | B11: 新鲜甜青豆米 | D11: 斤 | E11: 5 | F11: =H11/0.85 -> 21.176471 | G11: =H11/F11 -> 0.85 | H11: 18 | I11: =E11*H11 -> 90
A12: 7 | B12: 胡萝卜 | D12: 斤 | E12: 5 | F12: =H12/0.85 -> 2.9411765 | G12: =H12/F12 -> 0.85 | H12: 2.5 | I12: =E12*H12 -> 12.5
A13: 8 | B13: 甜玉米棒 | D13: 个 | E13: 5 | F13: =H13/0.85 -> 3.5294118 | G13: =H13/F13 -> 0.85 | H13: 3 | I13: =E13*H13 -> 15
A14: 9 | B14: 西红柿 | D14: 斤 | E14: 5 | F14: =H14/0.85 -> 4.4705882 | G14: =H14/F14 -> 0.85 | H14: 3.8 | I14: =E14*H14 -> 19
A15: 10 | B15: 冬瓜 | D15: 斤 | E15: 19 | F15: =H15/0.85 -> 2.9411765 | G15: =H15/F15 -> 0.85 | H15: 2.5 | I15: =E15*H15 -> 47.5
A16: 11 | B16: 平包菜 | D16: 斤 | E16: 5.4 | F16: =H16/0.85 -> 2.3529412 | G16: =H16/F16 -> 0.85 | H16: 2 | I16: =E16*H16 -> 10.8
A17: 12 | B17: 娃娃菜 | C17: 散装 | D17: 斤 | E17: 15 | F17: =H17/0.85 -> 5.2941176 | G17: =H17/F17 -> 0.85 | H17: 4.5 | I17: =E17*H17 -> 67.5
A18: 13 | B18: 油麦菜 | D18: 斤 | E18: 6 | F18: =H18/0.85 -> 4.1176471 | G18: =H18/F18 -> 0.85 | H18: 3.5 | I18: =E18*H18 -> 21
A19: 14 | B19: 南非橙 | D19: 斤 | E19: 28 | F19: =H19/0.85 -> 10 | G19: =H19/F19 -> 0.85 | H19: 8.5 | I19: =E19*H19 -> 238
A20: 15 | B20: 嫩豆腐 | D20: 斤 | E20: 8 | F20: =H20/0.85 -> 4.1176471 | G20: =H20/F20 -> 0.85 | H20: 3.5 | I20: =E20*H20 -> 28
A21: 16 | B21: 【鲜】五花肉沫 | D21: 斤 | E21: 5 | F21: =H21/0.85 -> 19.764706 | G21: =H21/F21 -> 0.85 | H21: 16.8 | I21: =E21*H21 -> 84
A22: 17 | B22: 【鲜】猪瘦肉丝 | D22: 斤 | E22: 5 | F22: =H22/0.85 -> 25.882353 | G22: =H22/F22 -> 0.85 | H22: 22 | I22: =E22*H22 -> 110
A23: 18 | B23: 【鲜】猪通排骨 | D23: 斤 | E23: 8 | F23: =H23/0.85 -> 33.882353 | G23: =H23/F23 -> 0.85 | H23: 28.8 | I23: =E23*H23 -> 230.4
A24: 19 | B24: 凤球唛番茄沙司 | C24: 1kg*12罐/件 | D24: 罐 | E24: 4 | F24: =H24/0.85 -> 19.764706 | G24: =H24/F24 -> 0.85 | H24: 16.8 | I24: =E24*H24 -> 67.2
A25: 20 | B25: 火腿肠 | D25: 件 | E25: 1 | F25: =H25/0.85 -> 197.64706 | G25: =H25/F25 -> 0.85 | H25: 168 | I25: =E25*H25 -> 168
A26: 21 | B26: 绿豆 | C26: 25kg/件 | D26: 斤 | E26: 8 | F26: =H26/0.85 -> 8 | G26: =H26/F26 -> 0.85 | H26: 6.8 | I26: =E26*H26 -> 54.4
A27: 22 | B27: 蒸肉白米粉(细） | C27: 散称 | D27: 斤 | E27: 5 | F27: =H27/0.85 -> 5.2941176 | G27: =H27/F27 -> 0.85 | H27: 4.5 | I27: =E27*H27 -> 22.5
A28: 23 | B28: 卤牛肉 | D28: 斤 | E28: 4 | F28: =H28/0.85 -> 103.52941 | G28: =H28/F28 -> 0.85 | H28: 88 | I28: =E28*H28 -> 352
A29: 24 | B29: 1911老酸奶 | D29: 杯 | E29: 40 | F29: =H29/0.85 -> 4.1176471 | G29: =H29/F29 -> 0.85 | H29: 3.5 | I29: =E29*H29 -> 140
A30: 25
A31: 供货合计: | B31: =SUM(I6:I30) -> 1941.4
A32: 金额大写： | B32: =B31 -> 1941.4
A33: 制表人 ：樊君丽 收货人： 送货人：

Sheet 19
A1: 武汉康恩农贸发展有限公司送货单
A3: 收货单位： | B3: 汉南数智化检测分公司
A4: 配送日期： | B4: 45188
A5: 序号 | B5: 名称 | C5: 规格 | D5: 单位 | E5: 数量 | F5: 超市价格 | G5: 折扣率 | H5: 折后价 | I5: 折后金额 | J5: 备注
A6: 1 | B6: （新鲜）河粉 | D6: 斤 | E6: 5 | F6: =H6/0.85 -> 3.5294118 | G6: =H6/F6 -> 0.85 | H6: 3 | I6: =E6*H6 -> 15
A7: 2 | B7: 热干面（熟） | D7: 斤 | E7: 5 | F7: =H7/0.85 -> 4.1176471 | G7: =H7/F7 -> 0.85 | H7: 3.5 | I7: =E7*H7 -> 17.5
A8: 3 | B8: 烧麦皮 | D8: 斤 | E8: 2 | F8: =H8/0.85 -> 4.1176471 | G8: =H8/F8 -> 0.85 | H8: 3.5 | I8: =E8*H8 -> 7
A9: 4 | B9: 生姜 | D9: 斤 | E9: 5 | F9: =H9/0.85 -> 15.058824 | G9: =H9/F9 -> 0.85 | H9: 12.8 | I9: =E9*H9 -> 64
A10: 5 | B10: 白萝卜 | D10: 斤 | E10: 9 | F10: =H10/0.85 -> 2.3529412 | G10: =H10/F10 -> 0.85 | H10: 2 | I10: =E10*H10 -> 18
A11: 6 | B11: 大红薯 | D11: 斤 | E11: 10 | F11: =H11/0.85 -> 4.1176471 | G11: =H11/F11 -> 0.85 | H11: 3.5 | I11: =E11*H11 -> 35
A12: 7 | B12: 红椒 | D12: 斤 | E12: 3 | F12: =H12/0.85 -> 9.1764706 | G12: =H12/F12 -> 0.85 | H12: 7.8 | I12: =E12*H12 -> 23.4
A13: 8 | B13: 芜湖青椒 | D13: 斤 | E13: 3 | F13: =H13/0.85 -> 5.2941176 | G13: =H13/F13 -> 0.85 | H13: 4.5 | I13: =E13*H13 -> 13.5
A14: 9 | B14: 老南瓜 | D14: 斤 | E14: 19 | F14: =H14/0.85 -> 2.9411765 | G14: =H14/F14 -> 0.85 | H14: 2.5 | I14: =E14*H14 -> 47.5
A15: 10 | B15: 平菇 | D15: 斤 | E15: 2 | F15: =H15/0.85 -> 12.705882 | G15: =H15/F15 -> 0.85 | H15: 10.8 | I15: =E15*H15 -> 21.6
A16: 11 | B16: 平包菜 | D16: 斤 | E16: 17 | F16: =H16/0.85 -> 2.3529412 | G16: =H16/F16 -> 0.85 | H16: 2 | I16: =E16*H16 -> 34
A17: 12 | B17: 嘎啦果 | D17: 斤 | E17: 13 | F17: =H17/0.85 -> 8 | G17: =H17/F17 -> 0.85 | H17: 6.8 | I17: =E17*H17 -> 88.4
... A21: 16 | B21: 【鲜】净胖头鱼头 | D21: 斤 | E21: 5.8 | F21: =H21/0.85 -> 23.529412 | G21: =H21/F21 -> 0.85 | H21: 20 | I21: =E21*H21 -> 116
A22: 17 | B22: 厨师乐加鲜味精 | C22: 2.27kg*10袋/件 | D22: 袋 | E22: 2 | F22: =H22/0.85 -> 52.941176 | G22: =H22/F22 -> 0.85 | H22: 45 | I22: =E22*H22 -> 90
A23: 18 | B23: 白砂糖 | D23: 斤 | E23: 8 | F23: =H23/0.85 -> 5.7647059 | G23: =H23/F23 -> 0.85 | H23: 4.9 | I23: =E23*H23 -> 39.2
A24: 19 | B24: 金龙鱼玉米油 | C24: 5L*4壶/件 | D24: 件 | E24: 2 | F24: =H24/0.85 -> 411.76471 | G24: =H24/F24 -> 0.85 | H24: 350 | I24: =E24*H24 -> 700
A25: 20 | B25: 1911老酸奶 | D25: 杯 | E25: 70 | F25: =H25/0.85 -> 4.1176471 | G25: =H25/F25 -> 0.85 | H25: 3.5 | I25: =E25*H25 -> 245
A26: 21 | B26: 卤牛肉 | D26: 斤 | E26: 4 | F26: =H26/0.85 -> 103.52941 | G26: =H26/F26 -> 0.85 | H26: 88 | I26: =E26*H26 -> 352
A27: 22
A28: 23
A29: 24
A30: 25
A31: 26
A32: 27
A33: 供货合计: | B33: =SUM(I6:I32) -> 2107.8
A34: 金额大写： | B34: =B33 -> 2107.8
A35: 制表人 ：樊君丽 收货人： 送货人：

Sheet 20.
A1: 武汉康恩农贸发展有限公司送货单
A3: 收货单位： | B3: 汉南数智化检测分公司
A4: 配送日期： | B4: 45189
A5: 序号 | B5: 名称 | C5: 规格 | D5: 单位 | E5: 数量 | F5: 超市价格 | G5: 折扣率 | H5: 折后价 | I5: 折后金额 | J5: 备注
A6: 1 | B6: （新鲜）河粉 | D6: 斤 | E6: 6 | F6: =H6/0.85 -> 3.5294118 | G6: =H6/F6 -> 0.85 | H6: 3 | I6: =E6*H6 -> 18
A7: 2 | B7: 热干面（熟） | D7: 斤 | E7: 6 | F7: =H7/0.85 -> 4.1176471 | G7: =H7/F7 -> 0.85 | H7: 3.5 | I7: =E7*H7 -> 21
A8: 3 | B8: 生面窝浆 | D8: 斤 | E8: 4 | F8: =H8/0.85 -> 7.0588235 | G8: =H8/F8 -> 0.85 | H8: 6 | I8: =E8*H8 -> 24
A9: 4 | B9: 小葱 | D9: 斤 | E9: 1 | F9: =H9/0.85 -> 8 | G9: =H9/F9 -> 0.85 | H9: 6.8 | I9: =E9*H9 -> 6.8
A10: 5 | B10: 白萝卜 | D10: 斤 | E10: 10 | F10: =H10/0.85 -> 2.3529412 | G10: =H10/F10 -> 0.85 | H10: 2 | I10: =E10*H10 -> 20
A11: 6 | B11: 红椒 | D11: 斤 | E11: 6 | F11: =H11/0.85 -> 9.1764706 | G11: =H11/F11 -> 0.85 | H11: 7.8 | I11: =E11*H11 -> 46.8
A12: 7 | B12: 甜玉米棒 | D12: 个 | E12: 11 | F12: =H12/0.85 -> 3.5294118 | G12: =H12/F12 -> 0.85 | H12: 3 | I12: =E12*H12 -> 33
A13: 8 | B13: 芜湖青椒 | D13: 斤 | E13: 6 | F13: =H13/0.85 -> 5.2941176 | G13: =H13/F13 -> 0.85 | H13: 4.5 | I13: =E13*H13 -> 27
A14: 9 | B14: 西红柿 | D14: 斤 | E14: 17 | F14: =H14/0.85 -> 4.4705882 | G14: =H14/F14 -> 0.85 | H14: 3.8 | I14: =E14*H14 -> 64.6
A15: 10 | B15: 净芋头 | C15: （去皮，小） | D15: 斤 | E15: 10 | F15: =H15/0.85 -> 13.882353 | G15: =H15/F15 -> 0.85 | H15: 11.8 | I15: =E15*H15 -> 118
A16: 11 | B16: 大白菜 | D16: 斤 | E16: 6 | F16: =H16/0.85 -> 4.1176471 | G16: =H16/F16 -> 0.85 | H16: 3.5 | I16: =E16*H16 -> 21
A17: 12 | B17: 生菜 | D17: 斤 | E17: 16.5 | F17: =H17/0.85 -> 5.6470588 | G17: =H17/F17 -> 0.85 | H17: 4.8 | I17: =E17*H17 -> 79.2
A18: 13 | B18: 细土芹 | D18: 斤 | E18: 3 | F18: =H18/0.85 -> 6.4705882 | G18: =H18/F18 -> 0.85 | H18: 5.5 | I18: =E18*H18 -> 16.5
A19: 14 | B19: 80苹果 | D19: 斤 | E19: 6.6 | F19: =H19/0.85 -> 10 | G19: =H19/F19 -> 0.85 | H19: 8.5 | I19: =E19*H19 -> 56.1
A20: 15 | B20: 香蕉 | D20: 斤 | E20: 11 | F20: =H20/0.85 -> 6.4705882 | G20: =H20/F20 -> 0.85 | H20: 5.5 | I20: =E20*H20 -> 60.5
A21: 16 | B21: 红壳鸡蛋 | C21: 12板/件 | D21: 件 | E21: 1 | F21: =H21/0.85 -> 352.94118 | G21: =H21/F21 -> 0.85 | H21: 300 | I21: =E21*H21 -> 300
A22: 17 | B22: 【鲜】五花肉沫 | D22: 斤 | E22: 15 | F22: =H22/0.85 -> 19.764706 | G22: =H22/F22 -> 0.85 | H22: 16.8 | I22: =E22*H22 -> 252
A23: 18 | B23: 【鲜】猪脊骨 | D23: 斤 | E23: 7 | F23: =H23/0.85 -> 17.411765 | G23: =H23/F23 -> 0.85 | H23: 14.8 | I23: =E23*H23 -> 103.6
A24: 19 | B24: 厨师乐加鲜味精 | C24: 2.27kg*10袋/件 | D24: 件 | E24: 1 | F24: =H24/0.85 -> 529.41176 | G24: =H24/F24 -> 0.85 | H24: 450 | I24: =E24*H24 -> 450
A25: 20 | B25: 银耳 | C25: 散称 | D25: 斤 | E25: 3 | F25: =H25/0.85 -> 76.470588 | G25: =H25/F25 -> 0.85 | H25: 65 | I25: =E25*H25 -> 195
A26: 21 | B26: 云鹤精制碘盐 | C26: 500g*50袋/件 | D26: 袋 | E26: 10 | F26: =H26/0.85 -> 2.3529412 | G26: =H26/F26 -> 0.85 | H26: 2 | I26: =E26*H26 -> 20
A27: 22 | B27: 卤牛肚 | D27: 斤 | E27: 5 | F27: =H27/0.85 -> 103.52941 | G27: =H27/F27 -> 0.85 | H27: 88 | I27: =E27*H27 -> 440
A28: 23 | B28: 永超榨菜 | C28: 8斤 | D28: 件 | E28: 1 | F28: =H28/0.85 -> 64.705882 | G28: =H28/F28 -> 0.85 | H28: 55 | I28: =E28*H28 -> 55
A29: 24 | B29: 米美佳东北香米15kg/袋 | C29: 15kg/袋 | D29: 袋 | E29: 1 | F29: =H29/0.85 -> 103.52941 | G29: =H29/F29 -> 0.85 | H29: 88 | I29: =E29*H29 -> 88
A30: 25 | B30: 1911老酸奶 | D30: 杯 | E30: 50 | F30: =H30/0.85 -> 4.1176471 | G30: =H30/F30 -> 0.85 | H30: 3.5 | I30: =E30*H30 -> 175
A31: 26
A32: 27
A33: 供货合计: | B33: =SUM(I6:I32) -> 2691.1
A34: 金额大写： | B34: =B33 -> 2691.1
A35: 制表人 ：樊君丽 收货人： 送货人：

Sheet 21.
A1: 武汉康恩农贸发展有限公司送货单
A3: 收货单位： | B3: 汉南数智化检测分公司
A4: 配送日期： | B4: 45190
A5: 序号 | B5: 名称 | C5: 规格 | D5: 单位 | E5: 数量 | F5: 超市价格 | G5: 折扣率 | H5: 折后价 | I5: 折后金额 | J5: 备注
A6: 1 | B6: （新鲜）河粉 | D6: 斤 | E6: 6 | F6: =H6/0.85 -> 3.5294118 | G6: =H6/F6 -> 0.85 | H6: 3 | I6: =E6*H6 -> 18
A7: 2 | B7: 热干面（熟） | D7: 斤 | E7: 2 | F7: =H7/0.85 -> 4.1176471 | G7: =H7/F7 -> 0.85 | H7: 3.5 | I7: =E7*H7 -> 7
A8: 3 | B8: 大葱 | D8: 斤 | E8: 1 | F8: =H8/0.85 -> 4.1176471 | G8: =H8/F8 -> 0.85 | H8: 3.5 | I8: =E8*H8 -> 3.5
A9: 4 | B9: 黄豆芽 | D9: 斤 | E9: 3 | F9: =H9/0.85 -> 2.9411765 | G9: =H9/F9 -> 0.85 | H9: 2.5 | I9: =E9*H9 -> 7.5
A10: 5 | B10: 红椒 | D10: 斤 | E10: 3.1 | F10: =H10/0.85 -> 9.1764706 | G10: =H10/F10 -> 0.85 | H10: 7.8 | I10: =E10*H10 -> 24.18
A11: 6 | B11: 芜湖青椒 | D11: 斤 | E11: 3 | F11: =H11/0.85 -> 5.2941176 | G11: =H11/F11 -> 0.85 | H11: 4.5 | I11: =E11*H11 -> 13.5
A12: 7 | B12: 西红柿 | D12: 斤 | E12: 5 | F12: =H12/0.85 -> 4.4705882 | G12: =H12/F12 -> 0.85 | H12: 3.8 | I12: =E12*H12 -> 19
A13: 8 | B13: 紫长茄子（细长） | D13: 斤 | E13: 8.2 | F13: =H13/0.85 -> 4.4705882 | G13: =H13/F13 -> 0.85 | H13: 3.8 | I13: =E13*H13 -> 31.16
A14: 9 | B14: 冬瓜 | D14: 斤 | E14: 7.4 | F14: =H14/0.85 -> 2.9411765 | G14: =H14/F14 -> 0.85 | H14: 2.5 | I14: =E14*H14 -> 18.5
A15: 10 | B15: 净莴苣 | D15: 斤 | E15: 20.9 | F15: =H15/0.85 -> 5.6470588 | G15: =H15/F15 -> 0.85 | H15: 4.8 | I15: =E15*H15 -> 100.32
A16: 11 | B16: 鲜香菇 | D16: 斤 | E16: 6 | F16: =H16/0.85 -> 11.529412 | G16: =H16/F16 -> 0.85 | H16: 9.8 | I16: =E16*H16 -> 58.8
A17: 12 | B17: 萝卜菜 | D17: 斤 | E17: 7 | F17: =H17/0.85 -> 6.4705882 | G17: =H17/F17 -> 0.85 | H17: 5.5 | I17: =E17*H17 -> 38.5
... A26: 21 | B26: 【鲜】猪血 | D26: 斤 | E26: 15 | F26: =H26/0.85 -> 5.8823529 | G26: =H26/F26 -> 0.85 | H26: 5 | I26: =E26*H26 -> 75
A27: 22 | B27: 【鲜】净大草鱼 | D27: 斤 | E27: 18 | F27: 13.2 | G27: =H27/F27 -> 1.0454545 | H27: 13.8 | I27: =E27*H27 -> 248.4
A28: 23 | B28: 卤牛肚 | D28: 斤 | E28: 3 | F28: =H28/0.85 -> 103.52941 | G28: =H28/F28 -> 0.85 | H28: 88 | I28: =E28*H28 -> 264
A29: 24 | B29: 1911老酸奶 | D29: 杯 | E29: 55 | F29: =H29/0.85 -> 4.1176471 | G29: =H29/F29 -> 0.85 | H29: 3.5 | I29: =E29*H29 -> 192.5
A30: 25
A31: 供货合计: | B31: =SUM(I6:I30) -> 1560.588
A32: 金额大写： | B32: =B31 -> 1560.588
A33: 制表人 ：樊君丽 收货人： 送货人：

Sheet 22
A1: 武汉康恩农贸发展有限公司送货单
A3: 收货单位： | B3: 汉南数智化检测分公司
A4: 配送日期： | B4: 45191
A5: 序号 | B5: 名称 | C5: 规格 | D5: 单位 | E5: 数量 | F5: 超市价格 | G5: 折扣率 | H5: 折后价 | I5: 折后金额 | J5: 备注
A6: 1 | B6: （新鲜）河粉 | D6: 斤 | E6: 6 | F6: =H6/0.85 -> 3.5294118 | G6: =H6/F6 -> 0.85 | H6: 3 | I6: =E6*H6 -> 18
A7: 2 | B7: 热干面（熟） | D7: 斤 | E7: 5 | F7: =H7/0.85 -> 4.1176471 | G7: =H7/F7 -> 0.85 | H7: 3.5 | I7: =E7*H7 -> 17.5
A8: 3 | B8: 青杭椒 | D8: 斤 | E8: 5 | F8: =H8/0.85 -> 6.8235294 | G8: =H8/F8 -> 0.85 | H8: 5.8 | I8: =E8*H8 -> 29
A9: 4 | B9: 黄豆芽 | D9: 斤 | E9: 10 | F9: =H9/0.85 -> 2.9411765 | G9: =H9/F9 -> 0.85 | H9: 2.5 | I9: =E9*H9 -> 25
A10: 5 | B10: 红椒 | D10: 斤 | E10: 3 | F10: =H10/0.85 -> 9.1764706 | G10: =H10/F10 -> 0.85 | H10: 7.8 | I10: =E10*H10 -> 23.4
A11: 6 | B11: 胡萝卜 | D11: 斤 | E11: 2 | F11: =H11/0.85 -> 2.9411765 | G11: =H11/F11 -> 0.85 | H11: 2.5 | I11: =E11*H11 -> 5
A12: 7 | B12: 甜玉米棒 | D12: 个 | E12: 7 | F12: =H12/0.85 -> 3.5294118 | G12: =H12/F12 -> 0.85 | H12: 3 | I12: =E12*H12 -> 21
A13: 8 | B13: 芜湖青椒 | D13: 斤 | E13: 3 | F13: =H13/0.85 -> 5.2941176 | G13: =H13/F13 -> 0.85 | H13: 4.5 | I13: =E13*H13 -> 13.5
A14: 9 | B14: 有机花菜 | D14: 斤 | E14: 13 | F14: =H14/0.85 -> 6.4705882 | G14: =H14/F14 -> 0.85 | H14: 5.5 | I14: =E14*H14 -> 71.5
A15: 10 | B15: 紫长茄子（细长） | D15: 斤 | E15: 15 | F15: =H15/0.85 -> 4.4705882 | G15: =H15/F15 -> 0.85 | H15: 3.8 | I15: =E15*H15 -> 57
A16: 11 | B16: 黄瓜 | D16: 斤 | E16: 3 | F16: =H16/0.85 -> 3.2941176 | G16: =H16/F16 -> 0.85 | H16: 2.8 | I16: =E16*H16 -> 8.4
A17: 12 | B17: 金针菇 | D17: 斤 | E17: 4 | F17: =H17/0.85 -> 8 | G17: =H17/F17 -> 0.85 | H17: 6.8 | I17: =E17*H17 -> 27.2
... A23: 18 | B23: 【鲜】猪五花肉片 | D23: 斤 | E23: 5 | F23: =H23/0.85 -> 21.764706 | G23: =H23/F23 -> 0.85 | H23: 18.5 | I23: =E23*H23 -> 92.5
A24: 19 | B24: 惠万家烟鸭胸 | C24: 5公斤/件/（32个） | D24: 件 | E24: 1 | F24: =H24/0.85 -> 141.17647 | G24: =H24/F24 -> 0.85 | H24: 120 | I24: =E24*H24 -> 120
A25: 20 | B25: 太合鸡脯肉 | C25: 9.8kg/件 | D25: 斤 | E25: 5 | F25: =H25/0.85 -> 11.529412 | G25: =H25/F25 -> 0.85 | H25: 9.8 | I25: =E25*H25 -> 49
A26: 21 | B26: 鑫海贸紫菜50g | C26: 50g*48包 | D26: 包 | E26: 10 | F26: =H26/0.85 -> 8 | G26: =H26/F26 -> 0.85 | H26: 6.8 | I26: =E26*H26 -> 68
A27: 22 | B27: 合鑫泰东北珍珠香米 | C27: 25kg/包 | D27: 袋 | E27: 2 | F27: =H27/0.85 -> 205.88235 | G27: =H27/F27 -> 0.85 | H27: 175 | I27: =E27*H27 -> 350
A28: 23 | B28: 1911老酸奶 | D28: 杯 | E28: 65 | F28: =H28/0.85 -> 4.1176471 | G28: =H28/F28 -> 0.85 | H28: 3.5 | I28: =E28*H28 -> 227.5
A29: 24
A30: 供货合计: | B30: =SUM(I6:I29) -> 1890.66
A31: 金额大写： | B31: =B30 -> 1890.66
A32: 制表人 ：樊君丽 收货人： 送货人：

Sheet 23
A1: 武汉康恩农贸发展有限公司送货单
A3: 收货单位： | B3: 汉南数智化检测分公司
A4: 配送日期： | B4: 45192
A5: 序号 | B5: 名称 | C5: 规格 | D5: 单位 | E5: 数量 | F5: 超市价格 | G5: 折扣率 | H5: 折后价 | I5: 折后金额 | J5: 备注
A6: 1 | B6: （新鲜）河粉 | D6: 斤 | E6: 5 | F6: =H6/0.85 -> 3.5294118 | G6: =H6/F6 -> 0.85 | H6: 3 | I6: =E6*H6 -> 15
A7: 2 | B7: 热干面（熟） | D7: 斤 | E7: 4 | F7: =H7/0.85 -> 4.1176471 | G7: =H7/F7 -> 0.85 | H7: 3.5 | I7: =E7*H7 -> 14
A8: 3 | B8: 蒜米 | D8: 斤 | E8: 4 | F8: =H8/0.85 -> 9.1764706 | G8: =H8/F8 -> 0.85 | H8: 7.8 | I8: =E8*H8 -> 31.2
A9: 4 | B9: 黄豆芽 | D9: 斤 | E9: 2 | F9: =H9/0.85 -> 2.9411765 | G9: =H9/F9 -> 0.85 | H9: 2.5 | I9: =E9*H9 -> 5
A10: 5 | B10: 大白菜 | D10: 斤 | E10: 12 | F10: =H10/0.85 -> 4.1176471 | G10: =H10/F10 -> 0.85 | H10: 3.5 | I10: =E10*H10 -> 42
A11: 6 | B11: 细土芹 | D11: 斤 | E11: 3 | F11: =H11/0.85 -> 6.4705882 | G11: =H11/F11 -> 0.85 | H11: 5.5 | I11: =E11*H11 -> 16.5
A12: 7 | B12: 薄千张 | D12: 斤 | E12: 3 | F12: =H12/0.85 -> 8 | G12: =H12/F12 -> 0.85 | H12: 6.8 | I12: =E12*H12 -> 20.4
A13: 8 | B13: 【鲜】猪血 | D13: 斤 | E13: 6 | F13: =H13/0.85 -> 5.8823529 | G13: =H13/F13 -> 0.85 | H13: 5 | I13: =E13*H13 -> 30
A14: 9 | B14: 芝麻酱 | C14: 散称 | D14: 斤 | E14: 5 | F14: =H14/0.85 -> 14.117647 | G14: =H14/F14 -> 0.85 | H14: 12 | I14: =E14*H14 -> 60
A15: 10 | B15: 卤牛肚 | D15: 斤 | E15: 3 | F15: =H15/0.85 -> 103.52941 | G15: =H15/F15 -> 0.85 | H15: 88 | I15: =E15*H15 -> 264
A16: 11 | B16: 手撕鸡 | D16: 只 | E16: 4 | F16: =H16/0.85 -> 30.588235 | G16: =H16/F16 -> 0.85 | H16: 26 | I16: =E16*H16 -> 104
A17: 12 | B17: 1911老酸奶 | D17: 杯 | E17: 30 | F17: =H17/0.85 -> 4.1176471 | G17: =H17/F17 -> 0.85 | H17: 3.5 | I17: =E17*H17 -> 105
A18: 13
A19: 14
A20: 15
A21: 16
A22: 17
A23: 18
A24: 19
A25: 20
A26: 21
A27: 22
A28: 23
A29: 24
A30: 供货合计: | B30: =SUM(I6:I29) -> 707.1
A31: 金额大写： | B31: =B30 -> 707.1
A32: 制表人 ：樊君丽 收货人： 送货人：

Sheet 24
A1: 武汉康恩农贸发展有限公司送货单
A3: 收货单位： | B3: 汉南数智化检测分公司
A4: 配送日期： | B4: 45193
A5: 序号 | B5: 名称 | C5: 规格 | D5: 单位 | E5: 数量 | F5: 超市价格 | G5: 折扣率 | H5: 折后价 | I5: 折后金额 | J5: 备注
A6: 1 | B6: 馄饨皮 | D6: 斤 | E6: 1 | F6: =H6/0.85 -> 4.1176471 | G6: =H6/F6 -> 0.85 | H6: 3.5 | I6: =E6*H6 -> 3.5
A7: 2 | B7: 热干面（熟） | D7: 斤 | E7: 5 | F7: =H7/0.85 -> 4.1176471 | G7: =H7/F7 -> 0.85 | H7: 3.5 | I7: =E7*H7 -> 17.5
A8: 3 | B8: 熟汤面 | D8: 斤 | E8: 8 | F8: =H8/0.85 -> 4.1176471 | G8: =H8/F8 -> 0.85 | H8: 3.5 | I8: =E8*H8 -> 28
A9: 4 | B9: 白萝卜 | D9: 斤 | E9: 7.8 | F9: =H9/0.85 -> 2.3529412 | G9: =H9/F9 -> 0.85 | H9: 2 | I9: =E9*H9 -> 15.6
A10: 5 | B10: 蒜苗 | D10: 斤 | E10: 4 | F10: =H10/0.85 -> 9.1764706 | G10: =H10/F10 -> 0.85 | H10: 7.8 | I10: =E10*H10 -> 31.2
A11: 6 | B11: 甜玉米棒 | D11: 个 | E11: 7 | F11: =H11/0.85 -> 3.5294118 | G11: =H11/F11 -> 0.85 | H11: 3 | I11: =E11*H11 -> 21
A12: 7 | B12: 水果黄瓜 | D12: 斤 | E12: 13 | F12: =H12/0.85 -> 5.8823529 | G12: =H12/F12 -> 0.85 | H12: 5 | I12: =E12*H12 -> 65
A13: 8 | B13: 大白菜 | D13: 斤 | E13: 2 | F13: =H13/0.85 -> 4.1176471 | G13: =H13/F13 -> 0.85 | H13: 3.5 | I13: =E13*H13 -> 7
A14: 9 | B14: 娃娃菜 | C14: 散装 | D14: 斤 | E14: 13 | F14: =H14/0.85 -> 5.2941176 | G14: =H14/F14 -> 0.85 | H14: 4.5 | I14: =E14*H14 -> 58.5
A15: 10 | B15: 【鲜】净三黄鸡 | D15: 斤 | E15: 12.4 | F15: =H15/0.85 -> 17.411765 | G15: =H15/F15 -> 0.85 | H15: 14.8 | I15: =E15*H15 -> 183.52
A16: 11 | B16: 【鲜】五花肉沫 | D16: 斤 | E16: 5 | F16: =H16/0.85 -> 19.764706 | G16: =H16/F16 -> 0.85 | H16: 16.8 | I16: =E16*H16 -> 84
A17: 12 | B17: 【鲜】猪脊骨 | D17: 斤 | E17: 6 | F17: =H17/0.85 -> 17.411765 | G17: =H17/F17 -> 0.85 | H17: 14.8 | I17: =E17*H17 -> 88.8
A18: 13 | B18: 【鲜】猪瘦肉片 | D18: 斤 | E18: 5 | F18: =H18/0.85 -> 25.882353 | G18: =H18/F18 -> 0.85 | H18: 22 | I18: =E18*H18 -> 110
A19: 14 | B19: 【鲜】猪瘦肉丝 | D19: 斤 | E19: 5 | F19: =H19/0.85 -> 25.882353 | G19: =H19/F19 -> 0.85 | H19: 22 | I19: =E19*H19 -> 110
A20: 15 | B20: 【鲜】净黄骨鱼 | D20: 斤 | E20: 6.7 | F20: =H20/0.85 -> 28.235294 | G20: =H20/F20 -> 0.85 | H20: 24 | I20: =E20*H20 -> 160.8
A21: 16 | B21: 风味豆豉 | C21: 1kg*3袋 | D21: 袋 | E21: 1 | F21: =H21/0.85 -> 16.470588 | G21: =H21/F21 -> 0.85 | H21: 14 | I21: =E21*H21 -> 14
A22: 17 | B22: 卤牛肉 | D22: 斤 | E22: 3 | F22: =H22/0.85 -> 103.52941 | G22: =H22/F22 -> 0.85 | H22: 88 | I22: =E22*H22 -> 264
A23: 18 | B23: 光明健能酸奶180g | C23: 180g | D23: 杯 | E23: 45 | F23: =H23/0.85 -> 4.1176471 | G23: =H23/F23 -> 0.85 | H23: 3.5 | I23: =E23*H23 -> 157.5
A24: 19
A25: 20
A26: 21
A27: 22
A28: 23
A29: 24
A30: 25
A31: 26
A32: 27
A33: 28
A34: 供货合计: | B34: =SUM(I6:I33) -> 1419.92
A35: 金额大写： | B35: =B34 -> 1419.92
A36: 制表人 ：樊君丽 收货人： 送货人：

Sheet 25
A1: 武汉康恩农贸发展有限公司送货单
A3: 收货单位： | B3: 汉南数智化检测分公司
A4: 配送日期： | B4: 45194
A5: 序号 | B5: 名称 | C5: 规格 | D5: 单位 | E5: 数量 | F5: 超市价格 | G5: 折扣率 | H5: 折后价 | I5: 折后金额 | J5: 备注
A6: 1 | B6: （新鲜）河粉 | D6: 斤 | E6: 10 | F6: =H6/0.85 -> 3.5294118 | G6: =H6/F6 -> 0.85 | H6: 3 | I6: =E6*H6 -> 30
A7: 2 | B7: 热干面（熟） | D7: 斤 | E7: 5 | F7: =H7/0.85 -> 4.1176471 | G7: =H7/F7 -> 0.85 | H7: 3.5 | I7: =E7*H7 -> 17.5
A8: 3 | B8: 新鲜毛豆米 | D8: 斤 | E8: 12 | F8: =H8/0.85 -> 17.058824 | G8: =H8/F8 -> 0.85 | H8: 14.5 | I8: =E8*H8 -> 174
A9: 4 | B9: 胡萝卜 | D9: 斤 | E9: 3 | F9: =H9/0.85 -> 2.9411765 | G9: =H9/F9 -> 0.85 | H9: 2.5 | I9: =E9*H9 -> 7.5
A10: 5 | B10: 甜玉米棒 | D10: 个 | E10: 10 | F10: =H10/0.85 -> 3.5294118 | G10: =H10/F10 -> 0.85 | H10: 3 | I10: =E10*H10 -> 30
A11: 6 | B11: 铁棍山药 | D11: 斤 | E11: 5 | F11: =H11/0.85 -> 11.529412 | G11: =H11/F11 -> 0.85 | H11: 9.8 | I11: =E11*H11 -> 49
A12: 7 | B12: 芜湖青椒 | D12: 斤 | E12: 6 | F12: =H12/0.85 -> 5.2941176 | G12: =H12/F12 -> 0.85 | H12: 4.5 | I12: =E12*H12 -> 27
A13: 8 | B13: 西红柿 | D13: 斤 | E13: 5 | F13: =H13/0.85 -> 4.4705882 | G13: =H13/F13 -> 0.85 | H13: 3.8 | I13: =E13*H13 -> 19
A14: 9 | B14: 有机花菜 | D14: 斤 | E14: 5 | F14: =H14/0.85 -> 6.4705882 | G14: =H14/F14 -> 0.85 | H14: 5.5 | I14: =E14*H14 -> 27.5
A15: 10 | B15: 空心菜 | D15: 斤 | E15: 19 | F15: =H15/0.85 -> 4.1176471 | G15: =H15/F15 -> 0.85 | H15: 3.5 | I15: =E15*H15 -> 66.5
A16: 11 | B16: 细土芹 | D16: 斤 | E16: 3 | F16: =H16/0.85 -> 6.4705882 | G16: =H16/F16 -> 0.85 | H16: 5.5 | I16: =E16*H16 -> 16.5
A17: 12 | B17: 油麦菜 | D17: 斤 | E17: 6 | F17: =H17/0.85 -> 4.1176471 | G17: =H17/F17 -> 0.85 | H17: 3.5 | I17: =E17*H17 -> 21
... A23: 19 | B23: 白砂糖 | D23: 斤 | E23: 10 | F23: =H23/0.85 -> 5.7647059 | G23: =H23/F23 -> 0.85 | H23: 4.9 | I23: =E23*H23 -> 49
A24: 20 | B24: 干辣椒节 | C24: 散称 | D24: 斤 | E24: 3 | F24: =H24/0.85 -> 30.588235 | G24: =H24/F24 -> 0.85 | H24: 26 | I24: =E24*H24 -> 78
A25: 21 | B25: 海天金标生抽1.9L | C25: 1.9L*6壶/件 | D25: 箱 | E25: 1 | F25: =H25/0.85 -> 152.94118 | G25: =H25/F25 -> 0.85 | H25: 130 | I25: =E25*H25 -> 130
A26: 22 | B26: 劲宝超级生粉 | C26: 5kg | D26: 袋 | E26: 1 | F26: =H26/0.85 -> 97.647059 | G26: =H26/F26 -> 0.85 | H26: 83 | I26: =E26*H26 -> 83
A27: 23 | B27: 文武酱菜外婆菜 | C27: 208g*40包/件 | D27: 包 | E27: 20 | F27: =H27/0.85 -> 2.9411765 | G27: =H27/F27 -> 0.85 | H27: 2.5 | I27: =E27*H27 -> 50
A28: 24 | B28: 金龙鱼玉米油 | C28: 5L*4壶/件 | D28: 件 | E28: 1 | F28: =H28/0.85 -> 411.76471 | G28: =H28/F28 -> 0.85 | H28: 350 | I28: =E28*H28 -> 350
A29: 25 | B29: 1911老酸奶 | D29: 杯 | E29: 60 | F29: =H29/0.85 -> 4.1176471 | G29: =H29/F29 -> 0.85 | H29: 3.5 | I29: =E29*H29 -> 210
A30: 26
A31: 27
A32: 28
A33: 供货合计: | B33: =SUM(I6:I32) -> 1870.3
A34: 金额大写： | B34: =B33 -> 1870.3
A35: 制表人 ：樊君丽 收货人： 送货人：

Sheet 27
A1: 武汉康恩农贸发展有限公司送货单
A3: 收货单位： | B3: 汉南数智化检测分公司
A4: 配送日期： | B4: 45196
A5: 序号 | B5: 名称 | C5: 规格 | D5: 单位 | E5: 数量 | F5: 超市价格 | G5: 折扣率 | H5: 折后价 | I5: 折后金额 | J5: 备注
A6: 1 | B6: （新鲜）河粉 | D6: 斤 | E6: 5 | F6: =H6/0.85 -> 3.5294118 | G6: =H6/F6 -> 0.85 | H6: 3 | I6: =E6*H6 -> 15
A7: 2 | B7: 干细粉 | C7: 散称 | D7: 斤 | E7: 4 | F7: =H7/0.85 -> 4.1176471 | G7: =H7/F7 -> 0.85 | H7: 3.5 | I7: =E7*H7 -> 14
A8: 3 | B8: 热干面（熟） | D8: 斤 | E8: 5 | F8: =H8/0.85 -> 4.1176471 | G8: =H8/F8 -> 0.85 | H8: 3.5 | I8: =E8*H8 -> 17.5
A9: 4 | B9: 生面窝浆 | D9: 斤 | E9: 4 | F9: =H9/0.85 -> 7.0588235 | G9: =H9/F9 -> 0.85 | H9: 6 | I9: =E9*H9 -> 24
A10: 5 | B10: 青豆角 | D10: 斤 | E10: 13 | F10: =H10/0.85 -> 5.2941176 | G10: =H10/F10 -> 0.85 | H10: 4.5 | I10: =E10*H10 -> 58.5
A11: 6 | B11: 铁棍山药 | D11: 斤 | E11: 13 | F11: =H11/0.85 -> 11.529412 | G11: =H11/F11 -> 0.85 | H11: 9.8 | I11: =E11*H11 -> 127.4
A12: 7 | B12: 西红柿 | D12: 斤 | E12: 5 | F12: =H12/0.85 -> 4.4705882 | G12: =H12/F12 -> 0.85 | H12: 3.8 | I12: =E12*H12 -> 19
A13: 8 | B13: 老南瓜 | D13: 斤 | E13: 8 | F13: =H13/0.85 -> 2.9411765 | G13: =H13/F13 -> 0.85 | H13: 2.5 | I13: =E13*H13 -> 20
A14: 9 | B14: 平菇 | D14: 斤 | E14: 2 | F14: =H14/0.85 -> 12.705882 | G14: =H14/F14 -> 0.85 | H14: 10.8 | I14: =E14*H14 -> 21.6
A15: 10 | B15: 平包菜 | D15: 斤 | E15: 15 | F15: =H15/0.85 -> 2.3529412 | G15: =H15/F15 -> 0.85 | H15: 2 | I15: =E15*H15 -> 30
A16: 11 | B16: 熟鹌鹑蛋 | D16: 斤 | E16: 5 | F16: =H16/0.85 -> 16.235294 | G16: =H16/F16 -> 0.85 | H16: 13.8 | I16: =E16*H16 -> 69
A17: 12 | B17: 【鲜】精品五花 | D17: 斤 | E17: 9 | F17: =H17/0.85 -> 24.470588 | G17: =H17/F17 -> 0.85 | H17: 20.8 | I17: =E17*H17 -> 187.2
A18: 13 | B18: 【鲜】五花肉沫 | D18: 斤 | E18: 8 | F18: =H18/0.85 -> 19.764706 | G18: =H18/F18 -> 0.85 | H18: 16.8 | I18: =E18*H18 -> 134.4
A19: 14 | B19: 松泉青虾仁 | C19: 650g/袋*8 | D19: 袋 | E19: 4 | F19: =H19/0.85 -> 70.588235 | G19: =H19/F19 -> 0.85 | H19: 60 | I19: =E19*H19 -> 240
A20: 15 | B20: 永超榨菜 | C20: 8斤 | D20: 件 | E20: 3 | F20: =H20/0.85 -> 64.705882 | G20: =H20/F20 -> 0.85 | H20: 55 | I20: =E20*H20 -> 165
A21: 16 | B21: 米美佳东北香米15kg/袋 | C21: 15kg/袋 | D21: 袋 | E21: 2 | F21: =H21/0.85 -> 103.52941 | G21: =H21/F21 -> 0.85 | H21: 88 | I21: =E21*H21 -> 176
A22: 17 | B22: 1911老酸奶 | D22: 杯 | E22: 63 | F22: =H22/0.85 -> 4.1176471 | G22: =H22/F22 -> 0.85 | H22: 3.5 | I22: =E22*H22 -> 220.5
A23: 18
A24: 19
A25: 20
A26: 21
A27: 22
A28: 23
A29: 24
A30: 25
A31: 26
A32: 供货合计: | B32: =SUM(I6:I31) -> 1539.1
A33: 金额大写： | B33: =B32 -> 1539.1
A34: 制表人 ：樊君丽 收货人： 送货人：

Sheet 26
A1: 武汉康恩农贸发展有限公司送货单
A3: 收货单位： | B3: 汉南数智化检测分公司
A4: 配送日期： | B4: 45195
A5: 序号 | B5: 名称 | C5: 规格 | D5: 单位 | E5: 数量 | F5: 超市价格 | G5: 折扣率 | H5: 折后价 | I5: 折后金额 | J5: 备注
A6: 1 | B6: （新鲜）河粉 | D6: 斤 | E6: 5 | F6: =H6/0.85 -> 3.5294118 | G6: =H6/F6 -> 0.85 | H6: 3 | I6: =E6*H6 -> 15
A7: 2 | B7: 热干面（熟） | D7: 斤 | E7: 4 | F7: =H7/0.85 -> 4.1176471 | G7: =H7/F7 -> 0.85 | H7: 3.5 | I7: =E7*H7 -> 14
A8: 3 | B8: 生姜 | D8: 斤 | E8: 5 | F8: =H8/0.85 -> 15.058824 | G8: =H8/F8 -> 0.85 | H8: 12.8 | I8: =E8*H8 -> 64
A9: 4 | B9: 小葱 | D9: 斤 | E9: 1 | F9: =H9/0.85 -> 8 | G9: =H9/F9 -> 0.85 | H9: 6.8 | I9: =E9*H9 -> 6.8
A10: 5 | B10: 大土豆 | D10: 斤 | E10: 17 | F10: =H10/0.85 -> 4.1176471 | G10: =H10/F10 -> 0.85 | H10: 3.5 | I10: =E10*H10 -> 59.5
A11: 6 | B11: 红椒 | D11: 斤 | E11: 3 | F11: =H11/0.85 -> 9.1764706 | G11: =H11/F11 -> 0.85 | H11: 7.8 | I11: =E11*H11 -> 23.4
A12: 7 | B12: 甜玉米棒 | D12: 个 | E12: 7 | F12: =H12/0.85 -> 3.5294118 | G12: =H12/F12 -> 0.85 | H12: 3 | I12: =E12*H12 -> 21
A13: 8 | B13: 芜湖青椒 | D13: 斤 | E13: 4 | F13: =H13/0.85 -> 5.2941176 | G13: =H13/F13 -> 0.85 | H13: 4.5 | I13: =E13*H13 -> 18
A14: 9 | B14: 生菜 | D14: 斤 | E14: 17 | F14: =H14/0.85 -> 5.6470588 | G14: =H14/F14 -> 0.85 | H14: 4.8 | I14: =E14*H14 -> 81.6
A15: 10 | B15: 嫩豆腐 | D15: 斤 | E15: 18 | F15: =H15/0.85 -> 4.1176471 | G15: =H15/F15 -> 0.85 | H15: 3.5 | I15: =E15*H15 -> 63
A16: 11 | B16: 红壳鸡蛋 | C16: 12板/件 | D16: 件 | E16: 1 | F16: =H16/0.85 -> 352.94118 | G16: =H16/F16 -> 0.85 | H16: 300 | I16: =E16*H16 -> 300
A17: 12 | B17: 【鲜】猪瘦肉丝 | D17: 斤 | E17: 5 | F17: =H17/0.85 -> 25.882353 | G17: =H17/F17 -> 0.85 | H17: 22 | I17: =E17*H17 -> 110
A18: 13 | B18: 安琪酵母 | C18: 500g*20袋/件 | D18: 袋 | E18: 1 | F18: =H18/0.85 -> 29.411765 | G18: =H18/F18 -> 0.85 | H18: 25 | I18: =E18*H18 -> 25
A19: 14 | B19: 三象水磨籼米粉 | C19: 500g*20包/件 | D19: 包 | E19: 6 | F19: =H19/0.85 -> 10 | G19: =H19/F19 -> 0.85 | H19: 8.5 | I19: =E19*H19 -> 51
A20: 15 | B20: 五得利六星面粉 | C20: 25kg/袋 | D20: 袋 | E20: 1 | F20: =H20/0.85 -> 150.58824 | G20: =H20/F20 -> 0.85 | H20: 128 | I20: =E20*H20 -> 128
A21: 16 | B21: 1911老酸奶 | D21: 杯 | E21: 27 | F21: =H21/0.85 -> 4.1176471 | G21: =H21/F21 -> 0.85 | H21: 3.5 | I21: =E21*H21 -> 94.5
A22: 17
A23: 18
A24: 19
A25: 20
A26: 21
A27: 22
A28: 23
A29: 24
A30: 25
A31: 26
A32: 27
A33: 28
A34: 供货合计: | B34: =SUM(I6:I33) -> 1074.8
A35: 金额大写： | B35: =B34 -> 1074.8
A36: 制表人 ：樊君丽 收货人： 送货人：

Sheet 28
A1: 武汉康恩农贸发展有限公司送货单
A3: 收货单位： | B3: 汉南数智化检测分公司
A4: 配送日期： | B4: 45197
A5: 序号 | B5: 名称 | C5: 规格 | D5: 单位 | E5: 数量 | F5: 超市价格 | G5: 折扣率 | H5: 折后价 | I5: 折后金额 | J5: 备注
A6: 1 | B6: （新鲜）河粉 | D6: 斤 | E6: 5 | F6: =H6/0.85 -> 3.5294118 | G6: =H6/F6 -> 0.85 | H6: 3 | I6: =E6*H6 -> 15
A7: 2 | B7: 热干面（熟） | D7: 斤 | E7: 5 | F7: =H7/0.85 -> 4.1176471 | G7: =H7/F7 -> 0.85 | H7: 3.5 | I7: =E7*H7 -> 17.5
A8: 3 | B8: 大葱 | D8: 斤 | E8: 1 | F8: =H8/0.85 -> 4.1176471 | G8: =H8/F8 -> 0.85 | H8: 3.5 | I8: =E8*H8 -> 3.5
A9: 4 | B9: 白萝卜 | D9: 斤 | E9: 4 | F9: =H9/0.85 -> 2.3529412 | G9: =H9/F9 -> 0.85 | H9: 2 | I9: =E9*H9 -> 8
A10: 5 | B10: 胡萝卜 | D10: 斤 | E10: 8 | F10: =H10/0.85 -> 2.9411765 | G10: =H10/F10 -> 0.85 | H10: 2.5 | I10: =E10*H10 -> 20
A11: 6 | B11: 甜玉米棒 | D11: 个 | E11: 7 | F11: =H11/0.85 -> 3.5294118 | G11: =H11/F11 -> 0.85 | H11: 3 | I11: =E11*H11 -> 21
A12: 7 | B12: 西兰花 | D12: 斤 | E12: 15 | F12: =H12/0.85 -> 8 | G12: =H12/F12 -> 0.85 | H12: 6.8 | I12: =E12*H12 -> 102
A13: 8 | B13: 紫长茄子（细长） | D13: 斤 | E13: 15 | F13: =H13/0.85 -> 4.4705882 | G13: =H13/F13 -> 0.85 | H13: 3.8 | I13: =E13*H13 -> 57
A14: 9 | B14: 细土芹 | D14: 斤 | E14: 4.8 | F14: =H14/0.85 -> 6.4705882 | G14: =H14/F14 -> 0.85 | H14: 5.5 | I14: =E14*H14 -> 26.4
A15: 10 | B15: 油麦菜 | D15: 斤 | E15: 10 | F15: =H15/0.85 -> 4.1176471 | G15: =H15/F15 -> 0.85 | H15: 3.5 | I15: =E15*H15 -> 35
A16: 11 | B16: 【鲜】净麻鸭 | D16: 斤 | E16: 10.8 | F16: =H16/0.85 -> 25.882353 | G16: =H16/F16 -> 0.85 | H16: 22 | I16: =E16*H16 -> 237.6
A17: 12 | B17: 【鲜】净三黄鸡 | D17: 斤 | E17: 7 | F17: =H17/0.85 -> 17.411765 | G17: =H17/F17 -> 0.85 | H17: 14.8 | I17: =E17*H17 -> 103.6
A18: 13 | B18: 【鲜】五花肉沫 | D18: 斤 | E18: 2 | F18: =H18/0.85 -> 19.764706 | G18: =H18/F18 -> 0.85 | H18: 16.8 | I18: =E18*H18 -> 33.6
A19: 14 | B19: 无核红枣（小） | C19: 散称 | D19: 斤 | E19: 5 | F19: =H19/0.85 -> 13.882353 | G19: =H19/F19 -> 0.85 | H19: 11.8 | I19: =E19*H19 -> 59
A20: 15 | B20: 1911老酸奶 | D20: 杯 | E20: 50 | F20: =H20/0.85 -> 4.1176471 | G20: =H20/F20 -> 0.85 | H20: 3.5 | I20: =E20*H20 -> 175
A21: 16
A22: 17
A23: 18
A24: 19
A25: 20
A26: 21
A27: 22
A28: 23
A29: 24
A30: 25
A31: 26
A32: 27
A33: 28
A34: 供货合计: | B34: =SUM(I6:I33) -> 914.2
A35: 金额大写： | B35: =B34 -> 914.2
A36: 制表人 ：樊君丽 收货人： 送货人：

Sheet 9月合计
A1: 39号食堂
A2: 日期 | B2: 单1 | C2: 单2
