Workbook

Sheet 6.29
A1: 武汉康恩农贸发展有限公司送货单
A3: 收货单位：汉南数智化检测分公司
A4: 配送日期：2023-6-29
A5: 序号 | B5: 名称 | C5: 规格 | D5: 单位 | E5: 数量 | F5: 单价 | G5: 金额 | H5: 备注
A6: 1 | B6: 云鹤牌精选绿色碘盐 | C6: 400g | D6: 包 | E6: 3 | F6: 2.5 | G6: =E6*F6 -> 7.5
A7: 2 | B7: 川郫红油豆瓣 | D7: 瓶 | E7: 1 | F7: 21.9 | G7: =E7*F7 -> 21.9
A8: 3 | B8: 金怡神食用玉米淀粉 | D8: 包 | E8: 2 | F8: 4.1 | G8: =E8*F8 -> 8.2
A9: 4 | B9: 仲景麻辣鱼 | D9: 包 | E9: 3 | F9: 11.9 | G9: =E9*F9 -> 35.7
A10: 5 | B10: 太太乐鸡精 | D10: 包 | E10: 2 | F10: 13.7 | G10: =E10*F10 -> 27.4
A11: 6 | B11: 鲁花生鲜蚝油 | D11: 瓶 | E11: 2 | F11: 16.9 | G11: =E11*F11 -> 33.8
A12: 7 | B12: 李锦记精选生抽 | D12: 瓶 | E12: 2 | F12: 9.9 | G12: =E12*F12 -> 19.8
A13: 8 | B13: 李锦记精选老抽 | D13: 瓶 | E13: 2 | F13: 11.9 | G13: =E13*F13 -> 23.8
A14: 9 | B14: 恒顺镇江香醋 | D14: 瓶 | E14: 1 | F14: 12.9 | G14: =E14*F14 -> 12.9
A15: 10 | B15: 李锦记蒸鱼豉油 | D15: 瓶 | E15: 1 | F15: 13.9 | G15: =E15*F15 -> 13.9
A16: 11 | B16: 汪德荣藤椒油 | D16: 瓶 | E16: 2 | F16: 16.9 | G16: =E16*F16 -> 33.8
A17: 12 | B17: 德庄重庆小火锅底料 | D17: 包 | E17: 1 | F17: 28.8 | G17: =E17*F17 -> 28.8
A18: 13 | B18: 鼎鼐白胡椒粉 | D18: 包 | E18: 1 | F18: 17.8 | G18: =E18*F18 -> 17.8
... A46: 41 | B46: 都悦小葱 | D46: 包 | E46: 5 | F46: 1.5 | G46: =E46*F46 -> 7.5
A47: 42 | B47: 光明益生菌酸奶（原味） | C47: 100g | D47: 杯 | E47: 63 | F47: 1.5 | G47: =E47*F47 -> 94.5
A48: 43
A49: 合计: | B49: =SUM(G6:G48) -> 1036.2
A50: 金额大写： | B50: =B49 -> 1036.2
A51: 制表人 ：樊君丽 收货人： 送货人：

Sheet 1
A1: 武汉康恩农贸发展有限公司送货单
A3: 收货单位：汉南数智化检测分公司
A4: 配送日期：2023-7-1
A5: 序号 | B5: 名称 | C5: 规格 | D5: 单位 | E5: 数量 | F5: 超市价格 | G5: 折扣率 | H5: 折后价 | I5: 折后金额 | J5: 备注
A6: 1 | B6: 大圆皮 | D6: 斤 | E6: 2 | F6: =H6/0.85 -> 4.7058824 | G6: =H6/F6 -> 0.85 | H6: 4 | I6: =E6*H6 -> 8
A7: 2 | B7: 干细粉 | C7: 散称 | D7: 斤 | E7: 5 | F7: =H7/0.85 -> 4.1176471 | G7: =H7/F7 -> 0.85 | H7: 3.5 | I7: =E7*H7 -> 17.5
A8: 3 | B8: 饺子皮 | D8: 斤 | E8: 2 | F8: =H8/0.85 -> 4.1176471 | G8: =H8/F8 -> 0.85 | H8: 3.5 | I8: =E8*H8 -> 7
A9: 4 | B9: 宽粉 | D9: 斤 | E9: 5 | F9: =H9/0.85 -> 3.5294118 | G9: =H9/F9 -> 0.85 | H9: 3 | I9: =E9*H9 -> 15
A10: 5 | B10: 热干面（熟） | D10: 斤 | E10: 10 | F10: =H10/0.85 -> 4.1176471 | G10: =H10/F10 -> 0.85 | H10: 3.5 | I10: =E10*H10 -> 35
A11: 6 | B11: 熟凉面 | D11: 斤 | E11: 10 | F11: =H11/0.85 -> 4.1176471 | G11: =H11/F11 -> 0.85 | H11: 3.5 | I11: =E11*H11 -> 35
A12: 7 | B12: 熟汤面 | D12: 斤 | E12: 5 | F12: =H12/0.85 -> 4.1176471 | G12: =H12/F12 -> 0.85 | H12: 3.5 | I12: =E12*H12 -> 17.5
A13: 8 | B13: 大葱 | D13: 斤 | E13: 2 | F13: =H13/0.85 -> 4.1176471 | G13: =H13/F13 -> 0.85 | H13: 3.5 | I13: =E13*H13 -> 7
A14: 9 | B14: 带皮蒜头 | D14: 斤 | E14: 5 | F14: =H14/0.85 -> 9.4117647 | G14: =H14/F14 -> 0.85 | H14: 8 | I14: =E14*H14 -> 40
A15: 10 | B15: 生姜 | D15: 斤 | E15: 10 | F15: =H15/0.85 -> 15.058824 | G15: =H15/F15 -> 0.85 | H15: 12.8 | I15: =E15*H15 -> 128
A16: 11 | B16: 白豆角 | D16: 斤 | E16: 13 | F16: =H16/0.85 -> 4.4705882 | G16: =H16/F16 -> 0.85 | H16: 3.8 | I16: =E16*H16 -> 49.4
A17: 12 | B17: 大土豆 | D17: 斤 | E17: 15 | F17: =H17/0.85 -> 4.1176471 | G17: =H17/F17 -> 0.85 | H17: 3.5 | I17: =E17*H17 -> 52.5
A18: 13 | B18: 紫长茄子（细长） | D18: 斤 | E18: 5 | F18: =H18/0.85 -> 4.4705882 | G18: =H18/F18 -> 0.85 | H18: 3.8 | I18: =E18*H18 -> 19
A19: 14 | B19: 黄瓜 | D19: 斤 | E19: 15 | F19: =H19/0.85 -> 3.2941176 | G19: =H19/F19 -> 0.85 | H19: 2.8 | I19: =E19*H19 -> 42
... A25: 20 | B25: 嫩豆腐 | D25: 斤 | E25: 3 | F25: =H25/0.85 -> 4.1176471 | G25: =H25/F25 -> 0.85 | H25: 3.5 | I25: =E25*H25 -> 10.5
A26: 21 | B26: 红壳鸡蛋 | C26: 12板/件 | D26: 件 | E26: 1 | F26: =H26/0.85 -> 352.94118 | G26: =H26/F26 -> 0.85 | H26: 300 | I26: =E26*H26 -> 300
A27: 22 | B27: 【鲜】猪板油 | D27: 斤 | E27: 5 | F27: =H27/0.85 -> 14.117647 | G27: =H27/F27 -> 0.85 | H27: 12 | I27: =E27*H27 -> 60
A28: 23 | B28: 【鲜】猪前腿肉沫 | D28: 斤 | E28: 5 | F28: =H28/0.85 -> 15.294118 | G28: =H28/F28 -> 0.85 | H28: 13 | I28: =E28*H28 -> 65
A29: 24 | B29: 【鲜】猪瘦肉片 | D29: 斤 | E29: 5 | F29: =H29/0.85 -> 23.529412 | G29: =H29/F29 -> 0.85 | H29: 20 | I29: =E29*H29 -> 100
A30: 25 | B30: 【鲜】猪瘦肉丝 | D30: 斤 | E30: 5 | F30: =H30/0.85 -> 23.529412 | G30: =H30/F30 -> 0.85 | H30: 20 | I30: =E30*H30 -> 100
A31: 26 | B31: 【鲜】猪通排骨 | D31: 斤 | E31: 8 | F31: =H31/0.85 -> 28.235294 | G31: =H31/F31 -> 0.85 | H31: 24 | I31: =E31*H31 -> 192
A32: 27 | B32: 【鲜】猪五花肉片 | D32: 斤 | E32: 5 | F32: =H32/0.85 -> 17.647059 | G32: =H32/F32 -> 0.85 | H32: 15 | I32: =E32*H32 -> 75
A33: 28 | B33: 【鲜】净胖头鱼头 | D33: 斤 | E33: 10.4 | F33: =H33/0.85 -> 23.529412 | G33: =H33/F33 -> 0.85 | H33: 20 | I33: =E33*H33 -> 208
A34: 29 | B34: 厨师乐加鲜味精 | C34: 2.27kg*10袋/件 | D34: 袋 | E34: 3 | F34: =H34/0.85 -> 52.941176 | G34: =H34/F34 -> 0.85 | H34: 45 | I34: =E34*H34 -> 135
A35: 30 | B35: 大桥鸡精900g | D35: 袋 | E35: 3 | F35: =H35/0.85 -> 42.823529 | G35: =H35/F35 -> 0.85 | H35: 36.4 | I35: =E35*H35 -> 109.2
A36: 31 | B36: （黄色）面包糠 | C36: 1kg*10袋/件 | D36: 袋 | E36: 1 | F36: =H36/0.85 -> 25.882353 | G36: =H36/F36 -> 0.85 | H36: 22 | I36: =E36*H36 -> 22
A37: 32 | B37: 安琪酵母 | C37: 500g*20袋/件 | D37: 袋 | E37: 1 | F37: =H37/0.85 -> 29.411765 | G37: =H37/F37 -> 0.85 | H37: 25 | I37: =E37*H37 -> 25
A38: 33 | B38: 白砂糖 | D38: 斤 | E38: 8 | F38: =H38/0.85 -> 5.7647059 | G38: =H38/F38 -> 0.85 | H38: 4.9 | I38: =E38*H38 -> 39.2
A39: 34 | B39: 白芝麻 | C39: 散称 | D39: 斤 | E39: 5 | F39: =H39/0.85 -> 17.647059 | G39: =H39/F39 -> 0.85 | H39: 15 | I39: =E39*H39 -> 75
A40: 35 | B40: 粗苕粉 | C40: 散称 | D40: 斤 | E40: 5 | F40: =H40/0.85 -> 8 | G40: =H40/F40 -> 0.85 | H40: 6.8 | I40: =E40*H40 -> 34
A41: 36 | B41: 东古南乳酱 | C41: 190g*48瓶/件 | D41: 瓶 | E41: 10 | F41: =H41/0.85 -> 7.0588235 | G41: =H41/F41 -> 0.85 | H41: 6 | I41: =E41*H41 -> 60
A42: 37 | B42: 福达坊芝麻酱6.25KG | C42: 6.25KG*4桶/件 | D42: 桶 | E42: 1 | F42: =H42/0.85 -> 235.29412 | G42: =H42/F42 -> 0.85 | H42: 200 | I42: =E42*H42 -> 200
A43: 38 | B43: 干辣椒节 | C43: 散称 | D43: 斤 | E43: 3 | F43: =H43/0.85 -> 30.588235 | G43: =H43/F43 -> 0.85 | H43: 26 | I43: =E43*H43 -> 78
A44: 39 | B44: 海天草菇老抽1.9L | C44: 1.9L*6壶/件 | D44: 件 | E44: 1 | F44: =H44/0.85 -> 170.58824 | G44: =H44/F44 -> 0.85 | H44: 145 | I44: =E44*H44 -> 145
A45: 40 | B45: 海天金标生抽1.9L | C45: 1.9L*6壶/件 | D45: 箱 | E45: 1 | F45: =H45/0.85 -> 152.94118 | G45: =H45/F45 -> 0.85 | H45: 130 | I45: =E45*H45 -> 130
A46: 41 | B46: 海天精制蚝油6kg | C46: 6kg*2桶 | D46: 件 | E46: 1 | F46: =H46/0.85 -> 97.647059 | G46: =H46/F46 -> 0.85 | H46: 83 | I46: =E46*H46 -> 83
...

Sheet 3
A1: 武汉康恩农贸发展有限公司送货单
A3: 收货单位： | B3: 汉南数智化检测分公司
A4: 配送日期： | B4: 45110
A5: 序号 | B5: 名称 | C5: 规格 | D5: 单位 | E5: 数量 | F5: 超市价格 | G5: 折扣率 | H5: 折后价 | I5: 折后金额 | J5: 备注
A6: 1 | B6: （新鲜）河粉 | D6: 斤 | E6: 11 | F6: =H6/0.85 -> 3.5294118 | G6: =H6/F6 -> 0.85 | H6: 3 | I6: =E6*H6 -> 33
A7: 2 | B7: 热干面（熟） | D7: 斤 | E7: 5 | F7: =H7/0.85 -> 4.1176471 | G7: =H7/F7 -> 0.85 | H7: 3.5 | I7: =E7*H7 -> 17.5
A8: 3 | B8: 熟汤面 | D8: 斤 | E8: 2 | F8: =H8/0.85 -> 4.1176471 | G8: =H8/F8 -> 0.85 | H8: 3.5 | I8: =E8*H8 -> 7
A9: 4 | B9: 青杭椒 | D9: 斤 | E9: 12 | F9: =H9/0.85 -> 4.4705882 | G9: =H9/F9 -> 0.85 | H9: 3.8 | I9: =E9*H9 -> 45.6
A10: 5 | B10: 蒜米 | D10: 斤 | E10: 4 | F10: =H10/0.85 -> 9.1764706 | G10: =H10/F10 -> 0.85 | H10: 7.8 | I10: =E10*H10 -> 31.2
A11: 6 | B11: 小葱 | D11: 斤 | E11: 5 | F11: =H11/0.85 -> 8 | G11: =H11/F11 -> 0.85 | H11: 6.8 | I11: =E11*H11 -> 34
A12: 7 | B12: 大红薯 | D12: 斤 | E12: 10 | F12: =H12/0.85 -> 4.1176471 | G12: =H12/F12 -> 0.85 | H12: 3.5 | I12: =E12*H12 -> 35
A13: 8 | B13: 红椒 | D13: 斤 | E13: 5 | F13: =H13/0.85 -> 9.1764706 | G13: =H13/F13 -> 0.85 | H13: 7.8 | I13: =E13*H13 -> 39
A14: 9 | B14: 甜玉米棒 | D14: 个 | E14: 20 | F14: =H14/0.85 -> 2.9411765 | G14: =H14/F14 -> 0.85 | H14: 2.5 | I14: =E14*H14 -> 50
A15: 10 | B15: 芜湖青椒 | D15: 斤 | E15: 5 | F15: =H15/0.85 -> 4.4705882 | G15: =H15/F15 -> 0.85 | H15: 3.8 | I15: =E15*H15 -> 19
A16: 11 | B16: 紫薯 | D16: 斤 | E16: 10 | F16: =H16/0.85 -> 6.8235294 | G16: =H16/F16 -> 0.85 | H16: 5.8 | I16: =E16*H16 -> 58
A17: 12 | B17: 油麦菜 | D17: 斤 | E17: 18 | F17: =H17/0.85 -> 4.1176471 | G17: =H17/F17 -> 0.85 | H17: 3.5 | I17: =E17*H17 -> 63
... A24: 19 | B24: 【鲜】猪五花肉片 | D24: 斤 | E24: 3 | F24: =H24/0.85 -> 17.647059 | G24: =H24/F24 -> 0.85 | H24: 15 | I24: =E24*H24 -> 45
A25: 20 | B25: 干葡萄干 | C25: 散称 | D25: 斤 | E25: 2 | F25: =H25/0.85 -> 23.529412 | G25: =H25/F25 -> 0.85 | H25: 20 | I25: =E25*H25 -> 40
A26: 21 | B26: 家乐浓缩鸡汁1kg | C26: 1kg*6瓶/件 | D26: 瓶 | E26: 3 | F26: =H26/0.85 -> 91.764706 | G26: =H26/F26 -> 0.85 | H26: 78 | I26: =E26*H26 -> 234
A27: 22 | B27: 绿豆 | C27: 25kg/件 | D27: 斤 | E27: 10 | F27: =H27/0.85 -> 8 | G27: =H27/F27 -> 0.85 | H27: 6.8 | I27: =E27*H27 -> 68
A28: 23 | B28: 狮球吉士粉 | C28: 3kg*4桶/件 | D28: 桶 | E28: 1 | F28: =H28/0.85 -> 52.941176 | G28: =H28/F28 -> 0.85 | H28: 45 | I28: =E28*H28 -> 45
A29: 24 | B29: 文武麻辣油丁 | C29: 16斤/件 | D29: 件 | E29: 1 | F29: =H29/0.85 -> 68.235294 | G29: =H29/F29 -> 0.85 | H29: 58 | I29: =E29*H29 -> 58
A30: 25 | B30: 鑫石羊郫县豆瓣酱4KG | C30: 4KG/桶*4桶/件 | D30: 桶 | E30: 2 | F30: =H30/0.85 -> 47.058824 | G30: =H30/F30 -> 0.85 | H30: 40 | I30: =E30*H30 -> 80
A31: 26 | B31: 幺麻子藤椒油 | C31: 250ml*10瓶 | D31: 件 | E31: 1 | F31: =H31/0.85 -> 211.76471 | G31: =H31/F31 -> 0.85 | H31: 180 | I31: =E31*H31 -> 180
A32: 27 | B32: 银耳 | C32: 散称 | D32: 斤 | E32: 2 | F32: =H32/0.85 -> 52.941176 | G32: =H32/F32 -> 0.85 | H32: 45 | I32: =E32*H32 -> 90
A33: 28 | B33: 红油榨菜丝 | D33: 件 | E33: 1 | F33: =H33/0.85 -> 64.705882 | G33: =H33/F33 -> 0.85 | H33: 55 | I33: =E33*H33 -> 55
A34: 29 | B34: 宣乐红丁 | C34: 13斤/件 | D34: 斤 | E34: 2 | F34: =H34/0.85 -> 5.2941176 | G34: =H34/F34 -> 0.85 | H34: 4.5 | I34: =E34*H34 -> 9
A35: 30 | B35: 原味酸豆角（切好的） | D35: 件 | E35: 1 | F35: =H35/0.85 -> 64.705882 | G35: =H35/F35 -> 0.85 | H35: 55 | I35: =E35*H35 -> 55
A36: 31 | B36: 八宝粥米 | C36: 散称 | D36: 斤 | E36: 5 | F36: =H36/0.85 -> 8 | G36: =H36/F36 -> 0.85 | H36: 6.8 | I36: =E36*H36 -> 34
A37: 32 | B37: 福达坊芝麻香油 | C37: 360ml*12瓶 | D37: 件 | E37: 1 | F37: =H37/0.85 -> 176.47059 | G37: =H37/F37 -> 0.85 | H37: 150 | I37: =E37*H37 -> 150
A38: 33 | B38: 缅甸香米25kg | C38: 25kg | D38: 袋 | E38: 1 | F38: =H38/0.85 -> 247.05882 | G38: =H38/F38 -> 0.85 | H38: 210 | I38: =E38*H38 -> 210
A39: 34 | B39: 光明健能酸奶180g | C39: 180g | D39: 杯 | E39: 50 | F39: =H39/0.85 -> 4.1176471 | G39: =H39/F39 -> 0.85 | H39: 3.5 | I39: =E39*H39 -> 175
A40: 供货合计: | B40: =SUM(I6:I39) -> 2898.8
A41: 金额大写： | B41: =B40 -> 2898.8
A42: 制表人 ：樊君丽 收货人： 送货人：

Sheet 4
A1: 武汉康恩农贸发展有限公司送货单
A3: 收货单位： | B3: 汉南数智化检测分公司
A4: 配送日期： | B4: 45111
A5: 序号 | B5: 名称 | C5: 规格 | D5: 单位 | E5: 数量 | F5: 超市价格 | G5: 折扣率 | H5: 折后价 | I5: 折后金额 | J5: 备注
A6: 1 | B6: 宽粉 | D6: 斤 | E6: 6 | F6: =H6/0.85 -> 3.5294118 | G6: =H6/F6 -> 0.85 | H6: 3 | I6: =E6*H6 -> 18
A7: 2 | B7: 熟凉面 | D7: 斤 | E7: 1 | F7: =H7/0.85 -> 4.1176471 | G7: =H7/F7 -> 0.85 | H7: 3.5 | I7: =E7*H7 -> 3.5
A8: 3 | B8: 熟汤面 | D8: 斤 | E8: 3 | F8: =H8/0.85 -> 4.1176471 | G8: =H8/F8 -> 0.85 | H8: 3.5 | I8: =E8*H8 -> 10.5
A9: 4 | B9: 蒜米 | D9: 斤 | E9: 4 | F9: =H9/0.85 -> 9.1764706 | G9: =H9/F9 -> 0.85 | H9: 7.8 | I9: =E9*H9 -> 31.2
A10: 5 | B10: 紫长茄子（细长） | D10: 斤 | E10: 8 | F10: =H10/0.85 -> 4.4705882 | G10: =H10/F10 -> 0.85 | H10: 3.8 | I10: =E10*H10 -> 30.4
A11: 6 | B11: 黄瓜 | D11: 斤 | E11: 2 | F11: =H11/0.85 -> 3.2941176 | G11: =H11/F11 -> 0.85 | H11: 2.8 | I11: =E11*H11 -> 5.6
A12: 7 | B12: 平包菜 | D12: 斤 | E12: 12 | F12: =H12/0.85 -> 2.3529412 | G12: =H12/F12 -> 0.85 | H12: 2 | I12: =E12*H12 -> 24
A13: 8 | B13: 【鲜】净三黄鸡 | D13: 斤 | E13: 7.7 | F13: =H13/0.85 -> 17.647059 | G13: =H13/F13 -> 0.85 | H13: 15 | I13: =E13*H13 -> 115.5
A14: 9 | B14: 鸡边腿剁块 | D14: 斤 | E14: 10 | F14: =H14/0.85 -> 11.764706 | G14: =H14/F14 -> 0.85 | H14: 10 | I14: =E14*H14 -> 100
A15: 10 | B15: 白砂糖 | D15: 斤 | E15: 10 | F15: =H15/0.85 -> 5.7647059 | G15: =H15/F15 -> 0.85 | H15: 4.9 | I15: =E15*H15 -> 49
A16: 11 | B16: 鲁花压榨玉米油 | C16: 5L*4壶/件 | D16: 件 | E16: 2 | F16: =H16/0.85 -> 500 | G16: =H16/F16 -> 0.85 | H16: 425 | I16: =E16*H16 -> 850
A17: 12 | B17: 玉米面粉 | C17: 散称 | D17: 斤 | E17: 5 | F17: =H17/0.85 -> 5.2941176 | G17: =H17/F17 -> 0.85 | H17: 4.5 | I17: =E17*H17 -> 22.5
A18: 13 | B18: 光明健能酸奶180g | C18: 180g | D18: 杯 | E18: 50 | F18: =H18/0.85 -> 4.1176471 | G18: =H18/F18 -> 0.85 | H18: 3.5 | I18: =E18*H18 -> 175
A19: 14
A20: 15
A21: 16
A22: 17
A23: 18
A24: 19
A25: 20
A26: 21
A27: 22
A28: 23
A29: 24
A30: 25
... A34: 29
A35: 供货合计: | B35: =SUM(I6:I34) -> 1435.2
A36: 金额大写： | B36: =B35 -> 1435.2
A37: 制表人 ：樊君丽 收货人： 送货人：

Sheet 5
A1: 武汉康恩农贸发展有限公司送货单
A3: 收货单位： | B3: 汉南数智化检测分公司
A4: 配送日期： | B4: 45112
A5: 序号 | B5: 名称 | C5: 规格 | D5: 单位 | E5: 数量 | F5: 超市价格 | G5: 折扣率 | H5: 折后价 | I5: 折后金额 | J5: 备注
A6: 1 | B6: （生）春卷皮 | D6: 斤 | E6: 2 | F6: =H6/0.85 -> 20 | G6: =H6/F6 -> 0.85 | H6: 17 | I6: =E6*H6 -> 34
A7: 2 | B7: 熟凉面 | D7: 斤 | E7: 2 | F7: =H7/0.85 -> 4.1176471 | G7: =H7/F7 -> 0.85 | H7: 3.5 | I7: =E7*H7 -> 7
A8: 3 | B8: 红椒 | D8: 斤 | E8: 3 | F8: =H8/0.85 -> 9.1764706 | G8: =H8/F8 -> 0.85 | H8: 7.8 | I8: =E8*H8 -> 23.4
A9: 4 | B9: 胡萝卜 | D9: 斤 | E9: 5 | F9: =H9/0.85 -> 2.9411765 | G9: =H9/F9 -> 0.85 | H9: 2.5 | I9: =E9*H9 -> 12.5
A10: 5 | B10: 甜玉米棒 | D10: 个 | E10: 3 | F10: =H10/0.85 -> 2.9411765 | G10: =H10/F10 -> 0.85 | H10: 2.5 | I10: =E10*H10 -> 7.5
A11: 6 | B11: 芜湖青椒 | D11: 斤 | E11: 6 | F11: =H11/0.85 -> 4.4705882 | G11: =H11/F11 -> 0.85 | H11: 3.8 | I11: =E11*H11 -> 22.8
A12: 7 | B12: 冬瓜 | D12: 斤 | E12: 10 | F12: =H12/0.85 -> 2.9411765 | G12: =H12/F12 -> 0.85 | H12: 2.5 | I12: =E12*H12 -> 25
A13: 8 | B13: 黄瓜 | D13: 斤 | E13: 4 | F13: =H13/0.85 -> 3.2941176 | G13: =H13/F13 -> 0.85 | H13: 2.8 | I13: =E13*H13 -> 11.2
A14: 9 | B14: 韭菜 | D14: 斤 | E14: 5 | F14: =H14/0.85 -> 4.1176471 | G14: =H14/F14 -> 0.85 | H14: 3.5 | I14: =E14*H14 -> 17.5
A15: 10 | B15: 生菜 | D15: 斤 | E15: 4 | F15: =H15/0.85 -> 6.4705882 | G15: =H15/F15 -> 0.85 | H15: 5.5 | I15: =E15*H15 -> 22
A16: 11 | B16: 小白菜 | D16: 斤 | E16: 20 | F16: =H16/0.85 -> 3.2941176 | G16: =H16/F16 -> 0.85 | H16: 2.8 | I16: =E16*H16 -> 56
A17: 12 | B17: 香梨 | D17: 斤 | E17: 20 | F17: =H17/0.85 -> 15.058824 | G17: =H17/F17 -> 0.85 | H17: 12.8 | I17: =E17*H17 -> 256
A18: 13 | B18: 皮蛋 | C18: 180个/件 | D18: 个 | E18: 15 | F18: =H18/0.85 -> 2.1176471 | G18: =H18/F18 -> 0.85 | H18: 1.8 | I18: =E18*H18 -> 27
A19: 14 | B19: 鸡脯肉丁 | D19: 斤 | E19: 10 | F19: =H19/0.85 -> 15.294118 | G19: =H19/F19 -> 0.85 | H19: 13 | I19: =E19*H19 -> 130
A20: 15 | B20: 【鲜】猪通排骨 | D20: 斤 | E20: 2 | F20: =H20/0.85 -> 28.235294 | G20: =H20/F20 -> 0.85 | H20: 24 | I20: =E20*H20 -> 48
A21: 16 | B21: 【鲜】猪血 | D21: 斤 | E21: 8 | F21: =H21/0.85 -> 5.8823529 | G21: =H21/F21 -> 0.85 | H21: 5 | I21: =E21*H21 -> 40
A22: 17 | B22: 【鲜】基围虾 | D22: 斤 | E22: 3 | F22: =H22/0.85 -> 49.411765 | G22: =H22/F22 -> 0.85 | H22: 42 | I22: =E22*H22 -> 126
A23: 18 | B23: 净鳝鱼 | D23: 斤 | E23: 7.3 | F23: =H23/0.85 -> 84.705882 | G23: =H23/F23 -> 0.85 | H23: 72 | I23: =E23*H23 -> 525.6
A24: 19 | B24: 米之佳酒鬼花生 | C24: 1.5kg/袋 | D24: 袋 | E24: 1 | F24: =H24/0.85 -> 41.176471 | G24: =H24/F24 -> 0.85 | H24: 35 | I24: =E24*H24 -> 35
A25: 20 | B25: 孝感米酒900g | C25: 900g*6瓶/件 | D25: 瓶 | E25: 5 | F25: =H25/0.85 -> 10 | G25: =H25/F25 -> 0.85 | H25: 8.5 | I25: =E25*H25 -> 42.5
A26: 21 | B26: 卤牛肉 | D26: 斤 | E26: 10 | F26: =H26/0.85 -> 103.52941 | G26: =H26/F26 -> 0.85 | H26: 88 | I26: =E26*H26 -> 880
A27: 22 | B27: 光明健能酸奶180g | C27: 180g | D27: 杯 | E27: 69 | F27: =H27/0.85 -> 4.1176471 | G27: =H27/F27 -> 0.85 | H27: 3.5 | I27: =E27*H27 -> 241.5
A28: 23
A29: 24
A30: 25
A31: 26
A32: 供货合计: | B32: =SUM(I6:I31) -> 2590.5
A33: 金额大写： | B33: =B32 -> 2590.5
A34: 制表人 ：樊君丽 收货人： 送货人：

Sheet 6
A1: 武汉康恩农贸发展有限公司送货单
A3: 收货单位： | B3: 汉南数智化检测分公司
A4: 配送日期： | B4: 45113
A5: 序号 | B5: 名称 | C5: 规格 | D5: 单位 | E5: 数量 | F5: 超市价格 | G5: 折扣率 | H5: 折后价 | I5: 折后金额 | J5: 备注
A6: 1 | B6: 饺子皮 | D6: 斤 | E6: 2 | F6: =H6/0.85 -> 4.1176471 | G6: =H6/F6 -> 0.85 | H6: 3.5 | I6: =E6*H6 -> 7
A7: 2 | B7: 热干面（熟） | D7: 斤 | E7: 4 | F7: =H7/0.85 -> 4.1176471 | G7: =H7/F7 -> 0.85 | H7: 3.5 | I7: =E7*H7 -> 14
A8: 3 | B8: 熟凉面 | D8: 斤 | E8: 2 | F8: =H8/0.85 -> 4.1176471 | G8: =H8/F8 -> 0.85 | H8: 3.5 | I8: =E8*H8 -> 7
A9: 4 | B9: 黄豆芽 | D9: 斤 | E9: 5 | F9: =H9/0.85 -> 2.9411765 | G9: =H9/F9 -> 0.85 | H9: 2.5 | I9: =E9*H9 -> 12.5
A10: 5 | B10: 西红柿 | D10: 斤 | E10: 14 | F10: =H10/0.85 -> 4.4705882 | G10: =H10/F10 -> 0.85 | H10: 3.8 | I10: =E10*H10 -> 53.2
A11: 6 | B11: 平菇 | D11: 斤 | E11: 2 | F11: =H11/0.85 -> 9.1764706 | G11: =H11/F11 -> 0.85 | H11: 7.8 | I11: =E11*H11 -> 15.6
A12: 7 | B12: 生菜 | D12: 斤 | E12: 15 | F12: =H12/0.85 -> 6.4705882 | G12: =H12/F12 -> 0.85 | H12: 5.5 | I12: =E12*H12 -> 82.5
A13: 8 | B13: 麒麟西瓜 | D13: 斤 | E13: 26.61 | F13: =H13/0.85 -> 5.6470588 | G13: =H13/F13 -> 0.85 | H13: 4.8 | I13: =E13*H13 -> 127.728
A14: 9 | B14: 薄千张 | D14: 斤 | E14: 5 | F14: =H14/0.85 -> 8 | G14: =H14/F14 -> 0.85 | H14: 6.8 | I14: =E14*H14 -> 34
A15: 10 | B15: 嫩豆腐 | D15: 斤 | E15: 5 | F15: =H15/0.85 -> 4.1176471 | G15: =H15/F15 -> 0.85 | H15: 3.5 | I15: =E15*H15 -> 17.5
A16: 11 | B16: 熟鹌鹑蛋 | D16: 斤 | E16: 4 | F16: =H16/0.85 -> 16.235294 | G16: =H16/F16 -> 0.85 | H16: 13.8 | I16: =E16*H16 -> 55.2
A17: 12 | B17: 【鲜】精品五花 | D17: 斤 | E17: 8 | F17: =H17/0.85 -> 20 | G17: =H17/F17 -> 0.85 | H17: 17 | I17: =E17*H17 -> 136
... A20: 15 | B20: 【鲜】净胖头鱼头 | D20: 斤 | E20: 9.1 | F20: =H20/0.85 -> 23.529412 | G20: =H20/F20 -> 0.85 | H20: 20 | I20: =E20*H20 -> 182
A21: 16 | B21: 大桥鸡精900g | C21: 900g*10袋/件 | D21: 袋 | E21: 3 | F21: =H21/0.85 -> 42.823529 | G21: =H21/F21 -> 0.85 | H21: 36.4 | I21: =E21*H21 -> 109.2
A22: 17 | B22: 双塔龙口粉丝 | C22: 500g*24袋/件 | D22: 袋 | E22: 5 | F22: =H22/0.85 -> 15.294118 | G22: =H22/F22 -> 0.85 | H22: 13 | I22: =E22*H22 -> 65
A23: 18 | B23: 缅甸香米25kg | C23: 25kg | D23: 袋 | E23: 1 | F23: =H23/0.85 -> 247.05882 | G23: =H23/F23 -> 0.85 | H23: 210 | I23: =E23*H23 -> 210
A24: 19 | B24: 光明健能酸奶180g | C24: 180g | D24: 杯 | E24: 20 | F24: =H24/0.85 -> 4.1176471 | G24: =H24/F24 -> 0.85 | H24: 3.5 | I24: =E24*H24 -> 70
A25: 20
A26: 21
A27: 22
A28: 23
A29: 24
A30: 25
A31: 26
A32: 27
A33: 28
A34: 29
A35: 供货合计: | B35: =SUM(I6:I34) -> 1376.428
A36: 金额大写： | B36: =B35 -> 1376.428
A37: 制表人 ：樊君丽 收货人： 送货人：

Sheet 7
A1: 武汉康恩农贸发展有限公司送货单
A3: 收货单位： | B3: 汉南数智化检测分公司
A4: 配送日期： | B4: 45114
A5: 序号 | B5: 名称 | C5: 规格 | D5: 单位 | E5: 数量 | F5: 超市价格 | G5: 折扣率 | H5: 折后价 | I5: 折后金额 | J5: 备注
A6: 1 | B6: （新鲜）河粉 | D6: 斤 | E6: 3 | F6: =H6/0.85 -> 3.5294118 | G6: =H6/F6 -> 0.85 | H6: 3 | I6: =E6*H6 -> 9
A7: 2 | B7: 饺子皮 | D7: 斤 | E7: 2 | F7: =H7/0.85 -> 4.1176471 | G7: =H7/F7 -> 0.85 | H7: 3.5 | I7: =E7*H7 -> 7
A8: 3 | B8: 热干面（熟） | D8: 斤 | E8: 4 | F8: =H8/0.85 -> 4.1176471 | G8: =H8/F8 -> 0.85 | H8: 3.5 | I8: =E8*H8 -> 14
A9: 4 | B9: 白豆角 | D9: 斤 | E9: 12 | F9: =H9/0.85 -> 4.4705882 | G9: =H9/F9 -> 0.85 | H9: 3.8 | I9: =E9*H9 -> 45.6
A10: 5 | B10: 红椒 | D10: 斤 | E10: 2 | F10: =H10/0.85 -> 9.1764706 | G10: =H10/F10 -> 0.85 | H10: 7.8 | I10: =E10*H10 -> 15.6
A11: 6 | B11: 黄瓜 | D11: 斤 | E11: 2 | F11: =H11/0.85 -> 3.2941176 | G11: =H11/F11 -> 0.85 | H11: 2.8 | I11: =E11*H11 -> 5.6
A12: 7 | B12: 大白菜 | D12: 斤 | E12: 12 | F12: =H12/0.85 -> 2.3529412 | G12: =H12/F12 -> 0.85 | H12: 2 | I12: =E12*H12 -> 24
A13: 8 | B13: 韭菜 | D13: 斤 | E13: 2 | F13: =H13/0.85 -> 4.1176471 | G13: =H13/F13 -> 0.85 | H13: 3.5 | I13: =E13*H13 -> 7
A14: 9 | B14: 平包菜 | D14: 斤 | E14: 1 | F14: =H14/0.85 -> 2.3529412 | G14: =H14/F14 -> 0.85 | H14: 2 | I14: =E14*H14 -> 2
A15: 10 | B15: 细土芹 | D15: 斤 | E15: 3 | F15: =H15/0.85 -> 6.4705882 | G15: =H15/F15 -> 0.85 | H15: 5.5 | I15: =E15*H15 -> 16.5
A16: 11 | B16: 小白菜 | D16: 斤 | E16: 2 | F16: =H16/0.85 -> 3.2941176 | G16: =H16/F16 -> 0.85 | H16: 2.8 | I16: =E16*H16 -> 5.6
A17: 12 | B17: 厚干子 | D17: 斤 | E17: 4 | F17: =H17/0.85 -> 8 | G17: =H17/F17 -> 0.85 | H17: 6.8 | I17: =E17*H17 -> 27.2
A18: 13 | B18: 红壳鸡蛋 | C18: 12板/件 | D18: 件 | E18: 1 | F18: =H18/0.85 -> 352.94118 | G18: =H18/F18 -> 0.85 | H18: 300 | I18: =E18*H18 -> 300
A19: 14 | B19: 【鲜】猪脊骨 | D19: 斤 | E19: 5 | F19: =H19/0.85 -> 15.294118 | G19: =H19/F19 -> 0.85 | H19: 13 | I19: =E19*H19 -> 65
A20: 15 | B20: 【鲜】猪前腿肉沫 | D20: 斤 | E20: 2 | F20: =H20/0.85 -> 15.294118 | G20: =H20/F20 -> 0.85 | H20: 13 | I20: =E20*H20 -> 26
A21: 16 | B21: 净草鱼块 | D21: 斤 | E21: 14.4 | F21: =H21/0.85 -> 16.235294 | G21: =H21/F21 -> 0.85 | H21: 13.8 | I21: =E21*H21 -> 198.72
A22: 17 | B22: （冻）绿茶饼 | C22: 300g*20袋/件 | D22: 袋 | E22: 5 | F22: =H22/0.85 -> 8.2352941 | G22: =H22/F22 -> 0.85 | H22: 7 | I22: =E22*H22 -> 35
A23: 18 | B23: 【冻】千味央厨香芋地瓜丸 | C23: 400g*10袋/件 | D23: 袋 | E23: 5 | F23: =H23/0.85 -> 8 | G23: =H23/F23 -> 0.85 | H23: 6.8 | I23: =E23*H23 -> 34
A24: 19 | B24: 千味央厨小油条 | C24: 720g袋*6袋 | D24: 袋 | E24: 2 | F24: =H24/0.85 -> 25.882353 | G24: =H24/F24 -> 0.85 | H24: 22 | I24: =E24*H24 -> 44
A25: 20 | B25: 干黄花菜 | D25: 斤 | E25: 3 | F25: =H25/0.85 -> 52.941176 | G25: =H25/F25 -> 0.85 | H25: 45 | I25: =E25*H25 -> 135
A26: 21 | B26: 干辣椒片 | D26: 斤 | E26: 2 | F26: =H26/0.85 -> 29.411765 | G26: =H26/F26 -> 0.85 | H26: 25 | I26: =E26*H26 -> 50
A27: 22 | B27: 花生碎 | C27: 5斤/包 | D27: 斤 | E27: 5 | F27: =H27/0.85 -> 14.117647 | G27: =H27/F27 -> 0.85 | H27: 12 | I27: =E27*H27 -> 60
A28: 23 | B28: 绿豆 | C28: 25kg/件 | D28: 斤 | E28: 10 | F28: =H28/0.85 -> 8 | G28: =H28/F28 -> 0.85 | H28: 6.8 | I28: =E28*H28 -> 68
A29: 24 | B29: 水发海带头 | C29: 18斤/件 | D29: 斤 | E29: 8 | F29: =H29/0.85 -> 9.4117647 | G29: =H29/F29 -> 0.85 | H29: 8 | I29: =E29*H29 -> 64
A30: 25 | B30: 坛坛乡剁椒1.15kg | C30: 1.15kg*6瓶/件 | D30: 瓶 | E30: 4 | F30: =H30/0.85 -> 19.411765 | G30: =H30/F30 -> 0.85 | H30: 16.5 | I30: =E30*H30 -> 66
A31: 26 | B31: 卤牛肚 | D31: 斤 | E31: 7.4 | F31: =H31/0.85 -> 103.52941 | G31: =H31/F31 -> 0.85 | H31: 88 | I31: =E31*H31 -> 651.2
A32: 27 | B32: 光明健能酸奶180g | C32: 180g | D32: 杯 | E32: 55 | F32: =H32/0.85 -> 4.1176471 | G32: =H32/F32 -> 0.85 | H32: 3.5 | I32: =E32*H32 -> 192.5
A33: 供货合计: | B33: =SUM(I6:I32) -> 2168.52
A34: 金额大写： | B34: =B33 -> 2168.52
A35: 制表人 ：樊君丽 收货人： 送货人：

Sheet 8
A1: 武汉康恩农贸发展有限公司送货单
A3: 收货单位： | B3: 汉南数智化检测分公司
A4: 配送日期： | B4: 45115
A5: 序号 | B5: 名称 | C5: 规格 | D5: 单位 | E5: 数量 | F5: 超市价格 | G5: 折扣率 | H5: 折后价 | I5: 折后金额 | J5: 备注
A6: 1 | B6: 麒麟西瓜 | D6: 斤 | E6: 18 | F6: =H6/0.85 -> 5.6470588 | G6: =H6/F6 -> 0.85 | H6: 4.8 | I6: =E6*H6 -> 86.4
A7: 2
A8: 3
A9: 4
A10: 5
A11: 6
A12: 7
A13: 8
A14: 9
A15: 10
A16: 11
A17: 12
A18: 13
... A32: 27
A33: 供货合计: | B33: =SUM(I6:I32) -> 86.4
A34: 金额大写： | B34: =B33 -> 86.4
A35: 制表人 ：樊君丽 收货人： 送货人：

Sheet 10
A1: 武汉康恩农贸发展有限公司送货单
A3: 收货单位： | B3: 汉南数智化检测分公司
A4: 配送日期： | B4: 45117
A5: 序号 | B5: 名称 | C5: 规格 | D5: 单位 | E5: 数量 | F5: 超市价格 | G5: 折扣率 | H5: 折后价 | I5: 折后金额 | J5: 备注
A6: 1 | B6: 大圆皮 | D6: 斤 | E6: 2 | F6: =H6/0.85 -> 4.7058824 | G6: =H6/F6 -> 0.85 | H6: 4 | I6: =E6*H6 -> 8
A7: 2 | B7: 干细粉 | C7: 散称 | D7: 斤 | E7: 5 | F7: =H7/0.85 -> 4.1176471 | G7: =H7/F7 -> 0.85 | H7: 3.5 | I7: =E7*H7 -> 17.5
A8: 3 | B8: 宽粉 | D8: 斤 | E8: 5 | F8: =H8/0.85 -> 3.5294118 | G8: =H8/F8 -> 0.85 | H8: 3 | I8: =E8*H8 -> 15
A9: 4 | B9: 热干面（熟） | D9: 斤 | E9: 3 | F9: =H9/0.85 -> 4.1176471 | G9: =H9/F9 -> 0.85 | H9: 3.5 | I9: =E9*H9 -> 10.5
A10: 5 | B10: 熟汤面 | D10: 斤 | E10: 2 | F10: =H10/0.85 -> 4.1176471 | G10: =H10/F10 -> 0.85 | H10: 3.5 | I10: =E10*H10 -> 7
A11: 6 | B11: 红皮洋葱 | D11: 斤 | E11: 3 | F11: =H11/0.85 -> 2.9411765 | G11: =H11/F11 -> 0.85 | H11: 2.5 | I11: =E11*H11 -> 7.5
A12: 7 | B12: 青杭椒 | D12: 斤 | E12: 12 | F12: =H12/0.85 -> 6.8235294 | G12: =H12/F12 -> 0.85 | H12: 5.8 | I12: =E12*H12 -> 69.6
A13: 8 | B13: 蒜米 | D13: 斤 | E13: 4 | F13: =H13/0.85 -> 9.1764706 | G13: =H13/F13 -> 0.85 | H13: 7.8 | I13: =E13*H13 -> 31.2
A14: 9 | B14: 大土豆 | D14: 斤 | E14: 8 | F14: =H14/0.85 -> 4.1176471 | G14: =H14/F14 -> 0.85 | H14: 3.5 | I14: =E14*H14 -> 28
A15: 10 | B15: 红椒 | D15: 斤 | E15: 2 | F15: =H15/0.85 -> 9.1764706 | G15: =H15/F15 -> 0.85 | H15: 7.8 | I15: =E15*H15 -> 15.6
A16: 11 | B16: 芜湖青椒 | D16: 斤 | E16: 3 | F16: =H16/0.85 -> 4.4705882 | G16: =H16/F16 -> 0.85 | H16: 3.8 | I16: =E16*H16 -> 11.4
A17: 12 | B17: 紫长茄子（细长） | D17: 斤 | E17: 16 | F17: =H17/0.85 -> 4.4705882 | G17: =H17/F17 -> 0.85 | H17: 3.8 | I17: =E17*H17 -> 60.8
A18: 13 | B18: 红苋菜 | D18: 斤 | E18: 14 | F18: =H18/0.85 -> 4.4705882 | G18: =H18/F18 -> 0.85 | H18: 3.8 | I18: =E18*H18 -> 53.2
A19: 14 | B19: 麒麟西瓜 | D19: 斤 | E19: 62 | F19: =H19/0.85 -> 5.6470588 | G19: =H19/F19 -> 0.85 | H19: 4.8 | I19: =E19*H19 -> 297.6
... A24: 19 | B24: 【鲜】猪瘦肉丝 | D24: 斤 | E24: 3 | F24: =H24/0.85 -> 23.529412 | G24: =H24/F24 -> 0.85 | H24: 20 | I24: =E24*H24 -> 60
A25: 20 | B25: 双塔龙口粉丝 | C25: 500g*24袋/件 | D25: 袋 | E25: 5 | F25: =H25/0.85 -> 15.294118 | G25: =H25/F25 -> 0.85 | H25: 13 | I25: =E25*H25 -> 65
A26: 21
A27: 22
A28: 23
A29: 24
A30: 25
A31: 26
A32: 27
A33: 28
A34: 供货合计: | B34: =SUM(I6:I33) -> 1210.55
A35: 金额大写： | B35: =B34 -> 1210.55
A36: 制表人 ：樊君丽 收货人： 送货人：

Sheet 11
A1: 武汉康恩农贸发展有限公司送货单
A3: 收货单位： | B3: 汉南数智化检测分公司
A4: 配送日期： | B4: 45118
A5: 序号 | B5: 名称 | C5: 规格 | D5: 单位 | E5: 数量 | F5: 超市价格 | G5: 折扣率 | H5: 折后价 | I5: 折后金额 | J5: 备注
A6: 1 | B6: 饺子皮 | D6: 斤 | E6: 5 | F6: =H6/0.85 -> 4.1176471 | G6: =H6/F6 -> 0.85 | H6: 3.5 | I6: =E6*H6 -> 17.5
A7: 2 | B7: 宽粉 | D7: 斤 | E7: 3 | F7: =H7/0.85 -> 2.9411765 | G7: =H7/F7 -> 0.85 | H7: 2.5 | I7: =E7*H7 -> 7.5
A8: 3 | B8: 热干面（熟） | D8: 斤 | E8: 3 | F8: =H8/0.85 -> 4.1176471 | G8: =H8/F8 -> 0.85 | H8: 3.5 | I8: =E8*H8 -> 10.5
A9: 4 | B9: 熟凉面 | D9: 斤 | E9: 2 | F9: =H9/0.85 -> 4.1176471 | G9: =H9/F9 -> 0.85 | H9: 3.5 | I9: =E9*H9 -> 7
A10: 5 | B10: 大葱 | D10: 斤 | E10: 2.1 | F10: =H10/0.85 -> 4.1176471 | G10: =H10/F10 -> 0.85 | H10: 3.5 | I10: =E10*H10 -> 7.35
A11: 6 | B11: 小葱 | D11: 斤 | E11: 2 | F11: =H11/0.85 -> 8 | G11: =H11/F11 -> 0.85 | H11: 6.8 | I11: =E11*H11 -> 13.6
A12: 7 | B12: 红椒 | D12: 斤 | E12: 2 | F12: =H12/0.85 -> 9.1764706 | G12: =H12/F12 -> 0.85 | H12: 7.8 | I12: =E12*H12 -> 15.6
A13: 8 | B13: 嫩藕 | D13: 斤 | E13: 5.5 | F13: =H13/0.85 -> 6.8235294 | G13: =H13/F13 -> 0.85 | H13: 5.8 | I13: =E13*H13 -> 31.9
A14: 9 | B14: 芜湖青椒 | D14: 斤 | E14: 2 | F14: =H14/0.85 -> 4.4705882 | G14: =H14/F14 -> 0.85 | H14: 3.8 | I14: =E14*H14 -> 7.6
A15: 10 | B15: 西红柿 | D15: 斤 | E15: 4 | F15: =H15/0.85 -> 4.4705882 | G15: =H15/F15 -> 0.85 | H15: 3.8 | I15: =E15*H15 -> 15.2
A16: 11 | B16: 有机花菜 | D16: 斤 | E16: 13 | F16: =H16/0.85 -> 6.4705882 | G16: =H16/F16 -> 0.85 | H16: 5.5 | I16: =E16*H16 -> 71.5
A17: 12 | B17: 黄瓜 | D17: 斤 | E17: 3.2 | F17: =H17/0.85 -> 3.2941176 | G17: =H17/F17 -> 0.85 | H17: 2.8 | I17: =E17*H17 -> 8.96
... A27: 22 | B27: 【鲜】猪五花肉片 | D27: 斤 | E27: 5 | F27: =H27/0.85 -> 17.647059 | G27: =H27/F27 -> 0.85 | H27: 15 | I27: =E27*H27 -> 75
A28: 23 | B28: 【鲜】净大鲫鱼 | C28: 4两 | D28: 斤 | E28: 26 | F28: =H28/0.85 -> 20.941176 | G28: =H28/F28 -> 0.85 | H28: 17.8 | I28: =E28*H28 -> 462.8
A29: 24 | B29: 白玉兰蛋糕专用低筋面粉 | C29: 22.68kg/袋 | D29: 袋 | E29: 1 | F29: =H29/0.85 -> 223.52941 | G29: =H29/F29 -> 0.85 | H29: 190 | I29: =E29*H29 -> 190
A30: 25 | B30: 金钻甜点奶油 | C30: 907g | D30: 盒 | E30: 2 | F30: =H30/0.85 -> 35.294118 | G30: =H30/F30 -> 0.85 | H30: 30 | I30: =E30*H30 -> 60
A31: 26 | B31: 三象水磨糯米粉 | C31: 500g | D31: 袋 | E31: 10 | F31: =H31/0.85 -> 11.529412 | G31: =H31/F31 -> 0.85 | H31: 9.8 | I31: =E31*H31 -> 98
A32: 27 | B32: 三象水磨籼米粉 | C32: 500g*20包/件 | D32: 包 | E32: 10 | F32: =H32/0.85 -> 10 | G32: =H32/F32 -> 0.85 | H32: 8.5 | I32: =E32*H32 -> 85
A33: 28 | B33: 食用小苏打 | C33: 140g*50袋/件 | D33: 袋 | E33: 1 | F33: =H33/0.85 -> 3.2941176 | G33: =H33/F33 -> 0.85 | H33: 2.8 | I33: =E33*H33 -> 2.8
A34: 29 | B34: 八宝粥米 | C34: 散称 | D34: 斤 | E34: 5 | F34: =H34/0.85 -> 10 | G34: =H34/F34 -> 0.85 | H34: 8.5 | I34: =E34*H34 -> 42.5
A35: 30 | B35: 缅甸香米25kg | C35: 25kg | D35: 袋 | E35: 1 | F35: =H35/0.85 -> 247.05882 | G35: =H35/F35 -> 0.85 | H35: 210 | I35: =E35*H35 -> 210
A36: 31 | B36: 九制话梅 | C36: （85g/袋） | D36: 袋 | E36: 2 | F36: =H36/0.85 -> 9.4117647 | G36: =H36/F36 -> 0.85 | H36: 8 | I36: =E36*H36 -> 16
A37: 32 | B37: 光明畅优0腹担风味发酵乳 | C37: 100g/杯 | D37: 杯 | E37: 60 | F37: =H37/0.85 -> 4.7058824 | G37: =H37/F37 -> 0.85 | H37: 4 | I37: =E37*H37 -> 240
A38: 33 | B38: 塔塔粉 | D38: 听 | E38: 3 | F38: =H38/0.85 -> 25.882353 | G38: =H38/F38 -> 0.85 | H38: 22 | I38: =E38*H38 -> 66
A39: 34
A40: 供货合计: | B40: =SUM(I6:I39) -> 2221.71
A41: 金额大写： | B41: =B40 -> 2221.71
A42: 制表人 ：樊君丽 收货人： 送货人：

Sheet 12
A1: 武汉康恩农贸发展有限公司送货单
A3: 收货单位： | B3: 汉南数智化检测分公司
A4: 配送日期： | B4: 45119
A5: 序号 | B5: 名称 | C5: 规格 | D5: 单位 | E5: 数量 | F5: 超市价格 | G5: 折扣率 | H5: 折后价 | I5: 折后金额 | J5: 备注
A6: 1 | B6: （新鲜）河粉 | D6: 斤 | E6: 5 | F6: =H6/0.85 -> 3.5294118 | G6: =H6/F6 -> 0.85 | H6: 3 | I6: =E6*H6 -> 15
A7: 2 | B7: 热干面（熟） | D7: 斤 | E7: 4 | F7: =H7/0.85 -> 4.1176471 | G7: =H7/F7 -> 0.85 | H7: 3.5 | I7: =E7*H7 -> 14
A8: 3 | B8: 熟凉面 | D8: 斤 | E8: 2 | F8: =H8/0.85 -> 4.1176471 | G8: =H8/F8 -> 0.85 | H8: 3.5 | I8: =E8*H8 -> 7
A9: 4 | B9: 生姜 | D9: 斤 | E9: 4 | F9: =H9/0.85 -> 15.058824 | G9: =H9/F9 -> 0.85 | H9: 12.8 | I9: =E9*H9 -> 51.2
A10: 5 | B10: 红椒 | D10: 斤 | E10: 3 | F10: =H10/0.85 -> 9.1764706 | G10: =H10/F10 -> 0.85 | H10: 7.8 | I10: =E10*H10 -> 23.4
A11: 6 | B11: 铁棍山药 | D11: 斤 | E11: 5 | F11: =H11/0.85 -> 11.529412 | G11: =H11/F11 -> 0.85 | H11: 9.8 | I11: =E11*H11 -> 49
A12: 7 | B12: 芜湖青椒 | D12: 斤 | E12: 3 | F12: =H12/0.85 -> 4.4705882 | G12: =H12/F12 -> 0.85 | H12: 3.8 | I12: =E12*H12 -> 11.4
A13: 8 | B13: 黄瓜 | D13: 斤 | E13: 7 | F13: =H13/0.85 -> 3.2941176 | G13: =H13/F13 -> 0.85 | H13: 2.8 | I13: =E13*H13 -> 19.6
A14: 9 | B14: 鲜香菇 | D14: 斤 | E14: 5 | F14: =H14/0.85 -> 10.352941 | G14: =H14/F14 -> 0.85 | H14: 8.8 | I14: =E14*H14 -> 44
A15: 10 | B15: 兰州包菜 | D15: 斤 | E15: 12 | F15: =H15/0.85 -> 2.3529412 | G15: =H15/F15 -> 0.85 | H15: 2 | I15: =E15*H15 -> 24
A16: 11 | B16: 黑布林 | D16: 斤 | E16: 15.5 | F16: =H16/0.85 -> 6.4705882 | G16: =H16/F16 -> 0.85 | H16: 5.5 | I16: =E16*H16 -> 85.25
A17: 12 | B17: 麒麟西瓜 | D17: 斤 | E17: 40 | F17: =H17/0.85 -> 5.6470588 | G17: =H17/F17 -> 0.85 | H17: 4.8 | I17: =E17*H17 -> 192
... A23: 18 | B23: 红豆 | D23: 斤 | E23: 5 | F23: =H23/0.85 -> 15.058824 | G23: =H23/F23 -> 0.85 | H23: 12.8 | I23: =E23*H23 -> 64
A24: 19 | B24: 皖顺福小米椒 | C24: 2kg*6袋/件 | D24: 袋 | E24: 2 | F24: =H24/0.85 -> 11.529412 | G24: =H24/F24 -> 0.85 | H24: 9.8 | I24: =E24*H24 -> 19.6
A25: 20 | B25: 鲁花压榨玉米油 | C25: 5L*4壶/件 | D25: 件 | E25: 2 | F25: =H25/0.85 -> 500 | G25: =H25/F25 -> 0.85 | H25: 425 | I25: =E25*H25 -> 850
A26: 21 | B26: 卤牛肉 | D26: 斤 | E26: 3 | F26: =H26/0.85 -> 103.52941 | G26: =H26/F26 -> 0.85 | H26: 88 | I26: =E26*H26 -> 264
A27: 22
A28: 23
A29: 24
A30: 25
A31: 26
A32: 27
A33: 28
A34: 29
A35: 30
A36: 供货合计: | B36: =SUM(I6:I35) -> 2649.93
A37: 金额大写： | B37: =B36 -> 2649.93
A38: 制表人 ：樊君丽 收货人： 送货人：

Sheet 13
A1: 武汉康恩农贸发展有限公司送货单
A3: 收货单位： | B3: 汉南数智化检测分公司
A4: 配送日期： | B4: 45120
A5: 序号 | B5: 名称 | C5: 规格 | D5: 单位 | E5: 数量 | F5: 超市价格 | G5: 折扣率 | H5: 折后价 | I5: 折后金额 | J5: 备注
A6: 1 | B6: （新鲜）河粉 | D6: 斤 | E6: 4 | F6: =H6/0.85 -> 3.5294118 | G6: =H6/F6 -> 0.85 | H6: 3 | I6: =E6*H6 -> 12
A7: 2 | B7: 热干面（熟） | D7: 斤 | E7: 4 | F7: =H7/0.85 -> 4.1176471 | G7: =H7/F7 -> 0.85 | H7: 3.5 | I7: =E7*H7 -> 14
A8: 3 | B8: 熟凉面 | D8: 斤 | E8: 2 | F8: =H8/0.85 -> 4.1176471 | G8: =H8/F8 -> 0.85 | H8: 3.5 | I8: =E8*H8 -> 7
A9: 4 | B9: 黄豆芽 | D9: 斤 | E9: 11 | F9: =H9/0.85 -> 2.9411765 | G9: =H9/F9 -> 0.85 | H9: 2.5 | I9: =E9*H9 -> 27.5
A10: 5 | B10: 四季豆 | D10: 斤 | E10: 21 | F10: =H10/0.85 -> 10 | G10: =H10/F10 -> 0.85 | H10: 8.5 | I10: =E10*H10 -> 178.5
A11: 6 | B11: 红椒 | D11: 斤 | E11: 6 | F11: =H11/0.85 -> 9.1764706 | G11: =H11/F11 -> 0.85 | H11: 7.8 | I11: =E11*H11 -> 46.8
A12: 7 | B12: 芜湖青椒 | D12: 斤 | E12: 7 | F12: =H12/0.85 -> 4.4705882 | G12: =H12/F12 -> 0.85 | H12: 3.8 | I12: =E12*H12 -> 26.6
A13: 8 | B13: 冬瓜 | D13: 斤 | E13: 11.6 | F13: =H13/0.85 -> 2.9411765 | G13: =H13/F13 -> 0.85 | H13: 2.5 | I13: =E13*H13 -> 29
A14: 9 | B14: 韭菜 | D14: 斤 | E14: 8 | F14: =H14/0.85 -> 4.1176471 | G14: =H14/F14 -> 0.85 | H14: 3.5 | I14: =E14*H14 -> 28
A15: 10 | B15: 细土芹 | D15: 斤 | E15: 5 | F15: =H15/0.85 -> 6.4705882 | G15: =H15/F15 -> 0.85 | H15: 5.5 | I15: =E15*H15 -> 27.5
A16: 11 | B16: 香菜 | D16: 斤 | E16: 2 | F16: =H16/0.85 -> 8 | G16: =H16/F16 -> 0.85 | H16: 6.8 | I16: =E16*H16 -> 13.6
A17: 12 | B17: 麒麟西瓜 | D17: 斤 | E17: 99 | F17: =H17/0.85 -> 5.6470588 | G17: =H17/F17 -> 0.85 | H17: 4.8 | I17: =E17*H17 -> 475.2
A18: 13 | B18: 薄千张 | D18: 斤 | E18: 12 | F18: =H18/0.85 -> 8 | G18: =H18/F18 -> 0.85 | H18: 6.8 | I18: =E18*H18 -> 81.6
A19: 14 | B19: 皮蛋 | C19: 180个/件 | D19: 个 | E19: 30 | F19: =H19/0.85 -> 2.1176471 | G19: =H19/F19 -> 0.85 | H19: 1.8 | I19: =E19*H19 -> 54
A20: 15 | B20: 【鲜】五花肉沫 | D20: 斤 | E20: 6 | F20: =H20/0.85 -> 17.647059 | G20: =H20/F20 -> 0.85 | H20: 15 | I20: =E20*H20 -> 90
A21: 16 | B21: 【鲜】猪肝 | D21: 斤 | E21: 10 | F21: =H21/0.85 -> 11.764706 | G21: =H21/F21 -> 0.85 | H21: 10 | I21: =E21*H21 -> 100
A22: 17 | B22: 【鲜】猪瘦肉丝 | D22: 斤 | E22: 3 | F22: =H22/0.85 -> 23.529412 | G22: =H22/F22 -> 0.85 | H22: 20 | I22: =E22*H22 -> 60
A23: 18 | B23: 【鲜】猪通排骨 | D23: 斤 | E23: 9 | F23: =H23/0.85 -> 28.235294 | G23: =H23/F23 -> 0.85 | H23: 24 | I23: =E23*H23 -> 216
A24: 19 | B24: 【鲜】猪五花肉片 | D24: 斤 | E24: 4 | F24: =H24/0.85 -> 17.647059 | G24: =H24/F24 -> 0.85 | H24: 15 | I24: =E24*H24 -> 60
A25: 20 | B25: 洪湖泡藕带 | C25: 400g*20袋 | D25: 袋 | E25: 20 | F25: =H25/0.85 -> 10.588235 | G25: =H25/F25 -> 0.85 | H25: 9 | I25: =E25*H25 -> 180
A26: 21 | B26: 双汇王中王火腿肠90g | C26: 90g*50根/件 | D26: 件 | E26: 1 | F26: =H26/0.85 -> 211.76471 | G26: =H26/F26 -> 0.85 | H26: 180 | I26: =E26*H26 -> 180
A27: 22 | B27: 小米 | C27: 散称 | D27: 斤 | E27: 5 | F27: =H27/0.85 -> 8 | G27: =H27/F27 -> 0.85 | H27: 6.8 | I27: =E27*H27 -> 34
A28: 23 | B28: 光明畅优0腹担风味发酵乳 | C28: 100g/杯 | D28: 杯 | E28: 60 | F28: =H28/0.85 -> 4.1176471 | G28: =H28/F28 -> 0.85 | H28: 3.5 | I28: =E28*H28 -> 210
A29: 24 | B29: 光明益生菌酸奶（原味） | C29: 100g | D29: 杯 | E29: 40 | F29: =H29/0.85 -> 1.7647059 | G29: =H29/F29 -> 0.85 | H29: 1.5 | I29: =E29*H29 -> 60
A30: 25
A31: 26
A32: 供货合计: | B32: =SUM(I6:I31) -> 2211.3
A33: 金额大写： | B33: =B32 -> 2211.3
A34: 制表人 ：樊君丽 收货人： 送货人：

Sheet 14
A1: 武汉康恩农贸发展有限公司送货单
A3: 收货单位： | B3: 汉南数智化检测分公司
A4: 配送日期： | B4: 45121
A5: 序号 | B5: 名称 | C5: 规格 | D5: 单位 | E5: 数量 | F5: 超市价格 | G5: 折扣率 | H5: 折后价 | I5: 折后金额 | J5: 备注
A6: 1 | B6: 大圆皮 | D6: 斤 | E6: 2 | F6: =H6/0.85 -> 4.7058824 | G6: =H6/F6 -> 0.85 | H6: 4 | I6: =E6*H6 -> 8
A7: 2 | B7: 馄饨皮 | D7: 斤 | E7: 2 | F7: =H7/0.85 -> 4.1176471 | G7: =H7/F7 -> 0.85 | H7: 3.5 | I7: =E7*H7 -> 7
A8: 3 | B8: 宽粉 | D8: 斤 | E8: 5 | F8: =H8/0.85 -> 3.5294118 | G8: =H8/F8 -> 0.85 | H8: 3 | I8: =E8*H8 -> 15
A9: 4 | B9: 热干面（熟） | D9: 斤 | E9: 4 | F9: =H9/0.85 -> 4.1176471 | G9: =H9/F9 -> 0.85 | H9: 3.5 | I9: =E9*H9 -> 14
A10: 5 | B10: 生姜 | D10: 斤 | E10: 5 | F10: =H10/0.85 -> 15.058824 | G10: =H10/F10 -> 0.85 | H10: 12.8 | I10: =E10*H10 -> 64
A11: 6 | B11: 大土豆 | D11: 斤 | E11: 12 | F11: =H11/0.85 -> 4.1176471 | G11: =H11/F11 -> 0.85 | H11: 3.5 | I11: =E11*H11 -> 42
A12: 7 | B12: 甜玉米棒 | D12: 个 | E12: 10 | F12: =H12/0.85 -> 2.9411765 | G12: =H12/F12 -> 0.85 | H12: 2.5 | I12: =E12*H12 -> 25
A13: 8 | B13: 韭菜 | D13: 斤 | E13: 2 | F13: =H13/0.85 -> 4.1176471 | G13: =H13/F13 -> 0.85 | H13: 3.5 | I13: =E13*H13 -> 7
A14: 9 | B14: 韭黄 | D14: 斤 | E14: 8 | F14: =H14/0.85 -> 11.529412 | G14: =H14/F14 -> 0.85 | H14: 9.8 | I14: =E14*H14 -> 78.4
A15: 10 | B15: 小白菜 | D15: 斤 | E15: 2 | F15: =H15/0.85 -> 3.2941176 | G15: =H15/F15 -> 0.85 | H15: 2.8 | I15: =E15*H15 -> 5.6
A16: 11 | B16: 油桃 | D16: 斤 | E16: 19 | F16: =H16/0.85 -> 1.1764706 | G16: =H16/F16 -> 0.85 | H16: 1 | I16: =E16*H16 -> 19
A17: 12 | B17: 厚干子 | D17: 斤 | E17: 5 | F17: =H17/0.85 -> 8 | G17: =H17/F17 -> 0.85 | H17: 6.8 | I17: =E17*H17 -> 34
A18: 13 | B18: 嫩豆腐 | D18: 斤 | E18: 4 | F18: =H18/0.85 -> 4.1176471 | G18: =H18/F18 -> 0.85 | H18: 3.5 | I18: =E18*H18 -> 14
A19: 14 | B19: 白壳鸡蛋 | C19: 12板/件 | D19: 板 | E19: 5 | F19: =H19/0.85 -> 30.588235 | G19: =H19/F19 -> 0.85 | H19: 26 | I19: =E19*H19 -> 130
A20: 15 | B20: 【鲜】净三黄鸡 | D20: 斤 | E20: 7 | F20: =H20/0.85 -> 17.411765 | G20: =H20/F20 -> 0.85 | H20: 14.8 | I20: =E20*H20 -> 103.6
A21: 16 | B21: 【鲜】五花肉沫 | D21: 斤 | E21: 5 | F21: =H21/0.85 -> 17.647059 | G21: =H21/F21 -> 0.85 | H21: 15 | I21: =E21*H21 -> 75
A22: 17 | B22: 【鲜】猪瘦肉丝 | D22: 斤 | E22: 3 | F22: =H22/0.85 -> 23.529412 | G22: =H22/F22 -> 0.85 | H22: 20 | I22: =E22*H22 -> 60
A23: 18 | B23: 活大财鱼 | C23: 3斤以上 | D23: 斤 | E23: 9.8 | F23: =H23/0.85 -> 17.647059 | G23: =H23/F23 -> 0.85 | H23: 15 | I23: =E23*H23 -> 147
A24: 19 | B24: 虾皮 | C24: 散称 | D24: 斤 | E24: 1 | F24: =H24/0.85 -> 29.411765 | G24: =H24/F24 -> 0.85 | H24: 25 | I24: =E24*H24 -> 25
A25: 20 | B25: 文武酱菜外婆菜 | C25: 208g*40包/件 | D25: 包 | E25: 30 | F25: =H25/0.85 -> 4.1176471 | G25: =H25/F25 -> 0.85 | H25: 3.5 | I25: =E25*H25 -> 105
A26: 21
A27: 22
A28: 23
A29: 24
A30: 25
A31: 26
A32: 供货合计: | B32: =SUM(I6:I31) -> 978.6
A33: 金额大写： | B33: =B32 -> 978.6
A34: 制表人 ：樊君丽 收货人： 送货人：

Sheet 17
A1: 武汉康恩农贸发展有限公司送货单
A3: 收货单位： | B3: 汉南数智化检测分公司
A4: 配送日期： | B4: 45124
A5: 序号 | B5: 名称 | C5: 规格 | D5: 单位 | E5: 数量 | F5: 超市价格 | G5: 折扣率 | H5: 折后价 | I5: 折后金额 | J5: 备注
A6: 1 | B6: （新鲜）河粉 | D6: 斤 | E6: 2 | F6: =H6/0.85 -> 3.5294118 | G6: =H6/F6 -> 0.85 | H6: 3 | I6: =E6*H6 -> 6
A7: 2 | B7: 大圆皮 | D7: 斤 | E7: 2 | F7: =H7/0.85 -> 4.7058824 | G7: =H7/F7 -> 0.85 | H7: 4 | I7: =E7*H7 -> 8
A8: 3 | B8: 干细粉 | C8: 散称 | D8: 斤 | E8: 2 | F8: =H8/0.85 -> 4.1176471 | G8: =H8/F8 -> 0.85 | H8: 3.5 | I8: =E8*H8 -> 7
A9: 4 | B9: 热干面（熟） | D9: 斤 | E9: 4 | F9: =H9/0.85 -> 4.1176471 | G9: =H9/F9 -> 0.85 | H9: 3.5 | I9: =E9*H9 -> 14
A10: 5 | B10: 熟凉面 | D10: 斤 | E10: 2 | F10: =H10/0.85 -> 4.1176471 | G10: =H10/F10 -> 0.85 | H10: 3.5 | I10: =E10*H10 -> 7
A11: 6 | B11: 红椒 | D11: 斤 | E11: 3 | F11: =H11/0.85 -> 9.1764706 | G11: =H11/F11 -> 0.85 | H11: 7.8 | I11: =E11*H11 -> 23.4
A12: 7 | B12: 芜湖青椒 | D12: 斤 | E12: 3 | F12: =H12/0.85 -> 4.4705882 | G12: =H12/F12 -> 0.85 | H12: 3.8 | I12: =E12*H12 -> 11.4
A13: 8 | B13: 净莴苣 | D13: 斤 | E13: 12 | F13: =H13/0.85 -> 5.6470588 | G13: =H13/F13 -> 0.85 | H13: 4.8 | I13: =E13*H13 -> 57.6
A14: 9 | B14: 生菜 | D14: 斤 | E14: 13 | F14: =H14/0.85 -> 6.4705882 | G14: =H14/F14 -> 0.85 | H14: 5.5 | I14: =E14*H14 -> 71.5
A15: 10 | B15: 嫩豆腐 | D15: 斤 | E15: 14 | F15: =H15/0.85 -> 4.1176471 | G15: =H15/F15 -> 0.85 | H15: 3.5 | I15: =E15*H15 -> 49
A16: 11 | B16: 红壳鸡蛋 | C16: 12板/件 | D16: 件 | E16: 1 | F16: =H16/0.85 -> 352.94118 | G16: =H16/F16 -> 0.85 | H16: 300 | I16: =E16*H16 -> 300
A17: 12 | B17: 【鲜】猪前腿肉沫 | D17: 斤 | E17: 2 | F17: =H17/0.85 -> 15.294118 | G17: =H17/F17 -> 0.85 | H17: 13 | I17: =E17*H17 -> 26
A18: 13 | B18: 【鲜】净胖头鱼头 | D18: 斤 | E18: 7.25 | F18: =H18/0.85 -> 23.529412 | G18: =H18/F18 -> 0.85 | H18: 20 | I18: =E18*H18 -> 145
A19: 14 | B19: 净大带鱼块 | D19: 斤 | E19: 12 | F19: =H19/0.85 -> 37.647059 | G19: =H19/F19 -> 0.85 | H19: 32 | I19: =E19*H19 -> 384
A20: 15 | B20: 厨师乐加鲜味精 | C20: 2.27kg*10袋/件 | D20: 袋 | E20: 3 | F20: =H20/0.85 -> 51.764706 | G20: =H20/F20 -> 0.85 | H20: 44 | I20: =E20*H20 -> 132
A21: 16 | B21: 大桥鸡精 | C21: 200g*40袋/件 | D21: 袋 | E21: 3 | F21: =H21/0.85 -> 42.823529 | G21: =H21/F21 -> 0.85 | H21: 36.4 | I21: =E21*H21 -> 109.2
A22: 17 | B22: 云鹤无碘盐 | C22: 350g*60袋/件 | D22: 袋 | E22: 10 | F22: =H22/0.85 -> 2.3529412 | G22: =H22/F22 -> 0.85 | H22: 2 | I22: =E22*H22 -> 20
A23: 18 | B23: 卤牛肉 | D23: 斤 | E23: 5 | F23: =H23/0.85 -> 103.52941 | G23: =H23/F23 -> 0.85 | H23: 88 | I23: =E23*H23 -> 440
A24: 19 | B24: 干黄豆 | C24: 50斤/件 | D24: 斤 | E24: 10 | F24: =H24/0.85 -> 6.4705882 | G24: =H24/F24 -> 0.85 | H24: 5.5 | I24: =E24*H24 -> 55
A25: 20 | B25: 光明畅优0腹担风味发酵乳 | C25: 100g/杯 | D25: 杯 | E25: 46 | F25: =H25/0.85 -> 4.1176471 | G25: =H25/F25 -> 0.85 | H25: 3.5 | I25: =E25*H25 -> 161
A26: 21
A27: 22
A28: 23
A29: 24
A30: 25
A31: 26
A32: 27
A33: 供货合计: | B33: =SUM(I6:I32) -> 2027.1
A34: 金额大写： | B34: =B33 -> 2027.1
A35: 制表人 ：樊君丽 收货人： 送货人：

Sheet 18
A1: 武汉康恩农贸发展有限公司送货单
A3: 收货单位： | B3: 汉南数智化检测分公司
A4: 配送日期： | B4: 45125
A5: 序号 | B5: 名称 | C5: 规格 | D5: 单位 | E5: 数量 | F5: 超市价格 | G5: 折扣率 | H5: 折后价 | I5: 折后金额 | J5: 备注
A6: 1 | B6: （新鲜）河粉 | D6: 斤 | E6: 4 | F6: =H6/0.85 -> 3.5294118 | G6: =H6/F6 -> 0.85 | H6: 3 | I6: =E6*H6 -> 12
A7: 2 | B7: 热干面（熟） | D7: 斤 | E7: 5 | F7: =H7/0.85 -> 4.1176471 | G7: =H7/F7 -> 0.85 | H7: 3.5 | I7: =E7*H7 -> 17.5
A8: 3 | B8: 大葱 | D8: 斤 | E8: 2 | F8: =H8/0.85 -> 4.1176471 | G8: =H8/F8 -> 0.85 | H8: 3.5 | I8: =E8*H8 -> 7
A9: 4 | B9: 新鲜红小米椒 | D9: 斤 | E9: 2 | F9: =H9/0.85 -> 19.764706 | G9: =H9/F9 -> 0.85 | H9: 16.8 | I9: =E9*H9 -> 33.6
A10: 5 | B10: 白豆角 | D10: 斤 | E10: 4 | F10: =H10/0.85 -> 4.4705882 | G10: =H10/F10 -> 0.85 | H10: 3.8 | I10: =E10*H10 -> 15.2
A11: 6 | B11: 红椒 | D11: 斤 | E11: 3 | F11: =H11/0.85 -> 9.1764706 | G11: =H11/F11 -> 0.85 | H11: 7.8 | I11: =E11*H11 -> 23.4
A12: 7 | B12: 甜玉米棒 | D12: 个 | E12: 10 | F12: =H12/0.85 -> 2.9411765 | G12: =H12/F12 -> 0.85 | H12: 2.5 | I12: =E12*H12 -> 25
A13: 8 | B13: 芜湖青椒 | D13: 斤 | E13: 3 | F13: =H13/0.85 -> 4.4705882 | G13: =H13/F13 -> 0.85 | H13: 3.8 | I13: =E13*H13 -> 11.4
A14: 9 | B14: 青丝瓜 | D14: 斤 | E14: 6 | F14: =H14/0.85 -> 5.2941176 | G14: =H14/F14 -> 0.85 | H14: 4.5 | I14: =E14*H14 -> 27
A15: 10 | B15: 85苹果 | D15: 斤 | E15: 23.19 | F15: =H15/0.85 -> 11.529412 | G15: =H15/F15 -> 0.85 | H15: 9.8 | I15: =E15*H15 -> 227.262
A16: 11 | B16: 美都无籽冰糖瓜 | D16: 斤 | E16: 25 | F16: =H16/0.85 -> 4.1176471 | G16: =H16/F16 -> 0.85 | H16: 3.5 | I16: =E16*H16 -> 87.5
A17: 12 | B17: 面筋 | D17: 斤 | E17: 8 | F17: =H17/0.85 -> 8 | G17: =H17/F17 -> 0.85 | H17: 6.8 | I17: =E17*H17 -> 54.4
... A24: 19 | B24: 【鲜】猪五花肉片 | D24: 斤 | E24: 5 | F24: =H24/0.85 -> 17.647059 | G24: =H24/F24 -> 0.85 | H24: 15 | I24: =E24*H24 -> 75
A25: 20 | B25: 清水笋丝 | C25: 2.5kg*6包/件 | D25: 包 | E25: 7 | F25: =H25/0.85 -> 15.929412 | G25: =H25/F25 -> 0.85 | H25: 13.54 | I25: =E25*H25 -> 94.78
A26: 21 | B26: 味福黑胡椒粉 | C26: 227g*10袋/件 | D26: 袋 | E26: 1 | F26: =H26/0.85 -> 29.411765 | G26: =H26/F26 -> 0.85 | H26: 25 | I26: =E26*H26 -> 25
A27: 22 | B27: 缅甸香米25kg | C27: 25kg | D27: 袋 | E27: 3 | F27: =H27/0.85 -> 247.05882 | G27: =H27/F27 -> 0.85 | H27: 210 | I27: =E27*H27 -> 630
A28: 23
A29: 24
A30: 25
A31: 26
A32: 供货合计: | B32: =SUM(I6:I31) -> 1810.042
A33: 金额大写： | B33: =B32 -> 1810.042
A34: 制表人 ：樊君丽 收货人： 送货人：

Sheet 19
A1: 武汉康恩农贸发展有限公司送货单
A3: 收货单位： | B3: 汉南数智化检测分公司
A4: 配送日期： | B4: 45126
A5: 序号 | B5: 名称 | C5: 规格 | D5: 单位 | E5: 数量 | F5: 超市价格 | G5: 折扣率 | H5: 折后价 | I5: 折后金额 | J5: 备注
A6: 1 | B6: （新鲜）河粉 | D6: 斤 | E6: 4 | F6: =H6/0.85 -> 3.5294118 | G6: =H6/F6 -> 0.85 | H6: 3 | I6: =E6*H6 -> 12
A7: 2 | B7: 热干面（熟） | D7: 斤 | E7: 4 | F7: =H7/0.85 -> 4.1176471 | G7: =H7/F7 -> 0.85 | H7: 3.5 | I7: =E7*H7 -> 14
A8: 3 | B8: 大葱 | D8: 斤 | E8: 2 | F8: =H8/0.85 -> 4.1176471 | G8: =H8/F8 -> 0.85 | H8: 3.5 | I8: =E8*H8 -> 7
A9: 4 | B9: 小葱 | D9: 斤 | E9: 2 | F9: =H9/0.85 -> 8 | G9: =H9/F9 -> 0.85 | H9: 6.8 | I9: =E9*H9 -> 13.6
A10: 5 | B10: 黄豆芽 | D10: 斤 | E10: 2 | F10: =H10/0.85 -> 2.9411765 | G10: =H10/F10 -> 0.85 | H10: 2.5 | I10: =E10*H10 -> 5
A11: 6 | B11: 新鲜毛豆米 | D11: 斤 | E11: 7 | F11: =H11/0.85 -> 14.117647 | G11: =H11/F11 -> 0.85 | H11: 12 | I11: =E11*H11 -> 84
A12: 7 | B12: 大红薯 | D12: 斤 | E12: 5 | F12: =H12/0.85 -> 4.1176471 | G12: =H12/F12 -> 0.85 | H12: 3.5 | I12: =E12*H12 -> 17.5
A13: 8 | B13: 胡萝卜 | D13: 斤 | E13: 7 | F13: =H13/0.85 -> 2.9411765 | G13: =H13/F13 -> 0.85 | H13: 2.5 | I13: =E13*H13 -> 17.5
A14: 9 | B14: 新藕 | D14: 斤 | E14: 12 | F14: =H14/0.85 -> 6.8235294 | G14: =H14/F14 -> 0.85 | H14: 5.8 | I14: =E14*H14 -> 69.6
A15: 10 | B15: 铁棍山药 | D15: 斤 | E15: 4.4 | F15: =H15/0.85 -> 11.529412 | G15: =H15/F15 -> 0.85 | H15: 9.8 | I15: =E15*H15 -> 43.12
A16: 11 | B16: 西红柿 | D16: 斤 | E16: 4 | F16: =H16/0.85 -> 4.4705882 | G16: =H16/F16 -> 0.85 | H16: 3.8 | I16: =E16*H16 -> 15.2
A17: 12 | B17: 薄千张 | D17: 斤 | E17: 2 | F17: =H17/0.85 -> 8 | G17: =H17/F17 -> 0.85 | H17: 6.8 | I17: =E17*H17 -> 13.6
... A21: 16 | B21: 卤牛肚 | D21: 斤 | E21: 4 | F21: =H21/0.85 -> 103.52941 | G21: =H21/F21 -> 0.85 | H21: 88 | I21: =E21*H21 -> 352
A22: 17
A23: 18
A24: 19
A25: 20
A26: 21
A27: 22
A28: 23
A29: 24
A30: 25
A31: 26
A32: 27
A33: 28
A34: 供货合计: | B34: =SUM(I6:I33) -> 1065.24
A35: 金额大写： | B35: =B34 -> 1065.24
A36: 制表人 ：樊君丽 收货人： 送货人：

Sheet 20
A1: 武汉康恩农贸发展有限公司送货单
A3: 收货单位： | B3: 汉南数智化检测分公司
A4: 配送日期： | B4: 45127
A5: 序号 | B5: 名称 | C5: 规格 | D5: 单位 | E5: 数量 | F5: 超市价格 | G5: 折扣率 | H5: 折后价 | I5: 折后金额 | J5: 备注
A6: 1 | B6: （新鲜）河粉 | D6: 斤 | E6: 5 | F6: =H6/0.85 -> 3.5294118 | G6: =H6/F6 -> 0.85 | H6: 3 | I6: =E6*H6 -> 15
A7: 2 | B7: 馄饨皮 | D7: 斤 | E7: 2 | F7: =H7/0.85 -> 4.1176471 | G7: =H7/F7 -> 0.85 | H7: 3.5 | I7: =E7*H7 -> 7
A8: 3 | B8: 热干面（熟） | D8: 斤 | E8: 3 | F8: =H8/0.85 -> 4.1176471 | G8: =H8/F8 -> 0.85 | H8: 3.5 | I8: =E8*H8 -> 10.5
A9: 4 | B9: 熟凉面 | D9: 斤 | E9: 2 | F9: =H9/0.85 -> 4.1176471 | G9: =H9/F9 -> 0.85 | H9: 3.5 | I9: =E9*H9 -> 7
A10: 5 | B10: 蒜米 | D10: 斤 | E10: 4 | F10: =H10/0.85 -> 9.1764706 | G10: =H10/F10 -> 0.85 | H10: 7.8 | I10: =E10*H10 -> 31.2
A11: 6 | B11: 白萝卜 | D11: 斤 | E11: 8 | F11: =H11/0.85 -> 2.3529412 | G11: =H11/F11 -> 0.85 | H11: 2 | I11: =E11*H11 -> 16
A12: 7 | B12: 红椒 | D12: 斤 | E12: 3 | F12: =H12/0.85 -> 9.1764706 | G12: =H12/F12 -> 0.85 | H12: 7.8 | I12: =E12*H12 -> 23.4
A13: 8 | B13: 鸡头米杆子 | D13: 斤 | E13: 14 | F13: =H13/0.85 -> 3.5294118 | G13: =H13/F13 -> 0.85 | H13: 3 | I13: =E13*H13 -> 42
A14: 9 | B14: 芜湖青椒 | D14: 斤 | E14: 15 | F14: =H14/0.85 -> 4.4705882 | G14: =H14/F14 -> 0.85 | H14: 3.8 | I14: =E14*H14 -> 57
A15: 10 | B15: 冬瓜 | D15: 斤 | E15: 10 | F15: =H15/0.85 -> 2.9411765 | G15: =H15/F15 -> 0.85 | H15: 2.5 | I15: =E15*H15 -> 25
A16: 11 | B16: 【鲜】筒子骨 | D16: 斤 | E16: 6 | F16: =H16/0.85 -> 15.294118 | G16: =H16/F16 -> 0.85 | H16: 13 | I16: =E16*H16 -> 78
A17: 12 | B17: 【鲜】五花肉沫 | D17: 斤 | E17: 3 | F17: =H17/0.85 -> 17.647059 | G17: =H17/F17 -> 0.85 | H17: 15 | I17: =E17*H17 -> 45
A18: 13 | B18: 【鲜】净牛蛙 | D18: 斤 | E18: 8 | F18: =H18/0.85 -> 45.882353 | G18: =H18/F18 -> 0.85 | H18: 39 | I18: =E18*H18 -> 312
A19: 14 | B19: 鑫海贸紫菜50g | C19: 50g*48包 | D19: 包 | E19: 10 | F19: =H19/0.85 -> 8 | G19: =H19/F19 -> 0.85 | H19: 6.8 | I19: =E19*H19 -> 68
A20: 15 | B20: 光明畅优0腹担风味发酵乳 | C20: 100g/杯 | D20: 杯 | E20: 55 | F20: =H20/0.85 -> 4.1176471 | G20: =H20/F20 -> 0.85 | H20: 3.5 | I20: =E20*H20 -> 192.5
A21: 16
A22: 17
A23: 18
A24: 19
A25: 20
A26: 21
A27: 22
A28: 23
A29: 24
A30: 25
A31: 26
A32: 27
A33: 供货合计: | B33: =SUM(I6:I32) -> 929.6
A34: 金额大写： | B34: =B33 -> 929.6
A35: 制表人 ：樊君丽 收货人： 送货人：

Sheet 21
A1: 武汉康恩农贸发展有限公司送货单
A3: 收货单位： | B3: 汉南数智化检测分公司
A4: 配送日期： | B4: 45128
A5: 序号 | B5: 名称 | C5: 规格 | D5: 单位 | E5: 数量 | F5: 超市价格 | G5: 折扣率 | H5: 折后价 | I5: 折后金额 | J5: 备注
A6: 1 | B6: （新鲜）河粉 | D6: 斤 | E6: 2 | F6: =H6/0.85 -> 3.5294118 | G6: =H6/F6 -> 0.85 | H6: 3 | I6: =E6*H6 -> 6
A7: 2 | B7: 熟凉面 | D7: 斤 | E7: 2 | F7: =H7/0.85 -> 4.1176471 | G7: =H7/F7 -> 0.85 | H7: 3.5 | I7: =E7*H7 -> 7
A8: 3 | B8: 青豆角 | D8: 斤 | E8: 10 | F8: =H8/0.85 -> 5.2941176 | G8: =H8/F8 -> 0.85 | H8: 4.5 | I8: =E8*H8 -> 45
A9: 4 | B9: 大土豆 | D9: 斤 | E9: 12 | F9: =H9/0.85 -> 4.1176471 | G9: =H9/F9 -> 0.85 | H9: 3.5 | I9: =E9*H9 -> 42
A10: 5 | B10: 红椒 | D10: 斤 | E10: 2 | F10: =H10/0.85 -> 9.1764706 | G10: =H10/F10 -> 0.85 | H10: 7.8 | I10: =E10*H10 -> 15.6
A11: 6 | B11: 芜湖青椒 | D11: 斤 | E11: 2 | F11: =H11/0.85 -> 4.4705882 | G11: =H11/F11 -> 0.85 | H11: 3.8 | I11: =E11*H11 -> 7.6
A12: 7 | B12: 平菇 | D12: 斤 | E12: 4 | F12: =H12/0.85 -> 9.1764706 | G12: =H12/F12 -> 0.85 | H12: 7.8 | I12: =E12*H12 -> 31.2
A13: 8 | B13: 小白菜 | D13: 斤 | E13: 10 | F13: =H13/0.85 -> 3.2941176 | G13: =H13/F13 -> 0.85 | H13: 2.8 | I13: =E13*H13 -> 28
A14: 9 | B14: 麒麟西瓜 | D14: 斤 | E14: 39.48 | F14: =H14/0.85 -> 5.6470588 | G14: =H14/F14 -> 0.85 | H14: 4.8 | I14: =E14*H14 -> 189.504
A15: 10 | B15: 厚干子 | D15: 斤 | E15: 4 | F15: =H15/0.85 -> 8 | G15: =H15/F15 -> 0.85 | H15: 6.8 | I15: =E15*H15 -> 27.2
A16: 11 | B16: 熟鹌鹑蛋 | D16: 斤 | E16: 4 | F16: =H16/0.85 -> 16.235294 | G16: =H16/F16 -> 0.85 | H16: 13.8 | I16: =E16*H16 -> 55.2
A17: 12 | B17: 【鲜】精品五花 | D17: 斤 | E17: 10 | F17: =H17/0.85 -> 20 | G17: =H17/F17 -> 0.85 | H17: 17 | I17: =E17*H17 -> 170
... A19: 16 | B19: 【鲜】猪肝 | D19: 斤 | E19: 3 | F19: =H19/0.85 -> 11.764706 | G19: =H19/F19 -> 0.85 | H19: 10 | I19: =E19*H19 -> 30
A20: 17 | B20: 南德调味料 | C20: 150g*46袋 | D20: 袋 | E20: 3 | F20: =H20/0.85 -> 8 | G20: =H20/F20 -> 0.85 | H20: 6.8 | I20: =E20*H20 -> 20.4
A21: 18 | B21: 王守义麻辣鲜 | C21: 102g | D21: 包 | E21: 3 | F21: =H21/0.85 -> 6.8235294 | G21: =H21/F21 -> 0.85 | H21: 5.8 | I21: =E21*H21 -> 17.4
A22: 19 | B22: 小丑娃花椒粉 | C22: 30g*28袋/件 | D22: 袋 | E22: 20 | F22: =H22/0.85 -> 5.2941176 | G22: =H22/F22 -> 0.85 | H22: 4.5 | I22: =E22*H22 -> 90
A23: 20 | B23: 光明畅优0腹担风味发酵乳 | C23: 100g/杯 | D23: 杯 | E23: 55 | F23: =H23/0.85 -> 4.1176471 | G23: =H23/F23 -> 0.85 | H23: 3.5 | I23: =E23*H23 -> 192.5
A24: 22
A25: 23
A26: 24
A27: 25
A28: 26
A29: 27
A30: 28
A31: 供货合计: | B31: =SUM(I6:I30) -> 1094.604
A32: 金额大写： | B32: =B31 -> 1094.604
A33: 制表人 ：樊君丽 收货人： 送货人：

Sheet 24
A1: 武汉康恩农贸发展有限公司送货单
A3: 收货单位： | B3: 汉南数智化检测分公司
A4: 配送日期： | B4: 45131
A5: 序号 | B5: 名称 | C5: 规格 | D5: 单位 | E5: 数量 | F5: 超市价格 | G5: 折扣率 | H5: 折后价 | I5: 折后金额 | J5: 备注
A6: 1 | B6: 宽粉 | D6: 斤 | E6: 4 | F6: =H6/0.85 -> 3.5294118 | G6: =H6/F6 -> 0.85 | H6: 3 | I6: =E6*H6 -> 12
A7: 2 | B7: 热干面（熟） | D7: 斤 | E7: 4 | F7: =H7/0.85 -> 4.1176471 | G7: =H7/F7 -> 0.85 | H7: 3.5 | I7: =E7*H7 -> 14
A8: 3 | B8: 熟凉面 | D8: 斤 | E8: 2 | F8: =H8/0.85 -> 4.1176471 | G8: =H8/F8 -> 0.85 | H8: 3.5 | I8: =E8*H8 -> 7
A9: 4 | B9: 红椒 | D9: 斤 | E9: 1 | F9: =H9/0.85 -> 9.1764706 | G9: =H9/F9 -> 0.85 | H9: 7.8 | I9: =E9*H9 -> 7.8
A10: 5 | B10: 芜湖青椒 | D10: 斤 | E10: 1 | F10: =H10/0.85 -> 4.4705882 | G10: =H10/F10 -> 0.85 | H10: 3.8 | I10: =E10*H10 -> 3.8
A11: 6 | B11: 韭菜 | D11: 斤 | E11: 4 | F11: =H11/0.85 -> 4.1176471 | G11: =H11/F11 -> 0.85 | H11: 3.5 | I11: =E11*H11 -> 14
A12: 7 | B12: 细土芹 | D12: 斤 | E12: 2 | F12: =H12/0.85 -> 6.4705882 | G12: =H12/F12 -> 0.85 | H12: 5.5 | I12: =E12*H12 -> 11
A13: 8 | B13: 油麦菜 | D13: 斤 | E13: 12 | F13: =H13/0.85 -> 4.1176471 | G13: =H13/F13 -> 0.85 | H13: 3.5 | I13: =E13*H13 -> 42
A14: 9 | B14: 麒麟西瓜 | D14: 斤 | E14: 38 | F14: =H14/0.85 -> 4.4705882 | G14: =H14/F14 -> 0.85 | H14: 3.8 | I14: =E14*H14 -> 144.4
A15: 10 | B15: 厚干子 | D15: 斤 | E15: 7 | F15: =H15/0.85 -> 8 | G15: =H15/F15 -> 0.85 | H15: 6.8 | I15: =E15*H15 -> 47.6
A16: 11 | B16: 嫩豆腐 | D16: 斤 | E16: 12 | F16: =H16/0.85 -> 4.1176471 | G16: =H16/F16 -> 0.85 | H16: 3.5 | I16: =E16*H16 -> 42
A17: 12 | B17: 皮蛋 | C17: 180个/件 | D17: 个 | E17: 60 | F17: =H17/0.85 -> 2.1176471 | G17: =H17/F17 -> 0.85 | H17: 1.8 | I17: =E17*H17 -> 108
A18: 13 | B18: 【鲜】五花肉沫 | D18: 斤 | E18: 14 | F18: =H18/0.85 -> 17.647059 | G18: =H18/F18 -> 0.85 | H18: 15 | I18: =E18*H18 -> 210
A19: 14 | B19: 【鲜】猪瘦肉丝 | D19: 斤 | E19: 2 | F19: =H19/0.85 -> 23.529412 | G19: =H19/F19 -> 0.85 | H19: 20 | I19: =E19*H19 -> 40
A20: 15 | B20: 白砂糖 | D20: 斤 | E20: 5 | F20: =H20/0.85 -> 5.7647059 | G20: =H20/F20 -> 0.85 | H20: 4.9 | I20: =E20*H20 -> 24.5
A21: 16 | B21: 干辣椒节 | C21: 散称 | D21: 斤 | E21: 5 | F21: =H21/0.85 -> 30.588235 | G21: =H21/F21 -> 0.85 | H21: 26 | I21: =E21*H21 -> 130
A22: 17 | B22: 鑫海贸紫菜50g | C22: 50g*48包 | D22: 包 | E22: 5 | F22: =H22/0.85 -> 8 | G22: =H22/F22 -> 0.85 | H22: 6.8 | I22: =E22*H22 -> 34
A23: 18 | B23: 芝麻酱 | C23: 散称 | D23: 斤 | E23: 10 | F23: =H23/0.85 -> 14.117647 | G23: =H23/F23 -> 0.85 | H23: 12 | I23: =E23*H23 -> 120
A24: 19 | B24: 卤牛肉 | D24: 斤 | E24: 5 | F24: =H24/0.85 -> 103.52941 | G24: =H24/F24 -> 0.85 | H24: 88 | I24: =E24*H24 -> 440
A25: 20 | B25: 宣乐红丁 | C25: 13斤/件 | D25: 件 | E25: 1 | F25: =H25/0.85 -> 52.941176 | G25: =H25/F25 -> 0.85 | H25: 45 | I25: =E25*H25 -> 45
A26: 21 | B26: 永超榨菜 | C26: 8斤 | D26: 件 | E26: 1 | F26: =H26/0.85 -> 64.705882 | G26: =H26/F26 -> 0.85 | H26: 55 | I26: =E26*H26 -> 55
A27: 22 | B27: 正和珍珠糯米 | C27: 50斤/袋 | D27: 斤 | E27: 10 | F27: =H27/0.85 -> 5.7647059 | G27: =H27/F27 -> 0.85 | H27: 4.9 | I27: =E27*H27 -> 49
A28: 23 | B28: 光明畅优0腹担风味发酵乳 | C28: 100g/杯 | D28: 杯 | E28: 55 | F28: =H28/0.85 -> 4.1176471 | G28: =H28/F28 -> 0.85 | H28: 3.5 | I28: =E28*H28 -> 192.5
A29: 24
A30: 供货合计: | B30: =SUM(I6:I29) -> 1793.6
A31: 金额大写： | B31: =B30 -> 1793.6
A32: 制表人 ：樊君丽 收货人： 送货人：

Sheet 25
A1: 武汉康恩农贸发展有限公司送货单
A3: 收货单位： | B3: 汉南数智化检测分公司
A4: 配送日期： | B4: 45132
A5: 序号 | B5: 名称 | C5: 规格 | D5: 单位 | E5: 数量 | F5: 超市价格 | G5: 折扣率 | H5: 折后价 | I5: 折后金额 | J5: 备注
A6: 1 | B6: （新鲜）河粉 | D6: 斤 | E6: 3 | F6: =H6/0.85 -> 3.5294118 | G6: =H6/F6 -> 0.85 | H6: 3 | I6: =E6*H6 -> 9
A7: 2 | B7: 大圆皮 | D7: 斤 | E7: 2 | F7: =H7/0.85 -> 4.7058824 | G7: =H7/F7 -> 0.85 | H7: 4 | I7: =E7*H7 -> 8
A8: 3 | B8: 热干面（熟） | D8: 斤 | E8: 3 | F8: =H8/0.85 -> 4.1176471 | G8: =H8/F8 -> 0.85 | H8: 3.5 | I8: =E8*H8 -> 10.5
A9: 4 | B9: 大葱 | D9: 斤 | E9: 2 | F9: =H9/0.85 -> 4.1176471 | G9: =H9/F9 -> 0.85 | H9: 3.5 | I9: =E9*H9 -> 7
A10: 5 | B10: 菱角米（去壳） | D10: 斤 | E10: 8 | F10: =H10/0.85 -> 21.176471 | G10: =H10/F10 -> 0.85 | H10: 18 | I10: =E10*H10 -> 144
A11: 6 | B11: 青豆角 | D11: 斤 | E11: 5 | F11: =H11/0.85 -> 5.2941176 | G11: =H11/F11 -> 0.85 | H11: 4.5 | I11: =E11*H11 -> 22.5
A12: 7 | B12: 红椒 | D12: 斤 | E12: 3 | F12: =H12/0.85 -> 9.1764706 | G12: =H12/F12 -> 0.85 | H12: 7.8 | I12: =E12*H12 -> 23.4
A13: 8 | B13: 芜湖青椒 | D13: 斤 | E13: 3 | F13: =H13/0.85 -> 4.4705882 | G13: =H13/F13 -> 0.85 | H13: 3.8 | I13: =E13*H13 -> 11.4
A14: 9 | B14: 西红柿 | D14: 斤 | E14: 5 | F14: =H14/0.85 -> 4.4705882 | G14: =H14/F14 -> 0.85 | H14: 3.8 | I14: =E14*H14 -> 19
A15: 10 | B15: 紫长茄子（细长） | D15: 斤 | E15: 5 | F15: =H15/0.85 -> 4.4705882 | G15: =H15/F15 -> 0.85 | H15: 3.8 | I15: =E15*H15 -> 19
A16: 11 | B16: 鲜香菇 | D16: 斤 | E16: 2 | F16: =H16/0.85 -> 11.529412 | G16: =H16/F16 -> 0.85 | H16: 9.8 | I16: =E16*H16 -> 19.6
A17: 12 | B17: 大白菜 | D17: 斤 | E17: 12 | F17: =H17/0.85 -> 2.3529412 | G17: =H17/F17 -> 0.85 | H17: 2 | I17: =E17*H17 -> 24
A18: 13 | B18: 麒麟西瓜 | D18: 斤 | E18: 38 | F18: =H18/0.85 -> 4.4705882 | G18: =H18/F18 -> 0.85 | H18: 3.8 | I18: =E18*H18 -> 144.4
A19: 14 | B19: 红壳鸡蛋 | C19: 12板/件 | D19: 件 | E19: 1 | F19: =H19/0.85 -> 352.94118 | G19: =H19/F19 -> 0.85 | H19: 300 | I19: =E19*H19 -> 300
A20: 15 | B20: 【鲜】牛腩 | D20: 斤 | E20: 8 | F20: =H20/0.85 -> 56.470588 | G20: =H20/F20 -> 0.85 | H20: 48 | I20: =E20*H20 -> 384
A21: 16 | B21: 【鲜】猪脊骨 | D21: 斤 | E21: 6 | F21: =H21/0.85 -> 15.294118 | G21: =H21/F21 -> 0.85 | H21: 13 | I21: =E21*H21 -> 78
A22: 17 | B22: 【鲜】净黄骨鱼 | D22: 斤 | E22: 3 | F22: =H22/0.85 -> 28.235294 | G22: =H22/F22 -> 0.85 | H22: 24 | I22: =E22*H22 -> 72
A23: 18 | B23: 白砂糖 | D23: 斤 | E23: 5 | F23: =H23/0.85 -> 5.7647059 | G23: =H23/F23 -> 0.85 | H23: 4.9 | I23: =E23*H23 -> 24.5
A24: 19 | B24: 干桂林米粉 | D24: 斤 | E24: 6 | F24: =H24/0.85 -> 5.2941176 | G24: =H24/F24 -> 0.85 | H24: 4.5 | I24: =E24*H24 -> 27
A25: 20 | B25: 水发海带头 | C25: 18斤/件 | D25: 斤 | E25: 6 | F25: =H25/0.85 -> 9.4117647 | G25: =H25/F25 -> 0.85 | H25: 8 | I25: =E25*H25 -> 48
A26: 21 | B26: 鲁花压榨玉米油 | C26: 5L*4壶/件 | D26: 件 | E26: 2 | F26: =H26/0.85 -> 500 | G26: =H26/F26 -> 0.85 | H26: 425 | I26: =E26*H26 -> 850
A27: 22 | B27: 光明畅优0腹担风味发酵乳 | C27: 100g/杯 | D27: 杯 | E27: 55 | F27: =H27/0.85 -> 4.1176471 | G27: =H27/F27 -> 0.85 | H27: 3.5 | I27: =E27*H27 -> 192.5
A28: 23 | B28: 缅甸香米25kg | C28: 25kg | D28: 袋 | E28: 1 | F28: =H28/0.85 -> 247.05882 | G28: =H28/F28 -> 0.85 | H28: 210 | I28: =E28*H28 -> 210
A29: 24
A30: 25
A31: 供货合计: | B31: =SUM(I6:I30) -> 2647.8
A32: 金额大写： | B32: =B31 -> 2647.8
A33: 制表人 ：樊君丽 收货人： 送货人：

Sheet 26
A1: 武汉康恩农贸发展有限公司送货单
A3: 收货单位： | B3: 汉南数智化检测分公司
A4: 配送日期： | B4: 45133
A5: 序号 | B5: 名称 | C5: 规格 | D5: 单位 | E5: 数量 | F5: 超市价格 | G5: 折扣率 | H5: 折后价 | I5: 折后金额 | J5: 备注
A6: 1 | B6: （新鲜）河粉 | D6: 斤 | E6: 4 | F6: =H6/0.85 -> 3.5294118 | G6: =H6/F6 -> 0.85 | H6: 3 | I6: =E6*H6 -> 12
A7: 2 | B7: 馄饨皮 | D7: 斤 | E7: 2 | F7: =H7/0.85 -> 4.1176471 | G7: =H7/F7 -> 0.85 | H7: 3.5 | I7: =E7*H7 -> 7
A8: 3 | B8: 热干面（熟） | D8: 斤 | E8: 4 | F8: =H8/0.85 -> 4.1176471 | G8: =H8/F8 -> 0.85 | H8: 3.5 | I8: =E8*H8 -> 14
A9: 4 | B9: 生姜 | D9: 斤 | E9: 4 | F9: =H9/0.85 -> 15.058824 | G9: =H9/F9 -> 0.85 | H9: 12.8 | I9: =E9*H9 -> 51.2
A10: 5 | B10: 白萝卜 | D10: 斤 | E10: 12 | F10: =H10/0.85 -> 2.3529412 | G10: =H10/F10 -> 0.85 | H10: 2 | I10: =E10*H10 -> 24
A11: 6 | B11: 大土豆 | D11: 斤 | E11: 12 | F11: =H11/0.85 -> 4.1176471 | G11: =H11/F11 -> 0.85 | H11: 3.5 | I11: =E11*H11 -> 42
A12: 7 | B12: 红椒 | D12: 斤 | E12: 2 | F12: =H12/0.85 -> 9.1764706 | G12: =H12/F12 -> 0.85 | H12: 7.8 | I12: =E12*H12 -> 15.6
A13: 8 | B13: 芜湖青椒 | D13: 斤 | E13: 6 | F13: =H13/0.85 -> 4.4705882 | G13: =H13/F13 -> 0.85 | H13: 3.8 | I13: =E13*H13 -> 22.8
A14: 9 | B14: 麒麟西瓜 | D14: 斤 | E14: 42.5 | F14: =H14/0.85 -> 5.6470588 | G14: =H14/F14 -> 0.85 | H14: 4.8 | I14: =E14*H14 -> 204
A15: 10 | B15: 白色臭干子 | D15: 斤 | E15: 10 | F15: =H15/0.85 -> 8 | G15: =H15/F15 -> 0.85 | H15: 6.8 | I15: =E15*H15 -> 68
A16: 11 | B16: 【鲜】五花肉沫 | D16: 斤 | E16: 3 | F16: =H16/0.85 -> 17.647059 | G16: =H16/F16 -> 0.85 | H16: 15 | I16: =E16*H16 -> 45
A17: 12 | B17: 【鲜】猪五花肉片 | D17: 斤 | E17: 5 | F17: =H17/0.85 -> 17.647059 | G17: =H17/F17 -> 0.85 | H17: 15 | I17: =E17*H17 -> 75
... A19: 14 | B19: 山西水塔陈醋 | D19: 件 | E19: 1 | F19: =H19/0.85 -> 76.470588 | G19: =H19/F19 -> 0.85 | H19: 65 | I19: =E19*H19 -> 65
A20: 15 | B20: 孝感米酒900g | C20: 900g*6瓶/件 | D20: 瓶 | E20: 1 | F20: =H20/0.85 -> 10 | G20: =H20/F20 -> 0.85 | H20: 8.5 | I20: =E20*H20 -> 8.5
A21: 16 | B21: 粤汉码头酸梅膏 | C21: 1.2l*12瓶/件 | D21: 瓶 | E21: 2 | F21: =H21/0.85 -> 23.529412 | G21: =H21/F21 -> 0.85 | H21: 20 | I21: =E21*H21 -> 40
A22: 17 | B22: 光明畅优0腹担风味发酵乳 | C22: 100g/杯 | D22: 杯 | E22: 55 | F22: =H22/0.85 -> 4.1176471 | G22: =H22/F22 -> 0.85 | H22: 3.5 | I22: =E22*H22 -> 192.5
A23: 18
A24: 19
A25: 20
A26: 21
A27: 22
A28: 23
A29: 24
A30: 25
A31: 26
A32: 27
A33: 28
A34: 供货合计: | B34: =SUM(I6:I33) -> 1079.8
A35: 金额大写： | B35: =B34 -> 1079.8
A36: 制表人 ：樊君丽 收货人： 送货人：

Sheet 27
A1: 武汉康恩农贸发展有限公司送货单
A3: 收货单位： | B3: 汉南数智化检测分公司
A4: 配送日期： | B4: 45134
A5: 序号 | B5: 名称 | C5: 规格 | D5: 单位 | E5: 数量 | F5: 超市价格 | G5: 折扣率 | H5: 折后价 | I5: 折后金额 | J5: 备注
A6: 1 | B6: （新鲜）河粉 | D6: 斤 | E6: 4 | F6: =H6/0.85 -> 3.5294118 | G6: =H6/F6 -> 0.85 | H6: 3 | I6: =E6*H6 -> 12
A7: 2 | B7: 馄饨皮 | D7: 斤 | E7: 1 | F7: =H7/0.85 -> 4.1176471 | G7: =H7/F7 -> 0.85 | H7: 3.5 | I7: =E7*H7 -> 3.5
A8: 3 | B8: 热干面（熟） | D8: 斤 | E8: 3 | F8: =H8/0.85 -> 4.1176471 | G8: =H8/F8 -> 0.85 | H8: 3.5 | I8: =E8*H8 -> 10.5
A9: 4 | B9: 熟凉面 | D9: 斤 | E9: 2 | F9: =H9/0.85 -> 4.1176471 | G9: =H9/F9 -> 0.85 | H9: 3.5 | I9: =E9*H9 -> 7
A10: 5 | B10: 小葱 | D10: 斤 | E10: 2 | F10: =H10/0.85 -> 8 | G10: =H10/F10 -> 0.85 | H10: 6.8 | I10: =E10*H10 -> 13.6
A11: 6 | B11: 红椒 | D11: 斤 | E11: 2 | F11: =H11/0.85 -> 9.1764706 | G11: =H11/F11 -> 0.85 | H11: 7.8 | I11: =E11*H11 -> 15.6
A12: 7 | B12: 甜玉米棒 | D12: 个 | E12: 10 | F12: =H12/0.85 -> 2.9411765 | G12: =H12/F12 -> 0.85 | H12: 2.5 | I12: =E12*H12 -> 25
A13: 8 | B13: 铁棍山药 | D13: 斤 | E13: 4.2 | F13: =H13/0.85 -> 11.529412 | G13: =H13/F13 -> 0.85 | H13: 9.8 | I13: =E13*H13 -> 41.16
A14: 9 | B14: 芜湖青椒 | D14: 斤 | E14: 14 | F14: =H14/0.85 -> 4.4705882 | G14: =H14/F14 -> 0.85 | H14: 3.8 | I14: =E14*H14 -> 53.2
A15: 10 | B15: 生菜 | D15: 斤 | E15: 14 | F15: =H15/0.85 -> 6.4705882 | G15: =H15/F15 -> 0.85 | H15: 5.5 | I15: =E15*H15 -> 77
A16: 11 | B16: 细土芹 | D16: 斤 | E16: 8 | F16: =H16/0.85 -> 6.4705882 | G16: =H16/F16 -> 0.85 | H16: 5.5 | I16: =E16*H16 -> 44
A17: 12 | B17: 小白菜 | D17: 斤 | E17: 2 | F17: =H17/0.85 -> 3.2941176 | G17: =H17/F17 -> 0.85 | H17: 2.8 | I17: =E17*H17 -> 5.6
... A20: 15 | B20: 【鲜】五花肉沫 | D20: 斤 | E20: 9 | F20: =H20/0.85 -> 17.647059 | G20: =H20/F20 -> 0.85 | H20: 15 | I20: =E20*H20 -> 135
A21: 16 | B21: （冻）蛋挞皮 | C21: 20g*60个/袋 | D21: 袋 | E21: 2 | F21: =H21/0.85 -> 41.176471 | G21: =H21/F21 -> 0.85 | H21: 35 | I21: =E21*H21 -> 70
A22: 17 | B22: 奥利客烘焙调理奶油 | C22: 907g/12瓶/件 | D22: 瓶 | E22: 1 | F22: =H22/0.85 -> 25.882353 | G22: =H22/F22 -> 0.85 | H22: 22 | I22: =E22*H22 -> 22
A23: 18 | B23: 花生米 | C23: 散称 | D23: 斤 | E23: 2 | F23: =H23/0.85 -> 11.529412 | G23: =H23/F23 -> 0.85 | H23: 9.8 | I23: =E23*H23 -> 19.6
A24: 19 | B24: 绿豆 | C24: 25kg/件 | D24: 斤 | E24: 10 | F24: =H24/0.85 -> 8 | G24: =H24/F24 -> 0.85 | H24: 6.8 | I24: =E24*H24 -> 68
A25: 20 | B25: 无核红枣 | C25: 散称 | D25: 斤 | E25: 3 | F25: =H25/0.85 -> 21.176471 | G25: =H25/F25 -> 0.85 | H25: 18 | I25: =E25*H25 -> 54
A26: 21 | B26: 卤牛肚 | D26: 斤 | E26: 5 | F26: =H26/0.85 -> 103.52941 | G26: =H26/F26 -> 0.85 | H26: 88 | I26: =E26*H26 -> 440
A27: 22 | B27: 光明畅优0腹担风味发酵乳 | C27: 100g/杯 | D27: 杯 | E27: 40 | F27: =H27/0.85 -> 4.1176471 | G27: =H27/F27 -> 0.85 | H27: 3.5 | I27: =E27*H27 -> 140
A28: 23
A29: 24
A30: 25
A31: 26
A32: 27
A33: 28
A34: 供货合计: | B34: =SUM(I6:I33) -> 1564
A35: 金额大写： | B35: =B34 -> 1564
A36: 制表人 ：樊君丽 收货人： 送货人：
H38: =B34 -> 1564

Sheet 28
A1: 武汉康恩农贸发展有限公司送货单
A3: 收货单位： | B3: 汉南数智化检测分公司
A4: 配送日期： | B4: 45135
A5: 序号 | B5: 名称 | C5: 规格 | D5: 单位 | E5: 数量 | F5: 超市价格 | G5: 折扣率 | H5: 折后价 | I5: 折后金额 | J5: 备注
A6: 1 | B6: （新鲜）河粉 | D6: 斤 | E6: 3 | F6: =H6/0.85 -> 3.5294118 | G6: =H6/F6 -> 0.85 | H6: 3 | I6: =E6*H6 -> 9
A7: 2 | B7: 干桂林米粉 | D7: 斤 | E7: 5 | F7: =H7/0.85 -> 5.2941176 | G7: =H7/F7 -> 0.85 | H7: 4.5 | I7: =E7*H7 -> 22.5
