Workbook

Sheet 1
A1: 武汉康恩农贸发展有限公司送货单
A3: 收货单位：汉南数智化检测分公司
A4: 配送日期：2023-8-1
A5: 序号 | B5: 名称 | C5: 规格 | D5: 单位 | E5: 数量 | F5: 超市价格 | G5: 折扣率 | H5: 折后价 | I5: 折后金额 | J5: 备注
A6: 1 | B6: （新鲜）河粉 | D6: 斤 | E6: 4 | F6: =H6/0.85 -> 3.5294118 | G6: =H6/F6 -> 0.85 | H6: 3 | I6: =E6*H6 -> 12
A7: 2 | B7: 热干面（熟） | D7: 斤 | E7: 4 | F7: =H7/0.85 -> 4.1176471 | G7: =H7/F7 -> 0.85 | H7: 3.5 | I7: =E7*H7 -> 14
A8: 3 | B8: 熟凉面 | D8: 斤 | E8: 2 | F8: =H8/0.85 -> 4.1176471 | G8: =H8/F8 -> 0.85 | H8: 3.5 | I8: =E8*H8 -> 7
A9: 4 | B9: 白萝卜 | D9: 斤 | E9: 5 | F9: =H9/0.85 -> 2.3529412 | G9: =H9/F9 -> 0.85 | H9: 2 | I9: =E9*H9 -> 10
A10: 5 | B10: 大红薯 | D10: 斤 | E10: 5 | F10: =H10/0.85 -> 4.1176471 | G10: =H10/F10 -> 0.85 | H10: 3.5 | I10: =E10*H10 -> 17.5
A11: 6 | B11: 胡萝卜 | D11: 斤 | E11: 3 | F11: =H11/0.85 -> 2.9411765 | G11: =H11/F11 -> 0.85 | H11: 2.5 | I11: =E11*H11 -> 7.5
A12: 7 | B12: 甜玉米棒 | D12: 个 | E12: 7 | F12: =H12/0.85 -> 3.5294118 | G12: =H12/F12 -> 0.85 | H12: 3 | I12: =E12*H12 -> 21
A13: 8 | B13: 黄瓜 | D13: 斤 | E13: 5.2 | F13: =H13/0.85 -> 3.2941176 | G13: =H13/F13 -> 0.85 | H13: 2.8 | I13: =E13*H13 -> 14.56
A14: 9 | B14: 青丝瓜 | D14: 斤 | E14: 15.2 | F14: =H14/0.85 -> 5.2941176 | G14: =H14/F14 -> 0.85 | H14: 4.5 | I14: =E14*H14 -> 68.4
A15: 10 | B15: 生菜 | D15: 斤 | E15: 13 | F15: =H15/0.85 -> 6.4705882 | G15: =H15/F15 -> 0.85 | H15: 5.5 | I15: =E15*H15 -> 71.5
A16: 11 | B16: 细土芹 | D16: 斤 | E16: 2 | F16: =H16/0.85 -> 6.4705882 | G16: =H16/F16 -> 0.85 | H16: 5.5 | I16: =E16*H16 -> 11
A17: 12 | B17: 红壳鸡蛋 | C17: 12板/件 | D17: 件 | E17: 1 | F17: =H17/0.85 -> 352.94118 | G17: =H17/F17 -> 0.85 | H17: 300 | I17: =E17*H17 -> 300
A18: 13 | B18: 【鲜】五花肉沫 | D18: 斤 | E18: 2 | F18: =H18/0.85 -> 19.764706 | G18: =H18/F18 -> 0.85 | H18: 16.8 | I18: =E18*H18 -> 33.6
A19: 14 | B19: 【鲜】猪脊骨 | D19: 斤 | E19: 5 | F19: =H19/0.85 -> 16.470588 | G19: =H19/F19 -> 0.85 | H19: 14 | I19: =E19*H19 -> 70
A20: 15 | B20: 手撕鸡 | D20: 只 | E20: 6 | F20: =H20/0.85 -> 30.588235 | G20: =H20/F20 -> 0.85 | H20: 26 | I20: =E20*H20 -> 156
A21: 16 | B21: 鲁花压榨玉米油 | C21: 5L*4壶/件 | D21: 件 | E21: 2 | F21: =H21/0.85 -> 500 | G21: =H21/F21 -> 0.85 | H21: 425 | I21: =E21*H21 -> 850
A22: 17 | B22: 缅甸香米25kg | C22: 25kg | D22: 袋 | E22: 1 | F22: =H22/0.85 -> 247.05882 | G22: =H22/F22 -> 0.85 | H22: 210 | I22: =E22*H22 -> 210
A23: 18 | B23: 光明畅优0腹担风味发酵乳 | C23: 100g/杯 | D23: 杯 | E23: 63 | F23: =H23/0.85 -> 4.1176471 | G23: =H23/F23 -> 0.85 | H23: 3.5 | I23: =E23*H23 -> 220.5
A24: 19 | B24: 【鲜】净大草鱼 | D24: 斤 | E24: 7.75 | F24: =H24/0.85 -> 16.235294 | G24: =H24/F24 -> 0.85 | H24: 13.8 | I24: =E24*H24 -> 106.95
A25: 20
A26: 21
A27: 22
A28: 23
A29: 24
A30: 25
A31: 合计: | B31: =SUM(I6:I30) -> 2201.51
A32: 金额大写： | B32: =B31 -> 2201.51
A33: 制表人 ：樊君丽 收货人： 送货人：

Sheet 2
A1: 武汉康恩农贸发展有限公司送货单
A3: 收货单位：汉南数智化检测分公司
A4: 配送日期：2023-8-1 | B4: 45140
A5: 序号 | B5: 名称 | C5: 规格 | D5: 单位 | E5: 数量 | F5: 超市价格 | G5: 折扣率 | H5: 折后价 | I5: 折后金额 | J5: 备注
A6: 1 | B6: （新鲜）河粉 | D6: 斤 | E6: 4 | F6: =H6/0.85 -> 3.5294118 | G6: =H6/F6 -> 0.85 | H6: 3 | I6: =E6*H6 -> 12
A7: 2 | B7: 大圆皮 | D7: 斤 | E7: 2 | F7: =H7/0.85 -> 4.7058824 | G7: =H7/F7 -> 0.85 | H7: 4 | I7: =E7*H7 -> 8
A8: 3 | B8: 干细粉 | C8: 散称 | D8: 斤 | E8: 5 | F8: =H8/0.85 -> 4.1176471 | G8: =H8/F8 -> 0.85 | H8: 3.5 | I8: =E8*H8 -> 17.5
A9: 4 | B9: 热干面（熟） | D9: 斤 | E9: 4 | F9: =H9/0.85 -> 4.1176471 | G9: =H9/F9 -> 0.85 | H9: 3.5 | I9: =E9*H9 -> 14
A10: 5 | B10: 白豆角 | D10: 斤 | E10: 15 | F10: =H10/0.85 -> 7.6470588 | G10: =H10/F10 -> 0.85 | H10: 6.5 | I10: =E10*H10 -> 97.5
A11: 6 | B11: 红椒 | D11: 斤 | E11: 4 | F11: =H11/0.85 -> 9.1764706 | G11: =H11/F11 -> 0.85 | H11: 7.8 | I11: =E11*H11 -> 31.2
A12: 7 | B12: 胡萝卜 | D12: 斤 | E12: 3 | F12: =H12/0.85 -> 2.9411765 | G12: =H12/F12 -> 0.85 | H12: 2.5 | I12: =E12*H12 -> 7.5
A13: 8 | B13: 芜湖青椒 | D13: 斤 | E13: 4 | F13: =H13/0.85 -> 5.2941176 | G13: =H13/F13 -> 0.85 | H13: 4.5 | I13: =E13*H13 -> 18
A14: 9 | B14: 西红柿 | D14: 斤 | E14: 5 | F14: =H14/0.85 -> 4.4705882 | G14: =H14/F14 -> 0.85 | H14: 3.8 | I14: =E14*H14 -> 19
A15: 10 | B15: 有机花菜 | D15: 斤 | E15: 3 | F15: =H15/0.85 -> 6.4705882 | G15: =H15/F15 -> 0.85 | H15: 5.5 | I15: =E15*H15 -> 16.5
A16: 11 | B16: 大白菜 | D16: 斤 | E16: 15 | F16: =H16/0.85 -> 2.1176471 | G16: =H16/F16 -> 0.85 | H16: 1.8 | I16: =E16*H16 -> 27
A17: 12 | B17: 细土芹 | D17: 斤 | E17: 2.78 | F17: =H17/0.85 -> 6.4705882 | G17: =H17/F17 -> 0.85 | H17: 5.5 | I17: =E17*H17 -> 15.29
A18: 13 | B18: 香菜 | D18: 斤 | E18: 2 | F18: =H18/0.85 -> 10.352941 | G18: =H18/F18 -> 0.85 | H18: 8.8 | I18: =E18*H18 -> 17.6
A19: 14 | B19: 麒麟西瓜 | D19: 斤 | E19: 38.7 | F19: =H19/0.85 -> 4.1176471 | G19: =H19/F19 -> 0.85 | H19: 3.5 | I19: =E19*H19 -> 135.45
A20: 15 | B20: 净大财鱼 | C20: 3斤以上 | D20: 斤 | E20: 3 | F20: =H20/0.85 -> 29.411765 | G20: =H20/F20 -> 0.85 | H20: 25 | I20: =E20*H20 -> 75
A21: 16 | B21: 【冻】思念白糯小汤圆（无馅） | C21: 500g*20包/件 | D21: 袋 | E21: 2 | F21: =H21/0.85 -> 10.588235 | G21: =H21/F21 -> 0.85 | H21: 9 | I21: =E21*H21 -> 18
A22: 17 | B22: 旺食堂蒙古肉 | C22: 500g*24袋 | D22: 袋 | E22: 13 | F22: =H22/0.85 -> 14.117647 | G22: =H22/F22 -> 0.85 | H22: 12 | I22: =E22*H22 -> 156
A23: 18 | B23: 海天金标生抽1.9L | C23: 1.9L*6壶/件 | D23: 箱 | E23: 1 | F23: =H23/0.85 -> 152.94118 | G23: =H23/F23 -> 0.85 | H23: 130 | I23: =E23*H23 -> 130
A24: 19 | B24: 盐渍海带丝 | C24: 18斤/件 | D24: 斤 | E24: 14 | F24: =H24/0.85 -> 9.1764706 | G24: =H24/F24 -> 0.85 | H24: 7.8 | I24: =E24*H24 -> 109.2
A25: 20 | B25: 百事可乐2L | C25: 2L*6瓶 | D25: 件 | E25: 1 | F25: =H25/0.85 -> 52.941176 | G25: =H25/F25 -> 0.85 | H25: 45 | I25: =E25*H25 -> 45
A26: 21 | B26: 光明畅优0腹担风味发酵乳 | C26: 100g/杯 | D26: 杯 | E26: 46 | F26: =H26/0.85 -> 4.1176471 | G26: =H26/F26 -> 0.85 | H26: 3.5 | I26: =E26*H26 -> 161
A27: 22
A28: 23
A29: 24
A30: 25
A31: 26
A32: 27
A33: 28
A34: 合计: | B34: =SUM(I6:I33) -> 1130.74
A35: 金额大写： | B35: =B34 -> 1130.74
A36: 制表人 ：樊君丽 收货人： 送货人：

Sheet 3
A1: 武汉康恩农贸发展有限公司送货单
A3: 收货单位： | B3: 汉南数智化检测分公司
A4: 配送日期： | B4: 45141
A5: 序号 | B5: 名称 | C5: 规格 | D5: 单位 | E5: 数量 | F5: 超市价格 | G5: 折扣率 | H5: 折后价 | I5: 折后金额 | J5: 备注
A6: 1 | B6: （新鲜）河粉 | D6: 斤 | E6: 4 | F6: =H6/0.85 -> 3.5294118 | G6: =H6/F6 -> 0.85 | H6: 3 | I6: =E6*H6 -> 12
A7: 2 | B7: 热干面（熟） | D7: 斤 | E7: 4 | F7: =H7/0.85 -> 4.1176471 | G7: =H7/F7 -> 0.85 | H7: 3.5 | I7: =E7*H7 -> 14
A8: 3 | B8: 大葱 | D8: 斤 | E8: 1 | F8: =H8/0.85 -> 4.1176471 | G8: =H8/F8 -> 0.85 | H8: 3.5 | I8: =E8*H8 -> 3.5
A9: 4 | B9: 大土豆 | D9: 斤 | E9: 10 | F9: =H9/0.85 -> 4.1176471 | G9: =H9/F9 -> 0.85 | H9: 3.5 | I9: =E9*H9 -> 35
A10: 5 | B10: 红椒 | D10: 斤 | E10: 4 | F10: =H10/0.85 -> 9.1764706 | G10: =H10/F10 -> 0.85 | H10: 7.8 | I10: =E10*H10 -> 31.2
A11: 6 | B11: 藕带 | D11: 斤 | E11: 17 | F11: =H11/0.85 -> 17.411765 | G11: =H11/F11 -> 0.85 | H11: 14.8 | I11: =E11*H11 -> 251.6
A12: 7 | B12: 芜湖青椒 | D12: 斤 | E12: 4 | F12: =H12/0.85 -> 5.2941176 | G12: =H12/F12 -> 0.85 | H12: 4.5 | I12: =E12*H12 -> 18
A13: 8 | B13: 有机花菜 | D13: 斤 | E13: 16 | F13: =H13/0.85 -> 6.4705882 | G13: =H13/F13 -> 0.85 | H13: 5.5 | I13: =E13*H13 -> 88
A14: 9 | B14: 冬瓜 | D14: 斤 | E14: 8 | F14: =H14/0.85 -> 2.9411765 | G14: =H14/F14 -> 0.85 | H14: 2.5 | I14: =E14*H14 -> 20
A15: 10 | B15: 麒麟西瓜 | D15: 斤 | E15: 42 | F15: =H15/0.85 -> 4.1176471 | G15: =H15/F15 -> 0.85 | H15: 3.5 | I15: =E15*H15 -> 147
A16: 11 | B16: 嫩豆腐 | D16: 斤 | E16: 16 | F16: =H16/0.85 -> 4.1176471 | G16: =H16/F16 -> 0.85 | H16: 3.5 | I16: =E16*H16 -> 56
A17: 12 | B17: 【鲜】净麻鸭 | D17: 斤 | E17: 18 | F17: =H17/0.85 -> 25.882353 | G17: =H17/F17 -> 0.85 | H17: 22 | I17: =E17*H17 -> 396
... A19: 14 | B19: 【鲜】猪通排骨 | D19: 斤 | E19: 6 | F19: =H19/0.85 -> 30.588235 | G19: =H19/F19 -> 0.85 | H19: 26 | I19: =E19*H19 -> 156
A20: 15 | B20: 奥利客烘焙调理奶油 | C20: 907g/12瓶/件 | D20: 瓶 | E20: 2 | F20: =H20/0.85 -> 25.882353 | G20: =H20/F20 -> 0.85 | H20: 22 | I20: =E20*H20 -> 44
A21: 16 | B21: 红花椒 | D21: 斤 | E21: 3 | F21: =H21/0.85 -> 103.52941 | G21: =H21/F21 -> 0.85 | H21: 88 | I21: =E21*H21 -> 264
A22: 17 | B22: 梦诺苹果汁 | C22: 1L | D22: 瓶 | E22: 6 | F22: =H22/0.85 -> 21.176471 | G22: =H22/F22 -> 0.85 | H22: 18 | I22: =E22*H22 -> 108
A23: 18 | B23: 孝感米酒900g | C23: 900g*6瓶/件 | D23: 瓶 | E23: 1 | F23: =H23/0.85 -> 10 | G23: =H23/F23 -> 0.85 | H23: 8.5 | I23: =E23*H23 -> 8.5
A24: 19 | B24: 百事可乐2L | C24: 2L*6瓶 | D24: 件 | E24: 2 | F24: =H24/0.85 -> 52.941176 | G24: =H24/F24 -> 0.85 | H24: 45 | I24: =E24*H24 -> 90
A25: 20 | B25: 娃哈哈桶装水 | C25: 16.8L | D25: 桶 | E25: 3 | F25: =H25/0.85 -> 25.882353 | G25: =H25/F25 -> 0.85 | H25: 22 | I25: =E25*H25 -> 66
A26: 21 | B26: 光明畅优0腹担风味发酵乳 | C26: 100g/杯 | D26: 杯 | E26: 58 | F26: =H26/0.85 -> 4.1176471 | G26: =H26/F26 -> 0.85 | H26: 3.5 | I26: =E26*H26 -> 203
A27: 22
A28: 23
A29: 24
A30: 25
A31: 26
A32: 27
A33: 28
A34: 供货合计: | B34: =SUM(I6:I33) -> 2095.8
A35: 金额大写： | B35: =B34 -> 2095.8
A36: 制表人 ：樊君丽 收货人： 送货人：

Sheet 4
A1: 武汉康恩农贸发展有限公司送货单
A3: 收货单位： | B3: 汉南数智化检测分公司
A4: 配送日期： | B4: 45142
A5: 序号 | B5: 名称 | C5: 规格 | D5: 单位 | E5: 数量 | F5: 超市价格 | G5: 折扣率 | H5: 折后价 | I5: 折后金额 | J5: 备注
A6: 1 | B6: （新鲜）河粉 | D6: 斤 | E6: 4 | F6: =H6/0.85 -> 3.5294118 | G6: =H6/F6 -> 0.85 | H6: 3 | I6: =E6*H6 -> 12
A7: 2 | B7: 热干面（熟） | D7: 斤 | E7: 4 | F7: =H7/0.85 -> 4.1176471 | G7: =H7/F7 -> 0.85 | H7: 3.5 | I7: =E7*H7 -> 14
A8: 3 | B8: 红皮洋葱 | D8: 斤 | E8: 3 | F8: =H8/0.85 -> 2.9411765 | G8: =H8/F8 -> 0.85 | H8: 2.5 | I8: =E8*H8 -> 7.5
A9: 4 | B9: 白豆角 | D9: 斤 | E9: 6 | F9: =H9/0.85 -> 7.6470588 | G9: =H9/F9 -> 0.85 | H9: 6.5 | I9: =E9*H9 -> 39
A10: 5 | B10: 黄豆芽 | D10: 斤 | E10: 10 | F10: =H10/0.85 -> 2.9411765 | G10: =H10/F10 -> 0.85 | H10: 2.5 | I10: =E10*H10 -> 25
A11: 6 | B11: 青豆角 | D11: 斤 | E11: 4 | F11: =H11/0.85 -> 5.2941176 | G11: =H11/F11 -> 0.85 | H11: 4.5 | I11: =E11*H11 -> 18
A12: 7 | B12: 红椒 | D12: 斤 | E12: 3 | F12: =H12/0.85 -> 9.1764706 | G12: =H12/F12 -> 0.85 | H12: 7.8 | I12: =E12*H12 -> 23.4
A13: 8 | B13: 青椒 | D13: 斤 | E13: 3 | F13: =H13/0.85 -> 4.1176471 | G13: =H13/F13 -> 0.85 | H13: 3.5 | I13: =E13*H13 -> 10.5
A14: 9 | B14: 紫长茄子（细长） | D14: 斤 | E14: 12 | F14: =H14/0.85 -> 4.4705882 | G14: =H14/F14 -> 0.85 | H14: 3.8 | I14: =E14*H14 -> 45.6
A15: 10 | B15: 青丝瓜 | D15: 斤 | E15: 4 | F15: =H15/0.85 -> 5.2941176 | G15: =H15/F15 -> 0.85 | H15: 4.5 | I15: =E15*H15 -> 18
A16: 11 | B16: 口蘑 | D16: 斤 | E16: 5 | F16: =H16/0.85 -> 13.882353 | G16: =H16/F16 -> 0.85 | H16: 11.8 | I16: =E16*H16 -> 59
A17: 12 | B17: 韭菜 | D17: 斤 | E17: 3 | F17: =H17/0.85 -> 5.8823529 | G17: =H17/F17 -> 0.85 | H17: 5 | I17: =E17*H17 -> 15
... A22: 17 | B22: 白砂糖 | D22: 斤 | E22: 5 | F22: =H22/0.85 -> 5.7647059 | G22: =H22/F22 -> 0.85 | H22: 4.9 | I22: =E22*H22 -> 24.5
A23: 18 | B23: 蒸肉白米粉(细） | C23: 散称 | D23: 斤 | E23: 5 | F23: =H23/0.85 -> 5.2941176 | G23: =H23/F23 -> 0.85 | H23: 4.5 | I23: =E23*H23 -> 22.5
A24: 19 | B24: 光明畅优0腹担风味发酵乳 | C24: 100g/杯 | D24: 杯 | E24: 50 | F24: =H24/0.85 -> 4.1176471 | G24: =H24/F24 -> 0.85 | H24: 3.5 | I24: =E24*H24 -> 175
A25: 20 | B25: 小葱 | D25: 斤 | E25: 2 | F25: =H25/0.85 -> 8 | G25: =H25/F25 -> 0.85 | H25: 6.8 | I25: =E25*H25 -> 13.6
A26: 21 | B26: 甜玉米棒 | D26: 个 | E26: 7 | F26: =H26/0.85 -> 3.5294118 | G26: =H26/F26 -> 0.85 | H26: 3 | I26: =E26*H26 -> 21
A27: 22 | B27: 平菇 | D27: 斤 | E27: 1 | F27: =H27/0.85 -> 9.1764706 | G27: =H27/F27 -> 0.85 | H27: 7.8 | I27: =E27*H27 -> 7.8
A28: 23 | B28: 熟鹌鹑蛋 | D28: 斤 | E28: 3 | F28: =H28/0.85 -> 16.235294 | G28: =H28/F28 -> 0.85 | H28: 13.8 | I28: =E28*H28 -> 41.4
A29: 24 | B29: 【鲜】猪瘦肉丝 | D29: 斤 | E29: 3 | F29: =H29/0.85 -> 25.882353 | G29: =H29/F29 -> 0.85 | H29: 22 | I29: =E29*H29 -> 66
A30: 25 | B30: 【鲜】基围虾 | D30: 斤 | E30: 8 | F30: =H30/0.85 -> 49.411765 | G30: =H30/F30 -> 0.85 | H30: 42 | I30: =E30*H30 -> 336
A31: 26 | B31: 【鲜】净黄骨鱼 | D31: 斤 | E31: 4.8 | F31: =H31/0.85 -> 28.235294 | G31: =H31/F31 -> 0.85 | H31: 24 | I31: =E31*H31 -> 115.2
A32: 27
A33: 供货合计: | B33: =SUM(I6:I32) -> 1473.95
A34: 金额大写： | B34: =B33 -> 1473.95
A35: 制表人 ：樊君丽 收货人： 送货人：

Sheet 6
A1: 武汉康恩农贸发展有限公司送货单
A3: 收货单位： | B3: 汉南数智化检测分公司
A4: 配送日期： | B4: 45144
A5: 序号 | B5: 名称 | C5: 规格 | D5: 单位 | E5: 数量 | F5: 超市价格 | G5: 折扣率 | H5: 折后价 | I5: 折后金额 | J5: 备注
A6: 1 | B6: 红椒 | D6: 斤 | E6: 2 | F6: =H6/0.85 -> 9.1764706 | G6: =H6/F6 -> 0.85 | H6: 7.8 | I6: =E6*H6 -> 15.6
A7: 2 | B7: 铁棍山药 | D7: 斤 | E7: 2.1 | F7: =H7/0.85 -> 11.529412 | G7: =H7/F7 -> 0.85 | H7: 9.8 | I7: =E7*H7 -> 20.58
A8: 3 | B8: 芜湖青椒 | D8: 斤 | E8: 2 | F8: =H8/0.85 -> 5.2941176 | G8: =H8/F8 -> 0.85 | H8: 4.5 | I8: =E8*H8 -> 9
A9: 4 | B9: 西红柿 | D9: 斤 | E9: 2 | F9: =H9/0.85 -> 4.4705882 | G9: =H9/F9 -> 0.85 | H9: 3.8 | I9: =E9*H9 -> 7.6
A10: 5 | B10: 【鲜】净大草鱼 | D10: 斤 | E10: 7 | F10: =H10/0.85 -> 16.235294 | G10: =H10/F10 -> 0.85 | H10: 13.8 | I10: =E10*H10 -> 96.6
A11: 6 | B11: 【鲜】净牛蛙 | D11: 斤 | E11: 13.4 | F11: =H11/0.85 -> 45.882353 | G11: =H11/F11 -> 0.85 | H11: 39 | I11: =E11*H11 -> 522.6
A12: 7 | B12: 1911老酸奶 | D12: 杯 | E12: 15 | F12: =H12/0.85 -> 4.1176471 | G12: =H12/F12 -> 0.85 | H12: 3.5 | I12: =E12*H12 -> 52.5
A13: 8
A14: 9
A15: 10
A16: 11
A17: 12
A18: 13
A19: 14
A20: 15
A21: 16
A22: 17
A23: 18
A24: 19
... A34: 29
A35: 供货合计: | B35: =SUM(I6:I34) -> 724.48
A36: 金额大写： | B36: =B35 -> 724.48
A37: 制表人 ：樊君丽 收货人： 送货人：
I39: =B35 -> 724.48

Sheet 7
A1: 武汉康恩农贸发展有限公司送货单
A3: 收货单位： | B3: 汉南数智化检测分公司
A4: 配送日期： | B4: 45145
A5: 序号 | B5: 名称 | C5: 规格 | D5: 单位 | E5: 数量 | F5: 超市价格 | G5: 折扣率 | H5: 折后价 | I5: 折后金额 | J5: 备注
A6: 1 | B6: （新鲜）河粉 | D6: 斤 | E6: 4 | F6: =H6/0.85 -> 3.5294118 | G6: =H6/F6 -> 0.85 | H6: 3 | I6: =E6*H6 -> 12
A7: 2 | B7: 干细粉 | C7: 散称 | D7: 斤 | E7: 5 | F7: =H7/0.85 -> 4.1176471 | G7: =H7/F7 -> 0.85 | H7: 3.5 | I7: =E7*H7 -> 17.5
A8: 3 | B8: 热干面（熟） | D8: 斤 | E8: 4 | F8: =H8/0.85 -> 4.1176471 | G8: =H8/F8 -> 0.85 | H8: 3.5 | I8: =E8*H8 -> 14
A9: 4 | B9: 烧麦皮 | D9: 斤 | E9: 2 | F9: =H9/0.85 -> 4.1176471 | G9: =H9/F9 -> 0.85 | H9: 3.5 | I9: =E9*H9 -> 7
A10: 5 | B10: 熟凉面 | D10: 斤 | E10: 2 | F10: =H10/0.85 -> 4.1176471 | G10: =H10/F10 -> 0.85 | H10: 3.5 | I10: =E10*H10 -> 7
A11: 6 | B11: 红皮洋葱 | D11: 斤 | E11: 3.3 | F11: =H11/0.85 -> 2.9411765 | G11: =H11/F11 -> 0.85 | H11: 2.5 | I11: =E11*H11 -> 8.25
A12: 7 | B12: 生姜 | D12: 斤 | E12: 4 | F12: =H12/0.85 -> 15.058824 | G12: =H12/F12 -> 0.85 | H12: 12.8 | I12: =E12*H12 -> 51.2
A13: 8 | B13: 红薯 | D13: 斤 | E13: 20 | F13: =H13/0.85 -> 4.1176471 | G13: =H13/F13 -> 0.85 | H13: 3.5 | I13: =E13*H13 -> 70
A14: 9 | B14: 红椒 | D14: 斤 | E14: 7 | F14: =H14/0.85 -> 9.1764706 | G14: =H14/F14 -> 0.85 | H14: 7.8 | I14: =E14*H14 -> 54.6
A15: 10 | B15: 甜玉米棒 | D15: 个 | E15: 7 | F15: =H15/0.85 -> 3.5294118 | G15: =H15/F15 -> 0.85 | H15: 3 | I15: =E15*H15 -> 21
A16: 11 | B16: 芜湖青椒 | D16: 斤 | E16: 7 | F16: =H16/0.85 -> 5.2941176 | G16: =H16/F16 -> 0.85 | H16: 4.5 | I16: =E16*H16 -> 31.5
A17: 12 | B17: 黄瓜 | D17: 斤 | E17: 3 | F17: =H17/0.85 -> 3.2941176 | G17: =H17/F17 -> 0.85 | H17: 2.8 | I17: =E17*H17 -> 8.4
A18: 13 | B18: 平包菜 | D18: 斤 | E18: 12 | F18: =H18/0.85 -> 2.3529412 | G18: =H18/F18 -> 0.85 | H18: 2 | I18: =E18*H18 -> 24
A19: 14 | B19: 细土芹 | D19: 斤 | E19: 3 | F19: =H19/0.85 -> 6.4705882 | G19: =H19/F19 -> 0.85 | H19: 5.5 | I19: =E19*H19 -> 16.5
... A25: 20 | B25: 【鲜】猪瘦肉丝 | D25: 斤 | E25: 8 | F25: =H25/0.85 -> 25.882353 | G25: =H25/F25 -> 0.85 | H25: 22 | I25: =E25*H25 -> 176
A26: 21 | B26: 厨师乐加鲜味精 | C26: 2.27kg*10袋/件 | D26: 袋 | E26: 3 | F26: =H26/0.85 -> 52.941176 | G26: =H26/F26 -> 0.85 | H26: 45 | I26: =E26*H26 -> 135
A27: 22 | B27: 海天白醋 | C27: 1.9L*6壶/件 | D27: 壶 | E27: 3 | F27: =H27/0.85 -> 10 | G27: =H27/F27 -> 0.85 | H27: 8.5 | I27: =E27*H27 -> 25.5
A28: 23 | B28: 双塔龙口粉丝 | C28: 500g*24袋/件 | D28: 袋 | E28: 4 | F28: =H28/0.85 -> 15.058824 | G28: =H28/F28 -> 0.85 | H28: 12.8 | I28: =E28*H28 -> 51.2
A29: 24 | B29: 卤牛肉 | D29: 斤 | E29: 6.7 | F29: =H29/0.85 -> 103.52941 | G29: =H29/F29 -> 0.85 | H29: 88 | I29: =E29*H29 -> 589.6
A30: 25 | B30: 缅甸香米25kg | C30: 25kg | D30: 袋 | E30: 1 | F30: =H30/0.85 -> 247.05882 | G30: =H30/F30 -> 0.85 | H30: 210 | I30: =E30*H30 -> 210
A31: 26 | B31: 光明畅优0腹担风味发酵乳 | C31: 100g/杯 | D31: 杯 | E31: 55 | F31: =H31/0.85 -> 4.1176471 | G31: =H31/F31 -> 0.85 | H31: 3.5 | I31: =E31*H31 -> 192.5
A32: 27
A33: 28
A34: 供货合计: | B34: =SUM(I6:I33) -> 2608.95
A35: 金额大写： | B35: =B34 -> 2608.95
A36: 制表人 ：樊君丽 收货人： 送货人：

Sheet 8
A1: 武汉康恩农贸发展有限公司送货单
A3: 收货单位： | B3: 汉南数智化检测分公司
A4: 配送日期： | B4: 45146
A5: 序号 | B5: 名称 | C5: 规格 | D5: 单位 | E5: 数量 | F5: 超市价格 | G5: 折扣率 | H5: 折后价 | I5: 折后金额 | J5: 备注
A6: 1 | B6: （新鲜）河粉 | D6: 斤 | E6: 4 | F6: =H6/0.85 -> 3.5294118 | G6: =H6/F6 -> 0.85 | H6: 3 | I6: =E6*H6 -> 12
A7: 2 | B7: 热干面（熟） | D7: 斤 | E7: 4 | F7: =H7/0.85 -> 4.1176471 | G7: =H7/F7 -> 0.85 | H7: 3.5 | I7: =E7*H7 -> 14
A8: 3 | B8: 大葱 | D8: 斤 | E8: 2 | F8: =H8/0.85 -> 4.1176471 | G8: =H8/F8 -> 0.85 | H8: 3.5 | I8: =E8*H8 -> 7
A9: 4 | B9: 大土豆 | D9: 斤 | E9: 12 | F9: =H9/0.85 -> 4.1176471 | G9: =H9/F9 -> 0.85 | H9: 3.5 | I9: =E9*H9 -> 42
A10: 5 | B10: 红椒 | D10: 斤 | E10: 2 | F10: =H10/0.85 -> 9.1764706 | G10: =H10/F10 -> 0.85 | H10: 7.8 | I10: =E10*H10 -> 15.6
A11: 6 | B11: 芜湖青椒 | D11: 斤 | E11: 2 | F11: =H11/0.85 -> 5.2941176 | G11: =H11/F11 -> 0.85 | H11: 4.5 | I11: =E11*H11 -> 9
A12: 7 | B12: 西红柿 | D12: 斤 | E12: 4 | F12: =H12/0.85 -> 4.4705882 | G12: =H12/F12 -> 0.85 | H12: 3.8 | I12: =E12*H12 -> 15.2
A13: 8 | B13: 青苦瓜 | D13: 斤 | E13: 12 | F13: =H13/0.85 -> 4.1176471 | G13: =H13/F13 -> 0.85 | H13: 3.5 | I13: =E13*H13 -> 42
A14: 9 | B14: 鲜香菇 | D14: 斤 | E14: 8 | F14: =H14/0.85 -> 11.529412 | G14: =H14/F14 -> 0.85 | H14: 9.8 | I14: =E14*H14 -> 78.4
A15: 10 | B15: 广东菜心 | D15: 斤 | E15: 13 | F15: =H15/0.85 -> 5.2941176 | G15: =H15/F15 -> 0.85 | H15: 4.5 | I15: =E15*H15 -> 58.5
A16: 11 | B16: 【鲜】净三黄鸡 | D16: 斤 | E16: 12 | F16: =H16/0.85 -> 17.411765 | G16: =H16/F16 -> 0.85 | H16: 14.8 | I16: =E16*H16 -> 177.6
A17: 12 | B17: 【鲜】五花肉沫 | D17: 斤 | E17: 5 | F17: =H17/0.85 -> 19.764706 | G17: =H17/F17 -> 0.85 | H17: 16.8 | I17: =E17*H17 -> 84
A18: 13 | B18: 白砂糖 | D18: 斤 | E18: 5 | F18: =H18/0.85 -> 5.7647059 | G18: =H18/F18 -> 0.85 | H18: 4.9 | I18: =E18*H18 -> 24.5
A19: 14 | B19: 雪碧柠檬味汽水 | C19: 2L*6瓶/箱 | D19: 箱 | E19: 2 | F19: =H19/0.85 -> 52.941176 | G19: =H19/F19 -> 0.85 | H19: 45 | I19: =E19*H19 -> 90
A20: 15 | B20: 光明畅优0腹担风味发酵乳 | C20: 100g/杯 | D20: 杯 | E20: 40 | F20: =H20/0.85 -> 4.1176471 | G20: =H20/F20 -> 0.85 | H20: 3.5 | I20: =E20*H20 -> 140
A21: 16
A22: 17
A23: 18
A24: 19
A25: 20
A26: 21
A27: 22
A28: 23
A29: 24
A30: 25
A31: 26
A32: 27
A33: 28
A34: 供货合计: | B34: =SUM(I6:I33) -> 809.8
A35: 金额大写： | B35: =B34 -> 809.8
A36: 制表人 ：樊君丽 收货人： 送货人：

Sheet 9
A1: 武汉康恩农贸发展有限公司送货单
A3: 收货单位： | B3: 汉南数智化检测分公司
A4: 配送日期： | B4: 45147
A5: 序号 | B5: 名称 | C5: 规格 | D5: 单位 | E5: 数量 | F5: 超市价格 | G5: 折扣率 | H5: 折后价 | I5: 折后金额 | J5: 备注
A6: 1 | B6: （新鲜）河粉 | D6: 斤 | E6: 4 | F6: =H6/0.85 -> 3.5294118 | G6: =H6/F6 -> 0.85 | H6: 3 | I6: =E6*H6 -> 12
A7: 2 | B7: 干细粉 | C7: 散称 | D7: 斤 | E7: 5 | F7: =H7/0.85 -> 4.1176471 | G7: =H7/F7 -> 0.85 | H7: 3.5 | I7: =E7*H7 -> 17.5
A8: 3 | B8: 热干面（熟） | D8: 斤 | E8: 4 | F8: =H8/0.85 -> 4.1176471 | G8: =H8/F8 -> 0.85 | H8: 3.5 | I8: =E8*H8 -> 14
A9: 4 | B9: 甜玉米棒 | D9: 个 | E9: 13 | F9: =H9/0.85 -> 3.5294118 | G9: =H9/F9 -> 0.85 | H9: 3 | I9: =E9*H9 -> 39
A10: 5 | B10: 西兰花 | D10: 斤 | E10: 8 | F10: =H10/0.85 -> 8 | G10: =H10/F10 -> 0.85 | H10: 6.8 | I10: =E10*H10 -> 54.4
A11: 6 | B11: 平菇 | D11: 斤 | E11: 1 | F11: =H11/0.85 -> 9.1764706 | G11: =H11/F11 -> 0.85 | H11: 7.8 | I11: =E11*H11 -> 7.8
A12: 7 | B12: 大白菜 | D12: 斤 | E12: 13 | F12: =H12/0.85 -> 2.1176471 | G12: =H12/F12 -> 0.85 | H12: 1.8 | I12: =E12*H12 -> 23.4
A13: 8 | B13: 韭菜 | D13: 斤 | E13: 1 | F13: =H13/0.85 -> 5.8823529 | G13: =H13/F13 -> 0.85 | H13: 5 | I13: =E13*H13 -> 5
A14: 9 | B14: 麒麟西瓜 | D14: 斤 | E14: 45 | F14: =H14/0.85 -> 4.1176471 | G14: =H14/F14 -> 0.85 | H14: 3.5 | I14: =E14*H14 -> 157.5
A15: 10 | B15: 嫩豆腐 | D15: 斤 | E15: 5 | F15: =H15/0.85 -> 4.1176471 | G15: =H15/F15 -> 0.85 | H15: 3.5 | I15: =E15*H15 -> 17.5
A16: 11 | B16: 红壳鸡蛋 | C16: 12板/件 | D16: 件 | E16: 1 | F16: =H16/0.85 -> 352.94118 | G16: =H16/F16 -> 0.85 | H16: 300 | I16: =E16*H16 -> 300
A17: 12 | B17: 熟鹌鹑蛋 | D17: 斤 | E17: 3 | F17: =H17/0.85 -> 16.235294 | G17: =H17/F17 -> 0.85 | H17: 13.8 | I17: =E17*H17 -> 41.4
A18: 13 | B18: 【鲜】净三黄鸡 | D18: 斤 | E18: 6 | F18: =H18/0.85 -> 17.411765 | G18: =H18/F18 -> 0.85 | H18: 14.8 | I18: =E18*H18 -> 88.8
A19: 14 | B19: 【鲜】五花肉沫 | D19: 斤 | E19: 2 | F19: =H19/0.85 -> 19.764706 | G19: =H19/F19 -> 0.85 | H19: 16.8 | I19: =E19*H19 -> 33.6
A20: 15 | B20: 【鲜】猪肝 | D20: 斤 | E20: 1 | F20: =H20/0.85 -> 11.764706 | G20: =H20/F20 -> 0.85 | H20: 10 | I20: =E20*H20 -> 10
A21: 16 | B21: 【鲜】猪通排骨 | D21: 斤 | E21: 8 | F21: =H21/0.85 -> 30.588235 | G21: =H21/F21 -> 0.85 | H21: 26 | I21: =E21*H21 -> 208
A22: 17 | B22: 【鲜】猪血 | D22: 斤 | E22: 7 | F22: =H22/0.85 -> 5.8823529 | G22: =H22/F22 -> 0.85 | H22: 5 | I22: =E22*H22 -> 35
A23: 18 | B23: 净鳝鱼 | D23: 斤 | E23: 5 | F23: =H23/0.85 -> 76.470588 | G23: =H23/F23 -> 0.85 | H23: 65 | I23: =E23*H23 -> 325
A24: 19 | B24: 松泉青虾仁 | C24: 650g/袋*8 | D24: 袋 | E24: 6 | F24: =H24/0.85 -> 70.588235 | G24: =H24/F24 -> 0.85 | H24: 60 | I24: =E24*H24 -> 360
A25: 20 | B25: 大桥鸡精900g | C25: 900g*10袋/件 | D25: 袋 | E25: 3 | F25: =H25/0.85 -> 42.823529 | G25: =H25/F25 -> 0.85 | H25: 36.4 | I25: =E25*H25 -> 109.2
A26: 21 | B26: 劲宝超级生粉 | C26: 5kg | D26: 袋 | E26: 4 | F26: =H26/0.85 -> 97.647059 | G26: =H26/F26 -> 0.85 | H26: 83 | I26: =E26*H26 -> 332
A27: 22 | B27: 雀巢怡运奶粉 | C27: 300g*12袋 | D27: 袋 | E27: 1 | F27: =H27/0.85 -> 30.588235 | G27: =H27/F27 -> 0.85 | H27: 26 | I27: =E27*H27 -> 26
A28: 23 | B28: 重庆三五火锅底料 | C28: 300g*32袋/件 | D28: 袋 | E28: 3 | F28: =H28/0.85 -> 15.058824 | G28: =H28/F28 -> 0.85 | H28: 12.8 | I28: =E28*H28 -> 38.4
A29: 24 | B29: 迷你百事可乐 | C29: 300ml | D29: 瓶 | E29: 36 | F29: =H29/0.85 -> 2.9411765 | G29: =H29/F29 -> 0.85 | H29: 2.5 | I29: =E29*H29 -> 90
A30: 25 | B30: 迷你雪碧 | C30: 300ml | D30: 瓶 | E30: 15 | F30: =H30/0.85 -> 2.9411765 | G30: =H30/F30 -> 0.85 | H30: 2.5 | I30: =E30*H30 -> 37.5
A31: 26
A32: 供货合计: | B32: =SUM(I6:I31) -> 2383
A33: 金额大写： | B33: =B32 -> 2383
A34: 制表人 ：樊君丽 收货人： 送货人：

Sheet 10
A1: 武汉康恩农贸发展有限公司送货单
A3: 收货单位： | B3: 汉南数智化检测分公司
A4: 配送日期： | B4: 45148
A5: 序号 | B5: 名称 | C5: 规格 | D5: 单位 | E5: 数量 | F5: 超市价格 | G5: 折扣率 | H5: 折后价 | I5: 折后金额 | J5: 备注
A6: 1 | B6: （新鲜）河粉 | D6: 斤 | E6: 4 | F6: =H6/0.85 -> 3.5294118 | G6: =H6/F6 -> 0.85 | H6: 3 | I6: =E6*H6 -> 12
A7: 2 | B7: 热干面（熟） | D7: 斤 | E7: 4 | F7: =H7/0.85 -> 4.1176471 | G7: =H7/F7 -> 0.85 | H7: 3.5 | I7: =E7*H7 -> 14
A8: 3 | B8: 刀豆 | D8: 斤 | E8: 15 | F8: =H8/0.85 -> 9.1764706 | G8: =H8/F8 -> 0.85 | H8: 7.8 | I8: =E8*H8 -> 117
A9: 4 | B9: 嫩藕 | D9: 斤 | E9: 12.64 | F9: =H9/0.85 -> 8 | G9: =H9/F9 -> 0.85 | H9: 6.8 | I9: =E9*H9 -> 85.952
A10: 5 | B10: 红椒 | D10: 斤 | E10: 4 | F10: =H10/0.85 -> 9.1764706 | G10: =H10/F10 -> 0.85 | H10: 7.8 | I10: =E10*H10 -> 31.2
A11: 6 | B11: 芜湖青椒 | D11: 斤 | E11: 4 | F11: =H11/0.85 -> 5.2941176 | G11: =H11/F11 -> 0.85 | H11: 4.5 | I11: =E11*H11 -> 18
A12: 7 | B12: 西红柿 | D12: 斤 | E12: 3.3 | F12: =H12/0.85 -> 4.4705882 | G12: =H12/F12 -> 0.85 | H12: 3.8 | I12: =E12*H12 -> 12.54
A13: 8 | B13: 瓠子 | D13: 斤 | E13: 6 | F13: =H13/0.85 -> 3.2941176 | G13: =H13/F13 -> 0.85 | H13: 2.8 | I13: =E13*H13 -> 16.8
A14: 9 | B14: 韭黄 | D14: 斤 | E14: 13 | F14: =H14/0.85 -> 15.058824 | G14: =H14/F14 -> 0.85 | H14: 12.8 | I14: =E14*H14 -> 166.4
A15: 10 | B15: 【鲜】五花肉沫 | D15: 斤 | E15: 5 | F15: =H15/0.85 -> 19.764706 | G15: =H15/F15 -> 0.85 | H15: 16.8 | I15: =E15*H15 -> 84
A16: 11 | B16: 【鲜】猪肝 | D16: 斤 | E16: 7 | F16: =H16/0.85 -> 11.764706 | G16: =H16/F16 -> 0.85 | H16: 10 | I16: =E16*H16 -> 70
A17: 12 | B17: 旺食堂蒙古肉 | C17: 500g*24袋 | D17: 袋 | E17: 16 | F17: =H17/0.85 -> 14.117647 | G17: =H17/F17 -> 0.85 | H17: 12 | I17: =E17*H17 -> 192
A18: 13 | B18: 孝感米酒900g | C18: 900g*6瓶/件 | D18: 瓶 | E18: 1 | F18: =H18/0.85 -> 10 | G18: =H18/F18 -> 0.85 | H18: 8.5 | I18: =E18*H18 -> 8.5
A19: 14 | B19: 永超榨菜 | C19: 8斤 | D19: 件 | E19: 1 | F19: =H19/0.85 -> 64.705882 | G19: =H19/F19 -> 0.85 | H19: 55 | I19: =E19*H19 -> 55
A20: 15 | B20: 迷你百事可乐 | C20: 300ml | D20: 瓶 | E20: 60 | F20: =H20/0.85 -> 2.9411765 | G20: =H20/F20 -> 0.85 | H20: 2.5 | I20: =E20*H20 -> 150
A21: 16
A22: 17
A23: 18
A24: 19
A25: 20
A26: 21
A27: 22
A28: 23
A29: 24
A30: 25
A31: 26
A32: 供货合计: | B32: =SUM(I6:I31) -> 1033.392
A33: 金额大写： | B33: =B32 -> 1033.392
A34: 制表人 ：樊君丽 收货人： 送货人：

Sheet 11
A1: 武汉康恩农贸发展有限公司送货单
A3: 收货单位： | B3: 汉南数智化检测分公司
A4: 配送日期： | B4: 45149
A5: 序号 | B5: 名称 | C5: 规格 | D5: 单位 | E5: 数量 | F5: 超市价格 | G5: 折扣率 | H5: 折后价 | I5: 折后金额 | J5: 备注
A6: 1 | B6: （新鲜）河粉 | D6: 斤 | E6: 4 | F6: =H6/0.85 -> 3.5294118 | G6: =H6/F6 -> 0.85 | H6: 3 | I6: =E6*H6 -> 12
A7: 2 | B7: 饺子皮 | D7: 斤 | E7: 3 | F7: =H7/0.85 -> 4.1176471 | G7: =H7/F7 -> 0.85 | H7: 3.5 | I7: =E7*H7 -> 10.5
A8: 3 | B8: 热干面（熟） | D8: 斤 | E8: 4 | F8: =H8/0.85 -> 4.1176471 | G8: =H8/F8 -> 0.85 | H8: 3.5 | I8: =E8*H8 -> 14
A9: 4 | B9: 蒜米 | D9: 斤 | E9: 4 | F9: =H9/0.85 -> 9.1764706 | G9: =H9/F9 -> 0.85 | H9: 7.8 | I9: =E9*H9 -> 31.2
A10: 5 | B10: 白萝卜 | D10: 斤 | E10: 8 | F10: =H10/0.85 -> 2.3529412 | G10: =H10/F10 -> 0.85 | H10: 2 | I10: =E10*H10 -> 16
A11: 6 | B11: 红椒 | D11: 斤 | E11: 3 | F11: =H11/0.85 -> 9.1764706 | G11: =H11/F11 -> 0.85 | H11: 7.8 | I11: =E11*H11 -> 23.4
A12: 7 | B12: 铁棍山药 | D12: 斤 | E12: 8 | F12: =H12/0.85 -> 11.529412 | G12: =H12/F12 -> 0.85 | H12: 9.8 | I12: =E12*H12 -> 78.4
A13: 8 | B13: 芜湖青椒 | D13: 斤 | E13: 3 | F13: =H13/0.85 -> 5.2941176 | G13: =H13/F13 -> 0.85 | H13: 4.5 | I13: =E13*H13 -> 13.5
A14: 9 | B14: 鲜香菇 | D14: 斤 | E14: 10 | F14: =H14/0.85 -> 11.529412 | G14: =H14/F14 -> 0.85 | H14: 9.8 | I14: =E14*H14 -> 98
A15: 10 | B15: 生菜 | D15: 斤 | E15: 14 | F15: =H15/0.85 -> 6.4705882 | G15: =H15/F15 -> 0.85 | H15: 5.5 | I15: =E15*H15 -> 77
A16: 11 | B16: 细土芹 | D16: 斤 | E16: 2 | F16: =H16/0.85 -> 6.4705882 | G16: =H16/F16 -> 0.85 | H16: 5.5 | I16: =E16*H16 -> 11
A17: 12 | B17: 熟鹌鹑蛋 | D17: 斤 | E17: 5 | F17: =H17/0.85 -> 16.235294 | G17: =H17/F17 -> 0.85 | H17: 13.8 | I17: =E17*H17 -> 69
... A20: 15 | B20: 美都西瓜 | D20: 斤 | E20: 57 | F20: =H20/0.85 -> 4.1176471 | G20: =H20/F20 -> 0.85 | H20: 3.5 | I20: =E20*H20 -> 199.5
A21: 16
A22: 17
A23: 18
A24: 19
A25: 20
A26: 21
A27: 22
A28: 23
A29: 24
A30: 25
A31: 26
A32: 27
A33: 28
A34: 供货合计: | B34: =SUM(I6:I33) -> 965.5
A35: 金额大写： | B35: =B34 -> 965.5
A36: 制表人 ：樊君丽 收货人： 送货人：

Sheet 14
A1: 武汉康恩农贸发展有限公司送货单
A3: 收货单位： | B3: 汉南数智化检测分公司
A4: 配送日期： | B4: 45152
A5: 序号 | B5: 名称 | C5: 规格 | D5: 单位 | E5: 数量 | F5: 超市价格 | G5: 折扣率 | H5: 折后价 | I5: 折后金额 | J5: 备注
A6: 1 | B6: （新鲜）河粉 | D6: 斤 | E6: 4 | F6: =H6/0.85 -> 3.5294118 | G6: =H6/F6 -> 0.85 | H6: 3 | I6: =E6*H6 -> 12
A7: 2 | B7: 干细粉 | C7: 散称 | D7: 斤 | E7: 5 | F7: =H7/0.85 -> 4.1176471 | G7: =H7/F7 -> 0.85 | H7: 3.5 | I7: =E7*H7 -> 17.5
A8: 3 | B8: 热干面（熟） | D8: 斤 | E8: 4 | F8: =H8/0.85 -> 4.1176471 | G8: =H8/F8 -> 0.85 | H8: 3.5 | I8: =E8*H8 -> 14
A9: 4 | B9: 小葱 | D9: 斤 | E9: 1 | F9: =H9/0.85 -> 8 | G9: =H9/F9 -> 0.85 | H9: 6.8 | I9: =E9*H9 -> 6.8
A10: 5 | B10: 菱角米（去壳） | D10: 斤 | E10: 3 | F10: =H10/0.85 -> 23.529412 | G10: =H10/F10 -> 0.85 | H10: 20 | I10: =E10*H10 -> 60
A11: 6 | B11: 鲜莲子米心（手剥） | D11: 斤 | E11: 3 | F11: =H11/0.85 -> 41.176471 | G11: =H11/F11 -> 0.85 | H11: 35 | I11: =E11*H11 -> 105
A12: 7 | B12: 新鲜毛豆米 | D12: 斤 | E12: 9 | F12: =H12/0.85 -> 14.117647 | G12: =H12/F12 -> 0.85 | H12: 12 | I12: =E12*H12 -> 108
A13: 8 | B13: 大红薯 | D13: 斤 | E13: 5 | F13: =H13/0.85 -> 4.1176471 | G13: =H13/F13 -> 0.85 | H13: 3.5 | I13: =E13*H13 -> 17.5
A14: 9 | B14: 大藕 | D14: 斤 | E14: 10.5 | F14: =H14/0.85 -> 8 | G14: =H14/F14 -> 0.85 | H14: 6.8 | I14: =E14*H14 -> 71.4
A15: 10 | B15: 红椒 | D15: 斤 | E15: 4 | F15: =H15/0.85 -> 9.1764706 | G15: =H15/F15 -> 0.85 | H15: 7.8 | I15: =E15*H15 -> 31.2
A16: 11 | B16: 胡萝卜 | D16: 斤 | E16: 5 | F16: =H16/0.85 -> 2.9411765 | G16: =H16/F16 -> 0.85 | H16: 2.5 | I16: =E16*H16 -> 12.5
A17: 12 | B17: 芜湖青椒 | D17: 斤 | E17: 4 | F17: =H17/0.85 -> 5.2941176 | G17: =H17/F17 -> 0.85 | H17: 4.5 | I17: =E17*H17 -> 18
A18: 13 | B18: 西红柿 | D18: 斤 | E18: 4 | F18: =H18/0.85 -> 4.4705882 | G18: =H18/F18 -> 0.85 | H18: 3.8 | I18: =E18*H18 -> 15.2
A19: 14 | B19: 细土芹 | D19: 斤 | E19: 3 | F19: =H19/0.85 -> 6.4705882 | G19: =H19/F19 -> 0.85 | H19: 5.5 | I19: =E19*H19 -> 16.5
... A22: 17 | B22: 【鲜】五花肉沫 | D22: 斤 | E22: 6 | F22: =H22/0.85 -> 19.764706 | G22: =H22/F22 -> 0.85 | H22: 16.8 | I22: =E22*H22 -> 100.8
A23: 18 | B23: 旺食堂蒙古肉 | C23: 500g*24袋 | D23: 袋 | E23: 4 | F23: =H23/0.85 -> 14.117647 | G23: =H23/F23 -> 0.85 | H23: 12 | I23: =E23*H23 -> 48
A24: 19 | B24: 安琪酵母 | C24: 500g*20袋/件 | D24: 袋 | E24: 1 | F24: =H24/0.85 -> 29.411765 | G24: =H24/F24 -> 0.85 | H24: 25 | I24: =E24*H24 -> 25
A25: 20 | B25: 卤牛肚 | D25: 斤 | E25: 5 | F25: =H25/0.85 -> 103.52941 | G25: =H25/F25 -> 0.85 | H25: 88 | I25: =E25*H25 -> 440
A26: 21 | B26: 鲁至尊面粉 | C26: 25kg | D26: 袋 | E26: 1 | F26: =H26/0.85 -> 174.11765 | G26: =H26/F26 -> 0.85 | H26: 148 | I26: =E26*H26 -> 148
A27: 22 | B27: 光明健能酸奶180g | C27: 180g | D27: 杯 | E27: 60 | F27: =H27/0.85 -> 4.1176471 | G27: =H27/F27 -> 0.85 | H27: 3.5 | I27: =E27*H27 -> 210
A28: 23
A29: 24
A30: 25
A31: 26
A32: 27
A33: 供货合计: | B33: =SUM(I6:I32) -> 1662.9
A34: 金额大写： | B34: =B33 -> 1662.9
A35: 制表人 ：樊君丽 收货人： 送货人：

Sheet 15
A1: 武汉康恩农贸发展有限公司送货单
A3: 收货单位： | B3: 汉南数智化检测分公司
A4: 配送日期： | B4: 45153
A5: 序号 | B5: 名称 | C5: 规格 | D5: 单位 | E5: 数量 | F5: 超市价格 | G5: 折扣率 | H5: 折后价 | I5: 折后金额 | J5: 备注
A6: 1 | B6: （新鲜）河粉 | D6: 斤 | E6: 4 | F6: =H6/0.85 -> 3.5294118 | G6: =H6/F6 -> 0.85 | H6: 3 | I6: =E6*H6 -> 12
A7: 2 | B7: 大圆皮 | D7: 斤 | E7: 2 | F7: =H7/0.85 -> 4.7058824 | G7: =H7/F7 -> 0.85 | H7: 4 | I7: =E7*H7 -> 8
A8: 3 | B8: 热干面（熟） | D8: 斤 | E8: 4 | F8: =H8/0.85 -> 4.1176471 | G8: =H8/F8 -> 0.85 | H8: 3.5 | I8: =E8*H8 -> 14
A9: 4 | B9: 生姜 | D9: 斤 | E9: 5 | F9: =H9/0.85 -> 15.058824 | G9: =H9/F9 -> 0.85 | H9: 12.8 | I9: =E9*H9 -> 64
A10: 5 | B10: 青豆角 | D10: 斤 | E10: 6 | F10: =H10/0.85 -> 5.2941176 | G10: =H10/F10 -> 0.85 | H10: 4.5 | I10: =E10*H10 -> 27
A11: 6 | B11: 甜玉米棒 | D11: 个 | E11: 7 | F11: =H11/0.85 -> 3.5294118 | G11: =H11/F11 -> 0.85 | H11: 3 | I11: =E11*H11 -> 21
A12: 7 | B12: 紫长茄子（细长） | D12: 斤 | E12: 6 | F12: =H12/0.85 -> 4.4705882 | G12: =H12/F12 -> 0.85 | H12: 3.8 | I12: =E12*H12 -> 22.8
A13: 8 | B13: 青丝瓜 | D13: 斤 | E13: 5 | F13: =H13/0.85 -> 5.2941176 | G13: =H13/F13 -> 0.85 | H13: 4.5 | I13: =E13*H13 -> 22.5
A14: 9 | B14: 小白菜 | D14: 斤 | E14: 12 | F14: =H14/0.85 -> 4.1176471 | G14: =H14/F14 -> 0.85 | H14: 3.5 | I14: =E14*H14 -> 42
A15: 10 | B15: 红壳鸡蛋 | C15: 12板/件 | D15: 件 | E15: 1 | F15: =H15/0.85 -> 352.94118 | G15: =H15/F15 -> 0.85 | H15: 300 | I15: =E15*H15 -> 300
A16: 11 | B16: 【鲜】五花肉沫 | D16: 斤 | E16: 8 | F16: =H16/0.85 -> 19.764706 | G16: =H16/F16 -> 0.85 | H16: 16.8 | I16: =E16*H16 -> 134.4
A17: 12 | B17: 【鲜】猪瘦肉片 | D17: 斤 | E17: 3 | F17: =H17/0.85 -> 25.882353 | G17: =H17/F17 -> 0.85 | H17: 22 | I17: =E17*H17 -> 66
A18: 13 | B18: 【鲜】净小鲫鱼 | C18: 2-3两 | D18: 斤 | E18: 15.6 | F18: =H18/0.85 -> 17.411765 | G18: =H18/F18 -> 0.85 | H18: 14.8 | I18: =E18*H18 -> 230.88
A19: 14 | B19: 卤牛肉 | D19: 斤 | E19: 5 | F19: =H19/0.85 -> 103.52941 | G19: =H19/F19 -> 0.85 | H19: 88 | I19: =E19*H19 -> 440
A20: 15 | B20: 缅甸香米25kg | C20: 25kg | D20: 袋 | E20: 1 | F20: =H20/0.85 -> 247.05882 | G20: =H20/F20 -> 0.85 | H20: 210 | I20: =E20*H20 -> 210
A21: 16 | B21: 1911老酸奶 | D21: 杯 | E21: 50 | F21: =H21/0.85 -> 4.1176471 | G21: =H21/F21 -> 0.85 | H21: 3.5 | I21: =E21*H21 -> 175
A22: 17
A23: 18
A24: 19
A25: 20
A26: 21
A27: 22
A28: 23
A29: 24
A30: 25
A31: 26
A32: 27
A33: 28
A34: 供货合计: | B34: =SUM(I6:I33) -> 1789.58
A35: 金额大写： | B35: =B34 -> 1789.58
A36: 制表人 ：樊君丽 收货人： 送货人：

Sheet 16
A1: 武汉康恩农贸发展有限公司送货单
A3: 收货单位： | B3: 汉南数智化检测分公司
A4: 配送日期： | B4: 45154
A5: 序号 | B5: 名称 | C5: 规格 | D5: 单位 | E5: 数量 | F5: 超市价格 | G5: 折扣率 | H5: 折后价 | I5: 折后金额 | J5: 备注
A6: 1 | B6: （新鲜）河粉 | D6: 斤 | E6: 4 | F6: =H6/0.85 -> 3.5294118 | G6: =H6/F6 -> 0.85 | H6: 3 | I6: =E6*H6 -> 12
A7: 2 | B7: 热干面（熟） | D7: 斤 | E7: 4 | F7: =H7/0.85 -> 4.1176471 | G7: =H7/F7 -> 0.85 | H7: 3.5 | I7: =E7*H7 -> 14
A8: 3 | B8: 生面窝浆 | D8: 斤 | E8: 3 | F8: =H8/0.85 -> 7.0588235 | G8: =H8/F8 -> 0.85 | H8: 6 | I8: =E8*H8 -> 18
A9: 4 | B9: 红椒 | D9: 斤 | E9: 3 | F9: =H9/0.85 -> 9.1764706 | G9: =H9/F9 -> 0.85 | H9: 7.8 | I9: =E9*H9 -> 23.4
A10: 5 | B10: 新鲜蒜苗 | D10: 斤 | E10: 3 | F10: =H10/0.85 -> 9.1764706 | G10: =H10/F10 -> 0.85 | H10: 7.8 | I10: =E10*H10 -> 23.4
A11: 6 | B11: 芜湖青椒 | D11: 斤 | E11: 3 | F11: =H11/0.85 -> 5.2941176 | G11: =H11/F11 -> 0.85 | H11: 4.5 | I11: =E11*H11 -> 13.5
A12: 7 | B12: 黄瓜 | D12: 斤 | E12: 15 | F12: =H12/0.85 -> 3.2941176 | G12: =H12/F12 -> 0.85 | H12: 2.8 | I12: =E12*H12 -> 42
A13: 8 | B13: 平菇 | D13: 斤 | E13: 1 | F13: =H13/0.85 -> 9.1764706 | G13: =H13/F13 -> 0.85 | H13: 7.8 | I13: =E13*H13 -> 7.8
A14: 9 | B14: 平包菜 | D14: 斤 | E14: 13 | F14: =H14/0.85 -> 2.3529412 | G14: =H14/F14 -> 0.85 | H14: 2 | I14: =E14*H14 -> 26
A15: 10 | B15: 细土芹 | D15: 斤 | E15: 5 | F15: =H15/0.85 -> 6.4705882 | G15: =H15/F15 -> 0.85 | H15: 5.5 | I15: =E15*H15 -> 27.5
A16: 11 | B16: 薄干子 | D16: 斤 | E16: 6 | F16: =H16/0.85 -> 8 | G16: =H16/F16 -> 0.85 | H16: 6.8 | I16: =E16*H16 -> 40.8
A17: 12 | B17: 嫩豆腐 | D17: 斤 | E17: 4 | F17: =H17/0.85 -> 4.1176471 | G17: =H17/F17 -> 0.85 | H17: 3.5 | I17: =E17*H17 -> 14
... A20: 15 | B20: 【鲜】净胖头鱼头 | D20: 斤 | E20: 4.5 | F20: =H20/0.85 -> 23.529412 | G20: =H20/F20 -> 0.85 | H20: 20 | I20: =E20*H20 -> 90
A21: 16 | B21: 【冻】思念白糯小汤圆（无馅） | C21: 500g*20包/件 | D21: 袋 | E21: 2 | F21: =H21/0.85 -> 10.588235 | G21: =H21/F21 -> 0.85 | H21: 9 | I21: =E21*H21 -> 18
A22: 17 | B22: 【冻】鱿鱼须 | C22: 350g | D22: 袋 | E22: 10 | F22: =H22/0.85 -> 25.882353 | G22: =H22/F22 -> 0.85 | H22: 22 | I22: =E22*H22 -> 220
A23: 18 | B23: 王牌冻基围虾 | C23: 1.4kg*10盒/件 | D23: 盒 | E23: 10 | F23: =H23/0.85 -> 88.235294 | G23: =H23/F23 -> 0.85 | H23: 75 | I23: =E23*H23 -> 750
A24: 19 | B24: 八角 | C24: 散称 | D24: 斤 | E24: 0.5 | F24: =H24/0.85 -> 56.470588 | G24: =H24/F24 -> 0.85 | H24: 48 | I24: =E24*H24 -> 24
A25: 20 | B25: 白砂糖 | D25: 斤 | E25: 5 | F25: =H25/0.85 -> 5.7647059 | G25: =H25/F25 -> 0.85 | H25: 4.9 | I25: =E25*H25 -> 24.5
A26: 21 | B26: 大桥鸡精900g | C26: 900g*10袋/件 | D26: 袋 | E26: 3 | F26: =H26/0.85 -> 42.823529 | G26: =H26/F26 -> 0.85 | H26: 36.4 | I26: =E26*H26 -> 109.2
A27: 22 | B27: 蛋糕油 | D27: 桶 | E27: 1 | F27: =H27/0.85 -> 84.705882 | G27: =H27/F27 -> 0.85 | H27: 72 | I27: =E27*H27 -> 72
A28: 23 | B28: 桂皮 | C28: 散称 | D28: 斤 | E28: 0.5 | F28: =H28/0.85 -> 32.941176 | G28: =H28/F28 -> 0.85 | H28: 28 | I28: =E28*H28 -> 14
A29: 24 | B29: 海天精制蚝油6kg | C29: 6kg*2桶 | D29: 桶 | E29: 1 | F29: =H29/0.85 -> 48.823529 | G29: =H29/F29 -> 0.85 | H29: 41.5 | I29: =E29*H29 -> 41.5
A30: 25 | B30: 鲁花压榨玉米油 | C30: 5L*4壶/件 | D30: 件 | E30: 2 | F30: =H30/0.85 -> 500 | G30: =H30/F30 -> 0.85 | H30: 425 | I30: =E30*H30 -> 850
A31: 26 | B31: 光明健能酸奶180g | C31: 180g | D31: 杯 | E31: 65 | F31: =H31/0.85 -> 4.1176471 | G31: =H31/F31 -> 0.85 | H31: 3.5 | I31: =E31*H31 -> 227.5
A32: 27
A33: 28
A34: 供货合计: | B34: =SUM(I6:I33) -> 2846.7
A35: 金额大写： | B35: =B34 -> 2846.7
A36: 制表人 ：樊君丽 收货人： 送货人：

Sheet 17
A1: 武汉康恩农贸发展有限公司送货单
A3: 收货单位： | B3: 汉南数智化检测分公司
A4: 配送日期： | B4: 45155
A5: 序号 | B5: 名称 | C5: 规格 | D5: 单位 | E5: 数量 | F5: 超市价格 | G5: 折扣率 | H5: 折后价 | I5: 折后金额 | J5: 备注
A6: 1 | B6: （新鲜）河粉 | D6: 斤 | E6: 4 | F6: =H6/0.85 -> 3.5294118 | G6: =H6/F6 -> 0.85 | H6: 3 | I6: =E6*H6 -> 12
A7: 2 | B7: 热干面（熟） | D7: 斤 | E7: 4 | F7: =H7/0.85 -> 4.1176471 | G7: =H7/F7 -> 0.85 | H7: 3.5 | I7: =E7*H7 -> 14
A8: 3 | B8: 白萝卜 | D8: 斤 | E8: 19 | F8: =H8/0.85 -> 2.3529412 | G8: =H8/F8 -> 0.85 | H8: 2 | I8: =E8*H8 -> 38
A9: 4 | B9: 胡萝卜 | D9: 斤 | E9: 9.1 | F9: =H9/0.85 -> 2.9411765 | G9: =H9/F9 -> 0.85 | H9: 2.5 | I9: =E9*H9 -> 22.75
A10: 5 | B10: 甜玉米棒 | D10: 个 | E10: 7 | F10: =H10/0.85 -> 3.5294118 | G10: =H10/F10 -> 0.85 | H10: 3 | I10: =E10*H10 -> 21
A11: 6 | B11: 西红柿 | D11: 斤 | E11: 13 | F11: =H11/0.85 -> 4.4705882 | G11: =H11/F11 -> 0.85 | H11: 3.8 | I11: =E11*H11 -> 49.4
A12: 7 | B12: 平菇 | D12: 斤 | E12: 4 | F12: =H12/0.85 -> 9.1764706 | G12: =H12/F12 -> 0.85 | H12: 7.8 | I12: =E12*H12 -> 31.2
A13: 8 | B13: 鲜香菇 | D13: 斤 | E13: 2 | F13: =H13/0.85 -> 10.352941 | G13: =H13/F13 -> 0.85 | H13: 8.8 | I13: =E13*H13 -> 17.6
A14: 9 | B14: 娃娃菜 | C14: 散装 | D14: 斤 | E14: 14 | F14: =H14/0.85 -> 6.8235294 | G14: =H14/F14 -> 0.85 | H14: 5.8 | I14: =E14*H14 -> 81.2
A15: 10 | B15: 麒麟西瓜 | D15: 斤 | E15: 49 | F15: =H15/0.85 -> 4.1176471 | G15: =H15/F15 -> 0.85 | H15: 3.5 | I15: =E15*H15 -> 171.5
A16: 11 | B16: 【鲜】五花肉沫 | D16: 斤 | E16: 2 | F16: =H16/0.85 -> 19.764706 | G16: =H16/F16 -> 0.85 | H16: 16.8 | I16: =E16*H16 -> 33.6
A17: 12 | B17: 豆沙 | C17: 1.75kg*8袋/件 | D17: 袋 | E17: 1 | F17: =H17/0.85 -> 21.176471 | G17: =H17/F17 -> 0.85 | H17: 18 | I17: =E17*H17 -> 18
A18: 13 | B18: 干红枣片 | C18: 散称 | D18: 斤 | E18: 1 | F18: =H18/0.85 -> 18.823529 | G18: =H18/F18 -> 0.85 | H18: 16 | I18: =E18*H18 -> 16
A19: 14 | B19: 老红糖（散称） | D19: 斤 | E19: 3 | F19: =H19/0.85 -> 8 | G19: =H19/F19 -> 0.85 | H19: 6.8 | I19: =E19*H19 -> 20.4
A20: 15 | B20: 烤鸭 | D20: 只 | E20: 4 | F20: =H20/0.85 -> 34.117647 | G20: =H20/F20 -> 0.85 | H20: 29 | I20: =E20*H20 -> 116
A21: 16 | B21: 1911老酸奶 | D21: 杯 | E21: 70 | F21: =H21/0.85 -> 4.1176471 | G21: =H21/F21 -> 0.85 | H21: 3.5 | I21: =E21*H21 -> 245
A22: 17
A23: 18
A24: 19
A25: 20
A26: 21
A27: 22
A28: 23
A29: 24
A30: 25
A31: 26
A32: 27
A33: 供货合计: | B33: =SUM(I6:I32) -> 907.65
A34: 金额大写： | B34: =B33 -> 907.65
A35: 制表人 ：樊君丽 收货人： 送货人：

Sheet 18
A1: 武汉康恩农贸发展有限公司送货单
A3: 收货单位： | B3: 汉南数智化检测分公司
A4: 配送日期： | B4: 45156
A5: 序号 | B5: 名称 | C5: 规格 | D5: 单位 | E5: 数量 | F5: 超市价格 | G5: 折扣率 | H5: 折后价 | I5: 折后金额 | J5: 备注
A6: 1 | B6: （新鲜）河粉 | D6: 斤 | E6: 4 | F6: =H6/0.85 -> 3.5294118 | G6: =H6/F6 -> 0.85 | H6: 3 | I6: =E6*H6 -> 12
A7: 2 | B7: 干细粉 | C7: 散称 | D7: 斤 | E7: 5 | F7: =H7/0.85 -> 4.1176471 | G7: =H7/F7 -> 0.85 | H7: 3.5 | I7: =E7*H7 -> 17.5
A8: 3 | B8: 热干面（熟） | D8: 斤 | E8: 4 | F8: =H8/0.85 -> 4.1176471 | G8: =H8/F8 -> 0.85 | H8: 3.5 | I8: =E8*H8 -> 14
A9: 4 | B9: 烧麦皮 | D9: 斤 | E9: 2 | F9: =H9/0.85 -> 4.1176471 | G9: =H9/F9 -> 0.85 | H9: 3.5 | I9: =E9*H9 -> 7
A10: 5 | B10: 大葱 | D10: 斤 | E10: 1 | F10: =H10/0.85 -> 4.1176471 | G10: =H10/F10 -> 0.85 | H10: 3.5 | I10: =E10*H10 -> 3.5
A11: 6 | B11: 红椒 | D11: 斤 | E11: 3 | F11: =H11/0.85 -> 9.1764706 | G11: =H11/F11 -> 0.85 | H11: 7.8 | I11: =E11*H11 -> 23.4
A12: 7 | B12: 铁棍山药 | D12: 斤 | E12: 2 | F12: =H12/0.85 -> 11.529412 | G12: =H12/F12 -> 0.85 | H12: 9.8 | I12: =E12*H12 -> 19.6
A13: 8 | B13: 芜湖青椒 | D13: 斤 | E13: 3 | F13: =H13/0.85 -> 5.2941176 | G13: =H13/F13 -> 0.85 | H13: 4.5 | I13: =E13*H13 -> 13.5
A14: 9 | B14: 西红柿 | D14: 斤 | E14: 6 | F14: =H14/0.85 -> 4.4705882 | G14: =H14/F14 -> 0.85 | H14: 3.8 | I14: =E14*H14 -> 22.8
A15: 10 | B15: 有机花菜 | D15: 斤 | E15: 12 | F15: =H15/0.85 -> 6.4705882 | G15: =H15/F15 -> 0.85 | H15: 5.5 | I15: =E15*H15 -> 66
A16: 11 | B16: 净莴苣 | D16: 斤 | E16: 19 | F16: =H16/0.85 -> 5.6470588 | G16: =H16/F16 -> 0.85 | H16: 4.8 | I16: =E16*H16 -> 91.2
A17: 12 | B17: 空心菜 | D17: 斤 | E17: 20 | F17: =H17/0.85 -> 4.1176471 | H17: 3.5 | I17: =E17*H17 -> 70
A18: 13 | B18: 【鲜】五花肉沫 | D18: 斤 | E18: 11 | F18: =H18/0.85 -> 19.764706 | G18: =H18/F18 -> 0.85 | H18: 16.8 | I18: =E18*H18 -> 184.8
A19: 14 | B19: 【鲜】猪脊骨 | D19: 斤 | E19: 3 | F19: =H19/0.85 -> 16.470588 | G19: =H19/F19 -> 0.85 | H19: 14 | I19: =E19*H19 -> 42
A20: 15 | B20: 【鲜】猪五花肉片 | D20: 斤 | E20: 5 | F20: =H20/0.85 -> 19.764706 | G20: =H20/F20 -> 0.85 | H20: 16.8 | I20: =E20*H20 -> 84
A21: 16 | B21: 云鹤精制碘盐 | C21: 500g*50袋/件 | D21: 袋 | E21: 10 | F21: =H21/0.85 -> 2.3529412 | G21: =H21/F21 -> 0.85 | H21: 2 | I21: =E21*H21 -> 20
A22: 17 | B22: 干黄豆 | C22: 50斤/件 | D22: 斤 | E22: 5 | F22: =H22/0.85 -> 6.4705882 | G22: =H22/F22 -> 0.85 | H22: 5.5 | I22: =E22*H22 -> 27.5
A23: 18 | B23: 正和珍珠糯米 | C23: 50斤/袋 | D23: 斤 | E23: 5 | F23: =H23/0.85 -> 5.8823529 | G23: =H23/F23 -> 0.85 | H23: 5 | I23: =E23*H23 -> 25
A24: 19 | B24: 1911老酸奶 | D24: 杯 | E24: 40 | F24: =H24/0.85 -> 4.1176471 | G24: =H24/F24 -> 0.85 | H24: 3.5 | I24: =E24*H24 -> 140
A25: 20 | B25: 伊利一杯优酪酸奶 | C25: 100g | D25: 杯 | E25: 5 | F25: =H25/0.85 -> 4.1176471 | G25: =H25/F25 -> 0.85 | H25: 3.5 | I25: =E25*H25 -> 17.5
A26: 21
A27: 22
A28: 23
A29: 24
A30: 25
A31: 26
A32: 27
A33: 28
A34: 供货合计: | B34: =SUM(I6:I33) -> 901.3
A35: 金额大写： | B35: =B34 -> 901.3
A36: 制表人 ：樊君丽 收货人： 送货人：

Sheet 20.
A1: 武汉康恩农贸发展有限公司送货单
A3: 收货单位： | B3: 汉南数智化检测分公司
A4: 配送日期： | B4: 45158
A5: 序号 | B5: 名称 | C5: 规格 | D5: 单位 | E5: 数量 | F5: 超市价格 | G5: 折扣率 | H5: 折后价 | I5: 折后金额 | J5: 备注
A6: 1 | B6: 新鲜毛豆米 | D6: 斤 | E6: 3 | F6: =H6/0.85 -> 14.117647 | G6: =H6/F6 -> 0.85 | H6: 12 | I6: =E6*H6 -> 36
A7: 2 | B7: 红椒 | D7: 斤 | E7: 2 | F7: =H7/0.85 -> 9.1764706 | G7: =H7/F7 -> 0.85 | H7: 7.8 | I7: =E7*H7 -> 15.6
A8: 3 | B8: 芜湖青椒 | D8: 斤 | E8: 2 | F8: =H8/0.85 -> 5.2941176 | G8: =H8/F8 -> 0.85 | H8: 4.5 | I8: =E8*H8 -> 9
A9: 4 | B9: 西红柿 | D9: 斤 | E9: 3 | F9: =H9/0.85 -> 4.4705882 | G9: =H9/F9 -> 0.85 | H9: 3.8 | I9: =E9*H9 -> 11.4
A10: 5 | B10: 兰州包菜 | D10: 斤 | E10: 4.3 | F10: =H10/0.85 -> 2.3529412 | G10: =H10/F10 -> 0.85 | H10: 2 | I10: =E10*H10 -> 8.6
A11: 6 | B11: 薄干子 | D11: 斤 | E11: 5 | F11: =H11/0.85 -> 8 | G11: =H11/F11 -> 0.85 | H11: 6.8 | I11: =E11*H11 -> 34
A12: 7 | B12: 【鲜】精品五花 | D12: 斤 | E12: 3 | F12: =H12/0.85 -> 22.352941 | G12: =H12/F12 -> 0.85 | H12: 19 | I12: =E12*H12 -> 57
A13: 8 | B13: 光明益生菌酸奶（原味） | C13: 100g | D13: 杯 | E13: 25 | F13: =H13/0.85 -> 1.7647059 | G13: =H13/F13 -> 0.85 | H13: 1.5 | I13: =E13*H13 -> 37.5
A14: 9
A15: 10
A16: 11
A17: 12
A18: 13
A19: 14
A20: 15
A21: 16
A22: 17
A23: 18
A24: 19
A25: 20
... A31: 26
A32: 供货合计: | B32: =SUM(I6:I31) -> 209.1
A33: 金额大写： | B33: =B32 -> 209.1
A34: 制表人 ：樊君丽 收货人： 送货人：

Sheet 21.
A1: 武汉康恩农贸发展有限公司送货单
A3: 收货单位： | B3: 汉南数智化检测分公司
A4: 配送日期： | B4: 45159
A5: 序号 | B5: 名称 | C5: 规格 | D5: 单位 | E5: 数量 | F5: 超市价格 | G5: 折扣率 | H5: 折后价 | I5: 折后金额 | J5: 备注
A6: 1 | B6: （新鲜）河粉 | D6: 斤 | E6: 4 | F6: =H6/0.85 -> 3.5294118 | G6: =H6/F6 -> 0.85 | H6: 3 | I6: =E6*H6 -> 12
A7: 2 | B7: 饺子皮 | D7: 斤 | E7: 2 | F7: =H7/0.85 -> 4.1176471 | G7: =H7/F7 -> 0.85 | H7: 3.5 | I7: =E7*H7 -> 7
A8: 3 | B8: 热干面（熟） | D8: 斤 | E8: 6 | F8: =H8/0.85 -> 4.1176471 | G8: =H8/F8 -> 0.85 | H8: 3.5 | I8: =E8*H8 -> 21
A9: 4 | B9: 红皮洋葱 | D9: 斤 | E9: 3 | F9: =H9/0.85 -> 2.9411765 | G9: =H9/F9 -> 0.85 | H9: 2.5 | I9: =E9*H9 -> 7.5
A10: 5 | B10: 蒜米 | D10: 斤 | E10: 4 | F10: =H10/0.85 -> 9.1764706 | G10: =H10/F10 -> 0.85 | H10: 7.8 | I10: =E10*H10 -> 31.2
A11: 6 | B11: 大红薯 | D11: 斤 | E11: 5 | F11: =H11/0.85 -> 4.1176471 | G11: =H11/F11 -> 0.85 | H11: 3.5 | I11: =E11*H11 -> 17.5
A12: 7 | B12: 红椒 | D12: 斤 | E12: 3 | F12: =H12/0.85 -> 9.1764706 | G12: =H12/F12 -> 0.85 | H12: 7.8 | I12: =E12*H12 -> 23.4
A13: 8 | B13: 芜湖青椒 | D13: 斤 | E13: 3 | F13: =H13/0.85 -> 5.2941176 | G13: =H13/F13 -> 0.85 | H13: 4.5 | I13: =E13*H13 -> 13.5
A14: 9 | B14: 韭菜花 | D14: 斤 | E14: 13 | F14: =H14/0.85 -> 14.117647 | G14: =H14/F14 -> 0.85 | H14: 12 | I14: =E14*H14 -> 156
A15: 10 | B15: 细土芹 | D15: 斤 | E15: 3 | F15: =H15/0.85 -> 6.4705882 | G15: =H15/F15 -> 0.85 | H15: 5.5 | I15: =E15*H15 -> 16.5
A16: 11 | B16: 油麦菜 | D16: 斤 | E16: 16 | F16: =H16/0.85 -> 4.1176471 | G16: =H16/F16 -> 0.85 | H16: 3.5 | I16: =E16*H16 -> 56
A17: 12 | B17: 嫩豆腐 | D17: 斤 | E17: 15 | F17: =H17/0.85 -> 4.1176471 | G17: =H17/F17 -> 0.85 | H17: 3.5 | I17: =E17*H17 -> 52.5
A18: 13 | B18: 红壳鸡蛋 | C18: 12板/件 | D18: 件 | E18: 1 | F18: =H18/0.85 -> 352.94118 | G18: =H18/F18 -> 0.85 | H18: 300 | I18: =E18*H18 -> 300
A19: 14 | B19: 【鲜】猪脊骨 | D19: 斤 | E19: 7 | F19: =H19/0.85 -> 16.470588 | G19: =H19/F19 -> 0.85 | H19: 14 | I19: =E19*H19 -> 98
A20: 15 | B20: 惠万家烟鸭胸 | D20: 件 | E20: 1 | F20: =H20/0.85 -> 152.94118 | G20: =H20/F20 -> 0.85 | H20: 130 | I20: =E20*H20 -> 130
A21: 16 | B21: 水发海带头 | C21: 18斤/件 | D21: 斤 | E21: 8 | F21: =H21/0.85 -> 9.4117647 | G21: =H21/F21 -> 0.85 | H21: 8 | I21: =E21*H21 -> 64
A22: 17 | B22: 卤牛肉 | D22: 斤 | E22: 5 | F22: =H22/0.85 -> 103.52941 | G22: =H22/F22 -> 0.85 | H22: 88 | I22: =E22*H22 -> 440
A23: 18 | B23: 干黄豆 | C23: 50斤/件 | D23: 斤 | E23: 5 | F23: =H23/0.85 -> 6.4705882 | G23: =H23/F23 -> 0.85 | H23: 5.5 | I23: =E23*H23 -> 27.5
A24: 19 | B24: 缅甸香米25kg | C24: 25kg | D24: 袋 | E24: 1 | F24: =H24/0.85 -> 247.05882 | G24: =H24/F24 -> 0.85 | H24: 210 | I24: =E24*H24 -> 210
A25: 20 | B25: 光明益生菌酸奶（红枣味） | C25: 100g | D25: 杯 | E25: 60 | F25: =H25/0.85 -> 1.8823529 | G25: =H25/F25 -> 0.85 | H25: 1.6 | I25: =E25*H25 -> 96
A26: 21
A27: 22
A28: 23
A29: 24
A30: 25
A31: 26
A32: 27
A33: 供货合计: | B33: =SUM(I6:I32) -> 1779.6
A34: 金额大写： | B34: =B33 -> 1779.6
A35: 制表人 ：樊君丽 收货人： 送货人：

Sheet 22
A1: 武汉康恩农贸发展有限公司送货单
A3: 收货单位： | B3: 汉南数智化检测分公司
A4: 配送日期： | B4: 45160
A5: 序号 | B5: 名称 | C5: 规格 | D5: 单位 | E5: 数量 | F5: 超市价格 | G5: 折扣率 | H5: 折后价 | I5: 折后金额 | J5: 备注
A6: 1 | B6: （新鲜）河粉 | D6: 斤 | E6: 4 | F6: =H6/0.85 -> 3.5294118 | G6: =H6/F6 -> 0.85 | H6: 3 | I6: =E6*H6 -> 12
A7: 2 | B7: 热干面（熟） | D7: 斤 | E7: 4 | F7: =H7/0.85 -> 4.1176471 | G7: =H7/F7 -> 0.85 | H7: 3.5 | I7: =E7*H7 -> 14
A8: 3 | B8: 大葱 | D8: 斤 | E8: 1 | F8: =H8/0.85 -> 4.1176471 | G8: =H8/F8 -> 0.85 | H8: 3.5 | I8: =E8*H8 -> 3.5
A9: 4 | B9: 小葱 | D9: 斤 | E9: 1 | F9: =H9/0.85 -> 8 | G9: =H9/F9 -> 0.85 | H9: 6.8 | I9: =E9*H9 -> 6.8
A10: 5 | B10: 刀豆 | D10: 斤 | E10: 14 | F10: =H10/0.85 -> 11.529412 | G10: =H10/F10 -> 0.85 | H10: 9.8 | I10: =E10*H10 -> 137.2
A11: 6 | B11: 大土豆 | D11: 斤 | E11: 16 | F11: =H11/0.85 -> 4.1176471 | G11: =H11/F11 -> 0.85 | H11: 3.5 | I11: =E11*H11 -> 56
A12: 7 | B12: 甜玉米棒 | D12: 个 | E12: 7 | F12: =H12/0.85 -> 3.5294118 | G12: =H12/F12 -> 0.85 | H12: 3 | I12: =E12*H12 -> 21
A13: 8 | B13: 老南瓜 | D13: 斤 | E13: 26 | F13: =H13/0.85 -> 2.9411765 | G13: =H13/F13 -> 0.85 | H13: 2.5 | I13: =E13*H13 -> 65
A14: 9 | B14: 平菇 | D14: 斤 | E14: 6.1 | F14: =H14/0.85 -> 11.529412 | G14: =H14/F14 -> 0.85 | H14: 9.8 | I14: =E14*H14 -> 59.78
A15: 10 | B15: 大白菜 | D15: 斤 | E15: 15 | F15: =H15/0.85 -> 2.1176471 | G15: =H15/F15 -> 0.85 | H15: 1.8 | I15: =E15*H15 -> 27
A16: 11 | B16: 熟鹌鹑蛋 | D16: 斤 | E16: 3 | F16: =H16/0.85 -> 16.235294 | G16: =H16/F16 -> 0.85 | H16: 13.8 | I16: =E16*H16 -> 41.4
A17: 12 | B17: 【鲜】猪脚 | D17: 斤 | E17: 10 | F17: =H17/0.85 -> 32.941176 | G17: =H17/F17 -> 0.85 | H17: 28 | I17: =E17*H17 -> 280
A18: 13 | B18: 安佳黄油 | D18: 斤 | E18: 1 | F18: =H18/0.85 -> 80 | G18: =H18/F18 -> 0.85 | H18: 68 | I18: =E18*H18 -> 68
A19: 14 | B19: 坛坛乡剁椒1.15kg | C19: 1.15kg*6瓶/件 | D19: 瓶 | E19: 2 | F19: =H19/0.85 -> 19.411765 | G19: =H19/F19 -> 0.85 | H19: 16.5 | I19: =E19*H19 -> 33
A20: 15 | B20: 1911老酸奶 | D20: 杯 | E20: 42 | F20: =H20/0.85 -> 4.1176471 | G20: =H20/F20 -> 0.85 | H20: 3.5 | I20: =E20*H20 -> 147
A21: 16
A22: 17
A23: 18
A24: 19
A25: 20
A26: 21
A27: 22
A28: 23
A29: 24
A30: 供货合计: | B30: =SUM(I6:I29) -> 971.68
A31: 金额大写： | B31: =B30 -> 971.68
A32: 制表人 ：樊君丽 收货人： 送货人：

Sheet 23
A1: 武汉康恩农贸发展有限公司送货单
A3: 收货单位： | B3: 汉南数智化检测分公司
A4: 配送日期： | B4: 45161
A5: 序号 | B5: 名称 | C5: 规格 | D5: 单位 | E5: 数量 | F5: 超市价格 | G5: 折扣率 | H5: 折后价 | I5: 折后金额 | J5: 备注
A6: 1 | B6: （新鲜）河粉 | D6: 斤 | E6: 4 | F6: =H6/0.85 -> 3.5294118 | G6: =H6/F6 -> 0.85 | H6: 3 | I6: =E6*H6 -> 12
A7: 2 | B7: 干细粉 | C7: 散称 | D7: 斤 | E7: 6 | F7: =H7/0.85 -> 4.1176471 | G7: =H7/F7 -> 0.85 | H7: 3.5 | I7: =E7*H7 -> 21
A8: 3 | B8: 热干面（熟） | D8: 斤 | E8: 4 | F8: =H8/0.85 -> 4.1176471 | G8: =H8/F8 -> 0.85 | H8: 3.5 | I8: =E8*H8 -> 14
A9: 4 | B9: 红椒 | D9: 斤 | E9: 4 | F9: =H9/0.85 -> 9.1764706 | G9: =H9/F9 -> 0.85 | H9: 7.8 | I9: =E9*H9 -> 31.2
A10: 5 | B10: 胡萝卜 | D10: 斤 | E10: 10.2 | F10: =H10/0.85 -> 2.9411765 | G10: =H10/F10 -> 0.85 | H10: 2.5 | I10: =E10*H10 -> 25.5
A11: 6 | B11: 铁棍山药 | D11: 斤 | E11: 19 | F11: =H11/0.85 -> 11.529412 | G11: =H11/F11 -> 0.85 | H11: 9.8 | I11: =E11*H11 -> 186.2
A12: 7 | B12: 芜湖青椒 | D12: 斤 | E12: 4 | F12: =H12/0.85 -> 5.2941176 | G12: =H12/F12 -> 0.85 | H12: 4.5 | I12: =E12*H12 -> 18
A13: 8 | B13: 黄瓜 | D13: 斤 | E13: 10.2 | F13: =H13/0.85 -> 3.2941176 | G13: =H13/F13 -> 0.85 | H13: 2.8 | I13: =E13*H13 -> 28.56
A14: 9 | B14: 金针菇 | D14: 斤 | E14: 6 | F14: =H14/0.85 -> 8 | G14: =H14/F14 -> 0.85 | H14: 6.8 | I14: =E14*H14 -> 40.8
A15: 10 | B15: 生菜 | D15: 斤 | E15: 19 | F15: =H15/0.85 -> 6.4705882 | G15: =H15/F15 -> 0.85 | H15: 5.5 | I15: =E15*H15 -> 104.5
A16: 11 | B16: 油麦菜 | D16: 斤 | E16: 4 | F16: =H16/0.85 -> 4.1176471 | G16: =H16/F16 -> 0.85 | H16: 3.5 | I16: =E16*H16 -> 14
A17: 12 | B17: 麒麟西瓜 | D17: 斤 | E17: 28 | F17: =H17/0.85 -> 4.1176471 | G17: =H17/F17 -> 0.85 | H17: 3.5 | I17: =E17*H17 -> 98
A18: 13 | B18: 【鲜】猪瘦肉丝 | D18: 斤 | E18: 8 | F18: =H18/0.85 -> 25.882353 | G18: =H18/F18 -> 0.85 | H18: 22 | I18: =E18*H18 -> 176
A19: 14 | B19: 【鲜】猪通排骨 | D19: 斤 | E19: 18 | F19: =H19/0.85 -> 30.588235 | G19: =H19/F19 -> 0.85 | H19: 26 | I19: =E19*H19 -> 468
A20: 15 | B20: 【冻】太合鸡脯肉 | C20: 9.8kg/件 | D20: 斤 | E20: 13 | F20: =H20/0.85 -> 11.529412 | G20: =H20/F20 -> 0.85 | H20: 9.8 | I20: =E20*H20 -> 127.4
A21: 16 | B21: 白砂糖 | D21: 斤 | E21: 5 | F21: =H21/0.85 -> 5.7647059 | G21: =H21/F21 -> 0.85 | H21: 4.9 | I21: =E21*H21 -> 24.5
A22: 17 | B22: 孝感米酒900g | C22: 900g*6瓶/件 | D22: 瓶 | E22: 2 | F22: =H22/0.85 -> 10 | G22: =H22/F22 -> 0.85 | H22: 8.5 | I22: =E22*H22 -> 17
A23: 18 | B23: 1911老酸奶 | D23: 杯 | E23: 65 | F23: =H23/0.85 -> 4.1176471 | G23: =H23/F23 -> 0.85 | H23: 3.5 | I23: =E23*H23 -> 227.5
A24: 19
A25: 20
A26: 21
A27: 22
A28: 23
A29: 24
A30: 25
A31: 供货合计: | B31: =SUM(I6:I30) -> 1634.16
A32: 金额大写： | B32: =B31 -> 1634.16
A33: 制表人 ：樊君丽 收货人： 送货人：

Sheet 24
A1: 武汉康恩农贸发展有限公司送货单
A3: 收货单位： | B3: 汉南数智化检测分公司
A4: 配送日期： | B4: 45162
A5: 序号 | B5: 名称 | C5: 规格 | D5: 单位 | E5: 数量 | F5: 超市价格 | G5: 折扣率 | H5: 折后价 | I5: 折后金额 | J5: 备注
A6: 1 | B6: （新鲜）河粉 | D6: 斤 | E6: 4 | F6: =H6/0.85 -> 3.5294118 | G6: =H6/F6 -> 0.85 | H6: 3 | I6: =E6*H6 -> 12
A7: 2 | B7: 热干面（熟） | D7: 斤 | E7: 4 | F7: =H7/0.85 -> 4.1176471 | G7: =H7/F7 -> 0.85 | H7: 3.5 | I7: =E7*H7 -> 14
A8: 3 | B8: 大葱 | D8: 斤 | E8: 2 | F8: =H8/0.85 -> 4.1176471 | G8: =H8/F8 -> 0.85 | H8: 3.5 | I8: =E8*H8 -> 7
A9: 4 | B9: 板栗米 | D9: 斤 | E9: 8 | F9: =H9/0.85 -> 18.823529 | G9: =H9/F9 -> 0.85 | H9: 16 | I9: =E9*H9 -> 128
A10: 5 | B10: 大红薯 | D10: 斤 | E10: 10 | F10: =H10/0.85 -> 4.1176471 | G10: =H10/F10 -> 0.85 | H10: 3.5 | I10: =E10*H10 -> 35
A11: 6 | B11: 红椒 | D11: 斤 | E11: 3 | F11: =H11/0.85 -> 9.1764706 | G11: =H11/F11 -> 0.85 | H11: 7.8 | I11: =E11*H11 -> 23.4
A12: 7 | B12: 甜玉米棒 | D12: 个 | E12: 7 | F12: =H12/0.85 -> 3.5294118 | G12: =H12/F12 -> 0.85 | H12: 3 | I12: =E12*H12 -> 21
A13: 8 | B13: 芜湖青椒 | D13: 斤 | E13: 4 | F13: =H13/0.85 -> 5.2941176 | G13: =H13/F13 -> 0.85 | H13: 4.5 | I13: =E13*H13 -> 18
A14: 9 | B14: 西红柿 | D14: 斤 | E14: 5 | F14: =H14/0.85 -> 4.4705882 | G14: =H14/F14 -> 0.85 | H14: 3.8 | I14: =E14*H14 -> 19
A15: 10 | B15: 冬瓜 | D15: 斤 | E15: 20 | F15: =H15/0.85 -> 2.9411765 | G15: =H15/F15 -> 0.85 | H15: 2.5 | I15: =E15*H15 -> 50
A16: 11 | B16: 平包菜 | D16: 斤 | E16: 18 | F16: =H16/0.85 -> 2.3529412 | G16: =H16/F16 -> 0.85 | H16: 2 | I16: =E16*H16 -> 36
A17: 12 | B17: 麒麟西瓜 | D17: 斤 | E17: 45.9 | F17: =H17/0.85 -> 4.1176471 | G17: =H17/F17 -> 0.85 | H17: 3.5 | I17: =E17*H17 -> 160.65
... A19: 14 | B19: 【鲜】五花肉沫 | D19: 斤 | E19: 8 | F19: =H19/0.85 -> 19.764706 | G19: =H19/F19 -> 0.85 | H19: 16.8 | I19: =E19*H19 -> 134.4
A20: 15 | B20: 清水笋丝 | C20: 2.5kg*6包/件 | D20: 包 | E20: 8 | F20: =H20/0.85 -> 15.929412 | G20: =H20/F20 -> 0.85 | H20: 13.54 | I20: =E20*H20 -> 108.32
A21: 16 | B21: 1911老酸奶 | D21: 杯 | E21: 50 | F21: =H21/0.85 -> 4.1176471 | G21: =H21/F21 -> 0.85 | H21: 3.5 | I21: =E21*H21 -> 175
A22: 17
A23: 18
A24: 19
A25: 20
A26: 21
A27: 22
A28: 23
A29: 24
A30: 25
A31: 26
A32: 27
A33: 供货合计: | B33: =SUM(I6:I32) -> 1279.21
A34: 金额大写： | B34: =B33 -> 1279.21
A35: 制表人 ：樊君丽 收货人： 送货人：

Sheet 25
A1: 武汉康恩农贸发展有限公司送货单
A3: 收货单位： | B3: 汉南数智化检测分公司
A4: 配送日期： | B4: 45163
A5: 序号 | B5: 名称 | C5: 规格 | D5: 单位 | E5: 数量 | F5: 超市价格 | G5: 折扣率 | H5: 折后价 | I5: 折后金额 | J5: 备注
A6: 1 | B6: （新鲜）河粉 | D6: 斤 | E6: 4 | F6: =H6/0.85 -> 3.5294118 | G6: =H6/F6 -> 0.85 | H6: 3 | I6: =E6*H6 -> 12
A7: 2 | B7: 热干面（熟） | D7: 斤 | E7: 4 | F7: =H7/0.85 -> 4.1176471 | G7: =H7/F7 -> 0.85 | H7: 3.5 | I7: =E7*H7 -> 14
A8: 3 | B8: 烧麦皮 | D8: 斤 | E8: 2 | F8: =H8/0.85 -> 4.1176471 | G8: =H8/F8 -> 0.85 | H8: 3.5 | I8: =E8*H8 -> 7
A9: 4 | B9: 生姜 | D9: 斤 | E9: 5 | F9: =H9/0.85 -> 15.058824 | G9: =H9/F9 -> 0.85 | H9: 12.8 | I9: =E9*H9 -> 64
A10: 5 | B10: 毛豆(剪好) | D10: 斤 | E10: 14 | F10: =H10/0.85 -> 8 | G10: =H10/F10 -> 0.85 | H10: 6.8 | I10: =E10*H10 -> 95.2
A11: 6 | B11: 青豆角 | D11: 斤 | E11: 6 | F11: =H11/0.85 -> 5.2941176 | G11: =H11/F11 -> 0.85 | H11: 4.5 | I11: =E11*H11 -> 27
A12: 7 | B12: 大土豆 | D12: 斤 | E12: 8 | F12: =H12/0.85 -> 4.1176471 | G12: =H12/F12 -> 0.85 | H12: 3.5 | I12: =E12*H12 -> 28
A13: 8 | B13: 红椒 | D13: 斤 | E13: 3 | F13: =H13/0.85 -> 9.1764706 | G13: =H13/F13 -> 0.85 | H13: 7.8 | I13: =E13*H13 -> 23.4
A14: 9 | B14: 芜湖青椒 | D14: 斤 | E14: 3 | F14: =H14/0.85 -> 5.2941176 | G14: =H14/F14 -> 0.85 | H14: 4.5 | I14: =E14*H14 -> 13.5
A15: 10 | B15: 有机花菜 | D15: 斤 | E15: 10 | F15: =H15/0.85 -> 6.4705882 | G15: =H15/F15 -> 0.85 | H15: 5.5 | I15: =E15*H15 -> 55
A16: 11 | B16: 青丝瓜 | D16: 斤 | E16: 5 | F16: =H16/0.85 -> 5.2941176 | G16: =H16/F16 -> 0.85 | H16: 4.5 | I16: =E16*H16 -> 22.5
A17: 12 | B17: 鲜香菇 | D17: 斤 | E17: 3 | F17: =H17/0.85 -> 10.352941 | G17: =H17/F17 -> 0.85 | H17: 8.8 | I17: =E17*H17 -> 26.4
... A21: 16 | B21: 白砂糖 | D21: 斤 | E21: 5 | F21: =H21/0.85 -> 5.7647059 | G21: =H21/F21 -> 0.85 | H21: 4.9 | I21: =E21*H21 -> 24.5
A22: 17 | B22: 海天蒸鱼豉油1.75L | C22: 1.75L*6壶/件 | D22: 壶 | E22: 3 | F22: =H22/0.85 -> 31.764706 | G22: =H22/F22 -> 0.85 | H22: 27 | I22: =E22*H22 -> 81
A23: 18 | B23: 文武酱菜外婆菜 | C23: 208g*40包/件 | D23: 包 | E23: 15 | F23: =H23/0.85 -> 4.1176471 | G23: =H23/F23 -> 0.85 | H23: 3.5 | I23: =E23*H23 -> 52.5
A24: 19 | B24: 永超榨菜 | C24: 8斤 | D24: 件 | E24: 1 | F24: =H24/0.85 -> 64.705882 | G24: =H24/F24 -> 0.85 | H24: 55 | I24: =E24*H24 -> 55
A25: 20 | B25: 缅甸香米25kg | C25: 25kg | D25: 袋 | E25: 1 | F25: =H25/0.85 -> 247.05882 | G25: =H25/F25 -> 0.85 | H25: 210 | I25: =E25*H25 -> 210
A26: 21 | B26: 1911老酸奶 | D26: 杯 | E26: 70 | F26: =H26/0.85 -> 4.1176471 | G26: =H26/F26 -> 0.85 | H26: 3.5 | I26: =E26*H26 -> 245
A27: 22
A28: 23
A29: 24
A30: 25
A31: 26
A32: 27
A33: 28
A34: 29
A35: 供货合计: | B35: =SUM(I6:I34) -> 1172.5
A36: 金额大写： | B36: =B35 -> 1172.5
A37: 制表人 ：樊君丽 收货人： 送货人：

Sheet 26
A1: 武汉康恩农贸发展有限公司送货单
A3: 收货单位： | B3: 汉南数智化检测分公司
A4: 配送日期： | B4: 45164
A5: 序号 | B5: 名称 | C5: 规格 | D5: 单位 | E5: 数量 | F5: 超市价格 | G5: 折扣率 | H5: 折后价 | I5: 折后金额 | J5: 备注
A6: 1 | B6: 西红柿 | D6: 斤 | E6: 6 | F6: =H6/0.85 -> 4.4705882 | G6: =H6/F6 -> 0.85 | H6: 3.8 | I6: =E6*H6 -> 22.8
A7: 2 | B7: 大白菜 | D7: 斤 | E7: 6.3 | F7: =H7/0.85 -> 2.1176471 | G7: =H7/F7 -> 0.85 | H7: 1.8 | I7: =E7*H7 -> 11.34
A8: 3 | B8: 芝麻酱 | C8: 散称 | D8: 斤 | E8: 2 | F8: =H8/0.85 -> 14.117647 | G8: =H8/F8 -> 0.85 | H8: 12 | I8: =E8*H8 -> 24
A9: 4
A10: 5
A11: 6
A12: 7
A13: 8
A14: 9
A15: 10
A16: 11
A17: 12
A18: 13
A19: 14
A20: 15
... A33: 28
A34: 供货合计: | B34: =SUM(I6:I33) -> 58.14
A35: 金额大写： | B35: =B34 -> 58.14
A36: 制表人 ：樊君丽 收货人： 送货人：

Sheet 27
A1: 武汉康恩农贸发展有限公司送货单
A3: 收货单位： | B3: 汉南数智化检测分公司
A4: 配送日期： | B4: 45165
A5: 序号 | B5: 名称 | C5: 规格 | D5: 单位 | E5: 数量 | F5: 超市价格 | G5: 折扣率 | H5: 折后价 | I5: 折后金额 | J5: 备注
A6: 1 | B6: 热干面（熟） | D6: 斤 | E6: 4 | F6: =H6/0.85 -> 4.1176471 | G6: =H6/F6 -> 0.85 | H6: 3.5 | I6: =E6*H6 -> 14
A7: 2
A8: 3
A9: 4
A10: 5
A11: 6
A12: 7
A13: 8
A14: 9
A15: 10
A16: 11
A17: 12
A18: 13
... A33: 28
A34: 供货合计: | B34: =SUM(I6:I33) -> 14
A35: 金额大写： | B35: =B34 -> 14
A36: 制表人 ：樊君丽 收货人： 送货人：

Sheet 28
A1: 武汉康恩农贸发展有限公司送货单
A3: 收货单位： | B3: 汉南数智化检测分公司
A4: 配送日期： | B4: 45166
A5: 序号 | B5: 名称 | C5: 规格 | D5: 单位 | E5: 数量 | F5: 超市价格 | G5: 折扣率 | H5: 折后价 | I5: 折后金额 | J5: 备注
A6: 1 | B6: （新鲜）河粉 | D6: 斤 | E6: 4 | F6: =H6/0.85 -> 3.5294118 | G6: =H6/F6 -> 0.85 | H6: 3 | I6: =E6*H6 -> 12
A7: 2 | B7: 干细粉 | C7: 散称 | D7: 斤 | E7: 6 | F7: =H7/0.85 -> 4.1176471 | G7: =H7/F7 -> 0.85 | H7: 3.5 | I7: =E7*H7 -> 21
A8: 3 | B8: 热干面（熟） | D8: 斤 | E8: 4 | F8: =H8/0.85 -> 4.1176471 | G8: =H8/F8 -> 0.85 | H8: 3.5 | I8: =E8*H8 -> 14
A9: 4 | B9: 小葱 | D9: 斤 | E9: 1 | F9: =H9/0.85 -> 8 | G9: =H9/F9 -> 0.85 | H9: 6.8 | I9: =E9*H9 -> 6.8
A10: 5 | B10: 新鲜玉米粒 | D10: 斤 | E10: 6 | F10: =H10/0.85 -> 9.4117647 | G10: =H10/F10 -> 0.85 | H10: 8 | I10: =E10*H10 -> 48
A11: 6 | B11: 红椒 | D11: 斤 | E11: 2 | F11: =H11/0.85 -> 9.1764706 | G11: =H11/F11 -> 0.85 | H11: 7.8 | I11: =E11*H11 -> 15.6
A12: 7 | B12: 胡萝卜 | D12: 斤 | E12: 8 | F12: =H12/0.85 -> 2.9411765 | G12: =H12/F12 -> 0.85 | H12: 2.5 | I12: =E12*H12 -> 20
A13: 8 | B13: 甜玉米棒 | D13: 个 | E13: 7 | F13: =H13/0.85 -> 3.5294118 | G13: =H13/F13 -> 0.85 | H13: 3 | I13: =E13*H13 -> 21
A14: 9 | B14: 芜湖青椒 | D14: 斤 | E14: 2 | F14: =H14/0.85 -> 5.2941176 | G14: =H14/F14 -> 0.85 | H14: 4.5 | I14: =E14*H14 -> 9
A15: 10 | B15: 西红柿 | D15: 斤 | E15: 5 | F15: =H15/0.85 -> 4.4705882 | G15: =H15/F15 -> 0.85 | H15: 3.8 | I15: =E15*H15 -> 19
A16: 11 | B16: 大白菜 | D16: 斤 | E16: 18 | F16: =H16/0.85 -> 2.1176471 | G16: =H16/F16 -> 0.85 | H16: 1.8 | I16: =E16*H16 -> 32.4
A17: 12 | B17: 嫩豆腐 | D17: 斤 | E17: 18 | F17: =H17/0.85 -> 4.1176471 | G17: =H17/F17 -> 0.85 | H17: 3.5 | I17: =E17*H17 -> 63
A18: 13 | B18: 红壳鸡蛋 | C18: 12板/件 | D18: 件 | E18: 1 | F18: =H18/0.85 -> 352.94118 | G18: =H18/F18 -> 0.85 | H18: 300 | I18: =E18*H18 -> 300
A19: 14 | B19: 【鲜】净麻鸭 | D19: 斤 | E19: 14 | F19: =H19/0.85 -> 25.882353 | G19: =H19/F19 -> 0.85 | H19: 22 | I19: =E19*H19 -> 308
A20: 15 | B20: 【鲜】五花肉沫 | D20: 斤 | E20: 5 | F20: =H20/0.85 -> 19.764706 | G20: =H20/F20 -> 0.85 | H20: 16.8 | I20: =E20*H20 -> 84
A21: 16 | B21: 【鲜】猪五花肉片 | D21: 斤 | E21: 3 | F21: =H21/0.85 -> 19.764706 | G21: =H21/F21 -> 0.85 | H21: 16.8 | I21: =E21*H21 -> 50.4
A22: 17 | B22: 【冻】鱿鱼须 | C22: 350g | D22: 袋 | E22: 5 | F22: =H22/0.85 -> 25.882353 | G22: =H22/F22 -> 0.85 | H22: 22 | I22: =E22*H22 -> 110
A23: 18 | B23: 旺食堂蒙古肉 | C23: 500g*24袋 | D23: 件 | E23: 1 | F23: =H23/0.85 -> 338.82353 | G23: =H23/F23 -> 0.85 | H23: 288 | I23: =E23*H23 -> 288
A24: 19 | B24: 兴昌农速冻甜青豆米 | C24: 1kg*15袋 | D24: 袋 | E24: 5 | F24: =H24/0.85 -> 18.823529 | G24: =H24/F24 -> 0.85 | H24: 16 | I24: =E24*H24 -> 80
A25: 20 | B25: 忠哥飘香猪尾 | C25: 400g*30袋 | D25: 件 | E25: 1 | F25: =H25/0.85 -> 776.47059 | G25: =H25/F25 -> 0.85 | H25: 660 | I25: =E25*H25 -> 660
A26: 21 | B26: 厨师乐加鲜味精 | C26: 2.27kg*10袋/件 | D26: 袋 | E26: 3 | F26: =H26/0.85 -> 52.941176 | G26: =H26/F26 -> 0.85 | H26: 45 | I26: =E26*H26 -> 135
A27: 22 | B27: 大桥鸡精900g | C27: 900g*10袋/件 | D27: 袋 | E27: 3 | F27: =H27/0.85 -> 42.823529 | G27: =H27/F27 -> 0.85 | H27: 36.4 | I27: =E27*H27 -> 109.2
A28: 23 | B28: 双汇王中王火腿肠 | C28: 55g*60根/件 | D28: 根 | E28: 10 | F28: =H28/0.85 -> 2.3529412 | G28: =H28/F28 -> 0.85 | H28: 2 | I28: =E28*H28 -> 20
A29: 24 | B29: 幺麻子藤椒油 | C29: 250ml*10瓶 | D29: 件 | E29: 1 | F29: =H29/0.85 -> 205.88235 | G29: =H29/F29 -> 0.85 | H29: 175 | I29: =E29*H29 -> 175
A30: 25 | B30: 芝麻酱 | C30: 散称 | D30: 斤 | E30: 11 | F30: =H30/0.85 -> 14.117647 | G30: =H30/F30 -> 0.85 | H30: 12 | I30: =E30*H30 -> 132
A31: 26 | B31: 卤牛肉 | D31: 斤 | E31: 5 | F31: =H31/0.85 -> 103.52941 | G31: =H31/F31 -> 0.85 | H31: 88 | I31: =E31*H31 -> 440
A32: 27 | B32: 1911老酸奶 | D32: 杯 | E32: 55 | F32: =H32/0.85 -> 4.1176471 | G32: =H32/F32 -> 0.85 | H32: 3.5 | I32: =E32*H32 -> 192.5
A33: 28
A34: 29
A35: 30
A36: 31
A37: 32
A38: 供货合计: | B38: =SUM(I6:I37) -> 3365.9
A39: 金额大写： | B39: =B38 -> 3365.9
A40: 制表人 ：樊君丽 收货人： 送货人：

Sheet 29
A1: 武汉康恩农贸发展有限公司送货单
A3: 收货单位： | B3: 汉南数智化检测分公司
A4: 配送日期： | B4: 45167
A5: 序号 | B5: 名称 | C5: 规格 | D5: 单位 | E5: 数量 | F5: 超市价格 | G5: 折扣率 | H5: 折后价 | I5: 折后金额 | J5: 备注
A6: 1 | B6: （新鲜）河粉 | D6: 斤 | E6: 4 | F6: =H6/0.85 -> 3.5294118 | G6: =H6/F6 -> 0.85 | H6: 3 | I6: =E6*H6 -> 12
A7: 2 | B7: 饺子皮 | D7: 斤 | E7: 4 | F7: =H7/0.85 -> 4.1176471 | G7: =H7/F7 -> 0.85 | H7: 3.5 | I7: =E7*H7 -> 14
A8: 3 | B8: 热干面（熟） | D8: 斤 | E8: 5 | F8: =H8/0.85 -> 4.1176471 | G8: =H8/F8 -> 0.85 | H8: 3.5 | I8: =E8*H8 -> 17.5
A9: 4 | B9: 大葱 | D9: 斤 | E9: 2 | F9: =H9/0.85 -> 4.1176471 | G9: =H9/F9 -> 0.85 | H9: 3.5 | I9: =E9*H9 -> 7
A10: 5 | B10: 蒜米 | D10: 斤 | E10: 4 | F10: =H10/0.85 -> 9.1764706 | G10: =H10/F10 -> 0.85 | H10: 7.8 | I10: =E10*H10 -> 31.2
A11: 6 | B11: 有机花菜 | D11: 斤 | E11: 16 | F11: =H11/0.85 -> 6.4705882 | G11: =H11/F11 -> 0.85 | H11: 5.5 | I11: =E11*H11 -> 88
A12: 7 | B12: 冬瓜 | D12: 斤 | E12: 7 | F12: =H12/0.85 -> 2.9411765 | G12: =H12/F12 -> 0.85 | H12: 2.5 | I12: =E12*H12 -> 17.5
A13: 8 | B13: 平菇 | D13: 斤 | E13: 1 | F13: =H13/0.85 -> 11.529412 | G13: =H13/F13 -> 0.85 | H13: 9.8 | I13: =E13*H13 -> 9.8
A14: 9 | B14: 韭菜 | D14: 斤 | E14: 8 | F14: =H14/0.85 -> 5.8823529 | G14: =H14/F14 -> 0.85 | H14: 5 | I14: =E14*H14 -> 40
A15: 10 | B15: 平包菜 | D15: 斤 | E15: 5 | F15: =H15/0.85 -> 2.3529412 | G15: =H15/F15 -> 0.85 | H15: 2 | I15: =E15*H15 -> 10
A16: 11 | B16: 小白菜 | D16: 斤 | E16: 18 | F16: =H16/0.85 -> 4.1176471 | G16: =H16/F16 -> 0.85 | H16: 3.5 | I16: =E16*H16 -> 63
